2018-04-16 18:45:15,065 ERROR [ERROR]: Caught exception in the launcher.
2018-04-16 18:45:15,066 ERROR [ERROR]: !=== Caught a fatal exception: ===!
2018-04-16 18:45:15,066 ERROR [ERROR]: Exception: 
list index out of range
  File "C:/Users/Ian/Documents/GitHub/Terra/launcher.py", line 8, in <module>
    Main().run()

  File "C:\Users\Ian\Documents\GitHub\Terra\terra\main.py", line 199, in run
    self.render()

  File "C:\Users\Ian\Documents\GitHub\Terra\terra\main.py", line 156, in render
    game_screen = self.current_screen.render(ui_screen)

  File "C:\Users\Ian\Documents\GitHub\Terra\terra\menu\titlescreen.py", line 39, in render
    self.main_menu.render(game_screen, ui_screen)

  File "C:\Users\Ian\Documents\GitHub\Terra\terra\menu\mainmenu.py", line 244, in render
    map_preview = draw_map_preview_from_file(container_width, container_height, option[0], asset_type=asset_type)

  File "C:\Users\Ian\Documents\GitHub\Terra\terra\map\minimap.py", line 93, in draw_map_preview_from_file
    return draw_map_preview(container_width, container_height, bitmap, pieces, teams)

  File "C:\Users\Ian\Documents\GitHub\Terra\terra\map\minimap.py", line 61, in draw_map_preview
    minimap = generate_minimap(bitmap, pieces)

  File "C:\Users\Ian\Documents\GitHub\Terra\terra\map\minimap.py", line 16, in generate_minimap
    width = len(bitmap[0])

2018-04-16 18:45:46,871 WARNING [WARN]: Caught exception while sending message 'b'[TEAM_FI][RED]None''. Retry 2 of 3.
2018-04-16 18:45:46,871 WARNING [WARN]: Caught exception while sending message 'b'[TEAM_FI][RED]None''. Retry 3 of 3.
2018-04-17 11:06:27,228 WARNING [WARN]: Caught exception while sending message 'b'[TEAM_FI][RED]None''. Retry 2 of 3.
2018-04-17 11:06:27,229 WARNING [WARN]: Caught exception while sending message 'b'[TEAM_FI][RED]None''. Retry 3 of 3.
2018-04-17 11:06:58,942 WARNING [WARN]: Caught exception while sending message 'b'[TEAM_FI][RED]None''. Retry 2 of 3.
2018-04-17 11:06:58,942 WARNING [WARN]: Caught exception while sending message 'b'[TEAM_FI][RED]None''. Retry 3 of 3.
2018-04-17 11:10:20,315 WARNING [WARN]: Caught exception while sending message 'b'[TEAM_FI][RED]None''. Retry 2 of 3.
2018-04-17 11:10:20,315 WARNING [WARN]: Caught exception while sending message 'b'[TEAM_FI][RED]None''. Retry 3 of 3.
2018-04-17 11:10:53,762 WARNING [WARN]: Caught exception while sending message 'b'[TEAM_FI][RED]None''. Retry 2 of 3.
2018-04-17 11:10:53,763 WARNING [WARN]: Caught exception while sending message 'b'[TEAM_FI][RED]None''. Retry 3 of 3.
2018-04-17 11:11:08,229 WARNING [WARN]: Caught exception while sending message 'b'[TEAM_FI][RED]None''. Retry 2 of 3.
2018-04-17 11:11:08,229 WARNING [WARN]: Caught exception while sending message 'b'[TEAM_FI][RED]None''. Retry 3 of 3.
2018-04-17 11:42:27,901 ERROR [ERROR]: Caught exception in the launcher.
2018-04-17 11:42:27,911 ERROR [ERROR]: !=== Caught a fatal exception: ===!
2018-04-17 11:42:27,911 ERROR [ERROR]: Exception: 
subsurface rectangle outside surface area
  File "C:/Users/Ian/Documents/GitHub/Terra/launcher.py", line 8, in <module>
    Main().run()

  File "C:\Users\Ian\Documents\GitHub\Terra\terra\main.py", line 199, in run
    self.render()

  File "C:\Users\Ian\Documents\GitHub\Terra\terra\main.py", line 156, in render
    game_screen = self.current_screen.render(ui_screen)

  File "C:\Users\Ian\Documents\GitHub\Terra\terra\menu\titlescreen.py", line 39, in render
    self.main_menu.render(game_screen, ui_screen)

  File "C:\Users\Ian\Documents\GitHub\Terra\terra\menu\mainmenu.py", line 214, in render
    self.tutorial.render(game_screen, ui_screen)

  File "C:\Users\Ian\Documents\GitHub\Terra\terra\menu\tutorial.py", line 51, in render
    scrolled_text = text.subsurface((0, self.scroll_pos, self.width, self.height))

2018-04-17 12:33:15,854 ERROR [ERROR]: Caught exception in the launcher.
2018-04-17 12:33:15,860 ERROR [ERROR]: !=== Caught a fatal exception: ===!
2018-04-17 12:33:15,860 ERROR [ERROR]: Exception: 
6
  File "C:/Users/Ian/Documents/GitHub/Terra/launcher.py", line 8, in <module>
    Main().run()

  File "C:\Users\Ian\Documents\GitHub\Terra\terra\main.py", line 193, in run
    self.step(event)

  File "C:\Users\Ian\Documents\GitHub\Terra\terra\main.py", line 137, in step
    INPUT_CONTROLLER.invoke_handlers(event)

  File "C:\Users\Ian\Documents\GitHub\Terra\terra\control\inputcontroller.py", line 55, in invoke_handlers
    handler()

  File "C:\Users\Ian\Documents\GitHub\Terra\terra\menu\tutorial.py", line 57, in confirm
    self.page_right()

  File "C:\Users\Ian\Documents\GitHub\Terra\terra\menu\tutorial.py", line 76, in page_right
    self.text = get_multiline_text(tutorial_strings, self.current_page, width=self.width - 24, height=self.height * 2)

  File "C:\Users\Ian\Documents\GitHub\Terra\terra\strings.py", line 506, in get_multiline_text
    string = string_type[LANGUAGE][string_name]

2018-04-17 12:34:28,923 WARNING [WARN]: Caught exception while sending message 'b'[TEAM_FI][RED]None''. Retry 2 of 3.
2018-04-17 12:34:28,923 WARNING [WARN]: Caught exception while sending message 'b'[TEAM_FI][RED]None''. Retry 3 of 3.
2018-04-17 13:05:58,857 ERROR [ERROR]: Caught exception in the launcher.
2018-04-17 13:05:58,859 ERROR [ERROR]: !=== Caught a fatal exception: ===!
2018-04-17 13:05:58,859 ERROR [ERROR]: Exception: 
subsurface rectangle outside surface area
  File "C:/Users/Ian/Documents/GitHub/Terra/launcher.py", line 8, in <module>
    Main().run()

  File "C:\Users\Ian\Documents\GitHub\Terra\terra\main.py", line 199, in run
    self.render()

  File "C:\Users\Ian\Documents\GitHub\Terra\terra\main.py", line 156, in render
    game_screen = self.current_screen.render(ui_screen)

  File "C:\Users\Ian\Documents\GitHub\Terra\terra\menu\titlescreen.py", line 39, in render
    self.main_menu.render(game_screen, ui_screen)

  File "C:\Users\Ian\Documents\GitHub\Terra\terra\menu\mainmenu.py", line 214, in render
    self.tutorial.render(game_screen, ui_screen)

  File "C:\Users\Ian\Documents\GitHub\Terra\terra\menu\tutorial.py", line 90, in render
    self.text.get_width(), text_height))

2018-04-17 13:15:36,423 ERROR [ERROR]: Caught exception in the launcher.
2018-04-17 13:15:36,425 ERROR [ERROR]: !=== Caught a fatal exception: ===!
2018-04-17 13:15:36,425 ERROR [ERROR]: Exception: 
Invalid resolution for Surface
  File "C:/Users/Ian/Documents/GitHub/Terra/launcher.py", line 8, in <module>
    Main().run()

  File "C:\Users\Ian\Documents\GitHub\Terra\terra\main.py", line 193, in run
    self.step(event)

  File "C:\Users\Ian\Documents\GitHub\Terra\terra\main.py", line 137, in step
    INPUT_CONTROLLER.invoke_handlers(event)

  File "C:\Users\Ian\Documents\GitHub\Terra\terra\control\inputcontroller.py", line 55, in invoke_handlers
    handler()

  File "C:\Users\Ian\Documents\GitHub\Terra\terra\menu\mainmenu.py", line 123, in confirm
    self.handle_menu_selection(selection)

  File "C:\Users\Ian\Documents\GitHub\Terra\terra\menu\mainmenu.py", line 160, in handle_menu_selection
    self.tutorial = Tutorial()

  File "C:\Users\Ian\Documents\GitHub\Terra\terra\menu\tutorial.py", line 28, in __init__
    self.change_page(0)

  File "C:\Users\Ian\Documents\GitHub\Terra\terra\menu\tutorial.py", line 73, in change_page
    self.text = get_multiline_text(tutorial_strings, self.current_page, width=self.width - 24, height=-1)

  File "C:\Users\Ian\Documents\GitHub\Terra\terra\strings.py", line 513, in get_multiline_text
    new_text = draw_multiline_text(string, color, background, width, height)

  File "C:\Users\Ian\Documents\GitHub\Terra\terra\util\drawingutil.py", line 55, in draw_multiline_text
    text_surface = pygame.Surface((width, height), pygame.SRCALPHA, 32)

2018-04-17 13:16:21,364 ERROR [ERROR]: Caught exception in the launcher.
2018-04-17 13:16:21,365 ERROR [ERROR]: !=== Caught a fatal exception: ===!
2018-04-17 13:16:21,365 ERROR [ERROR]: Exception: 
subsurface rectangle outside surface area
  File "C:/Users/Ian/Documents/GitHub/Terra/launcher.py", line 8, in <module>
    Main().run()

  File "C:\Users\Ian\Documents\GitHub\Terra\terra\main.py", line 199, in run
    self.render()

  File "C:\Users\Ian\Documents\GitHub\Terra\terra\main.py", line 156, in render
    game_screen = self.current_screen.render(ui_screen)

  File "C:\Users\Ian\Documents\GitHub\Terra\terra\menu\titlescreen.py", line 39, in render
    self.main_menu.render(game_screen, ui_screen)

  File "C:\Users\Ian\Documents\GitHub\Terra\terra\menu\mainmenu.py", line 214, in render
    self.tutorial.render(game_screen, ui_screen)

  File "C:\Users\Ian\Documents\GitHub\Terra\terra\menu\tutorial.py", line 90, in render
    self.text.get_width(), text_height))

2018-04-17 13:16:50,203 ERROR [ERROR]: Caught exception in the launcher.
2018-04-17 13:16:50,205 ERROR [ERROR]: !=== Caught a fatal exception: ===!
2018-04-17 13:16:50,205 ERROR [ERROR]: Exception: 
Invalid resolution for Surface
  File "C:/Users/Ian/Documents/GitHub/Terra/launcher.py", line 8, in <module>
    Main().run()

  File "C:\Users\Ian\Documents\GitHub\Terra\terra\main.py", line 193, in run
    self.step(event)

  File "C:\Users\Ian\Documents\GitHub\Terra\terra\main.py", line 137, in step
    INPUT_CONTROLLER.invoke_handlers(event)

  File "C:\Users\Ian\Documents\GitHub\Terra\terra\control\inputcontroller.py", line 55, in invoke_handlers
    handler()

  File "C:\Users\Ian\Documents\GitHub\Terra\terra\menu\mainmenu.py", line 123, in confirm
    self.handle_menu_selection(selection)

  File "C:\Users\Ian\Documents\GitHub\Terra\terra\menu\mainmenu.py", line 160, in handle_menu_selection
    self.tutorial = Tutorial()

  File "C:\Users\Ian\Documents\GitHub\Terra\terra\menu\tutorial.py", line 28, in __init__
    self.change_page(0)

  File "C:\Users\Ian\Documents\GitHub\Terra\terra\menu\tutorial.py", line 73, in change_page
    self.text = get_multiline_text(tutorial_strings, self.current_page, width=self.width - 24, height=-1)

  File "C:\Users\Ian\Documents\GitHub\Terra\terra\strings.py", line 513, in get_multiline_text
    new_text = draw_multiline_text(string, color, background, width, height)

  File "C:\Users\Ian\Documents\GitHub\Terra\terra\util\drawingutil.py", line 55, in draw_multiline_text
    text_surface = pygame.Surface((width, height), pygame.SRCALPHA, 32)

2018-04-17 13:17:00,026 ERROR [ERROR]: Caught exception in the launcher.
2018-04-17 13:17:00,028 ERROR [ERROR]: !=== Caught a fatal exception: ===!
2018-04-17 13:17:00,028 ERROR [ERROR]: Exception: 
subsurface rectangle outside surface area
  File "C:/Users/Ian/Documents/GitHub/Terra/launcher.py", line 8, in <module>
    Main().run()

  File "C:\Users\Ian\Documents\GitHub\Terra\terra\main.py", line 199, in run
    self.render()

  File "C:\Users\Ian\Documents\GitHub\Terra\terra\main.py", line 156, in render
    game_screen = self.current_screen.render(ui_screen)

  File "C:\Users\Ian\Documents\GitHub\Terra\terra\menu\titlescreen.py", line 39, in render
    self.main_menu.render(game_screen, ui_screen)

  File "C:\Users\Ian\Documents\GitHub\Terra\terra\menu\mainmenu.py", line 214, in render
    self.tutorial.render(game_screen, ui_screen)

  File "C:\Users\Ian\Documents\GitHub\Terra\terra\menu\tutorial.py", line 90, in render
    self.text.get_width(), text_height))

2018-04-17 13:19:36,547 ERROR [ERROR]: Caught exception in the launcher.
2018-04-17 13:19:36,548 ERROR [ERROR]: !=== Caught a fatal exception: ===!
2018-04-17 13:19:36,548 ERROR [ERROR]: Exception: 
subsurface rectangle outside surface area
  File "C:/Users/Ian/Documents/GitHub/Terra/launcher.py", line 8, in <module>
    Main().run()

  File "C:\Users\Ian\Documents\GitHub\Terra\terra\main.py", line 199, in run
    self.render()

  File "C:\Users\Ian\Documents\GitHub\Terra\terra\main.py", line 156, in render
    game_screen = self.current_screen.render(ui_screen)

  File "C:\Users\Ian\Documents\GitHub\Terra\terra\menu\titlescreen.py", line 39, in render
    self.main_menu.render(game_screen, ui_screen)

  File "C:\Users\Ian\Documents\GitHub\Terra\terra\menu\mainmenu.py", line 214, in render
    self.tutorial.render(game_screen, ui_screen)

  File "C:\Users\Ian\Documents\GitHub\Terra\terra\menu\tutorial.py", line 90, in render
    self.text.get_width(), text_height))

2018-04-17 13:19:55,948 ERROR [ERROR]: Caught exception in the launcher.
2018-04-17 13:19:55,950 ERROR [ERROR]: !=== Caught a fatal exception: ===!
2018-04-17 13:19:55,950 ERROR [ERROR]: Exception: 
subsurface rectangle outside surface area
  File "C:/Users/Ian/Documents/GitHub/Terra/launcher.py", line 8, in <module>
    Main().run()

  File "C:/Users/Ian/Documents/GitHub/Terra\terra\main.py", line 199, in run
    self.render()

  File "C:/Users/Ian/Documents/GitHub/Terra\terra\main.py", line 156, in render
    game_screen = self.current_screen.render(ui_screen)

  File "C:/Users/Ian/Documents/GitHub/Terra\terra\menu\titlescreen.py", line 39, in render
    self.main_menu.render(game_screen, ui_screen)

  File "C:/Users/Ian/Documents/GitHub/Terra\terra\menu\mainmenu.py", line 214, in render
    self.tutorial.render(game_screen, ui_screen)

  File "C:/Users/Ian/Documents/GitHub/Terra\terra\menu\tutorial.py", line 90, in render
    self.text.get_width(), text_height))

2018-04-17 13:20:06,753 ERROR [ERROR]: Caught exception in the launcher.
2018-04-17 13:20:06,755 ERROR [ERROR]: !=== Caught a fatal exception: ===!
2018-04-17 13:20:06,755 ERROR [ERROR]: Exception: 
subsurface rectangle outside surface area
  File "C:/Users/Ian/Documents/GitHub/Terra/launcher.py", line 8, in <module>
    Main().run()

  File "C:\Users\Ian\Documents\GitHub\Terra\terra\main.py", line 199, in run
    self.render()

  File "C:\Users\Ian\Documents\GitHub\Terra\terra\main.py", line 156, in render
    game_screen = self.current_screen.render(ui_screen)

  File "C:\Users\Ian\Documents\GitHub\Terra\terra\menu\titlescreen.py", line 39, in render
    self.main_menu.render(game_screen, ui_screen)

  File "C:\Users\Ian\Documents\GitHub\Terra\terra\menu\mainmenu.py", line 214, in render
    self.tutorial.render(game_screen, ui_screen)

  File "C:\Users\Ian\Documents\GitHub\Terra\terra\menu\tutorial.py", line 90, in render
    self.text.get_width(), text_height))

2018-04-17 13:21:04,611 ERROR [ERROR]: Caught exception in the launcher.
2018-04-17 13:21:04,613 ERROR [ERROR]: !=== Caught a fatal exception: ===!
2018-04-17 13:21:04,613 ERROR [ERROR]: Exception: 
subsurface rectangle outside surface area
  File "C:/Users/Ian/Documents/GitHub/Terra/launcher.py", line 8, in <module>
    Main().run()

  File "C:\Users\Ian\Documents\GitHub\Terra\terra\main.py", line 199, in run
    self.render()

  File "C:\Users\Ian\Documents\GitHub\Terra\terra\main.py", line 156, in render
    game_screen = self.current_screen.render(ui_screen)

  File "C:\Users\Ian\Documents\GitHub\Terra\terra\menu\titlescreen.py", line 39, in render
    self.main_menu.render(game_screen, ui_screen)

  File "C:\Users\Ian\Documents\GitHub\Terra\terra\menu\mainmenu.py", line 214, in render
    self.tutorial.render(game_screen, ui_screen)

  File "C:\Users\Ian\Documents\GitHub\Terra\terra\menu\tutorial.py", line 94, in render
    self.text.get_width(), text_height))

2018-04-17 13:22:16,413 ERROR [ERROR]: Caught exception in the launcher.
2018-04-17 13:22:16,414 ERROR [ERROR]: !=== Caught a fatal exception: ===!
2018-04-17 13:22:16,415 ERROR [ERROR]: Exception: 
subsurface rectangle outside surface area
  File "C:/Users/Ian/Documents/GitHub/Terra/launcher.py", line 8, in <module>
    Main().run()

  File "C:\Users\Ian\Documents\GitHub\Terra\terra\main.py", line 199, in run
    self.render()

  File "C:\Users\Ian\Documents\GitHub\Terra\terra\main.py", line 156, in render
    game_screen = self.current_screen.render(ui_screen)

  File "C:\Users\Ian\Documents\GitHub\Terra\terra\menu\titlescreen.py", line 39, in render
    self.main_menu.render(game_screen, ui_screen)

  File "C:\Users\Ian\Documents\GitHub\Terra\terra\menu\mainmenu.py", line 214, in render
    self.tutorial.render(game_screen, ui_screen)

  File "C:\Users\Ian\Documents\GitHub\Terra\terra\menu\tutorial.py", line 94, in render
    self.text.get_width(), text_height))

2018-04-17 13:22:21,654 ERROR [ERROR]: Caught exception in the launcher.
2018-04-17 13:22:21,656 ERROR [ERROR]: !=== Caught a fatal exception: ===!
2018-04-17 13:22:21,656 ERROR [ERROR]: Exception: 
subsurface rectangle outside surface area
  File "C:/Users/Ian/Documents/GitHub/Terra/launcher.py", line 8, in <module>
    Main().run()

  File "C:/Users/Ian/Documents/GitHub/Terra\terra\main.py", line 199, in run
    self.render()

  File "C:/Users/Ian/Documents/GitHub/Terra\terra\main.py", line 156, in render
    game_screen = self.current_screen.render(ui_screen)

  File "C:/Users/Ian/Documents/GitHub/Terra\terra\menu\titlescreen.py", line 39, in render
    self.main_menu.render(game_screen, ui_screen)

  File "C:/Users/Ian/Documents/GitHub/Terra\terra\menu\mainmenu.py", line 214, in render
    self.tutorial.render(game_screen, ui_screen)

  File "C:/Users/Ian/Documents/GitHub/Terra\terra\menu\tutorial.py", line 94, in render
    self.text.get_width(), text_height))

2018-04-17 13:42:31,270 WARNING [WARN]: Caught exception while sending message 'b'[TEAM_FI][RED]None''. Retry 2 of 3.
2018-04-17 13:42:31,270 WARNING [WARN]: Caught exception while sending message 'b'[TEAM_FI][RED]None''. Retry 3 of 3.
2018-04-17 13:45:33,280 WARNING [WARN]: Caught exception while sending message 'b'[TEAM_FI][RED]None''. Retry 2 of 3.
2018-04-17 13:45:33,280 WARNING [WARN]: Caught exception while sending message 'b'[TEAM_FI][RED]None''. Retry 3 of 3.
2018-04-17 13:46:45,953 ERROR [ERROR]: Caught exception in the launcher.
2018-04-17 13:46:45,965 ERROR [ERROR]: !=== Caught a fatal exception: ===!
2018-04-17 13:46:45,965 ERROR [ERROR]: Exception: 
7 is not a valid MouseConstant
  File "C:/Users/Ian/Documents/GitHub/Terra/launcher.py", line 8, in <module>
    Main().run()

  File "C:\Users\Ian\Documents\GitHub\Terra\terra\main.py", line 193, in run
    self.step(event)

  File "C:\Users\Ian\Documents\GitHub\Terra\terra\main.py", line 137, in step
    INPUT_CONTROLLER.invoke_handlers(event)

  File "C:\Users\Ian\Documents\GitHub\Terra\terra\control\inputcontroller.py", line 44, in invoke_handlers
    event_handlers = self.__subscribers__.get((InputAction.PRESS, translate_mouse_button(event.button)))

  File "C:\Users\Ian\Documents\GitHub\Terra\terra\control\keybindings.py", line 50, in translate_mouse_button
    button = MouseConstant(input)

  File "C:\Users\Ian\AppData\Local\Programs\Python\Python36-32\lib\enum.py", line 291, in __call__
    return cls.__new__(cls, value)

  File "C:\Users\Ian\AppData\Local\Programs\Python\Python36-32\lib\enum.py", line 533, in __new__
    return cls._missing_(value)

  File "C:\Users\Ian\AppData\Local\Programs\Python\Python36-32\lib\enum.py", line 546, in _missing_
    raise ValueError("%r is not a valid %s" % (value, cls.__name__))

2018-04-17 13:48:06,842 WARNING [WARN]: Caught exception while sending message 'b'[TEAM_FI][RED]None''. Retry 2 of 3.
2018-04-17 13:48:06,842 WARNING [WARN]: Caught exception while sending message 'b'[TEAM_FI][RED]None''. Retry 3 of 3.
2018-04-17 14:07:15,494 WARNING [WARN]: Caught exception while sending message 'b'[TEAM_FI][RED]None''. Retry 2 of 3.
2018-04-17 14:07:15,495 WARNING [WARN]: Caught exception while sending message 'b'[TEAM_FI][RED]None''. Retry 3 of 3.
2018-04-17 14:08:58,254 WARNING [WARN]: Caught exception while sending message 'b'[TEAM_FI][RED]None''. Retry 2 of 3.
2018-04-17 14:08:58,254 WARNING [WARN]: Caught exception while sending message 'b'[TEAM_FI][RED]None''. Retry 3 of 3.
2018-04-17 14:09:58,050 WARNING [WARN]: Caught exception while sending message 'b'[TEAM_FI][RED]None''. Retry 2 of 3.
2018-04-17 14:09:58,051 WARNING [WARN]: Caught exception while sending message 'b'[TEAM_FI][RED]None''. Retry 3 of 3.
2018-04-17 14:11:15,146 WARNING [WARN]: Caught exception while sending message 'b'[TEAM_FI][RED]None''. Retry 2 of 3.
2018-04-17 14:11:15,146 WARNING [WARN]: Caught exception while sending message 'b'[TEAM_FI][RED]None''. Retry 3 of 3.
2018-04-17 14:12:01,554 WARNING [WARN]: Caught exception while sending message 'b'[TEAM_FI][RED]None''. Retry 2 of 3.
2018-04-17 14:12:01,554 WARNING [WARN]: Caught exception while sending message 'b'[TEAM_FI][RED]None''. Retry 3 of 3.
2018-04-17 14:12:21,389 WARNING [WARN]: Caught exception while sending message 'b'[TEAM_FI][RED]None''. Retry 2 of 3.
2018-04-17 14:12:21,389 WARNING [WARN]: Caught exception while sending message 'b'[TEAM_FI][RED]None''. Retry 3 of 3.
2018-04-17 14:12:39,137 WARNING [WARN]: Caught exception while sending message 'b'[TEAM_FI][RED]None''. Retry 2 of 3.
2018-04-17 14:12:39,137 WARNING [WARN]: Caught exception while sending message 'b'[TEAM_FI][RED]None''. Retry 3 of 3.
2018-04-17 14:13:45,475 WARNING [WARN]: Caught exception while sending message 'b'[TEAM_FI][RED]None''. Retry 2 of 3.
2018-04-17 14:13:45,475 WARNING [WARN]: Caught exception while sending message 'b'[TEAM_FI][RED]None''. Retry 3 of 3.
2018-04-17 14:13:51,076 ERROR [ERROR]: Caught exception in the launcher.
2018-04-17 14:13:51,081 ERROR [ERROR]: !=== Caught a fatal exception: ===!
2018-04-17 14:13:51,081 ERROR [ERROR]: Exception: 
must be str, not EffectType
  File "C:/Users/Ian/Documents/GitHub/Terra/launcher.py", line 8, in <module>
    Main().run()

  File "C:\Users\Ian\Documents\GitHub\Terra\terra\main.py", line 193, in run
    self.step(event)

  File "C:\Users\Ian\Documents\GitHub\Terra\terra\main.py", line 140, in step
    EVENT_BUS.invoke_handlers(event)

  File "C:\Users\Ian\Documents\GitHub\Terra\terra\event\eventbus.py", line 46, in invoke_handlers
    handler(event)

  File "C:\Users\Ian\Documents\GitHub\Terra\terra\effects\effectsmanager.py", line 61, in create_piece_effect_from_event
    self.create_effect(event.tx, event.ty, event_type_to_effect[event.event_type], None)

  File "C:\Users\Ian\Documents\GitHub\Terra\terra\effects\effectsmanager.py", line 48, in create_effect
    self.effects.append(AnimatedEffect(self, effect_type, gx, gy, team))

  File "C:\Users\Ian\Documents\GitHub\Terra\terra\effects\animatedeffect.py", line 19, in __init__
    print("AnimatedEffect created: " + self.effect_type)

2018-04-17 14:14:01,052 WARNING [WARN]: Caught exception while sending message 'b'[TEAM_FI][RED]None''. Retry 2 of 3.
2018-04-17 14:14:01,052 WARNING [WARN]: Caught exception while sending message 'b'[TEAM_FI][RED]None''. Retry 3 of 3.
2018-04-17 14:14:50,117 WARNING [WARN]: Caught exception while sending message 'b'[TEAM_FI][RED]None''. Retry 2 of 3.
2018-04-17 14:14:50,117 WARNING [WARN]: Caught exception while sending message 'b'[TEAM_FI][RED]None''. Retry 3 of 3.
2018-04-17 14:16:08,937 WARNING [WARN]: Caught exception while sending message 'b'[TEAM_FI][RED]None''. Retry 2 of 3.
2018-04-17 14:16:08,938 WARNING [WARN]: Caught exception while sending message 'b'[TEAM_FI][RED]None''. Retry 3 of 3.
2018-04-17 14:17:16,702 WARNING [WARN]: Caught exception while sending message 'b'[TEAM_FI][RED]None''. Retry 2 of 3.
2018-04-17 14:17:16,703 WARNING [WARN]: Caught exception while sending message 'b'[TEAM_FI][RED]None''. Retry 3 of 3.
2018-04-17 14:17:53,309 WARNING [WARN]: Caught exception while sending message 'b'[TEAM_FI][RED]None''. Retry 2 of 3.
2018-04-17 14:17:53,309 WARNING [WARN]: Caught exception while sending message 'b'[TEAM_FI][RED]None''. Retry 3 of 3.
2018-04-17 14:18:18,388 WARNING [WARN]: Caught exception while sending message 'b'[TEAM_FI][RED]None''. Retry 2 of 3.
2018-04-17 14:18:18,388 WARNING [WARN]: Caught exception while sending message 'b'[TEAM_FI][RED]None''. Retry 3 of 3.
2018-04-17 14:23:17,168 WARNING [WARN]: Caught exception while sending message 'b'[TEAM_FI][RED]None''. Retry 2 of 3.
2018-04-17 14:23:17,168 WARNING [WARN]: Caught exception while sending message 'b'[TEAM_FI][RED]None''. Retry 3 of 3.
2018-04-17 14:26:01,881 WARNING [WARN]: Caught exception while sending message 'b'[TEAM_FI][RED]None''. Retry 2 of 3.
2018-04-17 14:26:01,881 WARNING [WARN]: Caught exception while sending message 'b'[TEAM_FI][RED]None''. Retry 3 of 3.
2018-04-17 14:29:54,457 WARNING [WARN]: Caught exception while sending message 'b'[TEAM_FI][RED]None''. Retry 2 of 3.
2018-04-17 14:29:54,457 WARNING [WARN]: Caught exception while sending message 'b'[TEAM_FI][RED]None''. Retry 3 of 3.
2018-04-17 14:30:21,784 WARNING [WARN]: Caught exception while sending message 'b'[TEAM_FI][RED]None''. Retry 2 of 3.
2018-04-17 14:30:21,784 WARNING [WARN]: Caught exception while sending message 'b'[TEAM_FI][RED]None''. Retry 3 of 3.
2018-04-17 14:39:20,128 WARNING [WARN]: Caught exception while sending message 'b'[TEAM_FI][RED]None''. Retry 2 of 3.
2018-04-17 14:39:20,128 WARNING [WARN]: Caught exception while sending message 'b'[TEAM_FI][RED]None''. Retry 3 of 3.
2018-04-17 14:42:21,971 WARNING [WARN]: Caught exception while sending message 'b'[TEAM_FI][RED]None''. Retry 2 of 3.
2018-04-17 14:42:21,971 WARNING [WARN]: Caught exception while sending message 'b'[TEAM_FI][RED]None''. Retry 3 of 3.
2018-04-17 14:44:41,835 WARNING [WARN]: Caught exception while sending message 'b'[TEAM_FI][RED]None''. Retry 2 of 3.
2018-04-17 14:44:41,836 WARNING [WARN]: Caught exception while sending message 'b'[TEAM_FI][RED]None''. Retry 3 of 3.
2018-04-17 14:44:43,554 ERROR [ERROR]: Caught exception in the launcher.
2018-04-17 14:44:43,559 ERROR [ERROR]: !=== Caught a fatal exception: ===!
2018-04-17 14:44:43,559 ERROR [ERROR]: Exception: 
<Manager.PIECE: 'piece'>
  File "C:/Users/Ian/Documents/GitHub/Terra/launcher.py", line 8, in <module>
    Main().run()

  File "C:\Users\Ian\Documents\GitHub\Terra\terra\main.py", line 199, in run
    self.render()

  File "C:\Users\Ian\Documents\GitHub\Terra\terra\main.py", line 156, in render
    game_screen = self.current_screen.render(ui_screen)

  File "C:\Users\Ian\Documents\GitHub\Terra\terra\screens\results.py", line 50, in render
    for piece in self.get_manager(Manager.PIECE).get_all_pieces_for_team(self.winning_team):

  File "C:\Users\Ian\Documents\GitHub\Terra\terra\engine\gamescreen.py", line 47, in get_manager
    return SESSION.get(manager_type)

  File "C:\Users\Ian\Documents\GitHub\Terra\terra\managers\session.py", line 33, in get
    return self.managers[manager_type]

2018-04-17 14:44:56,010 WARNING [WARN]: Caught exception while sending message 'b'[TEAM_FI][RED]None''. Retry 2 of 3.
2018-04-17 14:44:56,011 WARNING [WARN]: Caught exception while sending message 'b'[TEAM_FI][RED]None''. Retry 3 of 3.
2018-04-17 14:46:00,344 ERROR [ERROR]: Caught exception in the launcher.
2018-04-17 14:46:00,346 ERROR [ERROR]: !=== Caught a fatal exception: ===!
2018-04-17 14:46:00,346 ERROR [ERROR]: Exception: 
<Manager.PIECE: 'piece'>
  File "C:/Users/Ian/Documents/GitHub/Terra/launcher.py", line 8, in <module>
    Main().run()

  File "C:/Users/Ian/Documents/GitHub/Terra\terra\main.py", line 199, in run
    self.render()

  File "C:/Users/Ian/Documents/GitHub/Terra\terra\main.py", line 156, in render
    game_screen = self.current_screen.render(ui_screen)

  File "C:/Users/Ian/Documents/GitHub/Terra\terra\screens\results.py", line 50, in render
    for piece in self.get_manager(Manager.PIECE).get_all_pieces_for_team(self.winning_team):

  File "C:/Users/Ian/Documents/GitHub/Terra\terra\engine\gamescreen.py", line 47, in get_manager
    return SESSION.get(manager_type)

  File "C:/Users/Ian/Documents/GitHub/Terra\terra\managers\session.py", line 33, in get
    return self.managers[manager_type]

2018-04-17 14:47:56,520 WARNING [WARN]: Caught exception while sending message 'b'[TEAM_FI][RED]None''. Retry 2 of 3.
2018-04-17 14:47:56,520 WARNING [WARN]: Caught exception while sending message 'b'[TEAM_FI][RED]None''. Retry 3 of 3.
2018-04-17 14:47:59,997 ERROR [ERROR]: Caught exception in the launcher.
2018-04-17 14:47:59,997 ERROR [ERROR]: !=== Caught a fatal exception: ===!
2018-04-17 14:47:59,997 ERROR [ERROR]: Exception: 
<PieceType.BASE: 11>
  File "C:/Users/Ian/Documents/GitHub/Terra/launcher.py", line 8, in <module>
    Main().run()

  File "C:\Users\Ian\Documents\GitHub\Terra\terra\main.py", line 199, in run
    self.render()

  File "C:\Users\Ian\Documents\GitHub\Terra\terra\main.py", line 156, in render
    game_screen = self.current_screen.render(ui_screen)

  File "C:\Users\Ian\Documents\GitHub\Terra\terra\screens\results.py", line 51, in render
    game_screen.blit(spr_pieces[piece.piece_type].subsurface(0, 0, 24, 24), (base_x + x, base_y + 24))

2018-04-17 14:48:28,974 WARNING [WARN]: Caught exception while sending message 'b'[TEAM_FI][RED]None''. Retry 2 of 3.
2018-04-17 14:48:28,975 WARNING [WARN]: Caught exception while sending message 'b'[TEAM_FI][RED]None''. Retry 3 of 3.
2018-04-17 14:48:51,887 WARNING [WARN]: Caught exception while sending message 'b'[TEAM_FI][RED]None''. Retry 2 of 3.
2018-04-17 14:48:51,887 WARNING [WARN]: Caught exception while sending message 'b'[TEAM_FI][RED]None''. Retry 3 of 3.
2018-04-17 14:49:02,000 WARNING [WARN]: Caught exception while sending message 'b'[TEAM_FI][RED]None''. Retry 2 of 3.
2018-04-17 14:49:02,000 WARNING [WARN]: Caught exception while sending message 'b'[TEAM_FI][RED]None''. Retry 3 of 3.
2018-04-17 17:15:22,344 WARNING [WARN]: Caught exception while sending message 'b'[TEAM_FI][RED]None''. Retry 2 of 3.
2018-04-17 17:15:22,345 WARNING [WARN]: Caught exception while sending message 'b'[TEAM_FI][RED]None''. Retry 3 of 3.
2018-04-17 17:15:33,013 ERROR [ERROR]: Caught exception in the launcher.
2018-04-17 17:15:33,014 ERROR [ERROR]: !=== Caught a fatal exception: ===!
2018-04-17 17:15:33,014 ERROR [ERROR]: Exception: 
'PieceManager' object is not iterable
  File "C:/Users/Ian/Documents/GitHub/Terra/launcher.py", line 8, in <module>
    Main().run()

  File "C:\Users\Ian\Documents\GitHub\Terra\terra\main.py", line 193, in run
    self.step(event)

  File "C:\Users\Ian\Documents\GitHub\Terra\terra\main.py", line 140, in step
    EVENT_BUS.invoke_handlers(event)

  File "C:\Users\Ian\Documents\GitHub\Terra\terra\event\eventbus.py", line 46, in invoke_handlers
    handler(event)

  File "C:\Users\Ian\Documents\GitHub\Terra\terra\ai\aiplayer.py", line 26, in handle_orders_phase
    for piece in my_pieces:

2018-04-17 17:16:05,200 WARNING [WARN]: Caught exception while sending message 'b'[TEAM_FI][RED]None''. Retry 2 of 3.
2018-04-17 17:16:05,200 WARNING [WARN]: Caught exception while sending message 'b'[TEAM_FI][RED]None''. Retry 3 of 3.
2018-04-17 17:18:05,074 WARNING [WARN]: Caught exception while sending message 'b'[TEAM_FI][RED]None''. Retry 2 of 3.
2018-04-17 17:18:05,074 WARNING [WARN]: Caught exception while sending message 'b'[TEAM_FI][RED]None''. Retry 3 of 3.
2018-04-17 17:19:07,814 WARNING [WARN]: Caught exception while sending message 'b'[TEAM_FI][RED]None''. Retry 2 of 3.
2018-04-17 17:19:07,814 WARNING [WARN]: Caught exception while sending message 'b'[TEAM_FI][RED]None''. Retry 3 of 3.
2018-04-17 17:20:41,697 WARNING [WARN]: Caught exception while sending message 'b'[TEAM_FI][RED]None''. Retry 2 of 3.
2018-04-17 17:20:41,697 WARNING [WARN]: Caught exception while sending message 'b'[TEAM_FI][RED]None''. Retry 3 of 3.
2018-04-17 17:21:29,719 WARNING [WARN]: Caught exception while sending message 'b'[TEAM_FI][RED]None''. Retry 2 of 3.
2018-04-17 17:21:29,720 WARNING [WARN]: Caught exception while sending message 'b'[TEAM_FI][RED]None''. Retry 3 of 3.
2018-04-17 17:26:01,335 WARNING [WARN]: Caught exception while sending message 'b'[TEAM_FI][RED]None''. Retry 2 of 3.
2018-04-17 17:26:01,337 WARNING [WARN]: Caught exception while sending message 'b'[TEAM_FI][RED]None''. Retry 3 of 3.
2018-04-17 17:27:43,962 WARNING [WARN]: Caught exception while sending message 'b'[TEAM_FI][RED]None''. Retry 2 of 3.
2018-04-17 17:27:43,962 WARNING [WARN]: Caught exception while sending message 'b'[TEAM_FI][RED]None''. Retry 3 of 3.
2018-04-17 17:28:00,157 WARNING [WARN]: Caught exception while sending message 'b'[TEAM_FI][RED]None''. Retry 2 of 3.
2018-04-17 17:28:00,157 WARNING [WARN]: Caught exception while sending message 'b'[TEAM_FI][RED]None''. Retry 3 of 3.
2018-04-17 17:54:14,346 WARNING [WARN]: Caught exception while sending message 'b'[TEAM_FI][RED]None''. Retry 2 of 3.
2018-04-17 17:54:14,346 WARNING [WARN]: Caught exception while sending message 'b'[TEAM_FI][RED]None''. Retry 3 of 3.
2018-04-17 18:34:54,596 WARNING [WARN]: Caught exception while sending message 'b'[TEAM_FI][RED]None''. Retry 2 of 3.
2018-04-17 18:34:54,596 WARNING [WARN]: Caught exception while sending message 'b'[TEAM_FI][RED]None''. Retry 3 of 3.
2018-04-17 18:34:54,647 ERROR [ERROR]: Caught exception in the launcher.
2018-04-17 18:34:54,648 ERROR [ERROR]: !=== Caught a fatal exception: ===!
2018-04-17 18:34:54,648 ERROR [ERROR]: Exception: 
name 'PieceType' is not defined
  File "C:/Users/Ian/Documents/GitHub/Terra/launcher.py", line 8, in <module>
    Main().run()

  File "C:\Users\Ian\Documents\GitHub\Terra\terra\main.py", line 193, in run
    self.step(event)

  File "C:\Users\Ian\Documents\GitHub\Terra\terra\main.py", line 140, in step
    EVENT_BUS.invoke_handlers(event)

  File "C:\Users\Ian\Documents\GitHub\Terra\terra\event\eventbus.py", line 46, in invoke_handlers
    handler(event)

  File "C:\Users\Ian\Documents\GitHub\Terra\terra\ai\aiplayer.py", line 53, in handle_orders_phase
    tasks = self.generate_tasks()

  File "C:\Users\Ian\Documents\GitHub\Terra\terra\ai\aiplayer.py", line 42, in generate_tasks
    harvestable_coords = [coord for coord in self.map.find_tiles_by_type(TileType.RESOURCE)

  File "C:\Users\Ian\Documents\GitHub\Terra\terra\ai\aiplayer.py", line 43, in <listcomp>
    if piece_manager.get_pieces_at(coord[0], coord[1], PieceType.GENERATOR)]

2018-04-17 18:35:13,734 WARNING [WARN]: Caught exception while sending message 'b'[TEAM_FI][RED]None''. Retry 2 of 3.
2018-04-17 18:35:13,734 WARNING [WARN]: Caught exception while sending message 'b'[TEAM_FI][RED]None''. Retry 3 of 3.
2018-04-17 18:37:38,634 WARNING [WARN]: Caught exception while sending message 'b'[TEAM_FI][RED]None''. Retry 2 of 3.
2018-04-17 18:37:38,636 WARNING [WARN]: Caught exception while sending message 'b'[TEAM_FI][RED]None''. Retry 3 of 3.
2018-04-17 18:38:56,928 WARNING [WARN]: Caught exception while sending message 'b'[TEAM_FI][RED]None''. Retry 2 of 3.
2018-04-17 18:38:56,928 WARNING [WARN]: Caught exception while sending message 'b'[TEAM_FI][RED]None''. Retry 3 of 3.
2018-04-17 18:49:02,724 WARNING [WARN]: Caught exception while sending message 'b'[TEAM_FI][RED]None''. Retry 2 of 3.
2018-04-17 18:49:02,724 WARNING [WARN]: Caught exception while sending message 'b'[TEAM_FI][RED]None''. Retry 3 of 3.
2018-04-17 18:49:09,020 WARNING [WARN]: Caught exception while sending message 'b'[TEAM_FI][RED]None''. Retry 2 of 3.
2018-04-17 18:49:09,021 WARNING [WARN]: Caught exception while sending message 'b'[TEAM_FI][RED]None''. Retry 3 of 3.
2018-04-17 18:52:06,141 WARNING [WARN]: Caught exception while sending message 'b'[TEAM_FI][RED]None''. Retry 2 of 3.
2018-04-17 18:52:06,142 WARNING [WARN]: Caught exception while sending message 'b'[TEAM_FI][RED]None''. Retry 3 of 3.
2018-04-17 18:52:55,738 WARNING [WARN]: Caught exception while sending message 'b'[TEAM_FI][RED]None''. Retry 2 of 3.
2018-04-17 18:52:55,738 WARNING [WARN]: Caught exception while sending message 'b'[TEAM_FI][RED]None''. Retry 3 of 3.
2018-04-17 18:53:06,072 WARNING [WARN]: Caught exception while sending message 'b'[TEAM_FI][RED]None''. Retry 2 of 3.
2018-04-17 18:53:06,072 WARNING [WARN]: Caught exception while sending message 'b'[TEAM_FI][RED]None''. Retry 3 of 3.
2018-04-17 18:53:34,603 WARNING [WARN]: Caught exception while sending message 'b'[TEAM_FI][RED]None''. Retry 2 of 3.
2018-04-17 18:53:34,603 WARNING [WARN]: Caught exception while sending message 'b'[TEAM_FI][RED]None''. Retry 3 of 3.
2018-04-17 18:53:59,558 WARNING [WARN]: Caught exception while sending message 'b'[TEAM_FI][RED]None''. Retry 2 of 3.
2018-04-17 18:53:59,558 WARNING [WARN]: Caught exception while sending message 'b'[TEAM_FI][RED]None''. Retry 3 of 3.
2018-04-17 19:54:06,904 WARNING [WARN]: Caught exception while sending message 'b'[TEAM_FI][RED]None''. Retry 2 of 3.
2018-04-17 19:54:06,904 WARNING [WARN]: Caught exception while sending message 'b'[TEAM_FI][RED]None''. Retry 3 of 3.
2018-04-17 19:54:06,962 ERROR [ERROR]: Caught exception in the launcher.
2018-04-17 19:54:06,964 ERROR [ERROR]: !=== Caught a fatal exception: ===!
2018-04-17 19:54:06,965 ERROR [ERROR]: Exception: 
'TaskType' object is not subscriptable
  File "C:/Users/Ian/Documents/GitHub/Terra/launcher.py", line 8, in <module>
    Main().run()

  File "C:/Users/Ian/Documents/GitHub/Terra\terra\main.py", line 193, in run
    self.step(event)

  File "C:/Users/Ian/Documents/GitHub/Terra\terra\main.py", line 140, in step
    EVENT_BUS.invoke_handlers(event)

  File "C:/Users/Ian/Documents/GitHub/Terra\terra\event\eventbus.py", line 46, in invoke_handlers
    handler(event)

  File "C:/Users/Ian/Documents/GitHub/Terra\terra\ai\aiplayer.py", line 85, in handle_orders_phase
    assignments = self.assign_tasks(tasks)

  File "C:/Users/Ian/Documents/GitHub/Terra\terra\ai\aiplayer.py", line 63, in assign_tasks
    eligible_pieces = task.get_eligible_pieces_for_task(self.get_manager(Manager.PIECE))

  File "C:/Users/Ian/Documents/GitHub/Terra\terra\ai\task.py", line 43, in get_eligible_pieces_for_task
    for archetype in TaskType.task_type_to_piece_archetype[self.task_type]:

2018-04-17 19:54:51,415 WARNING [WARN]: Caught exception while sending message 'b'[TEAM_FI][RED]None''. Retry 2 of 3.
2018-04-17 19:54:51,416 WARNING [WARN]: Caught exception while sending message 'b'[TEAM_FI][RED]None''. Retry 3 of 3.
2018-04-17 20:00:53,197 WARNING [WARN]: Caught exception while sending message 'b'[TEAM_FI][RED]None''. Retry 2 of 3.
2018-04-17 20:00:53,199 WARNING [WARN]: Caught exception while sending message 'b'[TEAM_FI][RED]None''. Retry 3 of 3.
2018-04-17 20:01:37,668 WARNING [WARN]: Caught exception while sending message 'b'[TEAM_FI][RED]None''. Retry 2 of 3.
2018-04-17 20:01:37,669 WARNING [WARN]: Caught exception while sending message 'b'[TEAM_FI][RED]None''. Retry 3 of 3.
2018-04-17 20:09:00,315 WARNING [WARN]: Caught exception while sending message 'b'[TEAM_FI][RED]None''. Retry 2 of 3.
2018-04-17 20:09:00,316 WARNING [WARN]: Caught exception while sending message 'b'[TEAM_FI][RED]None''. Retry 3 of 3.
2018-04-17 20:09:46,108 WARNING [WARN]: Caught exception while sending message 'b'[TEAM_FI][RED]None''. Retry 2 of 3.
2018-04-17 20:09:46,108 WARNING [WARN]: Caught exception while sending message 'b'[TEAM_FI][RED]None''. Retry 3 of 3.
2018-04-17 20:12:51,986 WARNING [WARN]: Caught exception while sending message 'b'[TEAM_FI][RED]None''. Retry 2 of 3.
2018-04-17 20:12:51,987 WARNING [WARN]: Caught exception while sending message 'b'[TEAM_FI][RED]None''. Retry 3 of 3.
2018-04-18 11:26:41,160 WARNING [WARN]: Caught exception while sending message 'b'[TEAM_FI][RED]None''. Retry 2 of 3.
2018-04-18 11:26:41,161 WARNING [WARN]: Caught exception while sending message 'b'[TEAM_FI][RED]None''. Retry 3 of 3.
2018-04-18 11:37:50,771 WARNING [WARN]: Caught exception while sending message 'b'[TEAM_FI][RED]None''. Retry 2 of 3.
2018-04-18 11:37:50,772 WARNING [WARN]: Caught exception while sending message 'b'[TEAM_FI][RED]None''. Retry 3 of 3.
2018-04-18 11:37:50,837 ERROR [ERROR]: Caught exception in the launcher.
2018-04-18 11:37:50,849 ERROR [ERROR]: !=== Caught a fatal exception: ===!
2018-04-18 11:37:50,850 ERROR [ERROR]: Exception: 
(7, 0)
  File "C:/Users/Ian/Documents/GitHub/Terra/launcher.py", line 8, in <module>
    Main().run()

  File "C:/Users/Ian/Documents/GitHub/Terra\terra\main.py", line 193, in run
    self.step(event)

  File "C:/Users/Ian/Documents/GitHub/Terra\terra\main.py", line 140, in step
    EVENT_BUS.invoke_handlers(event)

  File "C:/Users/Ian/Documents/GitHub/Terra\terra\event\eventbus.py", line 46, in invoke_handlers
    handler(event)

  File "C:/Users/Ian/Documents/GitHub/Terra\terra\ai\aiplayer.py", line 111, in handle_orders_phase
    self.confirm_assignments(assignments)

  File "C:/Users/Ian/Documents/GitHub/Terra\terra\ai\aiplayer.py", line 88, in confirm_assignments
    self.set_order_for_task(assignment.piece, assignment.task)

  File "C:/Users/Ian/Documents/GitHub/Terra\terra\ai\aiplayer.py", line 94, in set_order_for_task
    piece.attr(Attribute.MOVEMENT_TYPE), piece.attr(Attribute.MOVEMENT_RANGE))

  File "C:/Users/Ian/Documents/GitHub/Terra\terra\ai\pathfinder.py", line 50, in get_path_to_destination
    current = came_from[current]

2018-04-18 11:38:47,441 WARNING [WARN]: Caught exception while sending message 'b'[TEAM_FI][RED]None''. Retry 2 of 3.
2018-04-18 11:38:47,443 WARNING [WARN]: Caught exception while sending message 'b'[TEAM_FI][RED]None''. Retry 3 of 3.
2018-04-18 11:40:16,344 WARNING [WARN]: Caught exception while sending message 'b'[TEAM_FI][RED]None''. Retry 2 of 3.
2018-04-18 11:40:16,345 WARNING [WARN]: Caught exception while sending message 'b'[TEAM_FI][RED]None''. Retry 3 of 3.
2018-04-18 11:43:29,747 ERROR [ERROR]: Caught exception in the launcher.
2018-04-18 11:43:29,749 ERROR [ERROR]: !=== Caught a fatal exception: ===!
2018-04-18 11:43:29,749 ERROR [ERROR]: Exception: 
(7, 0)
  File "C:/Users/Ian/Documents/GitHub/Terra/launcher.py", line 8, in <module>
    Main().run()

  File "C:/Users/Ian/Documents/GitHub/Terra\terra\main.py", line 193, in run
    self.step(event)

  File "C:/Users/Ian/Documents/GitHub/Terra\terra\main.py", line 140, in step
    EVENT_BUS.invoke_handlers(event)

  File "C:/Users/Ian/Documents/GitHub/Terra\terra\event\eventbus.py", line 46, in invoke_handlers
    handler(event)

  File "C:/Users/Ian/Documents/GitHub/Terra\terra\ai\aiplayer.py", line 111, in handle_orders_phase
    self.confirm_assignments(assignments)

  File "C:/Users/Ian/Documents/GitHub/Terra\terra\ai\aiplayer.py", line 88, in confirm_assignments
    self.set_order_for_task(assignment.piece, assignment.task)

  File "C:/Users/Ian/Documents/GitHub/Terra\terra\ai\aiplayer.py", line 94, in set_order_for_task
    piece.attr(Attribute.MOVEMENT_TYPE), piece.attr(Attribute.MOVEMENT_RANGE))

  File "C:/Users/Ian/Documents/GitHub/Terra\terra\ai\pathfinder.py", line 50, in get_path_to_destination
    current = came_from[current]

2018-04-18 11:45:33,635 WARNING [WARN]: Caught exception while sending message 'b'[TEAM_FI][RED]None''. Retry 2 of 3.
2018-04-18 11:45:33,636 WARNING [WARN]: Caught exception while sending message 'b'[TEAM_FI][RED]None''. Retry 3 of 3.
2018-04-18 11:45:33,703 ERROR [ERROR]: Caught exception in the launcher.
2018-04-18 11:45:33,705 ERROR [ERROR]: !=== Caught a fatal exception: ===!
2018-04-18 11:45:33,705 ERROR [ERROR]: Exception: 
(7, 0)
  File "C:/Users/Ian/Documents/GitHub/Terra/launcher.py", line 8, in <module>
    Main().run()

  File "C:/Users/Ian/Documents/GitHub/Terra\terra\main.py", line 193, in run
    self.step(event)

  File "C:/Users/Ian/Documents/GitHub/Terra\terra\main.py", line 140, in step
    EVENT_BUS.invoke_handlers(event)

  File "C:/Users/Ian/Documents/GitHub/Terra\terra\event\eventbus.py", line 46, in invoke_handlers
    handler(event)

  File "C:/Users/Ian/Documents/GitHub/Terra\terra\ai\aiplayer.py", line 111, in handle_orders_phase
    self.confirm_assignments(assignments)

  File "C:/Users/Ian/Documents/GitHub/Terra\terra\ai\aiplayer.py", line 88, in confirm_assignments
    self.set_order_for_task(assignment.piece, assignment.task)

  File "C:/Users/Ian/Documents/GitHub/Terra\terra\ai\aiplayer.py", line 94, in set_order_for_task
    piece.attr(Attribute.MOVEMENT_TYPE), piece.attr(Attribute.MOVEMENT_RANGE))

  File "C:/Users/Ian/Documents/GitHub/Terra\terra\ai\pathfinder.py", line 51, in get_path_to_destination
    current = came_from[current]

2018-04-18 11:46:16,717 WARNING [WARN]: Caught exception while sending message 'b'[TEAM_FI][RED]None''. Retry 2 of 3.
2018-04-18 11:46:16,718 WARNING [WARN]: Caught exception while sending message 'b'[TEAM_FI][RED]None''. Retry 3 of 3.
2018-04-18 11:46:31,537 WARNING [WARN]: Caught exception while sending message 'b'[TEAM_FI][RED]None''. Retry 2 of 3.
2018-04-18 11:46:31,538 WARNING [WARN]: Caught exception while sending message 'b'[TEAM_FI][RED]None''. Retry 3 of 3.
2018-04-18 11:52:18,385 WARNING [WARN]: Caught exception while sending message 'b'[TEAM_FI][RED]None''. Retry 2 of 3.
2018-04-18 11:52:18,385 WARNING [WARN]: Caught exception while sending message 'b'[TEAM_FI][RED]None''. Retry 3 of 3.
2018-04-18 12:04:08,716 WARNING [WARN]: Caught exception while sending message 'b'[TEAM_FI][RED]None''. Retry 2 of 3.
2018-04-18 12:04:08,718 WARNING [WARN]: Caught exception while sending message 'b'[TEAM_FI][RED]None''. Retry 3 of 3.
2018-04-18 12:06:59,593 WARNING [WARN]: Caught exception while sending message 'b'[TEAM_FI][RED]None''. Retry 2 of 3.
2018-04-18 12:06:59,595 WARNING [WARN]: Caught exception while sending message 'b'[TEAM_FI][RED]None''. Retry 3 of 3.
2018-04-18 12:11:07,670 WARNING [WARN]: Caught exception while sending message 'b'[TEAM_FI][RED]None''. Retry 2 of 3.
2018-04-18 12:11:07,671 WARNING [WARN]: Caught exception while sending message 'b'[TEAM_FI][RED]None''. Retry 3 of 3.
2018-04-18 12:14:06,504 WARNING [WARN]: Caught exception while sending message 'b'[TEAM_FI][RED]None''. Retry 2 of 3.
2018-04-18 12:14:06,505 WARNING [WARN]: Caught exception while sending message 'b'[TEAM_FI][RED]None''. Retry 3 of 3.
2018-04-18 12:14:50,345 WARNING [WARN]: Caught exception while sending message 'b'[TEAM_FI][RED]None''. Retry 2 of 3.
2018-04-18 12:14:50,345 WARNING [WARN]: Caught exception while sending message 'b'[TEAM_FI][RED]None''. Retry 3 of 3.
2018-04-18 12:18:22,744 WARNING [WARN]: Caught exception while sending message 'b'[TEAM_FI][RED]None''. Retry 2 of 3.
2018-04-18 12:18:22,744 WARNING [WARN]: Caught exception while sending message 'b'[TEAM_FI][RED]None''. Retry 3 of 3.
2018-04-18 13:03:09,117 WARNING [WARN]: Caught exception while sending message 'b'[TEAM_FI][RED]None''. Retry 2 of 3.
2018-04-18 13:03:09,118 WARNING [WARN]: Caught exception while sending message 'b'[TEAM_FI][RED]None''. Retry 3 of 3.
2018-04-18 13:08:32,845 WARNING [WARN]: Caught exception while sending message 'b'[TEAM_FI][RED]None''. Retry 2 of 3.
2018-04-18 13:08:32,846 WARNING [WARN]: Caught exception while sending message 'b'[TEAM_FI][RED]None''. Retry 3 of 3.
2018-04-18 13:10:40,927 WARNING [WARN]: Caught exception while sending message 'b'[TEAM_FI][RED]None''. Retry 2 of 3.
2018-04-18 13:10:40,927 WARNING [WARN]: Caught exception while sending message 'b'[TEAM_FI][RED]None''. Retry 3 of 3.
2018-04-18 13:27:32,084 WARNING [WARN]: Caught exception while sending message 'b'[TEAM_FI][RED]None''. Retry 2 of 3.
2018-04-18 13:27:32,084 WARNING [WARN]: Caught exception while sending message 'b'[TEAM_FI][RED]None''. Retry 3 of 3.
2018-04-18 13:27:32,109 ERROR [ERROR]: Caught exception in the launcher.
2018-04-18 13:27:32,125 ERROR [ERROR]: !=== Caught a fatal exception: ===!
2018-04-18 13:27:32,125 ERROR [ERROR]: Exception: 
expected an indented block (pathfinder.py, line 11)
  File "C:/Users/Ian/Documents/GitHub/Terra/launcher.py", line 8, in <module>
    Main().run()

  File "C:\Users\Ian\Documents\GitHub\Terra\terra\main.py", line 193, in run
    self.step(event)

  File "C:\Users\Ian\Documents\GitHub\Terra\terra\main.py", line 140, in step
    EVENT_BUS.invoke_handlers(event)

  File "C:\Users\Ian\Documents\GitHub\Terra\terra\event\eventbus.py", line 46, in invoke_handlers
    handler(event)

  File "C:\Users\Ian\Documents\GitHub\Terra\terra\main.py", line 97, in handle_menu_selections
    self.set_screen_from_mode(Mode.LOBBY, event.mapname)

  File "C:\Users\Ian\Documents\GitHub\Terra\terra\main.py", line 64, in set_screen_from_mode
    new_screen = Lobby(False, map_name, map_type)

  File "C:\Users\Ian\Documents\GitHub\Terra\terra\screens\lobby.py", line 31, in __init__
    Session.set_up_local_game(map_name, map_type)

  File "C:\Users\Ian\Documents\GitHub\Terra\terra\managers\session.py", line 45, in set_up_local_game
    SESSION.__set_up__(map_name, bitmap, pieces, teams, upgrades, meta)

  File "C:\Users\Ian\Documents\GitHub\Terra\terra\managers\session.py", line 112, in __set_up__
    from terra.piece.piecemanager import PieceManager

  File "C:\Users\Ian\Documents\GitHub\Terra\terra\piece\piecemanager.py", line 10, in <module>
    from terra.piece.piece import Piece

  File "C:\Users\Ian\Documents\GitHub\Terra\terra\piece\piece.py", line 3, in <module>
    from terra.ai.pathfinder import get_path_to_destination

2018-04-18 13:27:55,270 WARNING [WARN]: Caught exception while sending message 'b'[TEAM_FI][RED]None''. Retry 2 of 3.
2018-04-18 13:27:55,270 WARNING [WARN]: Caught exception while sending message 'b'[TEAM_FI][RED]None''. Retry 3 of 3.
2018-04-18 13:27:55,280 ERROR [ERROR]: Caught exception in the launcher.
2018-04-18 13:27:55,282 ERROR [ERROR]: !=== Caught a fatal exception: ===!
2018-04-18 13:27:55,282 ERROR [ERROR]: Exception: 
expected an indented block (pathfinder.py, line 11)
  File "C:/Users/Ian/Documents/GitHub/Terra/launcher.py", line 8, in <module>
    Main().run()

  File "C:\Users\Ian\Documents\GitHub\Terra\terra\main.py", line 193, in run
    self.step(event)

  File "C:\Users\Ian\Documents\GitHub\Terra\terra\main.py", line 140, in step
    EVENT_BUS.invoke_handlers(event)

  File "C:\Users\Ian\Documents\GitHub\Terra\terra\event\eventbus.py", line 46, in invoke_handlers
    handler(event)

  File "C:\Users\Ian\Documents\GitHub\Terra\terra\main.py", line 97, in handle_menu_selections
    self.set_screen_from_mode(Mode.LOBBY, event.mapname)

  File "C:\Users\Ian\Documents\GitHub\Terra\terra\main.py", line 64, in set_screen_from_mode
    new_screen = Lobby(False, map_name, map_type)

  File "C:\Users\Ian\Documents\GitHub\Terra\terra\screens\lobby.py", line 31, in __init__
    Session.set_up_local_game(map_name, map_type)

  File "C:\Users\Ian\Documents\GitHub\Terra\terra\managers\session.py", line 45, in set_up_local_game
    SESSION.__set_up__(map_name, bitmap, pieces, teams, upgrades, meta)

  File "C:\Users\Ian\Documents\GitHub\Terra\terra\managers\session.py", line 112, in __set_up__
    from terra.piece.piecemanager import PieceManager

  File "C:\Users\Ian\Documents\GitHub\Terra\terra\piece\piecemanager.py", line 10, in <module>
    from terra.piece.piece import Piece

  File "C:\Users\Ian\Documents\GitHub\Terra\terra\piece\piece.py", line 3, in <module>
    from terra.ai.pathfinder import get_path_to_destination

2018-04-18 13:28:07,760 WARNING [WARN]: Caught exception while sending message 'b'[TEAM_FI][RED]None''. Retry 2 of 3.
2018-04-18 13:28:07,761 WARNING [WARN]: Caught exception while sending message 'b'[TEAM_FI][RED]None''. Retry 3 of 3.
2018-04-18 13:40:42,058 WARNING [WARN]: Caught exception while sending message 'b'[TEAM_FI][RED]None''. Retry 2 of 3.
2018-04-18 13:40:42,058 WARNING [WARN]: Caught exception while sending message 'b'[TEAM_FI][RED]None''. Retry 3 of 3.
2018-04-18 13:41:18,536 WARNING [WARN]: Caught exception while sending message 'b'[TEAM_FI][RED]None''. Retry 2 of 3.
2018-04-18 13:41:18,537 WARNING [WARN]: Caught exception while sending message 'b'[TEAM_FI][RED]None''. Retry 3 of 3.
2018-04-18 13:42:05,642 WARNING [WARN]: Caught exception while sending message 'b'[TEAM_FI][RED]None''. Retry 2 of 3.
2018-04-18 13:42:05,643 WARNING [WARN]: Caught exception while sending message 'b'[TEAM_FI][RED]None''. Retry 3 of 3.
2018-04-18 13:45:28,463 WARNING [WARN]: Caught exception while sending message 'b'[TEAM_FI][RED]None''. Retry 2 of 3.
2018-04-18 13:45:28,463 WARNING [WARN]: Caught exception while sending message 'b'[TEAM_FI][RED]None''. Retry 3 of 3.
2018-04-18 13:45:49,605 WARNING [WARN]: Caught exception while sending message 'b'[TEAM_FI][RED]None''. Retry 2 of 3.
2018-04-18 13:45:49,605 WARNING [WARN]: Caught exception while sending message 'b'[TEAM_FI][RED]None''. Retry 3 of 3.
2018-04-18 13:53:54,560 WARNING [WARN]: Caught exception while sending message 'b'[TEAM_FI][RED]None''. Retry 2 of 3.
2018-04-18 13:53:54,560 WARNING [WARN]: Caught exception while sending message 'b'[TEAM_FI][RED]None''. Retry 3 of 3.
2018-04-18 13:53:59,427 ERROR [ERROR]: Caught exception in the launcher.
2018-04-18 13:53:59,428 ERROR [ERROR]: !=== Caught a fatal exception: ===!
2018-04-18 13:53:59,428 ERROR [ERROR]: Exception: 
object of type 'Piece' has no len()
  File "C:/Users/Ian/Documents/GitHub/Terra/launcher.py", line 8, in <module>
    Main().run()

  File "C:\Users\Ian\Documents\GitHub\Terra\terra\main.py", line 193, in run
    self.step(event)

  File "C:\Users\Ian\Documents\GitHub\Terra\terra\main.py", line 140, in step
    EVENT_BUS.invoke_handlers(event)

  File "C:\Users\Ian\Documents\GitHub\Terra\terra\event\eventbus.py", line 46, in invoke_handlers
    handler(event)

  File "C:\Users\Ian\Documents\GitHub\Terra\terra\ai\aiplayer.py", line 121, in handle_orders_phase
    self.confirm_assignments(assignments)

  File "C:\Users\Ian\Documents\GitHub\Terra\terra\ai\aiplayer.py", line 89, in confirm_assignments
    self.set_order_for_task(assignment.piece, assignment.task)

  File "C:\Users\Ian\Documents\GitHub\Terra\terra\ai\aiplayer.py", line 97, in set_order_for_task
    destination = piece.step_along_path(path)

  File "C:\Users\Ian\Documents\GitHub\Terra\terra\piece\piece.py", line 383, in step_along_path
    if len(self.get_manager(Manager.PIECE).get_piece_at(pdest[0], pdest[1], self.team)) == 0:

2018-04-18 13:54:55,097 WARNING [WARN]: Caught exception while sending message 'b'[TEAM_FI][RED]None''. Retry 2 of 3.
2018-04-18 13:54:55,097 WARNING [WARN]: Caught exception while sending message 'b'[TEAM_FI][RED]None''. Retry 3 of 3.
2018-04-18 13:55:08,723 ERROR [ERROR]: Caught exception in the launcher.
2018-04-18 13:55:08,724 ERROR [ERROR]: !=== Caught a fatal exception: ===!
2018-04-18 13:55:08,724 ERROR [ERROR]: Exception: 
object of type 'NoneType' has no len()
  File "C:/Users/Ian/Documents/GitHub/Terra/launcher.py", line 8, in <module>
    Main().run()

  File "C:\Users\Ian\Documents\GitHub\Terra\terra\main.py", line 193, in run
    self.step(event)

  File "C:\Users\Ian\Documents\GitHub\Terra\terra\main.py", line 140, in step
    EVENT_BUS.invoke_handlers(event)

  File "C:\Users\Ian\Documents\GitHub\Terra\terra\event\eventbus.py", line 46, in invoke_handlers
    handler(event)

  File "C:\Users\Ian\Documents\GitHub\Terra\terra\ai\aiplayer.py", line 121, in handle_orders_phase
    self.confirm_assignments(assignments)

  File "C:\Users\Ian\Documents\GitHub\Terra\terra\ai\aiplayer.py", line 89, in confirm_assignments
    self.set_order_for_task(assignment.piece, assignment.task)

  File "C:\Users\Ian\Documents\GitHub\Terra\terra\ai\aiplayer.py", line 96, in set_order_for_task
    if len(path) > 2:

2018-04-18 13:56:02,172 WARNING [WARN]: Caught exception while sending message 'b'[TEAM_FI][RED]None''. Retry 2 of 3.
2018-04-18 13:56:02,172 WARNING [WARN]: Caught exception while sending message 'b'[TEAM_FI][RED]None''. Retry 3 of 3.
2018-04-18 13:56:05,676 ERROR [ERROR]: Caught exception in the launcher.
2018-04-18 13:56:05,678 ERROR [ERROR]: !=== Caught a fatal exception: ===!
2018-04-18 13:56:05,678 ERROR [ERROR]: Exception: 
'NoneType' object is not subscriptable
  File "C:/Users/Ian/Documents/GitHub/Terra/launcher.py", line 8, in <module>
    Main().run()

  File "C:\Users\Ian\Documents\GitHub\Terra\terra\main.py", line 193, in run
    self.step(event)

  File "C:\Users\Ian\Documents\GitHub\Terra\terra\main.py", line 140, in step
    EVENT_BUS.invoke_handlers(event)

  File "C:\Users\Ian\Documents\GitHub\Terra\terra\event\eventbus.py", line 46, in invoke_handlers
    handler(event)

  File "C:\Users\Ian\Documents\GitHub\Terra\terra\ai\aiplayer.py", line 121, in handle_orders_phase
    self.confirm_assignments(assignments)

  File "C:\Users\Ian\Documents\GitHub\Terra\terra\ai\aiplayer.py", line 89, in confirm_assignments
    self.set_order_for_task(assignment.piece, assignment.task)

  File "C:\Users\Ian\Documents\GitHub\Terra\terra\ai\aiplayer.py", line 102, in set_order_for_task
    'dx': destination[0],

2018-04-18 13:56:29,443 WARNING [WARN]: Caught exception while sending message 'b'[TEAM_FI][RED]None''. Retry 2 of 3.
2018-04-18 13:56:29,446 WARNING [WARN]: Caught exception while sending message 'b'[TEAM_FI][RED]None''. Retry 3 of 3.
2018-04-18 13:56:29,467 ERROR [ERROR]: Caught exception in the launcher.
2018-04-18 13:56:29,473 ERROR [ERROR]: !=== Caught a fatal exception: ===!
2018-04-18 13:56:29,473 ERROR [ERROR]: Exception: 
invalid syntax (aiplayer.py, line 96)
  File "C:/Users/Ian/Documents/GitHub/Terra/launcher.py", line 8, in <module>
    Main().run()

  File "C:/Users/Ian/Documents/GitHub/Terra\terra\main.py", line 193, in run
    self.step(event)

  File "C:/Users/Ian/Documents/GitHub/Terra\terra\main.py", line 140, in step
    EVENT_BUS.invoke_handlers(event)

  File "C:/Users/Ian/Documents/GitHub/Terra\terra\event\eventbus.py", line 46, in invoke_handlers
    handler(event)

  File "C:/Users/Ian/Documents/GitHub/Terra\terra\main.py", line 97, in handle_menu_selections
    self.set_screen_from_mode(Mode.LOBBY, event.mapname)

  File "C:/Users/Ian/Documents/GitHub/Terra\terra\main.py", line 64, in set_screen_from_mode
    new_screen = Lobby(False, map_name, map_type)

  File "C:/Users/Ian/Documents/GitHub/Terra\terra\screens\lobby.py", line 31, in __init__
    Session.set_up_local_game(map_name, map_type)

  File "C:/Users/Ian/Documents/GitHub/Terra\terra\managers\session.py", line 45, in set_up_local_game
    SESSION.__set_up__(map_name, bitmap, pieces, teams, upgrades, meta)

  File "C:/Users/Ian/Documents/GitHub/Terra\terra\managers\session.py", line 113, in __set_up__
    from terra.team.playermanager import PlayerManager

  File "C:/Users/Ian/Documents/GitHub/Terra\terra\team\playermanager.py", line 8, in <module>
    from terra.ai.aiplayer import AIPlayer

2018-04-18 13:57:13,633 WARNING [WARN]: Caught exception while sending message 'b'[TEAM_FI][RED]None''. Retry 2 of 3.
2018-04-18 13:57:13,635 WARNING [WARN]: Caught exception while sending message 'b'[TEAM_FI][RED]None''. Retry 3 of 3.
2018-04-18 13:57:13,785 ERROR [ERROR]: Caught exception in the launcher.
2018-04-18 13:57:13,787 ERROR [ERROR]: !=== Caught a fatal exception: ===!
2018-04-18 13:57:13,787 ERROR [ERROR]: Exception: 
'NoneType' object is not subscriptable
  File "C:/Users/Ian/Documents/GitHub/Terra/launcher.py", line 8, in <module>
    Main().run()

  File "C:/Users/Ian/Documents/GitHub/Terra\terra\main.py", line 193, in run
    self.step(event)

  File "C:/Users/Ian/Documents/GitHub/Terra\terra\main.py", line 140, in step
    EVENT_BUS.invoke_handlers(event)

  File "C:/Users/Ian/Documents/GitHub/Terra\terra\event\eventbus.py", line 46, in invoke_handlers
    handler(event)

  File "C:/Users/Ian/Documents/GitHub/Terra\terra\ai\aiplayer.py", line 121, in handle_orders_phase
    self.confirm_assignments(assignments)

  File "C:/Users/Ian/Documents/GitHub/Terra\terra\ai\aiplayer.py", line 89, in confirm_assignments
    self.set_order_for_task(assignment.piece, assignment.task)

  File "C:/Users/Ian/Documents/GitHub/Terra\terra\ai\aiplayer.py", line 102, in set_order_for_task
    'dx': destination[0],

2018-04-18 13:58:06,732 WARNING [WARN]: Caught exception while sending message 'b'[TEAM_FI][RED]None''. Retry 2 of 3.
2018-04-18 13:58:06,732 WARNING [WARN]: Caught exception while sending message 'b'[TEAM_FI][RED]None''. Retry 3 of 3.
2018-04-18 13:58:51,887 WARNING [WARN]: Caught exception while sending message 'b'[TEAM_FI][RED]None''. Retry 2 of 3.
2018-04-18 13:58:51,889 WARNING [WARN]: Caught exception while sending message 'b'[TEAM_FI][RED]None''. Retry 3 of 3.
2018-04-18 14:00:27,377 WARNING [WARN]: Caught exception while sending message 'b'[TEAM_FI][RED]None''. Retry 2 of 3.
2018-04-18 14:00:27,377 WARNING [WARN]: Caught exception while sending message 'b'[TEAM_FI][RED]None''. Retry 3 of 3.
2018-04-18 14:01:00,845 ERROR [ERROR]: Caught exception in the launcher.
2018-04-18 14:01:00,846 ERROR [ERROR]: !=== Caught a fatal exception: ===!
2018-04-18 14:01:00,846 ERROR [ERROR]: Exception: 
'NoneType' object is not subscriptable
  File "C:/Users/Ian/Documents/GitHub/Terra/launcher.py", line 8, in <module>
    Main().run()

  File "C:\Users\Ian\Documents\GitHub\Terra\terra\main.py", line 193, in run
    self.step(event)

  File "C:\Users\Ian\Documents\GitHub\Terra\terra\main.py", line 140, in step
    EVENT_BUS.invoke_handlers(event)

  File "C:\Users\Ian\Documents\GitHub\Terra\terra\event\eventbus.py", line 46, in invoke_handlers
    handler(event)

  File "C:\Users\Ian\Documents\GitHub\Terra\terra\ai\aiplayer.py", line 125, in handle_orders_phase
    self.confirm_assignments(assignments)

  File "C:\Users\Ian\Documents\GitHub\Terra\terra\ai\aiplayer.py", line 89, in confirm_assignments
    self.set_order_for_task(assignment.piece, assignment.task)

  File "C:\Users\Ian\Documents\GitHub\Terra\terra\ai\aiplayer.py", line 103, in set_order_for_task
    'dx': destination[0],

2018-04-18 14:01:21,356 WARNING [WARN]: Caught exception while sending message 'b'[TEAM_FI][RED]None''. Retry 2 of 3.
2018-04-18 14:01:21,356 WARNING [WARN]: Caught exception while sending message 'b'[TEAM_FI][RED]None''. Retry 3 of 3.
2018-04-18 14:01:41,494 WARNING [WARN]: Caught exception while sending message 'b'[TEAM_FI][RED]None''. Retry 2 of 3.
2018-04-18 14:01:41,494 WARNING [WARN]: Caught exception while sending message 'b'[TEAM_FI][RED]None''. Retry 3 of 3.
2018-04-18 14:02:33,818 ERROR [ERROR]: Caught exception in the launcher.
2018-04-18 14:02:33,821 ERROR [ERROR]: !=== Caught a fatal exception: ===!
2018-04-18 14:02:33,821 ERROR [ERROR]: Exception: 
'NoneType' object is not subscriptable
  File "C:/Users/Ian/Documents/GitHub/Terra/launcher.py", line 8, in <module>
    Main().run()

  File "C:/Users/Ian/Documents/GitHub/Terra\terra\main.py", line 193, in run
    self.step(event)

  File "C:/Users/Ian/Documents/GitHub/Terra\terra\main.py", line 140, in step
    EVENT_BUS.invoke_handlers(event)

  File "C:/Users/Ian/Documents/GitHub/Terra\terra\event\eventbus.py", line 46, in invoke_handlers
    handler(event)

  File "C:/Users/Ian/Documents/GitHub/Terra\terra\ai\aiplayer.py", line 125, in handle_orders_phase
    self.confirm_assignments(assignments)

  File "C:/Users/Ian/Documents/GitHub/Terra\terra\ai\aiplayer.py", line 89, in confirm_assignments
    self.set_order_for_task(assignment.piece, assignment.task)

  File "C:/Users/Ian/Documents/GitHub/Terra\terra\ai\aiplayer.py", line 103, in set_order_for_task
    'dx': destination[0],

2018-04-18 14:03:57,342 WARNING [WARN]: Caught exception while sending message 'b'[TEAM_FI][RED]None''. Retry 2 of 3.
2018-04-18 14:03:57,342 WARNING [WARN]: Caught exception while sending message 'b'[TEAM_FI][RED]None''. Retry 3 of 3.
2018-04-18 14:04:00,914 WARNING [WARN]: Caught exception while sending message 'b'[TEAM_FI][RED]None''. Retry 2 of 3.
2018-04-18 14:04:00,914 WARNING [WARN]: Caught exception while sending message 'b'[TEAM_FI][RED]None''. Retry 3 of 3.
2018-04-18 14:07:09,748 WARNING [WARN]: Caught exception while sending message 'b'[TEAM_FI][RED]None''. Retry 2 of 3.
2018-04-18 14:07:09,748 WARNING [WARN]: Caught exception while sending message 'b'[TEAM_FI][RED]None''. Retry 3 of 3.
2018-04-18 14:08:04,064 WARNING [WARN]: Caught exception while sending message 'b'[TEAM_FI][RED]None''. Retry 2 of 3.
2018-04-18 14:08:04,064 WARNING [WARN]: Caught exception while sending message 'b'[TEAM_FI][RED]None''. Retry 3 of 3.
2018-04-18 14:08:27,961 WARNING [WARN]: Caught exception while sending message 'b'[TEAM_FI][RED]None''. Retry 2 of 3.
2018-04-18 14:08:27,962 WARNING [WARN]: Caught exception while sending message 'b'[TEAM_FI][RED]None''. Retry 3 of 3.
2018-04-18 14:08:36,454 WARNING [WARN]: Caught exception while sending message 'b'[TEAM_FI][RED]None''. Retry 2 of 3.
2018-04-18 14:08:36,454 WARNING [WARN]: Caught exception while sending message 'b'[TEAM_FI][RED]None''. Retry 3 of 3.
2018-04-18 14:09:03,676 WARNING [WARN]: Caught exception while sending message 'b'[TEAM_FI][RED]None''. Retry 2 of 3.
2018-04-18 14:09:03,676 WARNING [WARN]: Caught exception while sending message 'b'[TEAM_FI][RED]None''. Retry 3 of 3.
2018-04-18 14:11:02,188 WARNING [WARN]: Caught exception while sending message 'b'[TEAM_FI][RED]None''. Retry 2 of 3.
2018-04-18 14:11:02,189 WARNING [WARN]: Caught exception while sending message 'b'[TEAM_FI][RED]None''. Retry 3 of 3.
2018-04-18 14:11:46,398 WARNING [WARN]: Caught exception while sending message 'b'[TEAM_FI][RED]None''. Retry 2 of 3.
2018-04-18 14:11:46,398 WARNING [WARN]: Caught exception while sending message 'b'[TEAM_FI][RED]None''. Retry 3 of 3.
2018-04-18 14:13:47,800 WARNING [WARN]: Caught exception while sending message 'b'[TEAM_FI][RED]None''. Retry 2 of 3.
2018-04-18 14:13:47,800 WARNING [WARN]: Caught exception while sending message 'b'[TEAM_FI][RED]None''. Retry 3 of 3.
2018-04-18 14:13:58,356 WARNING [WARN]: Caught exception while sending message 'b'[TEAM_FI][RED]None''. Retry 2 of 3.
2018-04-18 14:13:58,356 WARNING [WARN]: Caught exception while sending message 'b'[TEAM_FI][RED]None''. Retry 3 of 3.
2018-04-18 14:14:51,577 WARNING [WARN]: Caught exception while sending message 'b'[TEAM_FI][RED]None''. Retry 2 of 3.
2018-04-18 14:14:51,577 WARNING [WARN]: Caught exception while sending message 'b'[TEAM_FI][RED]None''. Retry 3 of 3.
2018-04-18 14:14:58,628 WARNING [WARN]: Caught exception while sending message 'b'[TEAM_FI][RED]None''. Retry 2 of 3.
2018-04-18 14:14:58,628 WARNING [WARN]: Caught exception while sending message 'b'[TEAM_FI][RED]None''. Retry 3 of 3.
2018-04-18 14:15:37,685 WARNING [WARN]: Caught exception while sending message 'b'[TEAM_FI][RED]None''. Retry 2 of 3.
2018-04-18 14:15:37,685 WARNING [WARN]: Caught exception while sending message 'b'[TEAM_FI][RED]None''. Retry 3 of 3.
2018-04-18 14:15:45,084 WARNING [WARN]: Caught exception while sending message 'b'[TEAM_FI][RED]None''. Retry 2 of 3.
2018-04-18 14:15:45,084 WARNING [WARN]: Caught exception while sending message 'b'[TEAM_FI][RED]None''. Retry 3 of 3.
2018-04-18 14:17:34,206 WARNING [WARN]: Caught exception while sending message 'b'[TEAM_FI][RED]None''. Retry 2 of 3.
2018-04-18 14:17:34,206 WARNING [WARN]: Caught exception while sending message 'b'[TEAM_FI][RED]None''. Retry 3 of 3.
2018-04-18 14:17:59,938 WARNING [WARN]: Caught exception while sending message 'b'[TEAM_FI][RED]None''. Retry 2 of 3.
2018-04-18 14:17:59,939 WARNING [WARN]: Caught exception while sending message 'b'[TEAM_FI][RED]None''. Retry 3 of 3.
2018-04-18 14:18:15,800 WARNING [WARN]: Caught exception while sending message 'b'[TEAM_FI][RED]None''. Retry 2 of 3.
2018-04-18 14:18:15,800 WARNING [WARN]: Caught exception while sending message 'b'[TEAM_FI][RED]None''. Retry 3 of 3.
2018-04-18 14:23:24,632 WARNING [WARN]: Caught exception while sending message 'b'[TEAM_FI][RED]None''. Retry 2 of 3.
2018-04-18 14:23:24,633 WARNING [WARN]: Caught exception while sending message 'b'[TEAM_FI][RED]None''. Retry 3 of 3.
2018-04-18 14:24:13,743 WARNING [WARN]: Caught exception while sending message 'b'[TEAM_FI][RED]None''. Retry 2 of 3.
2018-04-18 14:24:13,743 WARNING [WARN]: Caught exception while sending message 'b'[TEAM_FI][RED]None''. Retry 3 of 3.
2018-04-18 14:24:30,875 WARNING [WARN]: Caught exception while sending message 'b'[TEAM_FI][RED]None''. Retry 2 of 3.
2018-04-18 14:24:30,875 WARNING [WARN]: Caught exception while sending message 'b'[TEAM_FI][RED]None''. Retry 3 of 3.
2018-04-18 14:25:12,789 WARNING [WARN]: Caught exception while sending message 'b'[TEAM_FI][RED]None''. Retry 2 of 3.
2018-04-18 14:25:12,789 WARNING [WARN]: Caught exception while sending message 'b'[TEAM_FI][RED]None''. Retry 3 of 3.
2018-04-18 14:27:00,772 WARNING [WARN]: Caught exception while sending message 'b'[TEAM_FI][RED]None''. Retry 2 of 3.
2018-04-18 14:27:00,772 WARNING [WARN]: Caught exception while sending message 'b'[TEAM_FI][RED]None''. Retry 3 of 3.
2018-04-18 14:28:39,840 WARNING [WARN]: Caught exception while sending message 'b'[TEAM_FI][RED]None''. Retry 2 of 3.
2018-04-18 14:28:39,841 WARNING [WARN]: Caught exception while sending message 'b'[TEAM_FI][RED]None''. Retry 3 of 3.
2018-04-18 14:28:58,127 ERROR [ERROR]: Caught exception in the launcher.
2018-04-18 14:28:58,128 ERROR [ERROR]: !=== Caught a fatal exception: ===!
2018-04-18 14:28:58,128 ERROR [ERROR]: Exception: 
object of type 'NoneType' has no len()
  File "C:/Users/Ian/Documents/GitHub/Terra/launcher.py", line 8, in <module>
    Main().run()

  File "C:\Users\Ian\Documents\GitHub\Terra\terra\main.py", line 193, in run
    self.step(event)

  File "C:\Users\Ian\Documents\GitHub\Terra\terra\main.py", line 140, in step
    EVENT_BUS.invoke_handlers(event)

  File "C:\Users\Ian\Documents\GitHub\Terra\terra\event\eventbus.py", line 46, in invoke_handlers
    handler(event)

  File "C:\Users\Ian\Documents\GitHub\Terra\terra\ai\aiplayer.py", line 128, in handle_orders_phase
    self.confirm_assignments(assignments)

  File "C:\Users\Ian\Documents\GitHub\Terra\terra\ai\aiplayer.py", line 89, in confirm_assignments
    self.set_order_for_task(assignment.piece, assignment.task)

  File "C:\Users\Ian\Documents\GitHub\Terra\terra\ai\aiplayer.py", line 100, in set_order_for_task
    path = piece.get_path_to_destinations(adjacent_tiles)

  File "C:\Users\Ian\Documents\GitHub\Terra\terra\piece\piece.py", line 377, in get_path_to_destinations
    self.current_path = max(paths, key=lambda p: len(p))

  File "C:\Users\Ian\Documents\GitHub\Terra\terra\piece\piece.py", line 377, in <lambda>
    self.current_path = max(paths, key=lambda p: len(p))

2018-04-18 14:29:21,073 WARNING [WARN]: Caught exception while sending message 'b'[TEAM_FI][RED]None''. Retry 2 of 3.
2018-04-18 14:29:21,073 WARNING [WARN]: Caught exception while sending message 'b'[TEAM_FI][RED]None''. Retry 3 of 3.
2018-04-18 14:29:39,189 ERROR [ERROR]: Caught exception in the launcher.
2018-04-18 14:29:39,190 ERROR [ERROR]: !=== Caught a fatal exception: ===!
2018-04-18 14:29:39,190 ERROR [ERROR]: Exception: 
object of type 'NoneType' has no len()
  File "C:/Users/Ian/Documents/GitHub/Terra/launcher.py", line 8, in <module>
    Main().run()

  File "C:\Users\Ian\Documents\GitHub\Terra\terra\main.py", line 193, in run
    self.step(event)

  File "C:\Users\Ian\Documents\GitHub\Terra\terra\main.py", line 140, in step
    EVENT_BUS.invoke_handlers(event)

  File "C:\Users\Ian\Documents\GitHub\Terra\terra\event\eventbus.py", line 46, in invoke_handlers
    handler(event)

  File "C:\Users\Ian\Documents\GitHub\Terra\terra\ai\aiplayer.py", line 128, in handle_orders_phase
    self.confirm_assignments(assignments)

  File "C:\Users\Ian\Documents\GitHub\Terra\terra\ai\aiplayer.py", line 89, in confirm_assignments
    self.set_order_for_task(assignment.piece, assignment.task)

  File "C:\Users\Ian\Documents\GitHub\Terra\terra\ai\aiplayer.py", line 100, in set_order_for_task
    path = piece.get_path_to_destinations(adjacent_tiles)

  File "C:\Users\Ian\Documents\GitHub\Terra\terra\piece\piece.py", line 378, in get_path_to_destinations
    self.current_path = max(paths, key=lambda p: len(p))

  File "C:\Users\Ian\Documents\GitHub\Terra\terra\piece\piece.py", line 378, in <lambda>
    self.current_path = max(paths, key=lambda p: len(p))

2018-04-18 14:31:01,909 WARNING [WARN]: Caught exception while sending message 'b'[TEAM_FI][RED]None''. Retry 2 of 3.
2018-04-18 14:31:01,909 WARNING [WARN]: Caught exception while sending message 'b'[TEAM_FI][RED]None''. Retry 3 of 3.
2018-04-18 14:31:01,923 ERROR [ERROR]: Caught exception in the launcher.
2018-04-18 14:31:01,925 ERROR [ERROR]: !=== Caught a fatal exception: ===!
2018-04-18 14:31:01,925 ERROR [ERROR]: Exception: 
invalid syntax (piece.py, line 371)
  File "C:/Users/Ian/Documents/GitHub/Terra/launcher.py", line 8, in <module>
    Main().run()

  File "C:\Users\Ian\Documents\GitHub\Terra\terra\main.py", line 193, in run
    self.step(event)

  File "C:\Users\Ian\Documents\GitHub\Terra\terra\main.py", line 140, in step
    EVENT_BUS.invoke_handlers(event)

  File "C:\Users\Ian\Documents\GitHub\Terra\terra\event\eventbus.py", line 46, in invoke_handlers
    handler(event)

  File "C:\Users\Ian\Documents\GitHub\Terra\terra\main.py", line 99, in handle_menu_selections
    self.set_screen_from_mode(Mode.LOBBY, event.mapname, map_type=AssetType.SAVE)

  File "C:\Users\Ian\Documents\GitHub\Terra\terra\main.py", line 64, in set_screen_from_mode
    new_screen = Lobby(False, map_name, map_type)

  File "C:\Users\Ian\Documents\GitHub\Terra\terra\screens\lobby.py", line 31, in __init__
    Session.set_up_local_game(map_name, map_type)

  File "C:\Users\Ian\Documents\GitHub\Terra\terra\managers\session.py", line 45, in set_up_local_game
    SESSION.__set_up__(map_name, bitmap, pieces, teams, upgrades, meta)

  File "C:\Users\Ian\Documents\GitHub\Terra\terra\managers\session.py", line 112, in __set_up__
    from terra.piece.piecemanager import PieceManager

  File "C:\Users\Ian\Documents\GitHub\Terra\terra\piece\piecemanager.py", line 10, in <module>
    from terra.piece.piece import Piece

2018-04-18 14:31:10,371 WARNING [WARN]: Caught exception while sending message 'b'[TEAM_FI][RED]None''. Retry 2 of 3.
2018-04-18 14:31:10,371 WARNING [WARN]: Caught exception while sending message 'b'[TEAM_FI][RED]None''. Retry 3 of 3.
2018-04-18 14:31:10,419 ERROR [ERROR]: Caught exception in the launcher.
2018-04-18 14:31:10,420 ERROR [ERROR]: !=== Caught a fatal exception: ===!
2018-04-18 14:31:10,420 ERROR [ERROR]: Exception: 
'Piece' object has no attribute 'get_path'
  File "C:/Users/Ian/Documents/GitHub/Terra/launcher.py", line 8, in <module>
    Main().run()

  File "C:\Users\Ian\Documents\GitHub\Terra\terra\main.py", line 193, in run
    self.step(event)

  File "C:\Users\Ian\Documents\GitHub\Terra\terra\main.py", line 140, in step
    EVENT_BUS.invoke_handlers(event)

  File "C:\Users\Ian\Documents\GitHub\Terra\terra\event\eventbus.py", line 46, in invoke_handlers
    handler(event)

  File "C:\Users\Ian\Documents\GitHub\Terra\terra\ai\aiplayer.py", line 126, in handle_orders_phase
    assignments = self.assign_tasks(tasks)

  File "C:\Users\Ian\Documents\GitHub\Terra\terra\ai\aiplayer.py", line 65, in assign_tasks
    possible_assignments[piece] = task.score_piece_for_task(piece, self.get_manager(Manager.MAP))

  File "C:\Users\Ian\Documents\GitHub\Terra\terra\ai\task.py", line 53, in score_piece_for_task
    path = piece.get_path((self.tx, self.ty))

2018-04-18 14:31:56,851 WARNING [WARN]: Caught exception while sending message 'b'[TEAM_FI][RED]None''. Retry 2 of 3.
2018-04-18 14:31:56,851 WARNING [WARN]: Caught exception while sending message 'b'[TEAM_FI][RED]None''. Retry 3 of 3.
2018-04-18 14:32:18,549 ERROR [ERROR]: Caught exception in the launcher.
2018-04-18 14:32:18,550 ERROR [ERROR]: !=== Caught a fatal exception: ===!
2018-04-18 14:32:18,551 ERROR [ERROR]: Exception: 
object of type 'NoneType' has no len()
  File "C:/Users/Ian/Documents/GitHub/Terra/launcher.py", line 8, in <module>
    Main().run()

  File "C:\Users\Ian\Documents\GitHub\Terra\terra\main.py", line 193, in run
    self.step(event)

  File "C:\Users\Ian\Documents\GitHub\Terra\terra\main.py", line 140, in step
    EVENT_BUS.invoke_handlers(event)

  File "C:\Users\Ian\Documents\GitHub\Terra\terra\event\eventbus.py", line 46, in invoke_handlers
    handler(event)

  File "C:\Users\Ian\Documents\GitHub\Terra\terra\ai\aiplayer.py", line 128, in handle_orders_phase
    self.confirm_assignments(assignments)

  File "C:\Users\Ian\Documents\GitHub\Terra\terra\ai\aiplayer.py", line 89, in confirm_assignments
    self.set_order_for_task(assignment.piece, assignment.task)

  File "C:\Users\Ian\Documents\GitHub\Terra\terra\ai\aiplayer.py", line 100, in set_order_for_task
    path = piece.get_path_to_destinations(adjacent_tiles)

  File "C:\Users\Ian\Documents\GitHub\Terra\terra\piece\piece.py", line 374, in get_path_to_destinations
    self.current_path = max(paths, key=lambda p: len(p))

  File "C:\Users\Ian\Documents\GitHub\Terra\terra\piece\piece.py", line 374, in <lambda>
    self.current_path = max(paths, key=lambda p: len(p))

2018-04-18 14:33:25,405 WARNING [WARN]: Caught exception while sending message 'b'[TEAM_FI][RED]None''. Retry 2 of 3.
2018-04-18 14:33:25,405 WARNING [WARN]: Caught exception while sending message 'b'[TEAM_FI][RED]None''. Retry 3 of 3.
2018-04-18 14:35:05,249 WARNING [WARN]: Caught exception while sending message 'b'[TEAM_FI][RED]None''. Retry 2 of 3.
2018-04-18 14:35:05,250 WARNING [WARN]: Caught exception while sending message 'b'[TEAM_FI][RED]None''. Retry 3 of 3.
2018-04-18 14:37:34,598 WARNING [WARN]: Caught exception while sending message 'b'[TEAM_FI][RED]None''. Retry 2 of 3.
2018-04-18 14:37:34,598 WARNING [WARN]: Caught exception while sending message 'b'[TEAM_FI][RED]None''. Retry 3 of 3.
2018-04-18 14:41:21,481 WARNING [WARN]: Caught exception while sending message 'b'[TEAM_FI][RED]None''. Retry 2 of 3.
2018-04-18 14:41:21,481 WARNING [WARN]: Caught exception while sending message 'b'[TEAM_FI][RED]None''. Retry 3 of 3.
2018-04-18 14:46:06,667 WARNING [WARN]: Caught exception while sending message 'b'[TEAM_FI][RED]None''. Retry 2 of 3.
2018-04-18 14:46:06,668 WARNING [WARN]: Caught exception while sending message 'b'[TEAM_FI][RED]None''. Retry 3 of 3.
2018-04-18 14:46:59,603 WARNING [WARN]: Caught exception while sending message 'b'[TEAM_FI][RED]None''. Retry 2 of 3.
2018-04-18 14:46:59,604 WARNING [WARN]: Caught exception while sending message 'b'[TEAM_FI][RED]None''. Retry 3 of 3.
2018-04-18 14:49:45,375 WARNING [WARN]: Caught exception while sending message 'b'[TEAM_FI][RED]None''. Retry 2 of 3.
2018-04-18 14:49:45,376 WARNING [WARN]: Caught exception while sending message 'b'[TEAM_FI][RED]None''. Retry 3 of 3.
2018-04-18 14:50:16,293 WARNING [WARN]: Caught exception while sending message 'b'[TEAM_FI][RED]None''. Retry 2 of 3.
2018-04-18 14:50:16,293 WARNING [WARN]: Caught exception while sending message 'b'[TEAM_FI][RED]None''. Retry 3 of 3.
2018-04-18 14:50:22,508 ERROR [ERROR]: Caught exception in the launcher.
2018-04-18 14:50:22,509 ERROR [ERROR]: !=== Caught a fatal exception: ===!
2018-04-18 14:50:22,509 ERROR [ERROR]: Exception: 
object of type 'NoneType' has no len()
  File "C:/Users/Ian/Documents/GitHub/Terra/launcher.py", line 8, in <module>
    Main().run()

  File "C:\Users\Ian\Documents\GitHub\Terra\terra\main.py", line 193, in run
    self.step(event)

  File "C:\Users\Ian\Documents\GitHub\Terra\terra\main.py", line 140, in step
    EVENT_BUS.invoke_handlers(event)

  File "C:\Users\Ian\Documents\GitHub\Terra\terra\event\eventbus.py", line 46, in invoke_handlers
    handler(event)

  File "C:\Users\Ian\Documents\GitHub\Terra\terra\ai\aiplayer.py", line 133, in handle_orders_phase
    self.confirm_assignments(assignments)

  File "C:\Users\Ian\Documents\GitHub\Terra\terra\ai\aiplayer.py", line 89, in confirm_assignments
    self.set_order_for_task(assignment.piece, assignment.task)

  File "C:\Users\Ian\Documents\GitHub\Terra\terra\ai\aiplayer.py", line 106, in set_order_for_task
    destination = piece.step_along_path(path)

  File "C:\Users\Ian\Documents\GitHub\Terra\terra\piece\piece.py", line 388, in step_along_path
    steps = min(self.attr(Attribute.MOVEMENT_RANGE), len(path) - 1)

2018-04-18 14:51:02,255 WARNING [WARN]: Caught exception while sending message 'b'[TEAM_FI][RED]None''. Retry 2 of 3.
2018-04-18 14:51:02,255 WARNING [WARN]: Caught exception while sending message 'b'[TEAM_FI][RED]None''. Retry 3 of 3.
2018-04-18 14:51:48,660 WARNING [WARN]: Caught exception while sending message 'b'[TEAM_FI][RED]None''. Retry 2 of 3.
2018-04-18 14:51:48,660 WARNING [WARN]: Caught exception while sending message 'b'[TEAM_FI][RED]None''. Retry 3 of 3.
2018-04-18 14:55:22,660 WARNING [WARN]: Caught exception while sending message 'b'[TEAM_FI][RED]None''. Retry 2 of 3.
2018-04-18 14:55:22,660 WARNING [WARN]: Caught exception while sending message 'b'[TEAM_FI][RED]None''. Retry 3 of 3.
2018-04-18 14:59:30,239 ERROR [ERROR]: Caught exception in the launcher.
2018-04-18 14:59:30,264 ERROR [ERROR]: !=== Caught a fatal exception: ===!
2018-04-18 14:59:30,264 ERROR [ERROR]: Exception: 
video system not initialized
  File "C:/Users/Ian/Documents/GitHub/Terra/launcher.py", line 8, in <module>
    Main().run()

  File "C:\Users\Ian\Documents\GitHub\Terra\terra\main.py", line 193, in run
    self.step(event)

  File "C:\Users\Ian\Documents\GitHub\Terra\terra\main.py", line 137, in step
    INPUT_CONTROLLER.invoke_handlers(event)

  File "C:\Users\Ian\Documents\GitHub\Terra\terra\control\inputcontroller.py", line 55, in invoke_handlers
    handler()

  File "C:\Users\Ian\Documents\GitHub\Terra\terra\menu\menu.py", line 101, in set_cursor_pos_to_mouse_coords
    if self.cursor_in_menu_bounds():

  File "C:\Users\Ian\Documents\GitHub\Terra\terra\menu\menu.py", line 94, in cursor_in_menu_bounds
    mouse_x = get_pos()[0] / SETTINGS.get(Setting.SCREEN_SCALE)

