2018-05-01 14:40:25,071 WARNING [WARN]: Caught exception while sending message 'b'[TEAM_FI][RED]None''. Retry 2 of 3.
2018-05-01 14:40:25,072 WARNING [WARN]: Caught exception while sending message 'b'[TEAM_FI][RED]None''. Retry 3 of 3.
2018-05-01 14:54:01,185 ERROR [ERROR]: Caught exception in the launcher.
2018-05-01 14:54:01,201 ERROR [ERROR]: !=== Caught a fatal exception: ===!
2018-05-01 14:54:01,201 ERROR [ERROR]: Exception: 
'NoneType' object has no attribute 'team'
  File "C:/Users/Ian/Documents/GitHub/Terra/launcher.py", line 8, in <module>
    Main().run()

  File "C:\Users\Ian\Documents\GitHub\Terra\terra\main.py", line 193, in run
    self.step(event)

  File "C:\Users\Ian\Documents\GitHub\Terra\terra\main.py", line 140, in step
    EVENT_BUS.invoke_handlers(event)

  File "C:\Users\Ian\Documents\GitHub\Terra\terra\event\eventbus.py", line 46, in invoke_handlers
    handler(event)

  File "C:\Users\Ian\Documents\GitHub\Terra\terra\piece\piecemanager.py", line 405, in conduct_ranged_attack_from_event
    self.ranged_attack(event.gx, event.gy, event.team, event.tx, event.ty)

  File "C:\Users\Ian\Documents\GitHub\Terra\terra\piece\piecemanager.py", line 372, in ranged_attack
    aoe_multiplier = self.get_manager(Manager.TEAM).attr(origin_unit.team, origin_unit.piece_type, Attribute.RANGED_AOE_MULTIPLIER)

2018-05-01 14:54:57,935 WARNING [WARN]: Caught exception while sending message 'b'[TEAM_FI][RED]None''. Retry 2 of 3.
2018-05-01 14:54:57,935 WARNING [WARN]: Caught exception while sending message 'b'[TEAM_FI][RED]None''. Retry 3 of 3.
2018-05-01 14:54:57,976 ERROR [ERROR]: Caught exception in the launcher.
2018-05-01 14:54:57,999 ERROR [ERROR]: !=== Caught a fatal exception: ===!
2018-05-01 14:54:57,999 ERROR [ERROR]: Exception: 
<Manager.PIECE: 'piece'>
  File "C:/Users/Ian/Documents/GitHub/Terra/launcher.py", line 8, in <module>
    Main().run()

  File "C:/Users/Ian/Documents/GitHub/Terra\terra\main.py", line 193, in run
    self.step(event)

  File "C:/Users/Ian/Documents/GitHub/Terra\terra\main.py", line 140, in step
    EVENT_BUS.invoke_handlers(event)

  File "C:/Users/Ian/Documents/GitHub/Terra\terra\event\eventbus.py", line 46, in invoke_handlers
    handler(event)

  File "C:/Users/Ian/Documents/GitHub/Terra\terra\main.py", line 99, in handle_menu_selections
    self.set_screen_from_mode(Mode.LOBBY, event.mapname, map_type=AssetType.SAVE)

  File "C:/Users/Ian/Documents/GitHub/Terra\terra\main.py", line 66, in set_screen_from_mode
    new_screen = Lobby(False, map_name, map_type)

  File "C:/Users/Ian/Documents/GitHub/Terra\terra\screens\lobby.py", line 31, in __init__
    Session.set_up_local_game(map_name, map_type)

  File "C:/Users/Ian/Documents/GitHub/Terra\terra\managers\session.py", line 45, in set_up_local_game
    SESSION.__set_up__(map_name, bitmap, pieces, teams, upgrades, meta)

  File "C:/Users/Ian/Documents/GitHub/Terra\terra\managers\session.py", line 121, in __set_up__
    self.managers[Manager.TEAM] = TeamManager(teams, upgrades)

  File "C:/Users/Ian/Documents/GitHub/Terra\terra\team\teammanager.py", line 74, in __init__
    self.purchase_upgrade(team, UpgradeType[upgrade])

  File "C:/Users/Ian/Documents/GitHub/Terra\terra\team\teammanager.py", line 168, in purchase_upgrade
    self.on_upgrade_purchase(team, upgrade_type)

  File "C:/Users/Ian/Documents/GitHub/Terra\terra\team\teammanager.py", line 193, in on_upgrade_purchase
    for piece in self.get_manager(Manager.PIECE).get_all_pieces_for_team(team, piece_type=piece_type):

  File "C:/Users/Ian/Documents/GitHub/Terra\terra\engine\gameobject.py", line 45, in get_manager
    return SESSION.get(manager_type)

  File "C:/Users/Ian/Documents/GitHub/Terra\terra\managers\session.py", line 33, in get
    return self.managers[manager_type]

2018-05-01 14:56:23,754 WARNING [WARN]: Caught exception while sending message 'b'[TEAM_FI][RED]None''. Retry 2 of 3.
2018-05-01 14:56:23,755 WARNING [WARN]: Caught exception while sending message 'b'[TEAM_FI][RED]None''. Retry 3 of 3.
2018-05-01 14:56:23,796 ERROR [ERROR]: Caught exception in the launcher.
2018-05-01 14:56:23,799 ERROR [ERROR]: !=== Caught a fatal exception: ===!
2018-05-01 14:56:23,799 ERROR [ERROR]: Exception: 
<Manager.PIECE: 'piece'>
  File "C:/Users/Ian/Documents/GitHub/Terra/launcher.py", line 8, in <module>
    Main().run()

  File "C:/Users/Ian/Documents/GitHub/Terra\terra\main.py", line 193, in run
    self.step(event)

  File "C:/Users/Ian/Documents/GitHub/Terra\terra\main.py", line 140, in step
    EVENT_BUS.invoke_handlers(event)

  File "C:/Users/Ian/Documents/GitHub/Terra\terra\event\eventbus.py", line 46, in invoke_handlers
    handler(event)

  File "C:/Users/Ian/Documents/GitHub/Terra\terra\main.py", line 99, in handle_menu_selections
    self.set_screen_from_mode(Mode.LOBBY, event.mapname, map_type=AssetType.SAVE)

  File "C:/Users/Ian/Documents/GitHub/Terra\terra\main.py", line 66, in set_screen_from_mode
    new_screen = Lobby(False, map_name, map_type)

  File "C:/Users/Ian/Documents/GitHub/Terra\terra\screens\lobby.py", line 31, in __init__
    Session.set_up_local_game(map_name, map_type)

  File "C:/Users/Ian/Documents/GitHub/Terra\terra\managers\session.py", line 45, in set_up_local_game
    SESSION.__set_up__(map_name, bitmap, pieces, teams, upgrades, meta)

  File "C:/Users/Ian/Documents/GitHub/Terra\terra\managers\session.py", line 121, in __set_up__
    self.managers[Manager.TEAM] = TeamManager(teams, upgrades)

  File "C:/Users/Ian/Documents/GitHub/Terra\terra\team\teammanager.py", line 74, in __init__
    self.purchase_upgrade(team, UpgradeType[upgrade])

  File "C:/Users/Ian/Documents/GitHub/Terra\terra\team\teammanager.py", line 168, in purchase_upgrade
    self.on_upgrade_purchase(team, upgrade_type)

  File "C:/Users/Ian/Documents/GitHub/Terra\terra\team\teammanager.py", line 193, in on_upgrade_purchase
    for piece in self.get_manager(Manager.PIECE).get_all_pieces_for_team(team, piece_type=piece_type):

  File "C:/Users/Ian/Documents/GitHub/Terra\terra\engine\gameobject.py", line 45, in get_manager
    return SESSION.get(manager_type)

  File "C:/Users/Ian/Documents/GitHub/Terra\terra\managers\session.py", line 33, in get
    return self.managers[manager_type]

2018-05-01 14:59:24,126 WARNING [WARN]: Caught exception while sending message 'b'[TEAM_FI][RED]None''. Retry 2 of 3.
2018-05-01 14:59:24,127 WARNING [WARN]: Caught exception while sending message 'b'[TEAM_FI][RED]None''. Retry 3 of 3.
2018-05-01 15:02:03,266 ERROR [ERROR]: Caught exception in the launcher.
2018-05-01 15:02:03,268 ERROR [ERROR]: !=== Caught a fatal exception: ===!
2018-05-01 15:02:03,268 ERROR [ERROR]: Exception: 
'NoneType' object has no attribute 'team'
  File "C:/Users/Ian/Documents/GitHub/Terra/launcher.py", line 8, in <module>
    Main().run()

  File "C:/Users/Ian/Documents/GitHub/Terra\terra\main.py", line 193, in run
    self.step(event)

  File "C:/Users/Ian/Documents/GitHub/Terra\terra\main.py", line 140, in step
    EVENT_BUS.invoke_handlers(event)

  File "C:/Users/Ian/Documents/GitHub/Terra\terra\event\eventbus.py", line 46, in invoke_handlers
    handler(event)

  File "C:/Users/Ian/Documents/GitHub/Terra\terra\piece\piecemanager.py", line 405, in conduct_ranged_attack_from_event
    self.ranged_attack(event.gx, event.gy, event.team, event.tx, event.ty)

  File "C:/Users/Ian/Documents/GitHub/Terra\terra\piece\piecemanager.py", line 372, in ranged_attack
    aoe_multiplier = self.get_manager(Manager.TEAM).attr(origin_unit.team, origin_unit.piece_type, Attribute.RANGED_AOE_MULTIPLIER)

2018-05-01 15:20:06,250 WARNING [WARN]: Caught exception while sending message 'b'[TEAM_FI][RED]None''. Retry 2 of 3.
2018-05-01 15:20:06,251 WARNING [WARN]: Caught exception while sending message 'b'[TEAM_FI][RED]None''. Retry 3 of 3.
2018-05-01 15:20:30,478 WARNING [WARN]: Caught exception while sending message 'b'[TEAM_FI][RED]None''. Retry 2 of 3.
2018-05-01 15:20:30,479 WARNING [WARN]: Caught exception while sending message 'b'[TEAM_FI][RED]None''. Retry 3 of 3.
2018-05-01 15:20:47,692 WARNING [WARN]: Caught exception while sending message 'b'[TEAM_FI][RED]None''. Retry 2 of 3.
2018-05-01 15:20:47,693 WARNING [WARN]: Caught exception while sending message 'b'[TEAM_FI][RED]None''. Retry 3 of 3.
2018-05-01 15:28:04,024 WARNING [WARN]: Caught exception while sending message 'b'[TEAM_FI][RED]None''. Retry 2 of 3.
2018-05-01 15:28:04,024 WARNING [WARN]: Caught exception while sending message 'b'[TEAM_FI][RED]None''. Retry 3 of 3.
2018-05-01 16:30:22,022 WARNING [WARN]: Caught exception while sending message 'b'[TEAM_FI][RED]None''. Retry 2 of 3.
2018-05-01 16:30:22,022 WARNING [WARN]: Caught exception while sending message 'b'[TEAM_FI][RED]None''. Retry 3 of 3.
2018-05-01 16:30:22,042 ERROR [ERROR]: Caught exception in the launcher.
2018-05-01 16:30:22,062 ERROR [ERROR]: !=== Caught a fatal exception: ===!
2018-05-01 16:30:22,063 ERROR [ERROR]: Exception: 
Expecting property name enclosed in double quotes: line 1 column 226 (char 225)
  File "C:/Users/Ian/Documents/GitHub/Terra/launcher.py", line 8, in <module>
    Main().run()

  File "C:\Users\Ian\Documents\GitHub\Terra\terra\main.py", line 193, in run
    self.step(event)

  File "C:\Users\Ian\Documents\GitHub\Terra\terra\main.py", line 140, in step
    EVENT_BUS.invoke_handlers(event)

  File "C:\Users\Ian\Documents\GitHub\Terra\terra\event\eventbus.py", line 46, in invoke_handlers
    handler(event)

  File "C:\Users\Ian\Documents\GitHub\Terra\terra\main.py", line 97, in handle_menu_selections
    self.set_screen_from_mode(Mode.LOBBY, event.mapname)

  File "C:\Users\Ian\Documents\GitHub\Terra\terra\main.py", line 66, in set_screen_from_mode
    new_screen = Lobby(False, map_name, map_type)

  File "C:\Users\Ian\Documents\GitHub\Terra\terra\screens\lobby.py", line 31, in __init__
    Session.set_up_local_game(map_name, map_type)

  File "C:\Users\Ian\Documents\GitHub\Terra\terra\managers\session.py", line 45, in set_up_local_game
    SESSION.__set_up__(map_name, bitmap, pieces, teams, upgrades, meta)

  File "C:\Users\Ian\Documents\GitHub\Terra\terra\managers\session.py", line 112, in __set_up__
    from terra.piece.piecemanager import PieceManager

  File "C:\Users\Ian\Documents\GitHub\Terra\terra\piece\piecemanager.py", line 4, in <module>
    from terra.economy.upgrades import base_upgrades

  File "C:\Users\Ian\Documents\GitHub\Terra\terra\economy\upgrades.py", line 21, in <module>
    base_upgrades = read_upgrade_attributes_from_file()

  File "C:\Users\Ian\Documents\GitHub\Terra\terra\economy\upgrades.py", line 14, in read_upgrade_attributes_from_file
    return json.loads(attributes_file.read().replace('\n', ''), object_hook=as_enum)

  File "C:\Users\Ian\AppData\Local\Programs\Python\Python36-32\lib\json\__init__.py", line 367, in loads
    return cls(**kw).decode(s)

  File "C:\Users\Ian\AppData\Local\Programs\Python\Python36-32\lib\json\decoder.py", line 339, in decode
    obj, end = self.raw_decode(s, idx=_w(s, 0).end())

  File "C:\Users\Ian\AppData\Local\Programs\Python\Python36-32\lib\json\decoder.py", line 355, in raw_decode
    obj, end = self.scan_once(s, idx)

2018-05-01 16:30:56,909 WARNING [WARN]: Caught exception while sending message 'b'[TEAM_FI][RED]None''. Retry 2 of 3.
2018-05-01 16:30:56,909 WARNING [WARN]: Caught exception while sending message 'b'[TEAM_FI][RED]None''. Retry 3 of 3.
2018-05-01 16:31:40,643 WARNING [WARN]: Caught exception while sending message 'b'[TEAM_FI][RED]None''. Retry 2 of 3.
2018-05-01 16:31:40,643 WARNING [WARN]: Caught exception while sending message 'b'[TEAM_FI][RED]None''. Retry 3 of 3.
2018-05-01 16:36:26,743 WARNING [WARN]: Caught exception while sending message 'b'[TEAM_FI][RED]None''. Retry 2 of 3.
2018-05-01 16:36:26,743 WARNING [WARN]: Caught exception while sending message 'b'[TEAM_FI][RED]None''. Retry 3 of 3.
2018-05-01 16:36:56,096 WARNING [WARN]: Caught exception while sending message 'b'[TEAM_FI][RED]None''. Retry 2 of 3.
2018-05-01 16:36:56,096 WARNING [WARN]: Caught exception while sending message 'b'[TEAM_FI][RED]None''. Retry 3 of 3.
2018-05-01 16:37:10,819 WARNING [WARN]: Caught exception while sending message 'b'[TEAM_FI][RED]None''. Retry 2 of 3.
2018-05-01 16:37:10,819 WARNING [WARN]: Caught exception while sending message 'b'[TEAM_FI][RED]None''. Retry 3 of 3.
2018-05-01 16:48:17,920 WARNING [WARN]: Caught exception while sending message 'b'[TEAM_FI][RED]None''. Retry 2 of 3.
2018-05-01 16:48:17,921 WARNING [WARN]: Caught exception while sending message 'b'[TEAM_FI][RED]None''. Retry 3 of 3.
2018-05-01 16:50:18,442 WARNING [WARN]: Caught exception while sending message 'b'[TEAM_FI][RED]None''. Retry 2 of 3.
2018-05-01 16:50:18,442 WARNING [WARN]: Caught exception while sending message 'b'[TEAM_FI][RED]None''. Retry 3 of 3.
2018-05-01 16:50:29,908 WARNING [WARN]: Caught exception while sending message 'b'[TEAM_FI][RED]None''. Retry 2 of 3.
2018-05-01 16:50:29,908 WARNING [WARN]: Caught exception while sending message 'b'[TEAM_FI][RED]None''. Retry 3 of 3.
2018-05-01 16:50:46,652 WARNING [WARN]: Caught exception while sending message 'b'[TEAM_FI][RED]None''. Retry 2 of 3.
2018-05-01 16:50:46,652 WARNING [WARN]: Caught exception while sending message 'b'[TEAM_FI][RED]None''. Retry 3 of 3.
2018-05-01 16:51:23,206 WARNING [WARN]: Caught exception while sending message 'b'[TEAM_FI][RED]None''. Retry 2 of 3.
2018-05-01 16:51:23,206 WARNING [WARN]: Caught exception while sending message 'b'[TEAM_FI][RED]None''. Retry 3 of 3.
2018-05-01 17:51:06,641 WARNING [WARN]: Caught exception while sending message 'b'[TEAM_FI][RED]None''. Retry 2 of 3.
2018-05-01 17:51:06,641 WARNING [WARN]: Caught exception while sending message 'b'[TEAM_FI][RED]None''. Retry 3 of 3.
2018-05-02 00:11:51,217 WARNING [WARN]: Caught exception while sending message 'b'[TEAM_FI][RED]None''. Retry 2 of 3.
2018-05-02 00:11:51,218 WARNING [WARN]: Caught exception while sending message 'b'[TEAM_FI][RED]None''. Retry 3 of 3.
2018-05-02 00:11:51,239 ERROR [ERROR]: Caught exception in the launcher.
2018-05-02 00:11:51,248 ERROR [ERROR]: !=== Caught a fatal exception: ===!
2018-05-02 00:11:51,249 ERROR [ERROR]: Exception: 
'RESOURCE_PRODUCTION_1'
  File "C:/Users/Ian/Documents/GitHub/Terra/launcher.py", line 8, in <module>
    Main().run()

  File "C:\Users\Ian\Documents\GitHub\Terra\terra\main.py", line 193, in run
    self.step(event)

  File "C:\Users\Ian\Documents\GitHub\Terra\terra\main.py", line 140, in step
    EVENT_BUS.invoke_handlers(event)

  File "C:\Users\Ian\Documents\GitHub\Terra\terra\event\eventbus.py", line 46, in invoke_handlers
    handler(event)

  File "C:\Users\Ian\Documents\GitHub\Terra\terra\main.py", line 99, in handle_menu_selections
    self.set_screen_from_mode(Mode.LOBBY, event.mapname, map_type=AssetType.SAVE)

  File "C:\Users\Ian\Documents\GitHub\Terra\terra\main.py", line 66, in set_screen_from_mode
    new_screen = Lobby(False, map_name, map_type)

  File "C:\Users\Ian\Documents\GitHub\Terra\terra\screens\lobby.py", line 31, in __init__
    Session.set_up_local_game(map_name, map_type)

  File "C:\Users\Ian\Documents\GitHub\Terra\terra\managers\session.py", line 45, in set_up_local_game
    SESSION.__set_up__(map_name, bitmap, pieces, teams, upgrades, meta)

  File "C:\Users\Ian\Documents\GitHub\Terra\terra\managers\session.py", line 121, in __set_up__
    self.managers[Manager.TEAM] = TeamManager(teams, upgrades)

  File "C:\Users\Ian\Documents\GitHub\Terra\terra\team\teammanager.py", line 74, in __init__
    self.purchase_upgrade(team, UpgradeType[upgrade])

  File "C:\Users\Ian\AppData\Local\Programs\Python\Python36-32\lib\enum.py", line 327, in __getitem__
    return cls._member_map_[name]

2018-05-02 00:12:16,702 WARNING [WARN]: Caught exception while sending message 'b'[TEAM_FI][RED]None''. Retry 2 of 3.
2018-05-02 00:12:16,702 WARNING [WARN]: Caught exception while sending message 'b'[TEAM_FI][RED]None''. Retry 3 of 3.
2018-05-02 10:58:30,731 WARNING [WARN]: Caught exception while sending message 'b'[TEAM_FI][RED]None''. Retry 2 of 3.
2018-05-02 10:58:30,731 WARNING [WARN]: Caught exception while sending message 'b'[TEAM_FI][RED]None''. Retry 3 of 3.
2018-05-02 11:02:11,397 ERROR [ERROR]: Caught exception in the launcher.
2018-05-02 11:02:11,421 ERROR [ERROR]: !=== Caught a fatal exception: ===!
2018-05-02 11:02:11,422 ERROR [ERROR]: Exception: 
<Team.BLUE: '[BLU]'>
  File "C:/Users/Ian/Documents/GitHub/Terra/launcher.py", line 8, in <module>
    Main().run()

  File "C:\Users\Ian\Documents\GitHub\Terra\terra\main.py", line 193, in run
    self.step(event)

  File "C:\Users\Ian\Documents\GitHub\Terra\terra\main.py", line 140, in step
    EVENT_BUS.invoke_handlers(event)

  File "C:\Users\Ian\Documents\GitHub\Terra\terra\event\eventbus.py", line 46, in invoke_handlers
    handler(event)

  File "C:\Users\Ian\Documents\GitHub\Terra\terra\team\teammanager.py", line 301, in handle_base_destroyed
    self.remove_team(event.team)

  File "C:\Users\Ian\Documents\GitHub\Terra\terra\team\teammanager.py", line 291, in remove_team
    self.get_manager(Manager.PLAYER).handle_team_defeated(team)

  File "C:\Users\Ian\Documents\GitHub\Terra\terra\team\playermanager.py", line 103, in handle_team_defeated
    self.cursors[team].destroy()

2018-05-02 11:03:05,156 WARNING [WARN]: Caught exception while sending message 'b'[TEAM_FI][RED]None''. Retry 2 of 3.
2018-05-02 11:03:05,156 WARNING [WARN]: Caught exception while sending message 'b'[TEAM_FI][RED]None''. Retry 3 of 3.
2018-05-02 12:20:53,519 WARNING [WARN]: Caught exception while sending message 'b'[TEAM_FI][RED]None''. Retry 2 of 3.
2018-05-02 12:20:53,520 WARNING [WARN]: Caught exception while sending message 'b'[TEAM_FI][RED]None''. Retry 3 of 3.
2018-05-02 12:23:46,631 WARNING [WARN]: Caught exception while sending message 'b'[TEAM_FI][RED]None''. Retry 2 of 3.
2018-05-02 12:23:46,632 WARNING [WARN]: Caught exception while sending message 'b'[TEAM_FI][RED]None''. Retry 3 of 3.
2018-05-02 12:23:46,935 ERROR [ERROR]: Caught exception in the launcher.
2018-05-02 12:23:46,944 ERROR [ERROR]: !=== Caught a fatal exception: ===!
2018-05-02 12:23:46,945 ERROR [ERROR]: Exception: 
unsupported operand type(s) for *: 'int' and 'NoneType'
  File "C:/Users/Ian/Documents/GitHub/Terra/launcher.py", line 8, in <module>
    Main().run()

  File "C:/Users/Ian/Documents/GitHub/Terra\terra\main.py", line 193, in run
    self.step(event)

  File "C:/Users/Ian/Documents/GitHub/Terra\terra\main.py", line 140, in step
    EVENT_BUS.invoke_handlers(event)

  File "C:/Users/Ian/Documents/GitHub/Terra\terra\event\eventbus.py", line 46, in invoke_handlers
    handler(event)

  File "C:/Users/Ian/Documents/GitHub/Terra\terra\ai\aiplayer.py", line 532, in handle_orders_phase
    self.tasks = self.generate_tasks()

  File "C:/Users/Ian/Documents/GitHub/Terra\terra\ai\aiplayer.py", line 122, in generate_tasks
    tasks.extend(self.generate_research_tasks())

  File "C:/Users/Ian/Documents/GitHub/Terra\terra\ai\aiplayer.py", line 235, in generate_research_tasks
    upgrades_to_research.put(upgrade, self.score_researchable_upgrade(upgrade))

  File "C:/Users/Ian/Documents/GitHub/Terra\terra\ai\aiplayer.py", line 269, in score_researchable_upgrade
    score -= 2 * self.my_piece_counts.get(piece_type) / total_pieces

2018-05-02 12:24:11,075 WARNING [WARN]: Caught exception while sending message 'b'[TEAM_FI][RED]None''. Retry 2 of 3.
2018-05-02 12:24:11,076 WARNING [WARN]: Caught exception while sending message 'b'[TEAM_FI][RED]None''. Retry 3 of 3.
2018-05-02 12:24:11,377 ERROR [ERROR]: Caught exception in the launcher.
2018-05-02 12:24:11,395 ERROR [ERROR]: !=== Caught a fatal exception: ===!
2018-05-02 12:24:11,395 ERROR [ERROR]: Exception: 
'<' not supported between instances of 'UpgradeType' and 'UpgradeType'
  File "C:/Users/Ian/Documents/GitHub/Terra/launcher.py", line 8, in <module>
    Main().run()

  File "C:/Users/Ian/Documents/GitHub/Terra\terra\main.py", line 193, in run
    self.step(event)

  File "C:/Users/Ian/Documents/GitHub/Terra\terra\main.py", line 140, in step
    EVENT_BUS.invoke_handlers(event)

  File "C:/Users/Ian/Documents/GitHub/Terra\terra\event\eventbus.py", line 46, in invoke_handlers
    handler(event)

  File "C:/Users/Ian/Documents/GitHub/Terra\terra\ai\aiplayer.py", line 532, in handle_orders_phase
    self.tasks = self.generate_tasks()

  File "C:/Users/Ian/Documents/GitHub/Terra\terra\ai\aiplayer.py", line 122, in generate_tasks
    tasks.extend(self.generate_research_tasks())

  File "C:/Users/Ian/Documents/GitHub/Terra\terra\ai\aiplayer.py", line 235, in generate_research_tasks
    upgrades_to_research.put(upgrade, self.score_researchable_upgrade(upgrade))

  File "C:\Users\Ian\AppData\Local\Programs\Python\Python36-32\lib\queue.py", line 143, in put
    self._put(item)

  File "C:\Users\Ian\AppData\Local\Programs\Python\Python36-32\lib\queue.py", line 227, in _put
    heappush(self.queue, item)

2018-05-02 12:29:57,610 WARNING [WARN]: Caught exception while sending message 'b'[TEAM_FI][RED]None''. Retry 2 of 3.
2018-05-02 12:29:57,610 WARNING [WARN]: Caught exception while sending message 'b'[TEAM_FI][RED]None''. Retry 3 of 3.
2018-05-02 12:29:57,909 ERROR [ERROR]: Caught exception in the launcher.
2018-05-02 12:29:57,911 ERROR [ERROR]: !=== Caught a fatal exception: ===!
2018-05-02 12:29:57,911 ERROR [ERROR]: Exception: 
'<' not supported between instances of 'UpgradeType' and 'UpgradeType'
  File "C:/Users/Ian/Documents/GitHub/Terra/launcher.py", line 8, in <module>
    Main().run()

  File "C:/Users/Ian/Documents/GitHub/Terra\terra\main.py", line 193, in run
    self.step(event)

  File "C:/Users/Ian/Documents/GitHub/Terra\terra\main.py", line 140, in step
    EVENT_BUS.invoke_handlers(event)

  File "C:/Users/Ian/Documents/GitHub/Terra\terra\event\eventbus.py", line 46, in invoke_handlers
    handler(event)

  File "C:/Users/Ian/Documents/GitHub/Terra\terra\ai\aiplayer.py", line 537, in handle_orders_phase
    self.tasks = self.generate_tasks()

  File "C:/Users/Ian/Documents/GitHub/Terra\terra\ai\aiplayer.py", line 122, in generate_tasks
    tasks.extend(self.generate_research_tasks())

  File "C:/Users/Ian/Documents/GitHub/Terra\terra\ai\aiplayer.py", line 240, in generate_research_tasks
    queue_upgrade(upgrade)

  File "C:/Users/Ian/Documents/GitHub/Terra\terra\ai\aiplayer.py", line 222, in queue_upgrade
    upgrades_to_research.put((score, upgrade))

  File "C:\Users\Ian\AppData\Local\Programs\Python\Python36-32\lib\queue.py", line 143, in put
    self._put(item)

  File "C:\Users\Ian\AppData\Local\Programs\Python\Python36-32\lib\queue.py", line 227, in _put
    heappush(self.queue, item)

2018-05-02 12:30:14,355 WARNING [WARN]: Caught exception while sending message 'b'[TEAM_FI][RED]None''. Retry 2 of 3.
2018-05-02 12:30:14,355 WARNING [WARN]: Caught exception while sending message 'b'[TEAM_FI][RED]None''. Retry 3 of 3.
2018-05-02 12:31:15,753 WARNING [WARN]: Caught exception while sending message 'b'[TEAM_FI][RED]None''. Retry 2 of 3.
2018-05-02 12:31:15,753 WARNING [WARN]: Caught exception while sending message 'b'[TEAM_FI][RED]None''. Retry 3 of 3.
2018-05-02 12:31:50,367 ERROR [ERROR]: Caught exception in the launcher.
2018-05-02 12:31:50,372 ERROR [ERROR]: !=== Caught a fatal exception: ===!
2018-05-02 12:31:50,373 ERROR [ERROR]: Exception: 
'<' not supported between instances of 'UpgradeType' and 'UpgradeType'
  File "C:/Users/Ian/Documents/GitHub/Terra/launcher.py", line 8, in <module>
    Main().run()

  File "C:/Users/Ian/Documents/GitHub/Terra\terra\main.py", line 193, in run
    self.step(event)

  File "C:/Users/Ian/Documents/GitHub/Terra\terra\main.py", line 140, in step
    EVENT_BUS.invoke_handlers(event)

  File "C:/Users/Ian/Documents/GitHub/Terra\terra\event\eventbus.py", line 46, in invoke_handlers
    handler(event)

  File "C:/Users/Ian/Documents/GitHub/Terra\terra\ai\aiplayer.py", line 537, in handle_orders_phase
    self.tasks = self.generate_tasks()

  File "C:/Users/Ian/Documents/GitHub/Terra\terra\ai\aiplayer.py", line 122, in generate_tasks
    tasks.extend(self.generate_research_tasks())

  File "C:/Users/Ian/Documents/GitHub/Terra\terra\ai\aiplayer.py", line 249, in generate_research_tasks
    tasks.append(self.create_research_task(upgrades_to_research.get()))

  File "C:\Users\Ian\AppData\Local\Programs\Python\Python36-32\lib\queue.py", line 174, in get
    item = self._get()

  File "C:\Users\Ian\AppData\Local\Programs\Python\Python36-32\lib\queue.py", line 230, in _get
    return heappop(self.queue)

2018-05-02 12:32:24,789 WARNING [WARN]: Caught exception while sending message 'b'[TEAM_FI][RED]None''. Retry 2 of 3.
2018-05-02 12:32:24,789 WARNING [WARN]: Caught exception while sending message 'b'[TEAM_FI][RED]None''. Retry 3 of 3.
2018-05-02 12:32:25,851 ERROR [ERROR]: Caught exception in the launcher.
2018-05-02 12:32:25,853 ERROR [ERROR]: !=== Caught a fatal exception: ===!
2018-05-02 12:32:25,854 ERROR [ERROR]: Exception: 
'<' not supported between instances of 'UpgradeType' and 'UpgradeType'
  File "C:/Users/Ian/Documents/GitHub/Terra/launcher.py", line 8, in <module>
    Main().run()

  File "C:/Users/Ian/Documents/GitHub/Terra\terra\main.py", line 193, in run
    self.step(event)

  File "C:/Users/Ian/Documents/GitHub/Terra\terra\main.py", line 140, in step
    EVENT_BUS.invoke_handlers(event)

  File "C:/Users/Ian/Documents/GitHub/Terra\terra\event\eventbus.py", line 46, in invoke_handlers
    handler(event)

  File "C:/Users/Ian/Documents/GitHub/Terra\terra\ai\aiplayer.py", line 538, in handle_orders_phase
    self.tasks = self.generate_tasks()

  File "C:/Users/Ian/Documents/GitHub/Terra\terra\ai\aiplayer.py", line 122, in generate_tasks
    tasks.extend(self.generate_research_tasks())

  File "C:/Users/Ian/Documents/GitHub/Terra\terra\ai\aiplayer.py", line 249, in generate_research_tasks
    _, upgrade = upgrades_to_research.get()

  File "C:\Users\Ian\AppData\Local\Programs\Python\Python36-32\lib\queue.py", line 174, in get
    item = self._get()

  File "C:\Users\Ian\AppData\Local\Programs\Python\Python36-32\lib\queue.py", line 230, in _get
    return heappop(self.queue)

2018-05-02 12:32:43,756 WARNING [WARN]: Caught exception while sending message 'b'[TEAM_FI][RED]None''. Retry 2 of 3.
2018-05-02 12:32:43,757 WARNING [WARN]: Caught exception while sending message 'b'[TEAM_FI][RED]None''. Retry 3 of 3.
2018-05-02 12:33:32,551 ERROR [ERROR]: Caught exception in the launcher.
2018-05-02 12:33:32,553 ERROR [ERROR]: !=== Caught a fatal exception: ===!
2018-05-02 12:33:32,554 ERROR [ERROR]: Exception: 
'<' not supported between instances of 'UpgradeType' and 'UpgradeType'
  File "C:/Users/Ian/Documents/GitHub/Terra/launcher.py", line 8, in <module>
    Main().run()

  File "C:/Users/Ian/Documents/GitHub/Terra\terra\main.py", line 193, in run
    self.step(event)

  File "C:/Users/Ian/Documents/GitHub/Terra\terra\main.py", line 140, in step
    EVENT_BUS.invoke_handlers(event)

  File "C:/Users/Ian/Documents/GitHub/Terra\terra\event\eventbus.py", line 46, in invoke_handlers
    handler(event)

  File "C:/Users/Ian/Documents/GitHub/Terra\terra\ai\aiplayer.py", line 538, in handle_orders_phase
    self.tasks = self.generate_tasks()

  File "C:/Users/Ian/Documents/GitHub/Terra\terra\ai\aiplayer.py", line 122, in generate_tasks
    tasks.extend(self.generate_research_tasks())

  File "C:/Users/Ian/Documents/GitHub/Terra\terra\ai\aiplayer.py", line 249, in generate_research_tasks
    _, upgrade = upgrades_to_research.get()

  File "C:\Users\Ian\AppData\Local\Programs\Python\Python36-32\lib\queue.py", line 174, in get
    item = self._get()

  File "C:\Users\Ian\AppData\Local\Programs\Python\Python36-32\lib\queue.py", line 230, in _get
    return heappop(self.queue)

2018-05-02 12:35:46,276 WARNING [WARN]: Caught exception while sending message 'b'[TEAM_FI][RED]None''. Retry 2 of 3.
2018-05-02 12:35:46,276 WARNING [WARN]: Caught exception while sending message 'b'[TEAM_FI][RED]None''. Retry 3 of 3.
2018-05-02 12:37:21,434 WARNING [WARN]: Caught exception while sending message 'b'[TEAM_FI][RED]None''. Retry 2 of 3.
2018-05-02 12:37:21,435 WARNING [WARN]: Caught exception while sending message 'b'[TEAM_FI][RED]None''. Retry 3 of 3.
2018-05-02 12:38:33,574 WARNING [WARN]: Caught exception while sending message 'b'[TEAM_FI][RED]None''. Retry 2 of 3.
2018-05-02 12:38:33,575 WARNING [WARN]: Caught exception while sending message 'b'[TEAM_FI][RED]None''. Retry 3 of 3.
2018-05-02 12:39:04,366 WARNING [WARN]: Caught exception while sending message 'b'[TEAM_FI][RED]None''. Retry 2 of 3.
2018-05-02 12:39:04,367 WARNING [WARN]: Caught exception while sending message 'b'[TEAM_FI][RED]None''. Retry 3 of 3.
2018-05-02 12:40:56,724 WARNING [WARN]: Caught exception while sending message 'b'[TEAM_FI][RED]None''. Retry 2 of 3.
2018-05-02 12:40:56,724 WARNING [WARN]: Caught exception while sending message 'b'[TEAM_FI][RED]None''. Retry 3 of 3.
2018-05-02 12:42:05,771 WARNING [WARN]: Caught exception while sending message 'b'[TEAM_FI][RED]None''. Retry 2 of 3.
2018-05-02 12:42:05,771 WARNING [WARN]: Caught exception while sending message 'b'[TEAM_FI][RED]None''. Retry 3 of 3.
2018-05-02 14:40:15,046 WARNING [WARN]: Caught exception while sending message 'b'[TEAM_FI][RED]None''. Retry 2 of 3.
2018-05-02 14:40:15,046 WARNING [WARN]: Caught exception while sending message 'b'[TEAM_FI][RED]None''. Retry 3 of 3.
2018-05-02 15:01:00,223 WARNING [WARN]: Caught exception while sending message 'b'[TEAM_FI][RED]None''. Retry 2 of 3.
2018-05-02 15:01:00,223 WARNING [WARN]: Caught exception while sending message 'b'[TEAM_FI][RED]None''. Retry 3 of 3.
2018-05-02 15:04:16,086 WARNING [WARN]: Caught exception while sending message 'b'[TEAM_FI][RED]None''. Retry 2 of 3.
2018-05-02 15:04:16,086 WARNING [WARN]: Caught exception while sending message 'b'[TEAM_FI][RED]None''. Retry 3 of 3.
2018-05-02 15:17:35,138 WARNING [WARN]: Caught exception while sending message 'b'[TEAM_FI][RED]None''. Retry 2 of 3.
2018-05-02 15:17:35,138 WARNING [WARN]: Caught exception while sending message 'b'[TEAM_FI][RED]None''. Retry 3 of 3.
2018-05-02 15:17:54,863 WARNING [WARN]: Caught exception while sending message 'b'[TEAM_FI][RED]None''. Retry 2 of 3.
2018-05-02 15:17:54,863 WARNING [WARN]: Caught exception while sending message 'b'[TEAM_FI][RED]None''. Retry 3 of 3.
2018-05-02 15:32:30,714 WARNING [WARN]: Caught exception while sending message 'b'[TEAM_FI][RED]None''. Retry 2 of 3.
2018-05-02 15:32:30,714 WARNING [WARN]: Caught exception while sending message 'b'[TEAM_FI][RED]None''. Retry 3 of 3.
2018-05-02 15:32:37,557 WARNING [WARN]: Caught exception while sending message 'b'[TEAM_FI][RED]None''. Retry 2 of 3.
2018-05-02 15:32:37,557 WARNING [WARN]: Caught exception while sending message 'b'[TEAM_FI][RED]None''. Retry 3 of 3.
2018-05-02 15:34:16,431 WARNING [WARN]: Caught exception while sending message 'b'[TEAM_FI][RED]None''. Retry 2 of 3.
2018-05-02 15:34:16,431 WARNING [WARN]: Caught exception while sending message 'b'[TEAM_FI][RED]None''. Retry 3 of 3.
2018-05-02 16:17:12,062 WARNING [WARN]: Caught exception while sending message 'b'[TEAM_FI][RED]None''. Retry 2 of 3.
2018-05-02 16:17:12,062 WARNING [WARN]: Caught exception while sending message 'b'[TEAM_FI][RED]None''. Retry 3 of 3.
2018-05-02 16:36:19,474 WARNING [WARN]: Caught exception while sending message 'b'[TEAM_FI][RED]None''. Retry 2 of 3.
2018-05-02 16:36:19,475 WARNING [WARN]: Caught exception while sending message 'b'[TEAM_FI][RED]None''. Retry 3 of 3.
2018-05-04 13:12:47,437 WARNING [WARN]: Caught exception while sending message 'b'[TEAM_FI][RED]None''. Retry 2 of 3.
2018-05-04 13:12:47,437 WARNING [WARN]: Caught exception while sending message 'b'[TEAM_FI][RED]None''. Retry 3 of 3.
2018-05-04 13:12:47,500 ERROR [ERROR]: Caught exception in the launcher.
2018-05-04 13:12:47,548 ERROR [ERROR]: !=== Caught a fatal exception: ===!
2018-05-04 13:12:47,548 ERROR [ERROR]: Exception: 
GUARDIAN_ENTRENCHMENT
  File "C:/Users/Ian/Documents/GitHub/Terra/launcher.py", line 8, in <module>
    Main().run()

  File "C:\Users\Ian\Documents\GitHub\Terra\terra\main.py", line 193, in run
    self.step(event)

  File "C:\Users\Ian\Documents\GitHub\Terra\terra\main.py", line 140, in step
    EVENT_BUS.invoke_handlers(event)

  File "C:\Users\Ian\Documents\GitHub\Terra\terra\event\eventbus.py", line 46, in invoke_handlers
    handler(event)

  File "C:\Users\Ian\Documents\GitHub\Terra\terra\main.py", line 99, in handle_menu_selections
    self.set_screen_from_mode(Mode.LOBBY, event.mapname, map_type=AssetType.SAVE)

  File "C:\Users\Ian\Documents\GitHub\Terra\terra\main.py", line 66, in set_screen_from_mode
    new_screen = Lobby(False, map_name, map_type)

  File "C:\Users\Ian\Documents\GitHub\Terra\terra\screens\lobby.py", line 31, in __init__
    Session.set_up_local_game(map_name, map_type)

  File "C:\Users\Ian\Documents\GitHub\Terra\terra\managers\session.py", line 45, in set_up_local_game
    SESSION.__set_up__(map_name, bitmap, pieces, teams, upgrades, meta)

  File "C:\Users\Ian\Documents\GitHub\Terra\terra\managers\session.py", line 112, in __set_up__
    from terra.piece.piecemanager import PieceManager

  File "C:\Users\Ian\Documents\GitHub\Terra\terra\piece\piecemanager.py", line 4, in <module>
    from terra.economy.upgrades import base_upgrades

  File "C:\Users\Ian\Documents\GitHub\Terra\terra\economy\upgrades.py", line 21, in <module>
    base_upgrades = read_upgrade_attributes_from_file()

  File "C:\Users\Ian\Documents\GitHub\Terra\terra\economy\upgrades.py", line 14, in read_upgrade_attributes_from_file
    return json.loads(attributes_file.read().replace('\n', ''), object_hook=as_enum)

  File "C:\Users\Ian\AppData\Local\Programs\Python\Python36-32\lib\json\__init__.py", line 367, in loads
    return cls(**kw).decode(s)

  File "C:\Users\Ian\AppData\Local\Programs\Python\Python36-32\lib\json\decoder.py", line 339, in decode
    obj, end = self.raw_decode(s, idx=_w(s, 0).end())

  File "C:\Users\Ian\AppData\Local\Programs\Python\Python36-32\lib\json\decoder.py", line 355, in raw_decode
    obj, end = self.scan_once(s, idx)

  File "C:\Users\Ian\Documents\GitHub\Terra\terra\util\jsonutil.py", line 44, in as_enum
    new_dict[parse_enum(key)] = parse_enum(value)

  File "C:\Users\Ian\Documents\GitHub\Terra\terra\util\jsonutil.py", line 38, in parse_enum
    return [parse_enum(element) for element in obj]

  File "C:\Users\Ian\Documents\GitHub\Terra\terra\util\jsonutil.py", line 38, in <listcomp>
    return [parse_enum(element) for element in obj]

  File "C:\Users\Ian\Documents\GitHub\Terra\terra\util\jsonutil.py", line 33, in parse_enum
    return getattr(KNOWN_ENUMS[split_str[0]], split_str[1])

  File "C:\Users\Ian\AppData\Local\Programs\Python\Python36-32\lib\enum.py", line 324, in __getattr__
    raise AttributeError(name) from None

2018-05-04 13:13:27,019 WARNING [WARN]: Caught exception while sending message 'b'[TEAM_FI][RED]None''. Retry 2 of 3.
2018-05-04 13:13:27,020 WARNING [WARN]: Caught exception while sending message 'b'[TEAM_FI][RED]None''. Retry 3 of 3.
2018-05-04 13:15:43,555 WARNING [WARN]: Caught exception while sending message 'b'[TEAM_FI][RED]None''. Retry 2 of 3.
2018-05-04 13:15:43,556 WARNING [WARN]: Caught exception while sending message 'b'[TEAM_FI][RED]None''. Retry 3 of 3.
2018-05-06 13:49:52,026 WARNING [WARN]: Caught exception while sending message 'b'[TEAM_FI][RED]None''. Retry 2 of 3.
2018-05-06 13:49:52,027 WARNING [WARN]: Caught exception while sending message 'b'[TEAM_FI][RED]None''. Retry 3 of 3.
2018-05-06 14:02:45,721 WARNING [WARN]: Caught exception while sending message 'b'[TEAM_FI][RED]None''. Retry 2 of 3.
2018-05-06 14:02:45,722 WARNING [WARN]: Caught exception while sending message 'b'[TEAM_FI][RED]None''. Retry 3 of 3.
2018-05-06 14:02:46,054 ERROR [ERROR]: Caught exception in the launcher.
2018-05-06 14:02:46,061 ERROR [ERROR]: !=== Caught a fatal exception: ===!
2018-05-06 14:02:46,061 ERROR [ERROR]: Exception: 
'Personality' object has no attribute 'unit_construction_weight'
  File "C:/Users/Ian/Documents/GitHub/Terra/launcher.py", line 8, in <module>
    Main().run()

  File "C:\Users\Ian\Documents\GitHub\Terra\terra\main.py", line 193, in run
    self.step(event)

  File "C:\Users\Ian\Documents\GitHub\Terra\terra\main.py", line 140, in step
    EVENT_BUS.invoke_handlers(event)

  File "C:\Users\Ian\Documents\GitHub\Terra\terra\event\eventbus.py", line 46, in invoke_handlers
    handler(event)

  File "C:\Users\Ian\Documents\GitHub\Terra\terra\ai\aiplayer.py", line 534, in handle_orders_phase
    self.tasks = self.generate_tasks()

  File "C:\Users\Ian\Documents\GitHub\Terra\terra\ai\aiplayer.py", line 120, in generate_tasks
    tasks.extend(self.generate_economic_tasks())

  File "C:\Users\Ian\Documents\GitHub\Terra\terra\ai\aiplayer.py", line 197, in generate_economic_tasks
    tasks.extend(self.create_build_military_tasks())

  File "C:\Users\Ian\Documents\GitHub\Terra\terra\ai\aiplayer.py", line 344, in create_build_military_tasks
    counts_map[archetype] = count / self.personality.unit_construction_weight[archetype]

2018-05-06 14:03:15,248 WARNING [WARN]: Caught exception while sending message 'b'[TEAM_FI][RED]None''. Retry 2 of 3.
2018-05-06 14:03:15,248 WARNING [WARN]: Caught exception while sending message 'b'[TEAM_FI][RED]None''. Retry 3 of 3.
2018-05-06 14:40:44,302 WARNING [WARN]: Caught exception while sending message 'b'[TEAM_FI][RED]None''. Retry 2 of 3.
2018-05-06 14:40:44,302 WARNING [WARN]: Caught exception while sending message 'b'[TEAM_FI][RED]None''. Retry 3 of 3.
2018-05-06 14:40:44,385 ERROR [ERROR]: Caught exception in the launcher.
2018-05-06 14:40:44,395 ERROR [ERROR]: !=== Caught a fatal exception: ===!
2018-05-06 14:40:44,395 ERROR [ERROR]: Exception: 
'NoneType' object is not iterable
  File "C:/Users/Ian/Documents/GitHub/Terra/launcher.py", line 8, in <module>
    Main().run()

  File "C:\Users\Ian\Documents\GitHub\Terra\terra\main.py", line 193, in run
    self.step(event)

  File "C:\Users\Ian\Documents\GitHub\Terra\terra\main.py", line 140, in step
    EVENT_BUS.invoke_handlers(event)

  File "C:\Users\Ian\Documents\GitHub\Terra\terra\event\eventbus.py", line 46, in invoke_handlers
    handler(event)

  File "C:\Users\Ian\Documents\GitHub\Terra\terra\ai\aiplayer.py", line 536, in threaded_handle_orders_phase
    process = Process(target=self.debug_handle_orders_phase, args=(None))

  File "C:\Users\Ian\AppData\Local\Programs\Python\Python36-32\lib\multiprocessing\process.py", line 80, in __init__
    self._args = tuple(args)

2018-05-06 14:41:06,561 WARNING [WARN]: Caught exception while sending message 'b'[TEAM_FI][RED]None''. Retry 2 of 3.
2018-05-06 14:41:06,561 WARNING [WARN]: Caught exception while sending message 'b'[TEAM_FI][RED]None''. Retry 3 of 3.
2018-05-06 14:41:06,675 ERROR [ERROR]: Caught exception in the launcher.
2018-05-06 14:41:06,687 ERROR [ERROR]: !=== Caught a fatal exception: ===!
2018-05-06 14:41:06,688 ERROR [ERROR]: Exception: 
can't pickle pygame.Surface objects
  File "C:/Users/Ian/Documents/GitHub/Terra/launcher.py", line 8, in <module>
    Main().run()

  File "C:\Users\Ian\Documents\GitHub\Terra\terra\main.py", line 193, in run
    self.step(event)

  File "C:\Users\Ian\Documents\GitHub\Terra\terra\main.py", line 140, in step
    EVENT_BUS.invoke_handlers(event)

  File "C:\Users\Ian\Documents\GitHub\Terra\terra\event\eventbus.py", line 46, in invoke_handlers
    handler(event)

  File "C:\Users\Ian\Documents\GitHub\Terra\terra\ai\aiplayer.py", line 539, in threaded_handle_orders_phase
    process.start()

  File "C:\Users\Ian\AppData\Local\Programs\Python\Python36-32\lib\multiprocessing\process.py", line 105, in start
    self._popen = self._Popen(self)

  File "C:\Users\Ian\AppData\Local\Programs\Python\Python36-32\lib\multiprocessing\context.py", line 223, in _Popen
    return _default_context.get_context().Process._Popen(process_obj)

  File "C:\Users\Ian\AppData\Local\Programs\Python\Python36-32\lib\multiprocessing\context.py", line 322, in _Popen
    return Popen(process_obj)

  File "C:\Users\Ian\AppData\Local\Programs\Python\Python36-32\lib\multiprocessing\popen_spawn_win32.py", line 65, in __init__
    reduction.dump(process_obj, to_child)

  File "C:\Users\Ian\AppData\Local\Programs\Python\Python36-32\lib\multiprocessing\reduction.py", line 60, in dump
    ForkingPickler(file, protocol).dump(obj)

2018-05-06 14:49:03,336 WARNING [WARN]: Caught exception while sending message 'b'[TEAM_FI][RED]None''. Retry 2 of 3.
2018-05-06 14:49:03,336 WARNING [WARN]: Caught exception while sending message 'b'[TEAM_FI][RED]None''. Retry 3 of 3.
2018-05-06 14:49:35,298 WARNING [WARN]: Caught exception while sending message 'b'[TEAM_FI][RED]None''. Retry 2 of 3.
2018-05-06 14:49:35,298 WARNING [WARN]: Caught exception while sending message 'b'[TEAM_FI][RED]None''. Retry 3 of 3.
2018-05-06 14:49:54,914 WARNING [WARN]: Caught exception while sending message 'b'[TEAM_FI][RED]None''. Retry 2 of 3.
2018-05-06 14:49:54,914 WARNING [WARN]: Caught exception while sending message 'b'[TEAM_FI][RED]None''. Retry 3 of 3.
2018-05-06 14:50:25,868 WARNING [WARN]: Caught exception while sending message 'b'[TEAM_FI][RED]None''. Retry 2 of 3.
2018-05-06 14:50:25,868 WARNING [WARN]: Caught exception while sending message 'b'[TEAM_FI][RED]None''. Retry 3 of 3.
2018-05-06 14:50:44,957 WARNING [WARN]: Caught exception while sending message 'b'[TEAM_FI][RED]None''. Retry 2 of 3.
2018-05-06 14:50:44,958 WARNING [WARN]: Caught exception while sending message 'b'[TEAM_FI][RED]None''. Retry 3 of 3.
2018-05-06 14:51:03,663 WARNING [WARN]: Caught exception while sending message 'b'[TEAM_FI][RED]None''. Retry 2 of 3.
2018-05-06 14:51:03,663 WARNING [WARN]: Caught exception while sending message 'b'[TEAM_FI][RED]None''. Retry 3 of 3.
2018-05-06 14:54:10,941 WARNING [WARN]: Caught exception while sending message 'b'[TEAM_FI][RED]None''. Retry 2 of 3.
2018-05-06 14:54:10,941 WARNING [WARN]: Caught exception while sending message 'b'[TEAM_FI][RED]None''. Retry 3 of 3.
2018-05-06 15:04:47,043 WARNING [WARN]: Caught exception while sending message 'b'[TEAM_FI][RED]None''. Retry 2 of 3.
2018-05-06 15:04:47,043 WARNING [WARN]: Caught exception while sending message 'b'[TEAM_FI][RED]None''. Retry 3 of 3.
2018-05-06 15:04:52,099 ERROR [ERROR]: Caught exception in the launcher.
2018-05-06 15:04:52,111 ERROR [ERROR]: !=== Caught a fatal exception: ===!
2018-05-06 15:04:52,111 ERROR [ERROR]: Exception: 
<Team.BLUE: '[BLU]'>
  File "C:/Users/Ian/Documents/GitHub/Terra/launcher.py", line 8, in <module>
    Main().run()

  File "C:\Users\Ian\Documents\GitHub\Terra\terra\main.py", line 199, in run
    self.render()

  File "C:\Users\Ian\Documents\GitHub\Terra\terra\main.py", line 156, in render
    game_screen = self.current_screen.render(ui_screen)

  File "C:\Users\Ian\Documents\GitHub\Terra\terra\screens\battle.py", line 44, in render
    SESSION.render(map_screen, ui_screen)

  File "C:\Users\Ian\Documents\GitHub\Terra\terra\managers\session.py", line 136, in render
    manager.render(game_screen, ui_screen)

  File "C:\Users\Ian\Documents\GitHub\Terra\terra\team\teammanager.py", line 351, in render
    phase_bar.render(game_screen, ui_screen)

  File "C:\Users\Ian\Documents\GitHub\Terra\terra\ui\phasebar.py", line 85, in render
    ui_screen.blit(sprite[team], (GRID_WIDTH * x, RESOLUTION_HEIGHT - GRID_HEIGHT))

2018-05-06 15:05:48,846 WARNING [WARN]: Caught exception while sending message 'b'[TEAM_FI][RED]None''. Retry 2 of 3.
2018-05-06 15:05:48,846 WARNING [WARN]: Caught exception while sending message 'b'[TEAM_FI][RED]None''. Retry 3 of 3.
2018-05-06 15:05:54,860 WARNING [WARN]: Caught exception while sending message 'b'[TEAM_FI][RED]None''. Retry 2 of 3.
2018-05-06 15:05:54,860 WARNING [WARN]: Caught exception while sending message 'b'[TEAM_FI][RED]None''. Retry 3 of 3.
2018-05-06 15:07:54,543 WARNING [WARN]: Caught exception while sending message 'b'[TEAM_FI][RED]None''. Retry 2 of 3.
2018-05-06 15:07:54,543 WARNING [WARN]: Caught exception while sending message 'b'[TEAM_FI][RED]None''. Retry 3 of 3.
2018-05-06 15:11:58,209 WARNING [WARN]: Caught exception while sending message 'b'[TEAM_FI][RED]None''. Retry 2 of 3.
2018-05-06 15:11:58,209 WARNING [WARN]: Caught exception while sending message 'b'[TEAM_FI][RED]None''. Retry 3 of 3.
2018-05-06 15:12:01,828 WARNING [WARN]: Caught exception while sending message 'b'[TEAM_FI][RED]None''. Retry 2 of 3.
2018-05-06 15:12:01,828 WARNING [WARN]: Caught exception while sending message 'b'[TEAM_FI][RED]None''. Retry 3 of 3.
2018-05-06 15:15:56,914 WARNING [WARN]: Caught exception while sending message 'b'[TEAM_FI][RED]None''. Retry 2 of 3.
2018-05-06 15:15:56,914 WARNING [WARN]: Caught exception while sending message 'b'[TEAM_FI][RED]None''. Retry 3 of 3.
2018-05-06 15:17:01,180 WARNING [WARN]: Caught exception while sending message 'b'[TEAM_FI][RED]None''. Retry 2 of 3.
2018-05-06 15:17:01,180 WARNING [WARN]: Caught exception while sending message 'b'[TEAM_FI][RED]None''. Retry 3 of 3.
2018-05-06 15:17:58,802 WARNING [WARN]: Caught exception while sending message 'b'[TEAM_FI][RED]None''. Retry 2 of 3.
2018-05-06 15:17:58,802 WARNING [WARN]: Caught exception while sending message 'b'[TEAM_FI][RED]None''. Retry 3 of 3.
2018-05-06 15:18:08,801 WARNING [WARN]: Caught exception while sending message 'b'[TEAM_FI][RED]None''. Retry 2 of 3.
2018-05-06 15:18:08,802 WARNING [WARN]: Caught exception while sending message 'b'[TEAM_FI][RED]None''. Retry 3 of 3.
2018-05-06 15:21:19,087 WARNING [WARN]: Caught exception while sending message 'b'[TEAM_FI][RED]None''. Retry 2 of 3.
2018-05-06 15:21:19,087 WARNING [WARN]: Caught exception while sending message 'b'[TEAM_FI][RED]None''. Retry 3 of 3.
2018-05-06 15:22:25,943 WARNING [WARN]: Caught exception while sending message 'b'[TEAM_FI][RED]None''. Retry 2 of 3.
2018-05-06 15:22:25,943 WARNING [WARN]: Caught exception while sending message 'b'[TEAM_FI][RED]None''. Retry 3 of 3.
2018-05-06 15:26:25,444 WARNING [WARN]: Caught exception while sending message 'b'[TEAM_FI][RED]None''. Retry 2 of 3.
2018-05-06 15:26:25,445 WARNING [WARN]: Caught exception while sending message 'b'[TEAM_FI][RED]None''. Retry 3 of 3.
2018-05-06 16:42:02,787 WARNING [WARN]: Caught exception while sending message 'b'[TEAM_FI][RED]None''. Retry 2 of 3.
2018-05-06 16:42:02,787 WARNING [WARN]: Caught exception while sending message 'b'[TEAM_FI][RED]None''. Retry 3 of 3.
2018-05-06 16:43:17,890 WARNING [WARN]: Caught exception while sending message 'b'[TEAM_FI][RED]None''. Retry 2 of 3.
2018-05-06 16:43:17,891 WARNING [WARN]: Caught exception while sending message 'b'[TEAM_FI][RED]None''. Retry 3 of 3.
2018-05-06 16:43:55,707 WARNING [WARN]: Caught exception while sending message 'b'[TEAM_FI][RED]None''. Retry 2 of 3.
2018-05-06 16:43:55,707 WARNING [WARN]: Caught exception while sending message 'b'[TEAM_FI][RED]None''. Retry 3 of 3.
2018-05-06 16:56:43,683 WARNING [WARN]: Caught exception while sending message 'b'[TEAM_FI][RED]None''. Retry 2 of 3.
2018-05-06 16:56:43,683 WARNING [WARN]: Caught exception while sending message 'b'[TEAM_FI][RED]None''. Retry 3 of 3.
2018-05-06 16:57:31,502 WARNING [WARN]: Caught exception while sending message 'b'[TEAM_FI][RED]None''. Retry 2 of 3.
2018-05-06 16:57:31,502 WARNING [WARN]: Caught exception while sending message 'b'[TEAM_FI][RED]None''. Retry 3 of 3.
2018-05-07 18:24:46,053 WARNING [WARN]: Caught exception while sending message 'b'[TEAM_FI][RED]None''. Retry 2 of 3.
2018-05-07 18:24:46,054 WARNING [WARN]: Caught exception while sending message 'b'[TEAM_FI][RED]None''. Retry 3 of 3.
2018-05-07 19:18:50,232 WARNING [WARN]: Caught exception while sending message 'b'[TEAM_FI][RED]None''. Retry 2 of 3.
2018-05-07 19:18:50,232 WARNING [WARN]: Caught exception while sending message 'b'[TEAM_FI][RED]None''. Retry 3 of 3.
2018-05-09 15:02:19,447 WARNING [WARN]: Caught exception while sending message 'b'[TEAM_FI][RED]None''. Retry 2 of 3.
2018-05-09 15:02:19,448 WARNING [WARN]: Caught exception while sending message 'b'[TEAM_FI][RED]None''. Retry 3 of 3.
2018-05-09 17:16:38,054 WARNING [WARN]: Caught exception while sending message 'b'[TEAM_FI][RED]None''. Retry 2 of 3.
2018-05-09 17:16:38,054 WARNING [WARN]: Caught exception while sending message 'b'[TEAM_FI][RED]None''. Retry 3 of 3.
2018-05-09 17:17:45,628 WARNING [WARN]: Caught exception while sending message 'b'[TEAM_FI][RED]None''. Retry 2 of 3.
2018-05-09 17:17:45,628 WARNING [WARN]: Caught exception while sending message 'b'[TEAM_FI][RED]None''. Retry 3 of 3.
2018-05-09 17:21:24,616 WARNING [WARN]: Caught exception while sending message 'b'[TEAM_FI][RED]None''. Retry 2 of 3.
2018-05-09 17:21:24,616 WARNING [WARN]: Caught exception while sending message 'b'[TEAM_FI][RED]None''. Retry 3 of 3.
2018-05-09 17:21:58,338 WARNING [WARN]: Caught exception while sending message 'b'[TEAM_FI][RED]None''. Retry 2 of 3.
2018-05-09 17:21:58,339 WARNING [WARN]: Caught exception while sending message 'b'[TEAM_FI][RED]None''. Retry 3 of 3.
2018-05-09 17:21:58,376 ERROR [ERROR]: Caught exception in the launcher.
2018-05-09 17:21:58,393 ERROR [ERROR]: !=== Caught a fatal exception: ===!
2018-05-09 17:21:58,393 ERROR [ERROR]: Exception: 
'BattleCursor' object has no attribute 'menu'
  File "C:/Users/Ian/Documents/GitHub/Terra/launcher.py", line 8, in <module>
    Main().run()

  File "C:\Users\Ian\Documents\GitHub\Terra\terra\main.py", line 193, in run
    self.step(event)

  File "C:\Users\Ian\Documents\GitHub\Terra\terra\main.py", line 140, in step
    EVENT_BUS.invoke_handlers(event)

  File "C:\Users\Ian\Documents\GitHub\Terra\terra\event\eventbus.py", line 46, in invoke_handlers
    handler(event)

  File "C:\Users\Ian\Documents\GitHub\Terra\terra\main.py", line 97, in handle_menu_selections
    self.set_screen_from_mode(Mode.LOBBY, event.mapname)

  File "C:\Users\Ian\Documents\GitHub\Terra\terra\main.py", line 66, in set_screen_from_mode
    new_screen = Lobby(False, map_name, map_type)

  File "C:\Users\Ian\Documents\GitHub\Terra\terra\screens\lobby.py", line 31, in __init__
    Session.set_up_local_game(map_name, map_type)

  File "C:\Users\Ian\Documents\GitHub\Terra\terra\managers\session.py", line 45, in set_up_local_game
    SESSION.__set_up__(map_name, bitmap, pieces, teams, upgrades, meta)

  File "C:\Users\Ian\Documents\GitHub\Terra\terra\managers\session.py", line 124, in __set_up__
    self.managers[Manager.PLAYER] = PlayerManager()

  File "C:\Users\Ian\Documents\GitHub\Terra\terra\team\playermanager.py", line 29, in __init__
    self.cursors[team] = self.create_cursor(team)

  File "C:\Users\Ian\Documents\GitHub\Terra\terra\team\playermanager.py", line 68, in create_cursor
    return BattleCursor(team)

  File "C:\Users\Ian\Documents\GitHub\Terra\terra\ui\battlecursor.py", line 23, in __init__
    super().__init__(team)

  File "C:\Users\Ian\Documents\GitHub\Terra\terra\ui\cursor.py", line 34, in __init__
    self.scroll_camera()

  File "C:\Users\Ian\Documents\GitHub\Terra\terra\ui\cursor.py", line 93, in scroll_camera
    if self.is_active():

  File "C:\Users\Ian\Documents\GitHub\Terra\terra\ui\battlecursor.py", line 92, in is_active
    return super().is_active() and not self.menu and pygame.mouse.get_focused()

2018-05-09 17:22:27,804 WARNING [WARN]: Caught exception while sending message 'b'[TEAM_FI][RED]None''. Retry 2 of 3.
2018-05-09 17:22:27,805 WARNING [WARN]: Caught exception while sending message 'b'[TEAM_FI][RED]None''. Retry 3 of 3.
2018-05-09 17:22:27,849 ERROR [ERROR]: Caught exception in the launcher.
2018-05-09 17:22:27,852 ERROR [ERROR]: !=== Caught a fatal exception: ===!
2018-05-09 17:22:27,852 ERROR [ERROR]: Exception: 
'BattleCursor' object has no attribute 'menu'
  File "C:/Users/Ian/Documents/GitHub/Terra/launcher.py", line 8, in <module>
    Main().run()

  File "C:/Users/Ian/Documents/GitHub/Terra\terra\main.py", line 193, in run
    self.step(event)

  File "C:/Users/Ian/Documents/GitHub/Terra\terra\main.py", line 140, in step
    EVENT_BUS.invoke_handlers(event)

  File "C:/Users/Ian/Documents/GitHub/Terra\terra\event\eventbus.py", line 46, in invoke_handlers
    handler(event)

  File "C:/Users/Ian/Documents/GitHub/Terra\terra\main.py", line 97, in handle_menu_selections
    self.set_screen_from_mode(Mode.LOBBY, event.mapname)

  File "C:/Users/Ian/Documents/GitHub/Terra\terra\main.py", line 66, in set_screen_from_mode
    new_screen = Lobby(False, map_name, map_type)

  File "C:/Users/Ian/Documents/GitHub/Terra\terra\screens\lobby.py", line 31, in __init__
    Session.set_up_local_game(map_name, map_type)

  File "C:/Users/Ian/Documents/GitHub/Terra\terra\managers\session.py", line 45, in set_up_local_game
    SESSION.__set_up__(map_name, bitmap, pieces, teams, upgrades, meta)

  File "C:/Users/Ian/Documents/GitHub/Terra\terra\managers\session.py", line 124, in __set_up__
    self.managers[Manager.PLAYER] = PlayerManager()

  File "C:/Users/Ian/Documents/GitHub/Terra\terra\team\playermanager.py", line 29, in __init__
    self.cursors[team] = self.create_cursor(team)

  File "C:/Users/Ian/Documents/GitHub/Terra\terra\team\playermanager.py", line 68, in create_cursor
    return BattleCursor(team)

  File "C:/Users/Ian/Documents/GitHub/Terra\terra\ui\battlecursor.py", line 23, in __init__
    super().__init__(team)

  File "C:/Users/Ian/Documents/GitHub/Terra\terra\ui\cursor.py", line 34, in __init__
    self.scroll_camera()

  File "C:/Users/Ian/Documents/GitHub/Terra\terra\ui\cursor.py", line 93, in scroll_camera
    if self.is_active():

  File "C:/Users/Ian/Documents/GitHub/Terra\terra\ui\battlecursor.py", line 92, in is_active
    return not self.menu and pygame.mouse.get_focused()

2018-05-09 17:23:19,900 WARNING [WARN]: Caught exception while sending message 'b'[TEAM_FI][RED]None''. Retry 2 of 3.
2018-05-09 17:23:19,900 WARNING [WARN]: Caught exception while sending message 'b'[TEAM_FI][RED]None''. Retry 3 of 3.
2018-05-09 17:29:19,143 WARNING [WARN]: Caught exception while sending message 'b'[TEAM_FI][RED]None''. Retry 2 of 3.
2018-05-09 17:29:19,143 WARNING [WARN]: Caught exception while sending message 'b'[TEAM_FI][RED]None''. Retry 3 of 3.
2018-05-09 17:51:35,931 WARNING [WARN]: Caught exception while sending message 'b'[TEAM_FI][RED]None''. Retry 2 of 3.
2018-05-09 17:51:35,931 WARNING [WARN]: Caught exception while sending message 'b'[TEAM_FI][RED]None''. Retry 3 of 3.
2018-05-09 17:51:37,781 ERROR [ERROR]: Caught exception in the launcher.
2018-05-09 17:51:37,801 ERROR [ERROR]: !=== Caught a fatal exception: ===!
2018-05-09 17:51:37,801 ERROR [ERROR]: Exception: 
(<TileType.GRASS: 2>, <TileType.SEA: 1>) is not a valid TileType
  File "C:/Users/Ian/Documents/GitHub/Terra/launcher.py", line 8, in <module>
    Main().run()

  File "C:\Users\Ian\Documents\GitHub\Terra\terra\main.py", line 193, in run
    self.step(event)

  File "C:\Users\Ian\Documents\GitHub\Terra\terra\main.py", line 137, in step
    INPUT_CONTROLLER.invoke_handlers(event)

  File "C:\Users\Ian\Documents\GitHub\Terra\terra\control\inputcontroller.py", line 55, in invoke_handlers
    handler()

  File "C:\Users\Ian\Documents\GitHub\Terra\terra\ui\editorcursor.py", line 40, in cancel
    self.place_tile(self.tile_type[1])

  File "C:\Users\Ian\Documents\GitHub\Terra\terra\ui\editorcursor.py", line 76, in place_tile
    self.get_manager(Manager.MAP).update_tile_type(self.gx, self.gy, self.tile_type)

  File "C:\Users\Ian\Documents\GitHub\Terra\terra\map\mapmanager.py", line 121, in update_tile_type
    self.tile_grid[gy][gx] = Tile(self, new_tile_type, gx, gy)

  File "C:\Users\Ian\Documents\GitHub\Terra\terra\map\tile.py", line 13, in __init__
    self.tile_type = TileType(tile_type)

  File "C:\Users\Ian\AppData\Local\Programs\Python\Python36-32\lib\enum.py", line 291, in __call__
    return cls.__new__(cls, value)

  File "C:\Users\Ian\AppData\Local\Programs\Python\Python36-32\lib\enum.py", line 533, in __new__
    return cls._missing_(value)

  File "C:\Users\Ian\AppData\Local\Programs\Python\Python36-32\lib\enum.py", line 546, in _missing_
    raise ValueError("%r is not a valid %s" % (value, cls.__name__))

2018-05-09 17:52:07,748 WARNING [WARN]: Caught exception while sending message 'b'[TEAM_FI][RED]None''. Retry 2 of 3.
2018-05-09 17:52:07,749 WARNING [WARN]: Caught exception while sending message 'b'[TEAM_FI][RED]None''. Retry 3 of 3.
2018-05-09 17:52:08,848 ERROR [ERROR]: Caught exception in the launcher.
2018-05-09 17:52:08,851 ERROR [ERROR]: !=== Caught a fatal exception: ===!
2018-05-09 17:52:08,851 ERROR [ERROR]: Exception: 
(<TileType.GRASS: 2>, <TileType.SEA: 1>) is not a valid TileType
  File "C:/Users/Ian/Documents/GitHub/Terra/launcher.py", line 8, in <module>
    Main().run()

  File "C:/Users/Ian/Documents/GitHub/Terra\terra\main.py", line 193, in run
    self.step(event)

  File "C:/Users/Ian/Documents/GitHub/Terra\terra\main.py", line 137, in step
    INPUT_CONTROLLER.invoke_handlers(event)

  File "C:/Users/Ian/Documents/GitHub/Terra\terra\control\inputcontroller.py", line 55, in invoke_handlers
    handler()

  File "C:/Users/Ian/Documents/GitHub/Terra\terra\ui\editorcursor.py", line 40, in cancel
    self.place_tile(self.tile_type[1])

  File "C:/Users/Ian/Documents/GitHub/Terra\terra\ui\editorcursor.py", line 76, in place_tile
    self.get_manager(Manager.MAP).update_tile_type(self.gx, self.gy, self.tile_type)

  File "C:/Users/Ian/Documents/GitHub/Terra\terra\map\mapmanager.py", line 121, in update_tile_type
    self.tile_grid[gy][gx] = Tile(self, new_tile_type, gx, gy)

  File "C:/Users/Ian/Documents/GitHub/Terra\terra\map\tile.py", line 13, in __init__
    self.tile_type = TileType(tile_type)

  File "C:\Users\Ian\AppData\Local\Programs\Python\Python36-32\lib\enum.py", line 291, in __call__
    return cls.__new__(cls, value)

  File "C:\Users\Ian\AppData\Local\Programs\Python\Python36-32\lib\enum.py", line 533, in __new__
    return cls._missing_(value)

  File "C:\Users\Ian\AppData\Local\Programs\Python\Python36-32\lib\enum.py", line 546, in _missing_
    raise ValueError("%r is not a valid %s" % (value, cls.__name__))

2018-05-09 17:52:23,303 WARNING [WARN]: Caught exception while sending message 'b'[TEAM_FI][RED]None''. Retry 2 of 3.
2018-05-09 17:52:23,304 WARNING [WARN]: Caught exception while sending message 'b'[TEAM_FI][RED]None''. Retry 3 of 3.
2018-05-09 17:53:01,199 WARNING [WARN]: Caught exception while sending message 'b'[TEAM_FI][RED]None''. Retry 2 of 3.
2018-05-09 17:53:01,200 WARNING [WARN]: Caught exception while sending message 'b'[TEAM_FI][RED]None''. Retry 3 of 3.
2018-05-09 17:53:04,763 ERROR [ERROR]: Caught exception in the launcher.
2018-05-09 17:53:04,767 ERROR [ERROR]: !=== Caught a fatal exception: ===!
2018-05-09 17:53:04,767 ERROR [ERROR]: Exception: 
[<TileType.GRASS: 2>, <TileType.SEA: 1>] is not a valid TileType
  File "C:/Users/Ian/Documents/GitHub/Terra/launcher.py", line 8, in <module>
    Main().run()

  File "C:/Users/Ian/Documents/GitHub/Terra\terra\main.py", line 193, in run
    self.step(event)

  File "C:/Users/Ian/Documents/GitHub/Terra\terra\main.py", line 137, in step
    INPUT_CONTROLLER.invoke_handlers(event)

  File "C:/Users/Ian/Documents/GitHub/Terra\terra\control\inputcontroller.py", line 55, in invoke_handlers
    handler()

  File "C:/Users/Ian/Documents/GitHub/Terra\terra\ui\editorcursor.py", line 40, in cancel
    self.place_tile(self.tile_type[1])

  File "C:/Users/Ian/Documents/GitHub/Terra\terra\ui\editorcursor.py", line 76, in place_tile
    self.get_manager(Manager.MAP).update_tile_type(self.gx, self.gy, self.tile_type)

  File "C:/Users/Ian/Documents/GitHub/Terra\terra\map\mapmanager.py", line 121, in update_tile_type
    self.tile_grid[gy][gx] = Tile(self, new_tile_type, gx, gy)

  File "C:/Users/Ian/Documents/GitHub/Terra\terra\map\tile.py", line 13, in __init__
    self.tile_type = TileType(tile_type)

  File "C:\Users\Ian\AppData\Local\Programs\Python\Python36-32\lib\enum.py", line 291, in __call__
    return cls.__new__(cls, value)

  File "C:\Users\Ian\AppData\Local\Programs\Python\Python36-32\lib\enum.py", line 533, in __new__
    return cls._missing_(value)

  File "C:\Users\Ian\AppData\Local\Programs\Python\Python36-32\lib\enum.py", line 546, in _missing_
    raise ValueError("%r is not a valid %s" % (value, cls.__name__))

2018-05-09 17:54:52,832 WARNING [WARN]: Caught exception while sending message 'b'[TEAM_FI][RED]None''. Retry 2 of 3.
2018-05-09 17:54:52,832 WARNING [WARN]: Caught exception while sending message 'b'[TEAM_FI][RED]None''. Retry 3 of 3.
2018-05-09 17:54:53,630 ERROR [ERROR]: Caught exception in the launcher.
2018-05-09 17:54:53,632 ERROR [ERROR]: !=== Caught a fatal exception: ===!
2018-05-09 17:54:53,632 ERROR [ERROR]: Exception: 
list indices must be integers or slices, not float
  File "C:/Users/Ian/Documents/GitHub/Terra/launcher.py", line 8, in <module>
    Main().run()

  File "C:\Users\Ian\Documents\GitHub\Terra\terra\main.py", line 193, in run
    self.step(event)

  File "C:\Users\Ian\Documents\GitHub\Terra\terra\main.py", line 137, in step
    INPUT_CONTROLLER.invoke_handlers(event)

  File "C:\Users\Ian\Documents\GitHub\Terra\terra\control\inputcontroller.py", line 55, in invoke_handlers
    handler()

  File "C:\Users\Ian\Documents\GitHub\Terra\terra\ui\editorcursor.py", line 40, in cancel
    self.place_tile(self.tile_type[1])

  File "C:\Users\Ian\Documents\GitHub\Terra\terra\ui\editorcursor.py", line 76, in place_tile
    self.get_manager(Manager.MAP).update_tile_type(self.gx, self.gy, tile_type)

  File "C:\Users\Ian\Documents\GitHub\Terra\terra\map\mapmanager.py", line 121, in update_tile_type
    self.tile_grid[gy][gx] = Tile(self, new_tile_type, gx, gy)

2018-05-09 17:55:11,923 WARNING [WARN]: Caught exception while sending message 'b'[TEAM_FI][RED]None''. Retry 2 of 3.
2018-05-09 17:55:11,924 WARNING [WARN]: Caught exception while sending message 'b'[TEAM_FI][RED]None''. Retry 3 of 3.
2018-05-09 17:55:23,360 ERROR [ERROR]: Caught exception in the launcher.
2018-05-09 17:55:23,362 ERROR [ERROR]: !=== Caught a fatal exception: ===!
2018-05-09 17:55:23,362 ERROR [ERROR]: Exception: 
list indices must be integers or slices, not float
  File "C:/Users/Ian/Documents/GitHub/Terra/launcher.py", line 8, in <module>
    Main().run()

  File "C:/Users/Ian/Documents/GitHub/Terra\terra\main.py", line 193, in run
    self.step(event)

  File "C:/Users/Ian/Documents/GitHub/Terra\terra\main.py", line 137, in step
    INPUT_CONTROLLER.invoke_handlers(event)

  File "C:/Users/Ian/Documents/GitHub/Terra\terra\control\inputcontroller.py", line 55, in invoke_handlers
    handler()

  File "C:/Users/Ian/Documents/GitHub/Terra\terra\ui\editorcursor.py", line 40, in cancel
    self.place_tile(self.tile_type[1])

  File "C:/Users/Ian/Documents/GitHub/Terra\terra\ui\editorcursor.py", line 76, in place_tile
    self.get_manager(Manager.MAP).update_tile_type(self.gx, self.gy, tile_type)

  File "C:/Users/Ian/Documents/GitHub/Terra\terra\map\mapmanager.py", line 121, in update_tile_type
    self.tile_grid[gy][gx] = Tile(self, new_tile_type, gx, gy)

2018-05-09 17:56:29,352 WARNING [WARN]: Caught exception while sending message 'b'[TEAM_FI][RED]None''. Retry 2 of 3.
2018-05-09 17:56:29,353 WARNING [WARN]: Caught exception while sending message 'b'[TEAM_FI][RED]None''. Retry 3 of 3.
2018-05-09 17:56:30,204 ERROR [ERROR]: Caught exception in the launcher.
2018-05-09 17:56:30,206 ERROR [ERROR]: !=== Caught a fatal exception: ===!
2018-05-09 17:56:30,206 ERROR [ERROR]: Exception: 
list indices must be integers or slices, not float
  File "C:/Users/Ian/Documents/GitHub/Terra/launcher.py", line 8, in <module>
    Main().run()

  File "C:/Users/Ian/Documents/GitHub/Terra\terra\main.py", line 193, in run
    self.step(event)

  File "C:/Users/Ian/Documents/GitHub/Terra\terra\main.py", line 137, in step
    INPUT_CONTROLLER.invoke_handlers(event)

  File "C:/Users/Ian/Documents/GitHub/Terra\terra\control\inputcontroller.py", line 55, in invoke_handlers
    handler()

  File "C:/Users/Ian/Documents/GitHub/Terra\terra\ui\editorcursor.py", line 40, in cancel
    self.place_tile(self.tile_type[1])

  File "C:/Users/Ian/Documents/GitHub/Terra\terra\ui\editorcursor.py", line 76, in place_tile
    self.get_manager(Manager.MAP).update_tile_type(self.gx, self.gy, tile_type)

  File "C:/Users/Ian/Documents/GitHub/Terra\terra\map\mapmanager.py", line 121, in update_tile_type
    self.tile_grid[gy][gx] = Tile(self, new_tile_type, gx, gy)

2018-05-09 17:57:36,623 WARNING [WARN]: Caught exception while sending message 'b'[TEAM_FI][RED]None''. Retry 2 of 3.
2018-05-09 17:57:36,624 WARNING [WARN]: Caught exception while sending message 'b'[TEAM_FI][RED]None''. Retry 3 of 3.
2018-05-09 17:58:00,811 WARNING [WARN]: Caught exception while sending message 'b'[TEAM_FI][RED]None''. Retry 2 of 3.
2018-05-09 17:58:00,811 WARNING [WARN]: Caught exception while sending message 'b'[TEAM_FI][RED]None''. Retry 3 of 3.
2018-05-09 17:58:06,757 ERROR [ERROR]: Caught exception in the launcher.
2018-05-09 17:58:06,765 ERROR [ERROR]: !=== Caught a fatal exception: ===!
2018-05-09 17:58:06,765 ERROR [ERROR]: Exception: 
'NoneType' object has no attribute 'destroy'
  File "C:/Users/Ian/Documents/GitHub/Terra/launcher.py", line 8, in <module>
    Main().run()

  File "C:\Users\Ian\Documents\GitHub\Terra\terra\main.py", line 193, in run
    self.step(event)

  File "C:\Users\Ian\Documents\GitHub\Terra\terra\main.py", line 140, in step
    EVENT_BUS.invoke_handlers(event)

  File "C:\Users\Ian\Documents\GitHub\Terra\terra\event\eventbus.py", line 46, in invoke_handlers
    handler(event)

  File "C:\Users\Ian\Documents\GitHub\Terra\terra\piece\piecemanager.py", line 257, in destroy_piece_from_event
    self.destroy_piece(event.piece)

  File "C:\Users\Ian\Documents\GitHub\Terra\terra\piece\piecemanager.py", line 227, in destroy_piece
    piece.destroy()

2018-05-09 17:58:46,610 WARNING [WARN]: Caught exception while sending message 'b'[TEAM_FI][RED]None''. Retry 2 of 3.
2018-05-09 17:58:46,610 WARNING [WARN]: Caught exception while sending message 'b'[TEAM_FI][RED]None''. Retry 3 of 3.
2018-05-09 18:00:05,630 WARNING [WARN]: Caught exception while sending message 'b'[TEAM_FI][RED]None''. Retry 2 of 3.
2018-05-09 18:00:05,630 WARNING [WARN]: Caught exception while sending message 'b'[TEAM_FI][RED]None''. Retry 3 of 3.
2018-05-09 18:00:25,176 WARNING [WARN]: Caught exception while sending message 'b'[TEAM_FI][RED]None''. Retry 2 of 3.
2018-05-09 18:00:25,176 WARNING [WARN]: Caught exception while sending message 'b'[TEAM_FI][RED]None''. Retry 3 of 3.
2018-05-09 18:00:38,047 ERROR [ERROR]: Caught exception in the launcher.
2018-05-09 18:00:38,048 ERROR [ERROR]: !=== Caught a fatal exception: ===!
2018-05-09 18:00:38,048 ERROR [ERROR]: Exception: 
must be str, not int
  File "C:/Users/Ian/Documents/GitHub/Terra/launcher.py", line 8, in <module>
    Main().run()

  File "C:\Users\Ian\Documents\GitHub\Terra\terra\main.py", line 193, in run
    self.step(event)

  File "C:\Users\Ian\Documents\GitHub\Terra\terra\main.py", line 137, in step
    INPUT_CONTROLLER.invoke_handlers(event)

  File "C:\Users\Ian\Documents\GitHub\Terra\terra\control\inputcontroller.py", line 55, in invoke_handlers
    handler()

  File "C:\Users\Ian\Documents\GitHub\Terra\terra\ui\editorcursor.py", line 51, in scroll_up
    self.update_object_to_place(direction=1)

  File "C:\Users\Ian\Documents\GitHub\Terra\terra\ui\editorcursor.py", line 66, in update_object_to_place
    self.team = self.get_next_team(self.team, direction)

  File "C:\Users\Ian\Documents\GitHub\Terra\terra\ui\editorcursor.py", line 80, in get_next_team
    return Team(wrap(current_team.value + direction, 1, len(Team)))

2018-05-09 18:02:23,804 WARNING [WARN]: Caught exception while sending message 'b'[TEAM_FI][RED]None''. Retry 2 of 3.
2018-05-09 18:02:23,805 WARNING [WARN]: Caught exception while sending message 'b'[TEAM_FI][RED]None''. Retry 3 of 3.
2018-05-09 18:02:53,250 WARNING [WARN]: Caught exception while sending message 'b'[TEAM_FI][RED]None''. Retry 2 of 3.
2018-05-09 18:02:53,252 WARNING [WARN]: Caught exception while sending message 'b'[TEAM_FI][RED]None''. Retry 3 of 3.
2018-05-09 18:02:55,911 ERROR [ERROR]: Caught exception in the launcher.
2018-05-09 18:02:55,913 ERROR [ERROR]: !=== Caught a fatal exception: ===!
2018-05-09 18:02:55,913 ERROR [ERROR]: Exception: 
list index out of range
  File "C:/Users/Ian/Documents/GitHub/Terra/launcher.py", line 8, in <module>
    Main().run()

  File "C:/Users/Ian/Documents/GitHub/Terra\terra\main.py", line 193, in run
    self.step(event)

  File "C:/Users/Ian/Documents/GitHub/Terra\terra\main.py", line 137, in step
    INPUT_CONTROLLER.invoke_handlers(event)

  File "C:/Users/Ian/Documents/GitHub/Terra\terra\control\inputcontroller.py", line 55, in invoke_handlers
    handler()

  File "C:/Users/Ian/Documents/GitHub/Terra\terra\ui\editorcursor.py", line 51, in scroll_up
    self.update_object_to_place(direction=1)

  File "C:/Users/Ian/Documents/GitHub/Terra\terra\ui\editorcursor.py", line 66, in update_object_to_place
    self.team = self.get_next_team(self.team, direction)

  File "C:/Users/Ian/Documents/GitHub/Terra\terra\ui\editorcursor.py", line 80, in get_next_team
    return available_teams[clamp(available_teams.index(current_team) + direction, 0, len(available_teams))]

2018-05-09 18:03:18,278 WARNING [WARN]: Caught exception while sending message 'b'[TEAM_FI][RED]None''. Retry 2 of 3.
2018-05-09 18:03:18,280 WARNING [WARN]: Caught exception while sending message 'b'[TEAM_FI][RED]None''. Retry 3 of 3.
2018-05-09 18:03:19,780 ERROR [ERROR]: Caught exception in the launcher.
2018-05-09 18:03:19,781 ERROR [ERROR]: !=== Caught a fatal exception: ===!
2018-05-09 18:03:19,781 ERROR [ERROR]: Exception: 
unsupported operand type(s) for -: 'list' and 'int'
  File "C:/Users/Ian/Documents/GitHub/Terra/launcher.py", line 8, in <module>
    Main().run()

  File "C:/Users/Ian/Documents/GitHub/Terra\terra\main.py", line 193, in run
    self.step(event)

  File "C:/Users/Ian/Documents/GitHub/Terra\terra\main.py", line 137, in step
    INPUT_CONTROLLER.invoke_handlers(event)

  File "C:/Users/Ian/Documents/GitHub/Terra\terra\control\inputcontroller.py", line 55, in invoke_handlers
    handler()

  File "C:/Users/Ian/Documents/GitHub/Terra\terra\ui\editorcursor.py", line 51, in scroll_up
    self.update_object_to_place(direction=1)

  File "C:/Users/Ian/Documents/GitHub/Terra\terra\ui\editorcursor.py", line 66, in update_object_to_place
    self.team = self.get_next_team(self.team, direction)

  File "C:/Users/Ian/Documents/GitHub/Terra\terra\ui\editorcursor.py", line 80, in get_next_team
    return available_teams[clamp(available_teams.index(current_team) + direction, 0, len(available_teams - 1))]

2018-05-09 18:03:31,520 WARNING [WARN]: Caught exception while sending message 'b'[TEAM_FI][RED]None''. Retry 2 of 3.
2018-05-09 18:03:31,521 WARNING [WARN]: Caught exception while sending message 'b'[TEAM_FI][RED]None''. Retry 3 of 3.
2018-05-09 18:03:46,092 WARNING [WARN]: Caught exception while sending message 'b'[TEAM_FI][RED]None''. Retry 2 of 3.
2018-05-09 18:03:46,093 WARNING [WARN]: Caught exception while sending message 'b'[TEAM_FI][RED]None''. Retry 3 of 3.
2018-05-09 18:05:03,801 WARNING [WARN]: Caught exception while sending message 'b'[TEAM_FI][RED]None''. Retry 2 of 3.
2018-05-09 18:05:03,801 WARNING [WARN]: Caught exception while sending message 'b'[TEAM_FI][RED]None''. Retry 3 of 3.
2018-05-09 18:05:05,616 ERROR [ERROR]: Caught exception in the launcher.
2018-05-09 18:05:05,617 ERROR [ERROR]: !=== Caught a fatal exception: ===!
2018-05-09 18:05:05,617 ERROR [ERROR]: Exception: 
can only concatenate list (not "Team") to list
  File "C:/Users/Ian/Documents/GitHub/Terra/launcher.py", line 8, in <module>
    Main().run()

  File "C:\Users\Ian\Documents\GitHub\Terra\terra\main.py", line 193, in run
    self.step(event)

  File "C:\Users\Ian\Documents\GitHub\Terra\terra\main.py", line 137, in step
    INPUT_CONTROLLER.invoke_handlers(event)

  File "C:\Users\Ian\Documents\GitHub\Terra\terra\control\inputcontroller.py", line 55, in invoke_handlers
    handler()

  File "C:\Users\Ian\Documents\GitHub\Terra\terra\ui\editorcursor.py", line 51, in scroll_up
    self.update_object_to_place(direction=1)

  File "C:\Users\Ian\Documents\GitHub\Terra\terra\ui\editorcursor.py", line 66, in update_object_to_place
    self.team = self.get_next_team(self.team, direction)

  File "C:\Users\Ian\Documents\GitHub\Terra\terra\ui\editorcursor.py", line 79, in get_next_team
    available_teams = self.get_manager(Manager.TEAM).all_teams + Team.NONE

2018-05-09 18:05:20,634 WARNING [WARN]: Caught exception while sending message 'b'[TEAM_FI][RED]None''. Retry 2 of 3.
2018-05-09 18:05:20,634 WARNING [WARN]: Caught exception while sending message 'b'[TEAM_FI][RED]None''. Retry 3 of 3.
2018-05-09 18:17:05,452 WARNING [WARN]: Caught exception while sending message 'b'[TEAM_FI][RED]None''. Retry 2 of 3.
2018-05-09 18:17:05,452 WARNING [WARN]: Caught exception while sending message 'b'[TEAM_FI][RED]None''. Retry 3 of 3.
2018-05-09 18:17:48,613 WARNING [WARN]: Caught exception while sending message 'b'[TEAM_FI][RED]None''. Retry 2 of 3.
2018-05-09 18:17:48,614 WARNING [WARN]: Caught exception while sending message 'b'[TEAM_FI][RED]None''. Retry 3 of 3.
2018-05-09 18:17:48,662 ERROR [ERROR]: Caught exception in the launcher.
2018-05-09 18:17:48,664 ERROR [ERROR]: !=== Caught a fatal exception: ===!
2018-05-09 18:17:48,665 ERROR [ERROR]: Exception: 
'EditorCursor' object has no attribute 'menu'
  File "C:/Users/Ian/Documents/GitHub/Terra/launcher.py", line 8, in <module>
    Main().run()

  File "C:/Users/Ian/Documents/GitHub/Terra\terra\main.py", line 193, in run
    self.step(event)

  File "C:/Users/Ian/Documents/GitHub/Terra\terra\main.py", line 140, in step
    EVENT_BUS.invoke_handlers(event)

  File "C:/Users/Ian/Documents/GitHub/Terra\terra\event\eventbus.py", line 46, in invoke_handlers
    handler(event)

  File "C:/Users/Ian/Documents/GitHub/Terra\terra\main.py", line 112, in handle_menu_selections
    self.set_screen_from_mode(Mode.EDIT, event.mapname)

  File "C:/Users/Ian/Documents/GitHub/Terra\terra\main.py", line 62, in set_screen_from_mode
    new_screen = LevelEditor(map_name)

  File "C:/Users/Ian/Documents/GitHub/Terra\terra\screens\leveleditor.py", line 21, in __init__
    Session.set_up_level_editor(map_name)

  File "C:/Users/Ian/Documents/GitHub/Terra\terra\managers\session.py", line 91, in set_up_level_editor
    SESSION.__set_up__(map_name, bitmap, pieces, teams, upgrades, meta)

  File "C:/Users/Ian/Documents/GitHub/Terra\terra\managers\session.py", line 124, in __set_up__
    self.managers[Manager.PLAYER] = PlayerManager()

  File "C:/Users/Ian/Documents/GitHub/Terra\terra\team\playermanager.py", line 29, in __init__
    self.cursors[team] = self.create_cursor(team)

  File "C:/Users/Ian/Documents/GitHub/Terra\terra\team\playermanager.py", line 66, in create_cursor
    return EditorCursor()

  File "C:/Users/Ian/Documents/GitHub/Terra\terra\ui\editorcursor.py", line 21, in __init__
    super().__init__(Team.RED)

  File "C:/Users/Ian/Documents/GitHub/Terra\terra\ui\cursor.py", line 34, in __init__
    self.scroll_camera()

  File "C:/Users/Ian/Documents/GitHub/Terra\terra\ui\cursor.py", line 93, in scroll_camera
    if self.is_active():

  File "C:/Users/Ian/Documents/GitHub/Terra\terra\ui\editorcursor.py", line 43, in is_active
    return not self.menu and pygame.mouse.get_focused()

2018-05-09 18:18:02,834 WARNING [WARN]: Caught exception while sending message 'b'[TEAM_FI][RED]None''. Retry 2 of 3.
2018-05-09 18:18:02,835 WARNING [WARN]: Caught exception while sending message 'b'[TEAM_FI][RED]None''. Retry 3 of 3.
2018-05-09 18:19:01,962 WARNING [WARN]: Caught exception while sending message 'b'[TEAM_FI][RED]None''. Retry 2 of 3.
2018-05-09 18:19:01,962 WARNING [WARN]: Caught exception while sending message 'b'[TEAM_FI][RED]None''. Retry 3 of 3.
2018-05-09 18:19:09,909 ERROR [ERROR]: Caught exception in the launcher.
2018-05-09 18:19:09,910 ERROR [ERROR]: !=== Caught a fatal exception: ===!
2018-05-09 18:19:09,910 ERROR [ERROR]: Exception: 
'LevelEditor' object has no attribute 'current_tile_type'
  File "C:/Users/Ian/Documents/GitHub/Terra/launcher.py", line 8, in <module>
    Main().run()

  File "C:\Users\Ian\Documents\GitHub\Terra\terra\main.py", line 193, in run
    self.step(event)

  File "C:\Users\Ian\Documents\GitHub\Terra\terra\main.py", line 140, in step
    EVENT_BUS.invoke_handlers(event)

  File "C:\Users\Ian\Documents\GitHub\Terra\terra\event\eventbus.py", line 46, in invoke_handlers
    handler(event)

  File "C:\Users\Ian\Documents\GitHub\Terra\terra\screens\leveleditor.py", line 52, in handle_menu_selection
    self.fill_with_current_tile()

  File "C:\Users\Ian\Documents\GitHub\Terra\terra\screens\leveleditor.py", line 87, in fill_with_current_tile
    self.get_manager(Manager.MAP).fill_map_with_tile(self.current_tile_type)

2018-05-09 18:20:06,611 WARNING [WARN]: Caught exception while sending message 'b'[TEAM_FI][RED]None''. Retry 2 of 3.
2018-05-09 18:20:06,611 WARNING [WARN]: Caught exception while sending message 'b'[TEAM_FI][RED]None''. Retry 3 of 3.
2018-05-09 18:25:11,482 WARNING [WARN]: Caught exception while sending message 'b'[TEAM_FI][RED]None''. Retry 2 of 3.
2018-05-09 18:25:11,482 WARNING [WARN]: Caught exception while sending message 'b'[TEAM_FI][RED]None''. Retry 3 of 3.
2018-05-09 18:25:43,769 WARNING [WARN]: Caught exception while sending message 'b'[TEAM_FI][RED]None''. Retry 2 of 3.
2018-05-09 18:25:43,769 WARNING [WARN]: Caught exception while sending message 'b'[TEAM_FI][RED]None''. Retry 3 of 3.
2018-05-09 18:27:30,813 WARNING [WARN]: Caught exception while sending message 'b'[TEAM_FI][RED]None''. Retry 2 of 3.
2018-05-09 18:27:30,814 WARNING [WARN]: Caught exception while sending message 'b'[TEAM_FI][RED]None''. Retry 3 of 3.
2018-05-09 18:28:23,859 WARNING [WARN]: Caught exception while sending message 'b'[TEAM_FI][RED]None''. Retry 2 of 3.
2018-05-09 18:28:23,859 WARNING [WARN]: Caught exception while sending message 'b'[TEAM_FI][RED]None''. Retry 3 of 3.
2018-05-09 18:30:04,745 WARNING [WARN]: Caught exception while sending message 'b'[TEAM_FI][RED]None''. Retry 2 of 3.
2018-05-09 18:30:04,745 WARNING [WARN]: Caught exception while sending message 'b'[TEAM_FI][RED]None''. Retry 3 of 3.
2018-05-09 18:31:44,547 WARNING [WARN]: Caught exception while sending message 'b'[TEAM_FI][RED]None''. Retry 2 of 3.
2018-05-09 18:31:44,547 WARNING [WARN]: Caught exception while sending message 'b'[TEAM_FI][RED]None''. Retry 3 of 3.
2018-05-09 18:32:49,549 WARNING [WARN]: Caught exception while sending message 'b'[TEAM_FI][RED]None''. Retry 2 of 3.
2018-05-09 18:32:49,549 WARNING [WARN]: Caught exception while sending message 'b'[TEAM_FI][RED]None''. Retry 3 of 3.
2018-05-09 18:39:11,879 WARNING [WARN]: Caught exception while sending message 'b'[TEAM_FI][RED]None''. Retry 2 of 3.
2018-05-09 18:39:11,879 WARNING [WARN]: Caught exception while sending message 'b'[TEAM_FI][RED]None''. Retry 3 of 3.
2018-05-09 18:39:58,569 WARNING [WARN]: Caught exception while sending message 'b'[TEAM_FI][RED]None''. Retry 2 of 3.
2018-05-09 18:39:58,569 WARNING [WARN]: Caught exception while sending message 'b'[TEAM_FI][RED]None''. Retry 3 of 3.
2018-05-09 18:44:47,737 WARNING [WARN]: Caught exception while sending message 'b'[TEAM_FI][RED]None''. Retry 2 of 3.
2018-05-09 18:44:47,737 WARNING [WARN]: Caught exception while sending message 'b'[TEAM_FI][RED]None''. Retry 3 of 3.
2018-05-09 18:47:09,755 WARNING [WARN]: Caught exception while sending message 'b'[TEAM_FI][RED]None''. Retry 2 of 3.
2018-05-09 18:47:09,755 WARNING [WARN]: Caught exception while sending message 'b'[TEAM_FI][RED]None''. Retry 3 of 3.
2018-05-09 18:47:50,782 WARNING [WARN]: Caught exception while sending message 'b'[TEAM_FI][RED]None''. Retry 2 of 3.
2018-05-09 18:47:50,783 WARNING [WARN]: Caught exception while sending message 'b'[TEAM_FI][RED]None''. Retry 3 of 3.
2018-05-09 18:49:57,651 ERROR [ERROR]: Caught exception in the launcher.
2018-05-09 18:49:57,659 ERROR [ERROR]: !=== Caught a fatal exception: ===!
2018-05-09 18:49:57,659 ERROR [ERROR]: Exception: 
list index out of range
  File "C:/Users/Ian/Documents/GitHub/Terra/launcher.py", line 8, in <module>
    Main().run()

  File "C:/Users/Ian/Documents/GitHub/Terra\terra\main.py", line 199, in run
    self.render()

  File "C:/Users/Ian/Documents/GitHub/Terra\terra\main.py", line 156, in render
    game_screen = self.current_screen.render(ui_screen)

  File "C:/Users/Ian/Documents/GitHub/Terra\terra\screens\titlescreen.py", line 39, in render
    self.main_menu.render(game_screen, ui_screen)

  File "C:/Users/Ian/Documents/GitHub/Terra\terra\menu\mainmenu.py", line 264, in render
    map_preview = draw_map_preview_from_file(container_width, container_height, option[0], asset_type=asset_type)

  File "C:/Users/Ian/Documents/GitHub/Terra\terra\map\minimap.py", line 93, in draw_map_preview_from_file
    return draw_map_preview(container_width, container_height, bitmap, pieces, teams)

  File "C:/Users/Ian/Documents/GitHub/Terra\terra\map\minimap.py", line 61, in draw_map_preview
    minimap = generate_minimap(bitmap, pieces)

  File "C:/Users/Ian/Documents/GitHub/Terra\terra\map\minimap.py", line 16, in generate_minimap
    width = len(bitmap[0])

2018-05-09 18:50:35,995 WARNING [WARN]: Caught exception while sending message 'b'[TEAM_FI][RED]None''. Retry 2 of 3.
2018-05-09 18:50:35,995 WARNING [WARN]: Caught exception while sending message 'b'[TEAM_FI][RED]None''. Retry 3 of 3.
2018-05-09 18:51:11,250 WARNING [WARN]: Caught exception while sending message 'b'[TEAM_FI][RED]None''. Retry 2 of 3.
2018-05-09 18:51:11,250 WARNING [WARN]: Caught exception while sending message 'b'[TEAM_FI][RED]None''. Retry 3 of 3.
2018-05-09 18:51:36,810 WARNING [WARN]: Caught exception while sending message 'b'[TEAM_FI][RED]None''. Retry 2 of 3.
2018-05-09 18:51:36,811 WARNING [WARN]: Caught exception while sending message 'b'[TEAM_FI][RED]None''. Retry 3 of 3.
2018-05-09 18:53:29,865 WARNING [WARN]: Caught exception while sending message 'b'[TEAM_FI][RED]None''. Retry 2 of 3.
2018-05-09 18:53:29,866 WARNING [WARN]: Caught exception while sending message 'b'[TEAM_FI][RED]None''. Retry 3 of 3.
2018-05-09 18:56:13,559 WARNING [WARN]: Caught exception while sending message 'b'[TEAM_FI][RED]None''. Retry 2 of 3.
2018-05-09 18:56:13,560 WARNING [WARN]: Caught exception while sending message 'b'[TEAM_FI][RED]None''. Retry 3 of 3.
