2018-04-16 18:45:15,065 ERROR [ERROR]: Caught exception in the launcher.
2018-04-16 18:45:15,066 ERROR [ERROR]: !=== Caught a fatal exception: ===!
2018-04-16 18:45:15,066 ERROR [ERROR]: Exception: 
list index out of range
  File "C:/Users/Ian/Documents/GitHub/Terra/launcher.py", line 8, in <module>
    Main().run()

  File "C:\Users\Ian\Documents\GitHub\Terra\terra\main.py", line 199, in run
    self.render()

  File "C:\Users\Ian\Documents\GitHub\Terra\terra\main.py", line 156, in render
    game_screen = self.current_screen.render(ui_screen)

  File "C:\Users\Ian\Documents\GitHub\Terra\terra\menu\titlescreen.py", line 39, in render
    self.main_menu.render(game_screen, ui_screen)

  File "C:\Users\Ian\Documents\GitHub\Terra\terra\menu\mainmenu.py", line 244, in render
    map_preview = draw_map_preview_from_file(container_width, container_height, option[0], asset_type=asset_type)

  File "C:\Users\Ian\Documents\GitHub\Terra\terra\map\minimap.py", line 93, in draw_map_preview_from_file
    return draw_map_preview(container_width, container_height, bitmap, pieces, teams)

  File "C:\Users\Ian\Documents\GitHub\Terra\terra\map\minimap.py", line 61, in draw_map_preview
    minimap = generate_minimap(bitmap, pieces)

  File "C:\Users\Ian\Documents\GitHub\Terra\terra\map\minimap.py", line 16, in generate_minimap
    width = len(bitmap[0])

2018-04-16 18:45:46,871 WARNING [WARN]: Caught exception while sending message 'b'[TEAM_FI][RED]None''. Retry 2 of 3.
2018-04-16 18:45:46,871 WARNING [WARN]: Caught exception while sending message 'b'[TEAM_FI][RED]None''. Retry 3 of 3.
2018-04-17 11:06:27,228 WARNING [WARN]: Caught exception while sending message 'b'[TEAM_FI][RED]None''. Retry 2 of 3.
2018-04-17 11:06:27,229 WARNING [WARN]: Caught exception while sending message 'b'[TEAM_FI][RED]None''. Retry 3 of 3.
2018-04-17 11:06:58,942 WARNING [WARN]: Caught exception while sending message 'b'[TEAM_FI][RED]None''. Retry 2 of 3.
2018-04-17 11:06:58,942 WARNING [WARN]: Caught exception while sending message 'b'[TEAM_FI][RED]None''. Retry 3 of 3.
2018-04-17 11:10:20,315 WARNING [WARN]: Caught exception while sending message 'b'[TEAM_FI][RED]None''. Retry 2 of 3.
2018-04-17 11:10:20,315 WARNING [WARN]: Caught exception while sending message 'b'[TEAM_FI][RED]None''. Retry 3 of 3.
2018-04-17 11:10:53,762 WARNING [WARN]: Caught exception while sending message 'b'[TEAM_FI][RED]None''. Retry 2 of 3.
2018-04-17 11:10:53,763 WARNING [WARN]: Caught exception while sending message 'b'[TEAM_FI][RED]None''. Retry 3 of 3.
2018-04-17 11:11:08,229 WARNING [WARN]: Caught exception while sending message 'b'[TEAM_FI][RED]None''. Retry 2 of 3.
2018-04-17 11:11:08,229 WARNING [WARN]: Caught exception while sending message 'b'[TEAM_FI][RED]None''. Retry 3 of 3.
2018-04-17 11:42:27,901 ERROR [ERROR]: Caught exception in the launcher.
2018-04-17 11:42:27,911 ERROR [ERROR]: !=== Caught a fatal exception: ===!
2018-04-17 11:42:27,911 ERROR [ERROR]: Exception: 
subsurface rectangle outside surface area
  File "C:/Users/Ian/Documents/GitHub/Terra/launcher.py", line 8, in <module>
    Main().run()

  File "C:\Users\Ian\Documents\GitHub\Terra\terra\main.py", line 199, in run
    self.render()

  File "C:\Users\Ian\Documents\GitHub\Terra\terra\main.py", line 156, in render
    game_screen = self.current_screen.render(ui_screen)

  File "C:\Users\Ian\Documents\GitHub\Terra\terra\menu\titlescreen.py", line 39, in render
    self.main_menu.render(game_screen, ui_screen)

  File "C:\Users\Ian\Documents\GitHub\Terra\terra\menu\mainmenu.py", line 214, in render
    self.tutorial.render(game_screen, ui_screen)

  File "C:\Users\Ian\Documents\GitHub\Terra\terra\menu\tutorial.py", line 51, in render
    scrolled_text = text.subsurface((0, self.scroll_pos, self.width, self.height))

2018-04-17 12:33:15,854 ERROR [ERROR]: Caught exception in the launcher.
2018-04-17 12:33:15,860 ERROR [ERROR]: !=== Caught a fatal exception: ===!
2018-04-17 12:33:15,860 ERROR [ERROR]: Exception: 
6
  File "C:/Users/Ian/Documents/GitHub/Terra/launcher.py", line 8, in <module>
    Main().run()

  File "C:\Users\Ian\Documents\GitHub\Terra\terra\main.py", line 193, in run
    self.step(event)

  File "C:\Users\Ian\Documents\GitHub\Terra\terra\main.py", line 137, in step
    INPUT_CONTROLLER.invoke_handlers(event)

  File "C:\Users\Ian\Documents\GitHub\Terra\terra\control\inputcontroller.py", line 55, in invoke_handlers
    handler()

  File "C:\Users\Ian\Documents\GitHub\Terra\terra\menu\tutorial.py", line 57, in confirm
    self.page_right()

  File "C:\Users\Ian\Documents\GitHub\Terra\terra\menu\tutorial.py", line 76, in page_right
    self.text = get_multiline_text(tutorial_strings, self.current_page, width=self.width - 24, height=self.height * 2)

  File "C:\Users\Ian\Documents\GitHub\Terra\terra\strings.py", line 506, in get_multiline_text
    string = string_type[LANGUAGE][string_name]

2018-04-17 12:34:28,923 WARNING [WARN]: Caught exception while sending message 'b'[TEAM_FI][RED]None''. Retry 2 of 3.
2018-04-17 12:34:28,923 WARNING [WARN]: Caught exception while sending message 'b'[TEAM_FI][RED]None''. Retry 3 of 3.
2018-04-17 13:05:58,857 ERROR [ERROR]: Caught exception in the launcher.
2018-04-17 13:05:58,859 ERROR [ERROR]: !=== Caught a fatal exception: ===!
2018-04-17 13:05:58,859 ERROR [ERROR]: Exception: 
subsurface rectangle outside surface area
  File "C:/Users/Ian/Documents/GitHub/Terra/launcher.py", line 8, in <module>
    Main().run()

  File "C:\Users\Ian\Documents\GitHub\Terra\terra\main.py", line 199, in run
    self.render()

  File "C:\Users\Ian\Documents\GitHub\Terra\terra\main.py", line 156, in render
    game_screen = self.current_screen.render(ui_screen)

  File "C:\Users\Ian\Documents\GitHub\Terra\terra\menu\titlescreen.py", line 39, in render
    self.main_menu.render(game_screen, ui_screen)

  File "C:\Users\Ian\Documents\GitHub\Terra\terra\menu\mainmenu.py", line 214, in render
    self.tutorial.render(game_screen, ui_screen)

  File "C:\Users\Ian\Documents\GitHub\Terra\terra\menu\tutorial.py", line 90, in render
    self.text.get_width(), text_height))

2018-04-17 13:15:36,423 ERROR [ERROR]: Caught exception in the launcher.
2018-04-17 13:15:36,425 ERROR [ERROR]: !=== Caught a fatal exception: ===!
2018-04-17 13:15:36,425 ERROR [ERROR]: Exception: 
Invalid resolution for Surface
  File "C:/Users/Ian/Documents/GitHub/Terra/launcher.py", line 8, in <module>
    Main().run()

  File "C:\Users\Ian\Documents\GitHub\Terra\terra\main.py", line 193, in run
    self.step(event)

  File "C:\Users\Ian\Documents\GitHub\Terra\terra\main.py", line 137, in step
    INPUT_CONTROLLER.invoke_handlers(event)

  File "C:\Users\Ian\Documents\GitHub\Terra\terra\control\inputcontroller.py", line 55, in invoke_handlers
    handler()

  File "C:\Users\Ian\Documents\GitHub\Terra\terra\menu\mainmenu.py", line 123, in confirm
    self.handle_menu_selection(selection)

  File "C:\Users\Ian\Documents\GitHub\Terra\terra\menu\mainmenu.py", line 160, in handle_menu_selection
    self.tutorial = Tutorial()

  File "C:\Users\Ian\Documents\GitHub\Terra\terra\menu\tutorial.py", line 28, in __init__
    self.change_page(0)

  File "C:\Users\Ian\Documents\GitHub\Terra\terra\menu\tutorial.py", line 73, in change_page
    self.text = get_multiline_text(tutorial_strings, self.current_page, width=self.width - 24, height=-1)

  File "C:\Users\Ian\Documents\GitHub\Terra\terra\strings.py", line 513, in get_multiline_text
    new_text = draw_multiline_text(string, color, background, width, height)

  File "C:\Users\Ian\Documents\GitHub\Terra\terra\util\drawingutil.py", line 55, in draw_multiline_text
    text_surface = pygame.Surface((width, height), pygame.SRCALPHA, 32)

2018-04-17 13:16:21,364 ERROR [ERROR]: Caught exception in the launcher.
2018-04-17 13:16:21,365 ERROR [ERROR]: !=== Caught a fatal exception: ===!
2018-04-17 13:16:21,365 ERROR [ERROR]: Exception: 
subsurface rectangle outside surface area
  File "C:/Users/Ian/Documents/GitHub/Terra/launcher.py", line 8, in <module>
    Main().run()

  File "C:\Users\Ian\Documents\GitHub\Terra\terra\main.py", line 199, in run
    self.render()

  File "C:\Users\Ian\Documents\GitHub\Terra\terra\main.py", line 156, in render
    game_screen = self.current_screen.render(ui_screen)

  File "C:\Users\Ian\Documents\GitHub\Terra\terra\menu\titlescreen.py", line 39, in render
    self.main_menu.render(game_screen, ui_screen)

  File "C:\Users\Ian\Documents\GitHub\Terra\terra\menu\mainmenu.py", line 214, in render
    self.tutorial.render(game_screen, ui_screen)

  File "C:\Users\Ian\Documents\GitHub\Terra\terra\menu\tutorial.py", line 90, in render
    self.text.get_width(), text_height))

2018-04-17 13:16:50,203 ERROR [ERROR]: Caught exception in the launcher.
2018-04-17 13:16:50,205 ERROR [ERROR]: !=== Caught a fatal exception: ===!
2018-04-17 13:16:50,205 ERROR [ERROR]: Exception: 
Invalid resolution for Surface
  File "C:/Users/Ian/Documents/GitHub/Terra/launcher.py", line 8, in <module>
    Main().run()

  File "C:\Users\Ian\Documents\GitHub\Terra\terra\main.py", line 193, in run
    self.step(event)

  File "C:\Users\Ian\Documents\GitHub\Terra\terra\main.py", line 137, in step
    INPUT_CONTROLLER.invoke_handlers(event)

  File "C:\Users\Ian\Documents\GitHub\Terra\terra\control\inputcontroller.py", line 55, in invoke_handlers
    handler()

  File "C:\Users\Ian\Documents\GitHub\Terra\terra\menu\mainmenu.py", line 123, in confirm
    self.handle_menu_selection(selection)

  File "C:\Users\Ian\Documents\GitHub\Terra\terra\menu\mainmenu.py", line 160, in handle_menu_selection
    self.tutorial = Tutorial()

  File "C:\Users\Ian\Documents\GitHub\Terra\terra\menu\tutorial.py", line 28, in __init__
    self.change_page(0)

  File "C:\Users\Ian\Documents\GitHub\Terra\terra\menu\tutorial.py", line 73, in change_page
    self.text = get_multiline_text(tutorial_strings, self.current_page, width=self.width - 24, height=-1)

  File "C:\Users\Ian\Documents\GitHub\Terra\terra\strings.py", line 513, in get_multiline_text
    new_text = draw_multiline_text(string, color, background, width, height)

  File "C:\Users\Ian\Documents\GitHub\Terra\terra\util\drawingutil.py", line 55, in draw_multiline_text
    text_surface = pygame.Surface((width, height), pygame.SRCALPHA, 32)

2018-04-17 13:17:00,026 ERROR [ERROR]: Caught exception in the launcher.
2018-04-17 13:17:00,028 ERROR [ERROR]: !=== Caught a fatal exception: ===!
2018-04-17 13:17:00,028 ERROR [ERROR]: Exception: 
subsurface rectangle outside surface area
  File "C:/Users/Ian/Documents/GitHub/Terra/launcher.py", line 8, in <module>
    Main().run()

  File "C:\Users\Ian\Documents\GitHub\Terra\terra\main.py", line 199, in run
    self.render()

  File "C:\Users\Ian\Documents\GitHub\Terra\terra\main.py", line 156, in render
    game_screen = self.current_screen.render(ui_screen)

  File "C:\Users\Ian\Documents\GitHub\Terra\terra\menu\titlescreen.py", line 39, in render
    self.main_menu.render(game_screen, ui_screen)

  File "C:\Users\Ian\Documents\GitHub\Terra\terra\menu\mainmenu.py", line 214, in render
    self.tutorial.render(game_screen, ui_screen)

  File "C:\Users\Ian\Documents\GitHub\Terra\terra\menu\tutorial.py", line 90, in render
    self.text.get_width(), text_height))

2018-04-17 13:19:36,547 ERROR [ERROR]: Caught exception in the launcher.
2018-04-17 13:19:36,548 ERROR [ERROR]: !=== Caught a fatal exception: ===!
2018-04-17 13:19:36,548 ERROR [ERROR]: Exception: 
subsurface rectangle outside surface area
  File "C:/Users/Ian/Documents/GitHub/Terra/launcher.py", line 8, in <module>
    Main().run()

  File "C:\Users\Ian\Documents\GitHub\Terra\terra\main.py", line 199, in run
    self.render()

  File "C:\Users\Ian\Documents\GitHub\Terra\terra\main.py", line 156, in render
    game_screen = self.current_screen.render(ui_screen)

  File "C:\Users\Ian\Documents\GitHub\Terra\terra\menu\titlescreen.py", line 39, in render
    self.main_menu.render(game_screen, ui_screen)

  File "C:\Users\Ian\Documents\GitHub\Terra\terra\menu\mainmenu.py", line 214, in render
    self.tutorial.render(game_screen, ui_screen)

  File "C:\Users\Ian\Documents\GitHub\Terra\terra\menu\tutorial.py", line 90, in render
    self.text.get_width(), text_height))

2018-04-17 13:19:55,948 ERROR [ERROR]: Caught exception in the launcher.
2018-04-17 13:19:55,950 ERROR [ERROR]: !=== Caught a fatal exception: ===!
2018-04-17 13:19:55,950 ERROR [ERROR]: Exception: 
subsurface rectangle outside surface area
  File "C:/Users/Ian/Documents/GitHub/Terra/launcher.py", line 8, in <module>
    Main().run()

  File "C:/Users/Ian/Documents/GitHub/Terra\terra\main.py", line 199, in run
    self.render()

  File "C:/Users/Ian/Documents/GitHub/Terra\terra\main.py", line 156, in render
    game_screen = self.current_screen.render(ui_screen)

  File "C:/Users/Ian/Documents/GitHub/Terra\terra\menu\titlescreen.py", line 39, in render
    self.main_menu.render(game_screen, ui_screen)

  File "C:/Users/Ian/Documents/GitHub/Terra\terra\menu\mainmenu.py", line 214, in render
    self.tutorial.render(game_screen, ui_screen)

  File "C:/Users/Ian/Documents/GitHub/Terra\terra\menu\tutorial.py", line 90, in render
    self.text.get_width(), text_height))

2018-04-17 13:20:06,753 ERROR [ERROR]: Caught exception in the launcher.
2018-04-17 13:20:06,755 ERROR [ERROR]: !=== Caught a fatal exception: ===!
2018-04-17 13:20:06,755 ERROR [ERROR]: Exception: 
subsurface rectangle outside surface area
  File "C:/Users/Ian/Documents/GitHub/Terra/launcher.py", line 8, in <module>
    Main().run()

  File "C:\Users\Ian\Documents\GitHub\Terra\terra\main.py", line 199, in run
    self.render()

  File "C:\Users\Ian\Documents\GitHub\Terra\terra\main.py", line 156, in render
    game_screen = self.current_screen.render(ui_screen)

  File "C:\Users\Ian\Documents\GitHub\Terra\terra\menu\titlescreen.py", line 39, in render
    self.main_menu.render(game_screen, ui_screen)

  File "C:\Users\Ian\Documents\GitHub\Terra\terra\menu\mainmenu.py", line 214, in render
    self.tutorial.render(game_screen, ui_screen)

  File "C:\Users\Ian\Documents\GitHub\Terra\terra\menu\tutorial.py", line 90, in render
    self.text.get_width(), text_height))

2018-04-17 13:21:04,611 ERROR [ERROR]: Caught exception in the launcher.
2018-04-17 13:21:04,613 ERROR [ERROR]: !=== Caught a fatal exception: ===!
2018-04-17 13:21:04,613 ERROR [ERROR]: Exception: 
subsurface rectangle outside surface area
  File "C:/Users/Ian/Documents/GitHub/Terra/launcher.py", line 8, in <module>
    Main().run()

  File "C:\Users\Ian\Documents\GitHub\Terra\terra\main.py", line 199, in run
    self.render()

  File "C:\Users\Ian\Documents\GitHub\Terra\terra\main.py", line 156, in render
    game_screen = self.current_screen.render(ui_screen)

  File "C:\Users\Ian\Documents\GitHub\Terra\terra\menu\titlescreen.py", line 39, in render
    self.main_menu.render(game_screen, ui_screen)

  File "C:\Users\Ian\Documents\GitHub\Terra\terra\menu\mainmenu.py", line 214, in render
    self.tutorial.render(game_screen, ui_screen)

  File "C:\Users\Ian\Documents\GitHub\Terra\terra\menu\tutorial.py", line 94, in render
    self.text.get_width(), text_height))

2018-04-17 13:22:16,413 ERROR [ERROR]: Caught exception in the launcher.
2018-04-17 13:22:16,414 ERROR [ERROR]: !=== Caught a fatal exception: ===!
2018-04-17 13:22:16,415 ERROR [ERROR]: Exception: 
subsurface rectangle outside surface area
  File "C:/Users/Ian/Documents/GitHub/Terra/launcher.py", line 8, in <module>
    Main().run()

  File "C:\Users\Ian\Documents\GitHub\Terra\terra\main.py", line 199, in run
    self.render()

  File "C:\Users\Ian\Documents\GitHub\Terra\terra\main.py", line 156, in render
    game_screen = self.current_screen.render(ui_screen)

  File "C:\Users\Ian\Documents\GitHub\Terra\terra\menu\titlescreen.py", line 39, in render
    self.main_menu.render(game_screen, ui_screen)

  File "C:\Users\Ian\Documents\GitHub\Terra\terra\menu\mainmenu.py", line 214, in render
    self.tutorial.render(game_screen, ui_screen)

  File "C:\Users\Ian\Documents\GitHub\Terra\terra\menu\tutorial.py", line 94, in render
    self.text.get_width(), text_height))

2018-04-17 13:22:21,654 ERROR [ERROR]: Caught exception in the launcher.
2018-04-17 13:22:21,656 ERROR [ERROR]: !=== Caught a fatal exception: ===!
2018-04-17 13:22:21,656 ERROR [ERROR]: Exception: 
subsurface rectangle outside surface area
  File "C:/Users/Ian/Documents/GitHub/Terra/launcher.py", line 8, in <module>
    Main().run()

  File "C:/Users/Ian/Documents/GitHub/Terra\terra\main.py", line 199, in run
    self.render()

  File "C:/Users/Ian/Documents/GitHub/Terra\terra\main.py", line 156, in render
    game_screen = self.current_screen.render(ui_screen)

  File "C:/Users/Ian/Documents/GitHub/Terra\terra\menu\titlescreen.py", line 39, in render
    self.main_menu.render(game_screen, ui_screen)

  File "C:/Users/Ian/Documents/GitHub/Terra\terra\menu\mainmenu.py", line 214, in render
    self.tutorial.render(game_screen, ui_screen)

  File "C:/Users/Ian/Documents/GitHub/Terra\terra\menu\tutorial.py", line 94, in render
    self.text.get_width(), text_height))

2018-04-17 13:42:31,270 WARNING [WARN]: Caught exception while sending message 'b'[TEAM_FI][RED]None''. Retry 2 of 3.
2018-04-17 13:42:31,270 WARNING [WARN]: Caught exception while sending message 'b'[TEAM_FI][RED]None''. Retry 3 of 3.
2018-04-17 13:45:33,280 WARNING [WARN]: Caught exception while sending message 'b'[TEAM_FI][RED]None''. Retry 2 of 3.
2018-04-17 13:45:33,280 WARNING [WARN]: Caught exception while sending message 'b'[TEAM_FI][RED]None''. Retry 3 of 3.
2018-04-17 13:46:45,953 ERROR [ERROR]: Caught exception in the launcher.
2018-04-17 13:46:45,965 ERROR [ERROR]: !=== Caught a fatal exception: ===!
2018-04-17 13:46:45,965 ERROR [ERROR]: Exception: 
7 is not a valid MouseConstant
  File "C:/Users/Ian/Documents/GitHub/Terra/launcher.py", line 8, in <module>
    Main().run()

  File "C:\Users\Ian\Documents\GitHub\Terra\terra\main.py", line 193, in run
    self.step(event)

  File "C:\Users\Ian\Documents\GitHub\Terra\terra\main.py", line 137, in step
    INPUT_CONTROLLER.invoke_handlers(event)

  File "C:\Users\Ian\Documents\GitHub\Terra\terra\control\inputcontroller.py", line 44, in invoke_handlers
    event_handlers = self.__subscribers__.get((InputAction.PRESS, translate_mouse_button(event.button)))

  File "C:\Users\Ian\Documents\GitHub\Terra\terra\control\keybindings.py", line 50, in translate_mouse_button
    button = MouseConstant(input)

  File "C:\Users\Ian\AppData\Local\Programs\Python\Python36-32\lib\enum.py", line 291, in __call__
    return cls.__new__(cls, value)

  File "C:\Users\Ian\AppData\Local\Programs\Python\Python36-32\lib\enum.py", line 533, in __new__
    return cls._missing_(value)

  File "C:\Users\Ian\AppData\Local\Programs\Python\Python36-32\lib\enum.py", line 546, in _missing_
    raise ValueError("%r is not a valid %s" % (value, cls.__name__))

2018-04-17 13:48:06,842 WARNING [WARN]: Caught exception while sending message 'b'[TEAM_FI][RED]None''. Retry 2 of 3.
2018-04-17 13:48:06,842 WARNING [WARN]: Caught exception while sending message 'b'[TEAM_FI][RED]None''. Retry 3 of 3.
2018-04-17 14:07:15,494 WARNING [WARN]: Caught exception while sending message 'b'[TEAM_FI][RED]None''. Retry 2 of 3.
2018-04-17 14:07:15,495 WARNING [WARN]: Caught exception while sending message 'b'[TEAM_FI][RED]None''. Retry 3 of 3.
2018-04-17 14:08:58,254 WARNING [WARN]: Caught exception while sending message 'b'[TEAM_FI][RED]None''. Retry 2 of 3.
2018-04-17 14:08:58,254 WARNING [WARN]: Caught exception while sending message 'b'[TEAM_FI][RED]None''. Retry 3 of 3.
2018-04-17 14:09:58,050 WARNING [WARN]: Caught exception while sending message 'b'[TEAM_FI][RED]None''. Retry 2 of 3.
2018-04-17 14:09:58,051 WARNING [WARN]: Caught exception while sending message 'b'[TEAM_FI][RED]None''. Retry 3 of 3.
2018-04-17 14:11:15,146 WARNING [WARN]: Caught exception while sending message 'b'[TEAM_FI][RED]None''. Retry 2 of 3.
2018-04-17 14:11:15,146 WARNING [WARN]: Caught exception while sending message 'b'[TEAM_FI][RED]None''. Retry 3 of 3.
2018-04-17 14:12:01,554 WARNING [WARN]: Caught exception while sending message 'b'[TEAM_FI][RED]None''. Retry 2 of 3.
2018-04-17 14:12:01,554 WARNING [WARN]: Caught exception while sending message 'b'[TEAM_FI][RED]None''. Retry 3 of 3.
2018-04-17 14:12:21,389 WARNING [WARN]: Caught exception while sending message 'b'[TEAM_FI][RED]None''. Retry 2 of 3.
2018-04-17 14:12:21,389 WARNING [WARN]: Caught exception while sending message 'b'[TEAM_FI][RED]None''. Retry 3 of 3.
2018-04-17 14:12:39,137 WARNING [WARN]: Caught exception while sending message 'b'[TEAM_FI][RED]None''. Retry 2 of 3.
2018-04-17 14:12:39,137 WARNING [WARN]: Caught exception while sending message 'b'[TEAM_FI][RED]None''. Retry 3 of 3.
2018-04-17 14:13:45,475 WARNING [WARN]: Caught exception while sending message 'b'[TEAM_FI][RED]None''. Retry 2 of 3.
2018-04-17 14:13:45,475 WARNING [WARN]: Caught exception while sending message 'b'[TEAM_FI][RED]None''. Retry 3 of 3.
2018-04-17 14:13:51,076 ERROR [ERROR]: Caught exception in the launcher.
2018-04-17 14:13:51,081 ERROR [ERROR]: !=== Caught a fatal exception: ===!
2018-04-17 14:13:51,081 ERROR [ERROR]: Exception: 
must be str, not EffectType
  File "C:/Users/Ian/Documents/GitHub/Terra/launcher.py", line 8, in <module>
    Main().run()

  File "C:\Users\Ian\Documents\GitHub\Terra\terra\main.py", line 193, in run
    self.step(event)

  File "C:\Users\Ian\Documents\GitHub\Terra\terra\main.py", line 140, in step
    EVENT_BUS.invoke_handlers(event)

  File "C:\Users\Ian\Documents\GitHub\Terra\terra\event\eventbus.py", line 46, in invoke_handlers
    handler(event)

  File "C:\Users\Ian\Documents\GitHub\Terra\terra\effects\effectsmanager.py", line 61, in create_piece_effect_from_event
    self.create_effect(event.tx, event.ty, event_type_to_effect[event.event_type], None)

  File "C:\Users\Ian\Documents\GitHub\Terra\terra\effects\effectsmanager.py", line 48, in create_effect
    self.effects.append(AnimatedEffect(self, effect_type, gx, gy, team))

  File "C:\Users\Ian\Documents\GitHub\Terra\terra\effects\animatedeffect.py", line 19, in __init__
    print("AnimatedEffect created: " + self.effect_type)

2018-04-17 14:14:01,052 WARNING [WARN]: Caught exception while sending message 'b'[TEAM_FI][RED]None''. Retry 2 of 3.
2018-04-17 14:14:01,052 WARNING [WARN]: Caught exception while sending message 'b'[TEAM_FI][RED]None''. Retry 3 of 3.
2018-04-17 14:14:50,117 WARNING [WARN]: Caught exception while sending message 'b'[TEAM_FI][RED]None''. Retry 2 of 3.
2018-04-17 14:14:50,117 WARNING [WARN]: Caught exception while sending message 'b'[TEAM_FI][RED]None''. Retry 3 of 3.
2018-04-17 14:16:08,937 WARNING [WARN]: Caught exception while sending message 'b'[TEAM_FI][RED]None''. Retry 2 of 3.
2018-04-17 14:16:08,938 WARNING [WARN]: Caught exception while sending message 'b'[TEAM_FI][RED]None''. Retry 3 of 3.
2018-04-17 14:17:16,702 WARNING [WARN]: Caught exception while sending message 'b'[TEAM_FI][RED]None''. Retry 2 of 3.
2018-04-17 14:17:16,703 WARNING [WARN]: Caught exception while sending message 'b'[TEAM_FI][RED]None''. Retry 3 of 3.
2018-04-17 14:17:53,309 WARNING [WARN]: Caught exception while sending message 'b'[TEAM_FI][RED]None''. Retry 2 of 3.
2018-04-17 14:17:53,309 WARNING [WARN]: Caught exception while sending message 'b'[TEAM_FI][RED]None''. Retry 3 of 3.
2018-04-17 14:18:18,388 WARNING [WARN]: Caught exception while sending message 'b'[TEAM_FI][RED]None''. Retry 2 of 3.
2018-04-17 14:18:18,388 WARNING [WARN]: Caught exception while sending message 'b'[TEAM_FI][RED]None''. Retry 3 of 3.
2018-04-17 14:23:17,168 WARNING [WARN]: Caught exception while sending message 'b'[TEAM_FI][RED]None''. Retry 2 of 3.
2018-04-17 14:23:17,168 WARNING [WARN]: Caught exception while sending message 'b'[TEAM_FI][RED]None''. Retry 3 of 3.
2018-04-17 14:26:01,881 WARNING [WARN]: Caught exception while sending message 'b'[TEAM_FI][RED]None''. Retry 2 of 3.
2018-04-17 14:26:01,881 WARNING [WARN]: Caught exception while sending message 'b'[TEAM_FI][RED]None''. Retry 3 of 3.
2018-04-17 14:29:54,457 WARNING [WARN]: Caught exception while sending message 'b'[TEAM_FI][RED]None''. Retry 2 of 3.
2018-04-17 14:29:54,457 WARNING [WARN]: Caught exception while sending message 'b'[TEAM_FI][RED]None''. Retry 3 of 3.
2018-04-17 14:30:21,784 WARNING [WARN]: Caught exception while sending message 'b'[TEAM_FI][RED]None''. Retry 2 of 3.
2018-04-17 14:30:21,784 WARNING [WARN]: Caught exception while sending message 'b'[TEAM_FI][RED]None''. Retry 3 of 3.
2018-04-17 14:39:20,128 WARNING [WARN]: Caught exception while sending message 'b'[TEAM_FI][RED]None''. Retry 2 of 3.
2018-04-17 14:39:20,128 WARNING [WARN]: Caught exception while sending message 'b'[TEAM_FI][RED]None''. Retry 3 of 3.
2018-04-17 14:42:21,971 WARNING [WARN]: Caught exception while sending message 'b'[TEAM_FI][RED]None''. Retry 2 of 3.
2018-04-17 14:42:21,971 WARNING [WARN]: Caught exception while sending message 'b'[TEAM_FI][RED]None''. Retry 3 of 3.
2018-04-17 14:44:41,835 WARNING [WARN]: Caught exception while sending message 'b'[TEAM_FI][RED]None''. Retry 2 of 3.
2018-04-17 14:44:41,836 WARNING [WARN]: Caught exception while sending message 'b'[TEAM_FI][RED]None''. Retry 3 of 3.
2018-04-17 14:44:43,554 ERROR [ERROR]: Caught exception in the launcher.
2018-04-17 14:44:43,559 ERROR [ERROR]: !=== Caught a fatal exception: ===!
2018-04-17 14:44:43,559 ERROR [ERROR]: Exception: 
<Manager.PIECE: 'piece'>
  File "C:/Users/Ian/Documents/GitHub/Terra/launcher.py", line 8, in <module>
    Main().run()

  File "C:\Users\Ian\Documents\GitHub\Terra\terra\main.py", line 199, in run
    self.render()

  File "C:\Users\Ian\Documents\GitHub\Terra\terra\main.py", line 156, in render
    game_screen = self.current_screen.render(ui_screen)

  File "C:\Users\Ian\Documents\GitHub\Terra\terra\screens\results.py", line 50, in render
    for piece in self.get_manager(Manager.PIECE).get_all_pieces_for_team(self.winning_team):

  File "C:\Users\Ian\Documents\GitHub\Terra\terra\engine\gamescreen.py", line 47, in get_manager
    return SESSION.get(manager_type)

  File "C:\Users\Ian\Documents\GitHub\Terra\terra\managers\session.py", line 33, in get
    return self.managers[manager_type]

2018-04-17 14:44:56,010 WARNING [WARN]: Caught exception while sending message 'b'[TEAM_FI][RED]None''. Retry 2 of 3.
2018-04-17 14:44:56,011 WARNING [WARN]: Caught exception while sending message 'b'[TEAM_FI][RED]None''. Retry 3 of 3.
2018-04-17 14:46:00,344 ERROR [ERROR]: Caught exception in the launcher.
2018-04-17 14:46:00,346 ERROR [ERROR]: !=== Caught a fatal exception: ===!
2018-04-17 14:46:00,346 ERROR [ERROR]: Exception: 
<Manager.PIECE: 'piece'>
  File "C:/Users/Ian/Documents/GitHub/Terra/launcher.py", line 8, in <module>
    Main().run()

  File "C:/Users/Ian/Documents/GitHub/Terra\terra\main.py", line 199, in run
    self.render()

  File "C:/Users/Ian/Documents/GitHub/Terra\terra\main.py", line 156, in render
    game_screen = self.current_screen.render(ui_screen)

  File "C:/Users/Ian/Documents/GitHub/Terra\terra\screens\results.py", line 50, in render
    for piece in self.get_manager(Manager.PIECE).get_all_pieces_for_team(self.winning_team):

  File "C:/Users/Ian/Documents/GitHub/Terra\terra\engine\gamescreen.py", line 47, in get_manager
    return SESSION.get(manager_type)

  File "C:/Users/Ian/Documents/GitHub/Terra\terra\managers\session.py", line 33, in get
    return self.managers[manager_type]

2018-04-17 14:47:56,520 WARNING [WARN]: Caught exception while sending message 'b'[TEAM_FI][RED]None''. Retry 2 of 3.
2018-04-17 14:47:56,520 WARNING [WARN]: Caught exception while sending message 'b'[TEAM_FI][RED]None''. Retry 3 of 3.
2018-04-17 14:47:59,997 ERROR [ERROR]: Caught exception in the launcher.
2018-04-17 14:47:59,997 ERROR [ERROR]: !=== Caught a fatal exception: ===!
2018-04-17 14:47:59,997 ERROR [ERROR]: Exception: 
<PieceType.BASE: 11>
  File "C:/Users/Ian/Documents/GitHub/Terra/launcher.py", line 8, in <module>
    Main().run()

  File "C:\Users\Ian\Documents\GitHub\Terra\terra\main.py", line 199, in run
    self.render()

  File "C:\Users\Ian\Documents\GitHub\Terra\terra\main.py", line 156, in render
    game_screen = self.current_screen.render(ui_screen)

  File "C:\Users\Ian\Documents\GitHub\Terra\terra\screens\results.py", line 51, in render
    game_screen.blit(spr_pieces[piece.piece_type].subsurface(0, 0, 24, 24), (base_x + x, base_y + 24))

2018-04-17 14:48:28,974 WARNING [WARN]: Caught exception while sending message 'b'[TEAM_FI][RED]None''. Retry 2 of 3.
2018-04-17 14:48:28,975 WARNING [WARN]: Caught exception while sending message 'b'[TEAM_FI][RED]None''. Retry 3 of 3.
2018-04-17 14:48:51,887 WARNING [WARN]: Caught exception while sending message 'b'[TEAM_FI][RED]None''. Retry 2 of 3.
2018-04-17 14:48:51,887 WARNING [WARN]: Caught exception while sending message 'b'[TEAM_FI][RED]None''. Retry 3 of 3.
2018-04-17 14:49:02,000 WARNING [WARN]: Caught exception while sending message 'b'[TEAM_FI][RED]None''. Retry 2 of 3.
2018-04-17 14:49:02,000 WARNING [WARN]: Caught exception while sending message 'b'[TEAM_FI][RED]None''. Retry 3 of 3.
2018-04-17 17:15:22,344 WARNING [WARN]: Caught exception while sending message 'b'[TEAM_FI][RED]None''. Retry 2 of 3.
2018-04-17 17:15:22,345 WARNING [WARN]: Caught exception while sending message 'b'[TEAM_FI][RED]None''. Retry 3 of 3.
2018-04-17 17:15:33,013 ERROR [ERROR]: Caught exception in the launcher.
2018-04-17 17:15:33,014 ERROR [ERROR]: !=== Caught a fatal exception: ===!
2018-04-17 17:15:33,014 ERROR [ERROR]: Exception: 
'PieceManager' object is not iterable
  File "C:/Users/Ian/Documents/GitHub/Terra/launcher.py", line 8, in <module>
    Main().run()

  File "C:\Users\Ian\Documents\GitHub\Terra\terra\main.py", line 193, in run
    self.step(event)

  File "C:\Users\Ian\Documents\GitHub\Terra\terra\main.py", line 140, in step
    EVENT_BUS.invoke_handlers(event)

  File "C:\Users\Ian\Documents\GitHub\Terra\terra\event\eventbus.py", line 46, in invoke_handlers
    handler(event)

  File "C:\Users\Ian\Documents\GitHub\Terra\terra\ai\aiplayer.py", line 26, in handle_orders_phase
    for piece in my_pieces:

2018-04-17 17:16:05,200 WARNING [WARN]: Caught exception while sending message 'b'[TEAM_FI][RED]None''. Retry 2 of 3.
2018-04-17 17:16:05,200 WARNING [WARN]: Caught exception while sending message 'b'[TEAM_FI][RED]None''. Retry 3 of 3.
2018-04-17 17:18:05,074 WARNING [WARN]: Caught exception while sending message 'b'[TEAM_FI][RED]None''. Retry 2 of 3.
2018-04-17 17:18:05,074 WARNING [WARN]: Caught exception while sending message 'b'[TEAM_FI][RED]None''. Retry 3 of 3.
2018-04-17 17:19:07,814 WARNING [WARN]: Caught exception while sending message 'b'[TEAM_FI][RED]None''. Retry 2 of 3.
2018-04-17 17:19:07,814 WARNING [WARN]: Caught exception while sending message 'b'[TEAM_FI][RED]None''. Retry 3 of 3.
2018-04-17 17:20:41,697 WARNING [WARN]: Caught exception while sending message 'b'[TEAM_FI][RED]None''. Retry 2 of 3.
2018-04-17 17:20:41,697 WARNING [WARN]: Caught exception while sending message 'b'[TEAM_FI][RED]None''. Retry 3 of 3.
2018-04-17 17:21:29,719 WARNING [WARN]: Caught exception while sending message 'b'[TEAM_FI][RED]None''. Retry 2 of 3.
2018-04-17 17:21:29,720 WARNING [WARN]: Caught exception while sending message 'b'[TEAM_FI][RED]None''. Retry 3 of 3.
2018-04-17 17:26:01,335 WARNING [WARN]: Caught exception while sending message 'b'[TEAM_FI][RED]None''. Retry 2 of 3.
2018-04-17 17:26:01,337 WARNING [WARN]: Caught exception while sending message 'b'[TEAM_FI][RED]None''. Retry 3 of 3.
2018-04-17 17:27:43,962 WARNING [WARN]: Caught exception while sending message 'b'[TEAM_FI][RED]None''. Retry 2 of 3.
2018-04-17 17:27:43,962 WARNING [WARN]: Caught exception while sending message 'b'[TEAM_FI][RED]None''. Retry 3 of 3.
2018-04-17 17:28:00,157 WARNING [WARN]: Caught exception while sending message 'b'[TEAM_FI][RED]None''. Retry 2 of 3.
2018-04-17 17:28:00,157 WARNING [WARN]: Caught exception while sending message 'b'[TEAM_FI][RED]None''. Retry 3 of 3.
2018-04-17 17:54:14,346 WARNING [WARN]: Caught exception while sending message 'b'[TEAM_FI][RED]None''. Retry 2 of 3.
2018-04-17 17:54:14,346 WARNING [WARN]: Caught exception while sending message 'b'[TEAM_FI][RED]None''. Retry 3 of 3.
2018-04-17 18:34:54,596 WARNING [WARN]: Caught exception while sending message 'b'[TEAM_FI][RED]None''. Retry 2 of 3.
2018-04-17 18:34:54,596 WARNING [WARN]: Caught exception while sending message 'b'[TEAM_FI][RED]None''. Retry 3 of 3.
2018-04-17 18:34:54,647 ERROR [ERROR]: Caught exception in the launcher.
2018-04-17 18:34:54,648 ERROR [ERROR]: !=== Caught a fatal exception: ===!
2018-04-17 18:34:54,648 ERROR [ERROR]: Exception: 
name 'PieceType' is not defined
  File "C:/Users/Ian/Documents/GitHub/Terra/launcher.py", line 8, in <module>
    Main().run()

  File "C:\Users\Ian\Documents\GitHub\Terra\terra\main.py", line 193, in run
    self.step(event)

  File "C:\Users\Ian\Documents\GitHub\Terra\terra\main.py", line 140, in step
    EVENT_BUS.invoke_handlers(event)

  File "C:\Users\Ian\Documents\GitHub\Terra\terra\event\eventbus.py", line 46, in invoke_handlers
    handler(event)

  File "C:\Users\Ian\Documents\GitHub\Terra\terra\ai\aiplayer.py", line 53, in handle_orders_phase
    tasks = self.generate_tasks()

  File "C:\Users\Ian\Documents\GitHub\Terra\terra\ai\aiplayer.py", line 42, in generate_tasks
    harvestable_coords = [coord for coord in self.map.find_tiles_by_type(TileType.RESOURCE)

  File "C:\Users\Ian\Documents\GitHub\Terra\terra\ai\aiplayer.py", line 43, in <listcomp>
    if piece_manager.get_pieces_at(coord[0], coord[1], PieceType.GENERATOR)]

2018-04-17 18:35:13,734 WARNING [WARN]: Caught exception while sending message 'b'[TEAM_FI][RED]None''. Retry 2 of 3.
2018-04-17 18:35:13,734 WARNING [WARN]: Caught exception while sending message 'b'[TEAM_FI][RED]None''. Retry 3 of 3.
2018-04-17 18:37:38,634 WARNING [WARN]: Caught exception while sending message 'b'[TEAM_FI][RED]None''. Retry 2 of 3.
2018-04-17 18:37:38,636 WARNING [WARN]: Caught exception while sending message 'b'[TEAM_FI][RED]None''. Retry 3 of 3.
2018-04-17 18:38:56,928 WARNING [WARN]: Caught exception while sending message 'b'[TEAM_FI][RED]None''. Retry 2 of 3.
2018-04-17 18:38:56,928 WARNING [WARN]: Caught exception while sending message 'b'[TEAM_FI][RED]None''. Retry 3 of 3.
2018-04-17 18:49:02,724 WARNING [WARN]: Caught exception while sending message 'b'[TEAM_FI][RED]None''. Retry 2 of 3.
2018-04-17 18:49:02,724 WARNING [WARN]: Caught exception while sending message 'b'[TEAM_FI][RED]None''. Retry 3 of 3.
2018-04-17 18:49:09,020 WARNING [WARN]: Caught exception while sending message 'b'[TEAM_FI][RED]None''. Retry 2 of 3.
2018-04-17 18:49:09,021 WARNING [WARN]: Caught exception while sending message 'b'[TEAM_FI][RED]None''. Retry 3 of 3.
2018-04-17 18:52:06,141 WARNING [WARN]: Caught exception while sending message 'b'[TEAM_FI][RED]None''. Retry 2 of 3.
2018-04-17 18:52:06,142 WARNING [WARN]: Caught exception while sending message 'b'[TEAM_FI][RED]None''. Retry 3 of 3.
2018-04-17 18:52:55,738 WARNING [WARN]: Caught exception while sending message 'b'[TEAM_FI][RED]None''. Retry 2 of 3.
2018-04-17 18:52:55,738 WARNING [WARN]: Caught exception while sending message 'b'[TEAM_FI][RED]None''. Retry 3 of 3.
2018-04-17 18:53:06,072 WARNING [WARN]: Caught exception while sending message 'b'[TEAM_FI][RED]None''. Retry 2 of 3.
2018-04-17 18:53:06,072 WARNING [WARN]: Caught exception while sending message 'b'[TEAM_FI][RED]None''. Retry 3 of 3.
2018-04-17 18:53:34,603 WARNING [WARN]: Caught exception while sending message 'b'[TEAM_FI][RED]None''. Retry 2 of 3.
2018-04-17 18:53:34,603 WARNING [WARN]: Caught exception while sending message 'b'[TEAM_FI][RED]None''. Retry 3 of 3.
2018-04-17 18:53:59,558 WARNING [WARN]: Caught exception while sending message 'b'[TEAM_FI][RED]None''. Retry 2 of 3.
2018-04-17 18:53:59,558 WARNING [WARN]: Caught exception while sending message 'b'[TEAM_FI][RED]None''. Retry 3 of 3.
2018-04-17 19:54:06,904 WARNING [WARN]: Caught exception while sending message 'b'[TEAM_FI][RED]None''. Retry 2 of 3.
2018-04-17 19:54:06,904 WARNING [WARN]: Caught exception while sending message 'b'[TEAM_FI][RED]None''. Retry 3 of 3.
2018-04-17 19:54:06,962 ERROR [ERROR]: Caught exception in the launcher.
2018-04-17 19:54:06,964 ERROR [ERROR]: !=== Caught a fatal exception: ===!
2018-04-17 19:54:06,965 ERROR [ERROR]: Exception: 
'TaskType' object is not subscriptable
  File "C:/Users/Ian/Documents/GitHub/Terra/launcher.py", line 8, in <module>
    Main().run()

  File "C:/Users/Ian/Documents/GitHub/Terra\terra\main.py", line 193, in run
    self.step(event)

  File "C:/Users/Ian/Documents/GitHub/Terra\terra\main.py", line 140, in step
    EVENT_BUS.invoke_handlers(event)

  File "C:/Users/Ian/Documents/GitHub/Terra\terra\event\eventbus.py", line 46, in invoke_handlers
    handler(event)

  File "C:/Users/Ian/Documents/GitHub/Terra\terra\ai\aiplayer.py", line 85, in handle_orders_phase
    assignments = self.assign_tasks(tasks)

  File "C:/Users/Ian/Documents/GitHub/Terra\terra\ai\aiplayer.py", line 63, in assign_tasks
    eligible_pieces = task.get_eligible_pieces_for_task(self.get_manager(Manager.PIECE))

  File "C:/Users/Ian/Documents/GitHub/Terra\terra\ai\task.py", line 43, in get_eligible_pieces_for_task
    for archetype in TaskType.task_type_to_piece_archetype[self.task_type]:

2018-04-17 19:54:51,415 WARNING [WARN]: Caught exception while sending message 'b'[TEAM_FI][RED]None''. Retry 2 of 3.
2018-04-17 19:54:51,416 WARNING [WARN]: Caught exception while sending message 'b'[TEAM_FI][RED]None''. Retry 3 of 3.
2018-04-17 20:00:53,197 WARNING [WARN]: Caught exception while sending message 'b'[TEAM_FI][RED]None''. Retry 2 of 3.
2018-04-17 20:00:53,199 WARNING [WARN]: Caught exception while sending message 'b'[TEAM_FI][RED]None''. Retry 3 of 3.
2018-04-17 20:01:37,668 WARNING [WARN]: Caught exception while sending message 'b'[TEAM_FI][RED]None''. Retry 2 of 3.
2018-04-17 20:01:37,669 WARNING [WARN]: Caught exception while sending message 'b'[TEAM_FI][RED]None''. Retry 3 of 3.
2018-04-17 20:09:00,315 WARNING [WARN]: Caught exception while sending message 'b'[TEAM_FI][RED]None''. Retry 2 of 3.
2018-04-17 20:09:00,316 WARNING [WARN]: Caught exception while sending message 'b'[TEAM_FI][RED]None''. Retry 3 of 3.
2018-04-17 20:09:46,108 WARNING [WARN]: Caught exception while sending message 'b'[TEAM_FI][RED]None''. Retry 2 of 3.
2018-04-17 20:09:46,108 WARNING [WARN]: Caught exception while sending message 'b'[TEAM_FI][RED]None''. Retry 3 of 3.
2018-04-17 20:12:51,986 WARNING [WARN]: Caught exception while sending message 'b'[TEAM_FI][RED]None''. Retry 2 of 3.
2018-04-17 20:12:51,987 WARNING [WARN]: Caught exception while sending message 'b'[TEAM_FI][RED]None''. Retry 3 of 3.
2018-04-18 11:26:41,160 WARNING [WARN]: Caught exception while sending message 'b'[TEAM_FI][RED]None''. Retry 2 of 3.
2018-04-18 11:26:41,161 WARNING [WARN]: Caught exception while sending message 'b'[TEAM_FI][RED]None''. Retry 3 of 3.
2018-04-18 11:37:50,771 WARNING [WARN]: Caught exception while sending message 'b'[TEAM_FI][RED]None''. Retry 2 of 3.
2018-04-18 11:37:50,772 WARNING [WARN]: Caught exception while sending message 'b'[TEAM_FI][RED]None''. Retry 3 of 3.
2018-04-18 11:37:50,837 ERROR [ERROR]: Caught exception in the launcher.
2018-04-18 11:37:50,849 ERROR [ERROR]: !=== Caught a fatal exception: ===!
2018-04-18 11:37:50,850 ERROR [ERROR]: Exception: 
(7, 0)
  File "C:/Users/Ian/Documents/GitHub/Terra/launcher.py", line 8, in <module>
    Main().run()

  File "C:/Users/Ian/Documents/GitHub/Terra\terra\main.py", line 193, in run
    self.step(event)

  File "C:/Users/Ian/Documents/GitHub/Terra\terra\main.py", line 140, in step
    EVENT_BUS.invoke_handlers(event)

  File "C:/Users/Ian/Documents/GitHub/Terra\terra\event\eventbus.py", line 46, in invoke_handlers
    handler(event)

  File "C:/Users/Ian/Documents/GitHub/Terra\terra\ai\aiplayer.py", line 111, in handle_orders_phase
    self.confirm_assignments(assignments)

  File "C:/Users/Ian/Documents/GitHub/Terra\terra\ai\aiplayer.py", line 88, in confirm_assignments
    self.set_order_for_task(assignment.piece, assignment.task)

  File "C:/Users/Ian/Documents/GitHub/Terra\terra\ai\aiplayer.py", line 94, in set_order_for_task
    piece.attr(Attribute.MOVEMENT_TYPE), piece.attr(Attribute.MOVEMENT_RANGE))

  File "C:/Users/Ian/Documents/GitHub/Terra\terra\ai\pathfinder.py", line 50, in get_path_to_destination
    current = came_from[current]

2018-04-18 11:38:47,441 WARNING [WARN]: Caught exception while sending message 'b'[TEAM_FI][RED]None''. Retry 2 of 3.
2018-04-18 11:38:47,443 WARNING [WARN]: Caught exception while sending message 'b'[TEAM_FI][RED]None''. Retry 3 of 3.
2018-04-18 11:40:16,344 WARNING [WARN]: Caught exception while sending message 'b'[TEAM_FI][RED]None''. Retry 2 of 3.
2018-04-18 11:40:16,345 WARNING [WARN]: Caught exception while sending message 'b'[TEAM_FI][RED]None''. Retry 3 of 3.
2018-04-18 11:43:29,747 ERROR [ERROR]: Caught exception in the launcher.
2018-04-18 11:43:29,749 ERROR [ERROR]: !=== Caught a fatal exception: ===!
2018-04-18 11:43:29,749 ERROR [ERROR]: Exception: 
(7, 0)
  File "C:/Users/Ian/Documents/GitHub/Terra/launcher.py", line 8, in <module>
    Main().run()

  File "C:/Users/Ian/Documents/GitHub/Terra\terra\main.py", line 193, in run
    self.step(event)

  File "C:/Users/Ian/Documents/GitHub/Terra\terra\main.py", line 140, in step
    EVENT_BUS.invoke_handlers(event)

  File "C:/Users/Ian/Documents/GitHub/Terra\terra\event\eventbus.py", line 46, in invoke_handlers
    handler(event)

  File "C:/Users/Ian/Documents/GitHub/Terra\terra\ai\aiplayer.py", line 111, in handle_orders_phase
    self.confirm_assignments(assignments)

  File "C:/Users/Ian/Documents/GitHub/Terra\terra\ai\aiplayer.py", line 88, in confirm_assignments
    self.set_order_for_task(assignment.piece, assignment.task)

  File "C:/Users/Ian/Documents/GitHub/Terra\terra\ai\aiplayer.py", line 94, in set_order_for_task
    piece.attr(Attribute.MOVEMENT_TYPE), piece.attr(Attribute.MOVEMENT_RANGE))

  File "C:/Users/Ian/Documents/GitHub/Terra\terra\ai\pathfinder.py", line 50, in get_path_to_destination
    current = came_from[current]

2018-04-18 11:45:33,635 WARNING [WARN]: Caught exception while sending message 'b'[TEAM_FI][RED]None''. Retry 2 of 3.
2018-04-18 11:45:33,636 WARNING [WARN]: Caught exception while sending message 'b'[TEAM_FI][RED]None''. Retry 3 of 3.
2018-04-18 11:45:33,703 ERROR [ERROR]: Caught exception in the launcher.
2018-04-18 11:45:33,705 ERROR [ERROR]: !=== Caught a fatal exception: ===!
2018-04-18 11:45:33,705 ERROR [ERROR]: Exception: 
(7, 0)
  File "C:/Users/Ian/Documents/GitHub/Terra/launcher.py", line 8, in <module>
    Main().run()

  File "C:/Users/Ian/Documents/GitHub/Terra\terra\main.py", line 193, in run
    self.step(event)

  File "C:/Users/Ian/Documents/GitHub/Terra\terra\main.py", line 140, in step
    EVENT_BUS.invoke_handlers(event)

  File "C:/Users/Ian/Documents/GitHub/Terra\terra\event\eventbus.py", line 46, in invoke_handlers
    handler(event)

  File "C:/Users/Ian/Documents/GitHub/Terra\terra\ai\aiplayer.py", line 111, in handle_orders_phase
    self.confirm_assignments(assignments)

  File "C:/Users/Ian/Documents/GitHub/Terra\terra\ai\aiplayer.py", line 88, in confirm_assignments
    self.set_order_for_task(assignment.piece, assignment.task)

  File "C:/Users/Ian/Documents/GitHub/Terra\terra\ai\aiplayer.py", line 94, in set_order_for_task
    piece.attr(Attribute.MOVEMENT_TYPE), piece.attr(Attribute.MOVEMENT_RANGE))

  File "C:/Users/Ian/Documents/GitHub/Terra\terra\ai\pathfinder.py", line 51, in get_path_to_destination
    current = came_from[current]

2018-04-18 11:46:16,717 WARNING [WARN]: Caught exception while sending message 'b'[TEAM_FI][RED]None''. Retry 2 of 3.
2018-04-18 11:46:16,718 WARNING [WARN]: Caught exception while sending message 'b'[TEAM_FI][RED]None''. Retry 3 of 3.
2018-04-18 11:46:31,537 WARNING [WARN]: Caught exception while sending message 'b'[TEAM_FI][RED]None''. Retry 2 of 3.
2018-04-18 11:46:31,538 WARNING [WARN]: Caught exception while sending message 'b'[TEAM_FI][RED]None''. Retry 3 of 3.
2018-04-18 11:52:18,385 WARNING [WARN]: Caught exception while sending message 'b'[TEAM_FI][RED]None''. Retry 2 of 3.
2018-04-18 11:52:18,385 WARNING [WARN]: Caught exception while sending message 'b'[TEAM_FI][RED]None''. Retry 3 of 3.
2018-04-18 12:04:08,716 WARNING [WARN]: Caught exception while sending message 'b'[TEAM_FI][RED]None''. Retry 2 of 3.
2018-04-18 12:04:08,718 WARNING [WARN]: Caught exception while sending message 'b'[TEAM_FI][RED]None''. Retry 3 of 3.
2018-04-18 12:06:59,593 WARNING [WARN]: Caught exception while sending message 'b'[TEAM_FI][RED]None''. Retry 2 of 3.
2018-04-18 12:06:59,595 WARNING [WARN]: Caught exception while sending message 'b'[TEAM_FI][RED]None''. Retry 3 of 3.
2018-04-18 12:11:07,670 WARNING [WARN]: Caught exception while sending message 'b'[TEAM_FI][RED]None''. Retry 2 of 3.
2018-04-18 12:11:07,671 WARNING [WARN]: Caught exception while sending message 'b'[TEAM_FI][RED]None''. Retry 3 of 3.
2018-04-18 12:14:06,504 WARNING [WARN]: Caught exception while sending message 'b'[TEAM_FI][RED]None''. Retry 2 of 3.
2018-04-18 12:14:06,505 WARNING [WARN]: Caught exception while sending message 'b'[TEAM_FI][RED]None''. Retry 3 of 3.
2018-04-18 12:14:50,345 WARNING [WARN]: Caught exception while sending message 'b'[TEAM_FI][RED]None''. Retry 2 of 3.
2018-04-18 12:14:50,345 WARNING [WARN]: Caught exception while sending message 'b'[TEAM_FI][RED]None''. Retry 3 of 3.
2018-04-18 12:18:22,744 WARNING [WARN]: Caught exception while sending message 'b'[TEAM_FI][RED]None''. Retry 2 of 3.
2018-04-18 12:18:22,744 WARNING [WARN]: Caught exception while sending message 'b'[TEAM_FI][RED]None''. Retry 3 of 3.
2018-04-18 13:03:09,117 WARNING [WARN]: Caught exception while sending message 'b'[TEAM_FI][RED]None''. Retry 2 of 3.
2018-04-18 13:03:09,118 WARNING [WARN]: Caught exception while sending message 'b'[TEAM_FI][RED]None''. Retry 3 of 3.
2018-04-18 13:08:32,845 WARNING [WARN]: Caught exception while sending message 'b'[TEAM_FI][RED]None''. Retry 2 of 3.
2018-04-18 13:08:32,846 WARNING [WARN]: Caught exception while sending message 'b'[TEAM_FI][RED]None''. Retry 3 of 3.
2018-04-18 13:10:40,927 WARNING [WARN]: Caught exception while sending message 'b'[TEAM_FI][RED]None''. Retry 2 of 3.
2018-04-18 13:10:40,927 WARNING [WARN]: Caught exception while sending message 'b'[TEAM_FI][RED]None''. Retry 3 of 3.
2018-04-18 13:27:32,084 WARNING [WARN]: Caught exception while sending message 'b'[TEAM_FI][RED]None''. Retry 2 of 3.
2018-04-18 13:27:32,084 WARNING [WARN]: Caught exception while sending message 'b'[TEAM_FI][RED]None''. Retry 3 of 3.
2018-04-18 13:27:32,109 ERROR [ERROR]: Caught exception in the launcher.
2018-04-18 13:27:32,125 ERROR [ERROR]: !=== Caught a fatal exception: ===!
2018-04-18 13:27:32,125 ERROR [ERROR]: Exception: 
expected an indented block (pathfinder.py, line 11)
  File "C:/Users/Ian/Documents/GitHub/Terra/launcher.py", line 8, in <module>
    Main().run()

  File "C:\Users\Ian\Documents\GitHub\Terra\terra\main.py", line 193, in run
    self.step(event)

  File "C:\Users\Ian\Documents\GitHub\Terra\terra\main.py", line 140, in step
    EVENT_BUS.invoke_handlers(event)

  File "C:\Users\Ian\Documents\GitHub\Terra\terra\event\eventbus.py", line 46, in invoke_handlers
    handler(event)

  File "C:\Users\Ian\Documents\GitHub\Terra\terra\main.py", line 97, in handle_menu_selections
    self.set_screen_from_mode(Mode.LOBBY, event.mapname)

  File "C:\Users\Ian\Documents\GitHub\Terra\terra\main.py", line 64, in set_screen_from_mode
    new_screen = Lobby(False, map_name, map_type)

  File "C:\Users\Ian\Documents\GitHub\Terra\terra\screens\lobby.py", line 31, in __init__
    Session.set_up_local_game(map_name, map_type)

  File "C:\Users\Ian\Documents\GitHub\Terra\terra\managers\session.py", line 45, in set_up_local_game
    SESSION.__set_up__(map_name, bitmap, pieces, teams, upgrades, meta)

  File "C:\Users\Ian\Documents\GitHub\Terra\terra\managers\session.py", line 112, in __set_up__
    from terra.piece.piecemanager import PieceManager

  File "C:\Users\Ian\Documents\GitHub\Terra\terra\piece\piecemanager.py", line 10, in <module>
    from terra.piece.piece import Piece

  File "C:\Users\Ian\Documents\GitHub\Terra\terra\piece\piece.py", line 3, in <module>
    from terra.ai.pathfinder import get_path_to_destination

2018-04-18 13:27:55,270 WARNING [WARN]: Caught exception while sending message 'b'[TEAM_FI][RED]None''. Retry 2 of 3.
2018-04-18 13:27:55,270 WARNING [WARN]: Caught exception while sending message 'b'[TEAM_FI][RED]None''. Retry 3 of 3.
2018-04-18 13:27:55,280 ERROR [ERROR]: Caught exception in the launcher.
2018-04-18 13:27:55,282 ERROR [ERROR]: !=== Caught a fatal exception: ===!
2018-04-18 13:27:55,282 ERROR [ERROR]: Exception: 
expected an indented block (pathfinder.py, line 11)
  File "C:/Users/Ian/Documents/GitHub/Terra/launcher.py", line 8, in <module>
    Main().run()

  File "C:\Users\Ian\Documents\GitHub\Terra\terra\main.py", line 193, in run
    self.step(event)

  File "C:\Users\Ian\Documents\GitHub\Terra\terra\main.py", line 140, in step
    EVENT_BUS.invoke_handlers(event)

  File "C:\Users\Ian\Documents\GitHub\Terra\terra\event\eventbus.py", line 46, in invoke_handlers
    handler(event)

  File "C:\Users\Ian\Documents\GitHub\Terra\terra\main.py", line 97, in handle_menu_selections
    self.set_screen_from_mode(Mode.LOBBY, event.mapname)

  File "C:\Users\Ian\Documents\GitHub\Terra\terra\main.py", line 64, in set_screen_from_mode
    new_screen = Lobby(False, map_name, map_type)

  File "C:\Users\Ian\Documents\GitHub\Terra\terra\screens\lobby.py", line 31, in __init__
    Session.set_up_local_game(map_name, map_type)

  File "C:\Users\Ian\Documents\GitHub\Terra\terra\managers\session.py", line 45, in set_up_local_game
    SESSION.__set_up__(map_name, bitmap, pieces, teams, upgrades, meta)

  File "C:\Users\Ian\Documents\GitHub\Terra\terra\managers\session.py", line 112, in __set_up__
    from terra.piece.piecemanager import PieceManager

  File "C:\Users\Ian\Documents\GitHub\Terra\terra\piece\piecemanager.py", line 10, in <module>
    from terra.piece.piece import Piece

  File "C:\Users\Ian\Documents\GitHub\Terra\terra\piece\piece.py", line 3, in <module>
    from terra.ai.pathfinder import get_path_to_destination

2018-04-18 13:28:07,760 WARNING [WARN]: Caught exception while sending message 'b'[TEAM_FI][RED]None''. Retry 2 of 3.
2018-04-18 13:28:07,761 WARNING [WARN]: Caught exception while sending message 'b'[TEAM_FI][RED]None''. Retry 3 of 3.
2018-04-18 13:40:42,058 WARNING [WARN]: Caught exception while sending message 'b'[TEAM_FI][RED]None''. Retry 2 of 3.
2018-04-18 13:40:42,058 WARNING [WARN]: Caught exception while sending message 'b'[TEAM_FI][RED]None''. Retry 3 of 3.
2018-04-18 13:41:18,536 WARNING [WARN]: Caught exception while sending message 'b'[TEAM_FI][RED]None''. Retry 2 of 3.
2018-04-18 13:41:18,537 WARNING [WARN]: Caught exception while sending message 'b'[TEAM_FI][RED]None''. Retry 3 of 3.
2018-04-18 13:42:05,642 WARNING [WARN]: Caught exception while sending message 'b'[TEAM_FI][RED]None''. Retry 2 of 3.
2018-04-18 13:42:05,643 WARNING [WARN]: Caught exception while sending message 'b'[TEAM_FI][RED]None''. Retry 3 of 3.
2018-04-18 13:45:28,463 WARNING [WARN]: Caught exception while sending message 'b'[TEAM_FI][RED]None''. Retry 2 of 3.
2018-04-18 13:45:28,463 WARNING [WARN]: Caught exception while sending message 'b'[TEAM_FI][RED]None''. Retry 3 of 3.
2018-04-18 13:45:49,605 WARNING [WARN]: Caught exception while sending message 'b'[TEAM_FI][RED]None''. Retry 2 of 3.
2018-04-18 13:45:49,605 WARNING [WARN]: Caught exception while sending message 'b'[TEAM_FI][RED]None''. Retry 3 of 3.
2018-04-18 13:53:54,560 WARNING [WARN]: Caught exception while sending message 'b'[TEAM_FI][RED]None''. Retry 2 of 3.
2018-04-18 13:53:54,560 WARNING [WARN]: Caught exception while sending message 'b'[TEAM_FI][RED]None''. Retry 3 of 3.
2018-04-18 13:53:59,427 ERROR [ERROR]: Caught exception in the launcher.
2018-04-18 13:53:59,428 ERROR [ERROR]: !=== Caught a fatal exception: ===!
2018-04-18 13:53:59,428 ERROR [ERROR]: Exception: 
object of type 'Piece' has no len()
  File "C:/Users/Ian/Documents/GitHub/Terra/launcher.py", line 8, in <module>
    Main().run()

  File "C:\Users\Ian\Documents\GitHub\Terra\terra\main.py", line 193, in run
    self.step(event)

  File "C:\Users\Ian\Documents\GitHub\Terra\terra\main.py", line 140, in step
    EVENT_BUS.invoke_handlers(event)

  File "C:\Users\Ian\Documents\GitHub\Terra\terra\event\eventbus.py", line 46, in invoke_handlers
    handler(event)

  File "C:\Users\Ian\Documents\GitHub\Terra\terra\ai\aiplayer.py", line 121, in handle_orders_phase
    self.confirm_assignments(assignments)

  File "C:\Users\Ian\Documents\GitHub\Terra\terra\ai\aiplayer.py", line 89, in confirm_assignments
    self.set_order_for_task(assignment.piece, assignment.task)

  File "C:\Users\Ian\Documents\GitHub\Terra\terra\ai\aiplayer.py", line 97, in set_order_for_task
    destination = piece.step_along_path(path)

  File "C:\Users\Ian\Documents\GitHub\Terra\terra\piece\piece.py", line 383, in step_along_path
    if len(self.get_manager(Manager.PIECE).get_piece_at(pdest[0], pdest[1], self.team)) == 0:

2018-04-18 13:54:55,097 WARNING [WARN]: Caught exception while sending message 'b'[TEAM_FI][RED]None''. Retry 2 of 3.
2018-04-18 13:54:55,097 WARNING [WARN]: Caught exception while sending message 'b'[TEAM_FI][RED]None''. Retry 3 of 3.
2018-04-18 13:55:08,723 ERROR [ERROR]: Caught exception in the launcher.
2018-04-18 13:55:08,724 ERROR [ERROR]: !=== Caught a fatal exception: ===!
2018-04-18 13:55:08,724 ERROR [ERROR]: Exception: 
object of type 'NoneType' has no len()
  File "C:/Users/Ian/Documents/GitHub/Terra/launcher.py", line 8, in <module>
    Main().run()

  File "C:\Users\Ian\Documents\GitHub\Terra\terra\main.py", line 193, in run
    self.step(event)

  File "C:\Users\Ian\Documents\GitHub\Terra\terra\main.py", line 140, in step
    EVENT_BUS.invoke_handlers(event)

  File "C:\Users\Ian\Documents\GitHub\Terra\terra\event\eventbus.py", line 46, in invoke_handlers
    handler(event)

  File "C:\Users\Ian\Documents\GitHub\Terra\terra\ai\aiplayer.py", line 121, in handle_orders_phase
    self.confirm_assignments(assignments)

  File "C:\Users\Ian\Documents\GitHub\Terra\terra\ai\aiplayer.py", line 89, in confirm_assignments
    self.set_order_for_task(assignment.piece, assignment.task)

  File "C:\Users\Ian\Documents\GitHub\Terra\terra\ai\aiplayer.py", line 96, in set_order_for_task
    if len(path) > 2:

2018-04-18 13:56:02,172 WARNING [WARN]: Caught exception while sending message 'b'[TEAM_FI][RED]None''. Retry 2 of 3.
2018-04-18 13:56:02,172 WARNING [WARN]: Caught exception while sending message 'b'[TEAM_FI][RED]None''. Retry 3 of 3.
2018-04-18 13:56:05,676 ERROR [ERROR]: Caught exception in the launcher.
2018-04-18 13:56:05,678 ERROR [ERROR]: !=== Caught a fatal exception: ===!
2018-04-18 13:56:05,678 ERROR [ERROR]: Exception: 
'NoneType' object is not subscriptable
  File "C:/Users/Ian/Documents/GitHub/Terra/launcher.py", line 8, in <module>
    Main().run()

  File "C:\Users\Ian\Documents\GitHub\Terra\terra\main.py", line 193, in run
    self.step(event)

  File "C:\Users\Ian\Documents\GitHub\Terra\terra\main.py", line 140, in step
    EVENT_BUS.invoke_handlers(event)

  File "C:\Users\Ian\Documents\GitHub\Terra\terra\event\eventbus.py", line 46, in invoke_handlers
    handler(event)

  File "C:\Users\Ian\Documents\GitHub\Terra\terra\ai\aiplayer.py", line 121, in handle_orders_phase
    self.confirm_assignments(assignments)

  File "C:\Users\Ian\Documents\GitHub\Terra\terra\ai\aiplayer.py", line 89, in confirm_assignments
    self.set_order_for_task(assignment.piece, assignment.task)

  File "C:\Users\Ian\Documents\GitHub\Terra\terra\ai\aiplayer.py", line 102, in set_order_for_task
    'dx': destination[0],

2018-04-18 13:56:29,443 WARNING [WARN]: Caught exception while sending message 'b'[TEAM_FI][RED]None''. Retry 2 of 3.
2018-04-18 13:56:29,446 WARNING [WARN]: Caught exception while sending message 'b'[TEAM_FI][RED]None''. Retry 3 of 3.
2018-04-18 13:56:29,467 ERROR [ERROR]: Caught exception in the launcher.
2018-04-18 13:56:29,473 ERROR [ERROR]: !=== Caught a fatal exception: ===!
2018-04-18 13:56:29,473 ERROR [ERROR]: Exception: 
invalid syntax (aiplayer.py, line 96)
  File "C:/Users/Ian/Documents/GitHub/Terra/launcher.py", line 8, in <module>
    Main().run()

  File "C:/Users/Ian/Documents/GitHub/Terra\terra\main.py", line 193, in run
    self.step(event)

  File "C:/Users/Ian/Documents/GitHub/Terra\terra\main.py", line 140, in step
    EVENT_BUS.invoke_handlers(event)

  File "C:/Users/Ian/Documents/GitHub/Terra\terra\event\eventbus.py", line 46, in invoke_handlers
    handler(event)

  File "C:/Users/Ian/Documents/GitHub/Terra\terra\main.py", line 97, in handle_menu_selections
    self.set_screen_from_mode(Mode.LOBBY, event.mapname)

  File "C:/Users/Ian/Documents/GitHub/Terra\terra\main.py", line 64, in set_screen_from_mode
    new_screen = Lobby(False, map_name, map_type)

  File "C:/Users/Ian/Documents/GitHub/Terra\terra\screens\lobby.py", line 31, in __init__
    Session.set_up_local_game(map_name, map_type)

  File "C:/Users/Ian/Documents/GitHub/Terra\terra\managers\session.py", line 45, in set_up_local_game
    SESSION.__set_up__(map_name, bitmap, pieces, teams, upgrades, meta)

  File "C:/Users/Ian/Documents/GitHub/Terra\terra\managers\session.py", line 113, in __set_up__
    from terra.team.playermanager import PlayerManager

  File "C:/Users/Ian/Documents/GitHub/Terra\terra\team\playermanager.py", line 8, in <module>
    from terra.ai.aiplayer import AIPlayer

2018-04-18 13:57:13,633 WARNING [WARN]: Caught exception while sending message 'b'[TEAM_FI][RED]None''. Retry 2 of 3.
2018-04-18 13:57:13,635 WARNING [WARN]: Caught exception while sending message 'b'[TEAM_FI][RED]None''. Retry 3 of 3.
2018-04-18 13:57:13,785 ERROR [ERROR]: Caught exception in the launcher.
2018-04-18 13:57:13,787 ERROR [ERROR]: !=== Caught a fatal exception: ===!
2018-04-18 13:57:13,787 ERROR [ERROR]: Exception: 
'NoneType' object is not subscriptable
  File "C:/Users/Ian/Documents/GitHub/Terra/launcher.py", line 8, in <module>
    Main().run()

  File "C:/Users/Ian/Documents/GitHub/Terra\terra\main.py", line 193, in run
    self.step(event)

  File "C:/Users/Ian/Documents/GitHub/Terra\terra\main.py", line 140, in step
    EVENT_BUS.invoke_handlers(event)

  File "C:/Users/Ian/Documents/GitHub/Terra\terra\event\eventbus.py", line 46, in invoke_handlers
    handler(event)

  File "C:/Users/Ian/Documents/GitHub/Terra\terra\ai\aiplayer.py", line 121, in handle_orders_phase
    self.confirm_assignments(assignments)

  File "C:/Users/Ian/Documents/GitHub/Terra\terra\ai\aiplayer.py", line 89, in confirm_assignments
    self.set_order_for_task(assignment.piece, assignment.task)

  File "C:/Users/Ian/Documents/GitHub/Terra\terra\ai\aiplayer.py", line 102, in set_order_for_task
    'dx': destination[0],

2018-04-18 13:58:06,732 WARNING [WARN]: Caught exception while sending message 'b'[TEAM_FI][RED]None''. Retry 2 of 3.
2018-04-18 13:58:06,732 WARNING [WARN]: Caught exception while sending message 'b'[TEAM_FI][RED]None''. Retry 3 of 3.
2018-04-18 13:58:51,887 WARNING [WARN]: Caught exception while sending message 'b'[TEAM_FI][RED]None''. Retry 2 of 3.
2018-04-18 13:58:51,889 WARNING [WARN]: Caught exception while sending message 'b'[TEAM_FI][RED]None''. Retry 3 of 3.
2018-04-18 14:00:27,377 WARNING [WARN]: Caught exception while sending message 'b'[TEAM_FI][RED]None''. Retry 2 of 3.
2018-04-18 14:00:27,377 WARNING [WARN]: Caught exception while sending message 'b'[TEAM_FI][RED]None''. Retry 3 of 3.
2018-04-18 14:01:00,845 ERROR [ERROR]: Caught exception in the launcher.
2018-04-18 14:01:00,846 ERROR [ERROR]: !=== Caught a fatal exception: ===!
2018-04-18 14:01:00,846 ERROR [ERROR]: Exception: 
'NoneType' object is not subscriptable
  File "C:/Users/Ian/Documents/GitHub/Terra/launcher.py", line 8, in <module>
    Main().run()

  File "C:\Users\Ian\Documents\GitHub\Terra\terra\main.py", line 193, in run
    self.step(event)

  File "C:\Users\Ian\Documents\GitHub\Terra\terra\main.py", line 140, in step
    EVENT_BUS.invoke_handlers(event)

  File "C:\Users\Ian\Documents\GitHub\Terra\terra\event\eventbus.py", line 46, in invoke_handlers
    handler(event)

  File "C:\Users\Ian\Documents\GitHub\Terra\terra\ai\aiplayer.py", line 125, in handle_orders_phase
    self.confirm_assignments(assignments)

  File "C:\Users\Ian\Documents\GitHub\Terra\terra\ai\aiplayer.py", line 89, in confirm_assignments
    self.set_order_for_task(assignment.piece, assignment.task)

  File "C:\Users\Ian\Documents\GitHub\Terra\terra\ai\aiplayer.py", line 103, in set_order_for_task
    'dx': destination[0],

2018-04-18 14:01:21,356 WARNING [WARN]: Caught exception while sending message 'b'[TEAM_FI][RED]None''. Retry 2 of 3.
2018-04-18 14:01:21,356 WARNING [WARN]: Caught exception while sending message 'b'[TEAM_FI][RED]None''. Retry 3 of 3.
2018-04-18 14:01:41,494 WARNING [WARN]: Caught exception while sending message 'b'[TEAM_FI][RED]None''. Retry 2 of 3.
2018-04-18 14:01:41,494 WARNING [WARN]: Caught exception while sending message 'b'[TEAM_FI][RED]None''. Retry 3 of 3.
2018-04-18 14:02:33,818 ERROR [ERROR]: Caught exception in the launcher.
2018-04-18 14:02:33,821 ERROR [ERROR]: !=== Caught a fatal exception: ===!
2018-04-18 14:02:33,821 ERROR [ERROR]: Exception: 
'NoneType' object is not subscriptable
  File "C:/Users/Ian/Documents/GitHub/Terra/launcher.py", line 8, in <module>
    Main().run()

  File "C:/Users/Ian/Documents/GitHub/Terra\terra\main.py", line 193, in run
    self.step(event)

  File "C:/Users/Ian/Documents/GitHub/Terra\terra\main.py", line 140, in step
    EVENT_BUS.invoke_handlers(event)

  File "C:/Users/Ian/Documents/GitHub/Terra\terra\event\eventbus.py", line 46, in invoke_handlers
    handler(event)

  File "C:/Users/Ian/Documents/GitHub/Terra\terra\ai\aiplayer.py", line 125, in handle_orders_phase
    self.confirm_assignments(assignments)

  File "C:/Users/Ian/Documents/GitHub/Terra\terra\ai\aiplayer.py", line 89, in confirm_assignments
    self.set_order_for_task(assignment.piece, assignment.task)

  File "C:/Users/Ian/Documents/GitHub/Terra\terra\ai\aiplayer.py", line 103, in set_order_for_task
    'dx': destination[0],

2018-04-18 14:03:57,342 WARNING [WARN]: Caught exception while sending message 'b'[TEAM_FI][RED]None''. Retry 2 of 3.
2018-04-18 14:03:57,342 WARNING [WARN]: Caught exception while sending message 'b'[TEAM_FI][RED]None''. Retry 3 of 3.
2018-04-18 14:04:00,914 WARNING [WARN]: Caught exception while sending message 'b'[TEAM_FI][RED]None''. Retry 2 of 3.
2018-04-18 14:04:00,914 WARNING [WARN]: Caught exception while sending message 'b'[TEAM_FI][RED]None''. Retry 3 of 3.
2018-04-18 14:07:09,748 WARNING [WARN]: Caught exception while sending message 'b'[TEAM_FI][RED]None''. Retry 2 of 3.
2018-04-18 14:07:09,748 WARNING [WARN]: Caught exception while sending message 'b'[TEAM_FI][RED]None''. Retry 3 of 3.
2018-04-18 14:08:04,064 WARNING [WARN]: Caught exception while sending message 'b'[TEAM_FI][RED]None''. Retry 2 of 3.
2018-04-18 14:08:04,064 WARNING [WARN]: Caught exception while sending message 'b'[TEAM_FI][RED]None''. Retry 3 of 3.
2018-04-18 14:08:27,961 WARNING [WARN]: Caught exception while sending message 'b'[TEAM_FI][RED]None''. Retry 2 of 3.
2018-04-18 14:08:27,962 WARNING [WARN]: Caught exception while sending message 'b'[TEAM_FI][RED]None''. Retry 3 of 3.
2018-04-18 14:08:36,454 WARNING [WARN]: Caught exception while sending message 'b'[TEAM_FI][RED]None''. Retry 2 of 3.
2018-04-18 14:08:36,454 WARNING [WARN]: Caught exception while sending message 'b'[TEAM_FI][RED]None''. Retry 3 of 3.
2018-04-18 14:09:03,676 WARNING [WARN]: Caught exception while sending message 'b'[TEAM_FI][RED]None''. Retry 2 of 3.
2018-04-18 14:09:03,676 WARNING [WARN]: Caught exception while sending message 'b'[TEAM_FI][RED]None''. Retry 3 of 3.
2018-04-18 14:11:02,188 WARNING [WARN]: Caught exception while sending message 'b'[TEAM_FI][RED]None''. Retry 2 of 3.
2018-04-18 14:11:02,189 WARNING [WARN]: Caught exception while sending message 'b'[TEAM_FI][RED]None''. Retry 3 of 3.
2018-04-18 14:11:46,398 WARNING [WARN]: Caught exception while sending message 'b'[TEAM_FI][RED]None''. Retry 2 of 3.
2018-04-18 14:11:46,398 WARNING [WARN]: Caught exception while sending message 'b'[TEAM_FI][RED]None''. Retry 3 of 3.
2018-04-18 14:13:47,800 WARNING [WARN]: Caught exception while sending message 'b'[TEAM_FI][RED]None''. Retry 2 of 3.
2018-04-18 14:13:47,800 WARNING [WARN]: Caught exception while sending message 'b'[TEAM_FI][RED]None''. Retry 3 of 3.
2018-04-18 14:13:58,356 WARNING [WARN]: Caught exception while sending message 'b'[TEAM_FI][RED]None''. Retry 2 of 3.
2018-04-18 14:13:58,356 WARNING [WARN]: Caught exception while sending message 'b'[TEAM_FI][RED]None''. Retry 3 of 3.
2018-04-18 14:14:51,577 WARNING [WARN]: Caught exception while sending message 'b'[TEAM_FI][RED]None''. Retry 2 of 3.
2018-04-18 14:14:51,577 WARNING [WARN]: Caught exception while sending message 'b'[TEAM_FI][RED]None''. Retry 3 of 3.
2018-04-18 14:14:58,628 WARNING [WARN]: Caught exception while sending message 'b'[TEAM_FI][RED]None''. Retry 2 of 3.
2018-04-18 14:14:58,628 WARNING [WARN]: Caught exception while sending message 'b'[TEAM_FI][RED]None''. Retry 3 of 3.
2018-04-18 14:15:37,685 WARNING [WARN]: Caught exception while sending message 'b'[TEAM_FI][RED]None''. Retry 2 of 3.
2018-04-18 14:15:37,685 WARNING [WARN]: Caught exception while sending message 'b'[TEAM_FI][RED]None''. Retry 3 of 3.
2018-04-18 14:15:45,084 WARNING [WARN]: Caught exception while sending message 'b'[TEAM_FI][RED]None''. Retry 2 of 3.
2018-04-18 14:15:45,084 WARNING [WARN]: Caught exception while sending message 'b'[TEAM_FI][RED]None''. Retry 3 of 3.
2018-04-18 14:17:34,206 WARNING [WARN]: Caught exception while sending message 'b'[TEAM_FI][RED]None''. Retry 2 of 3.
2018-04-18 14:17:34,206 WARNING [WARN]: Caught exception while sending message 'b'[TEAM_FI][RED]None''. Retry 3 of 3.
2018-04-18 14:17:59,938 WARNING [WARN]: Caught exception while sending message 'b'[TEAM_FI][RED]None''. Retry 2 of 3.
2018-04-18 14:17:59,939 WARNING [WARN]: Caught exception while sending message 'b'[TEAM_FI][RED]None''. Retry 3 of 3.
2018-04-18 14:18:15,800 WARNING [WARN]: Caught exception while sending message 'b'[TEAM_FI][RED]None''. Retry 2 of 3.
2018-04-18 14:18:15,800 WARNING [WARN]: Caught exception while sending message 'b'[TEAM_FI][RED]None''. Retry 3 of 3.
2018-04-18 14:23:24,632 WARNING [WARN]: Caught exception while sending message 'b'[TEAM_FI][RED]None''. Retry 2 of 3.
2018-04-18 14:23:24,633 WARNING [WARN]: Caught exception while sending message 'b'[TEAM_FI][RED]None''. Retry 3 of 3.
2018-04-18 14:24:13,743 WARNING [WARN]: Caught exception while sending message 'b'[TEAM_FI][RED]None''. Retry 2 of 3.
2018-04-18 14:24:13,743 WARNING [WARN]: Caught exception while sending message 'b'[TEAM_FI][RED]None''. Retry 3 of 3.
2018-04-18 14:24:30,875 WARNING [WARN]: Caught exception while sending message 'b'[TEAM_FI][RED]None''. Retry 2 of 3.
2018-04-18 14:24:30,875 WARNING [WARN]: Caught exception while sending message 'b'[TEAM_FI][RED]None''. Retry 3 of 3.
2018-04-18 14:25:12,789 WARNING [WARN]: Caught exception while sending message 'b'[TEAM_FI][RED]None''. Retry 2 of 3.
2018-04-18 14:25:12,789 WARNING [WARN]: Caught exception while sending message 'b'[TEAM_FI][RED]None''. Retry 3 of 3.
2018-04-18 14:27:00,772 WARNING [WARN]: Caught exception while sending message 'b'[TEAM_FI][RED]None''. Retry 2 of 3.
2018-04-18 14:27:00,772 WARNING [WARN]: Caught exception while sending message 'b'[TEAM_FI][RED]None''. Retry 3 of 3.
2018-04-18 14:28:39,840 WARNING [WARN]: Caught exception while sending message 'b'[TEAM_FI][RED]None''. Retry 2 of 3.
2018-04-18 14:28:39,841 WARNING [WARN]: Caught exception while sending message 'b'[TEAM_FI][RED]None''. Retry 3 of 3.
2018-04-18 14:28:58,127 ERROR [ERROR]: Caught exception in the launcher.
2018-04-18 14:28:58,128 ERROR [ERROR]: !=== Caught a fatal exception: ===!
2018-04-18 14:28:58,128 ERROR [ERROR]: Exception: 
object of type 'NoneType' has no len()
  File "C:/Users/Ian/Documents/GitHub/Terra/launcher.py", line 8, in <module>
    Main().run()

  File "C:\Users\Ian\Documents\GitHub\Terra\terra\main.py", line 193, in run
    self.step(event)

  File "C:\Users\Ian\Documents\GitHub\Terra\terra\main.py", line 140, in step
    EVENT_BUS.invoke_handlers(event)

  File "C:\Users\Ian\Documents\GitHub\Terra\terra\event\eventbus.py", line 46, in invoke_handlers
    handler(event)

  File "C:\Users\Ian\Documents\GitHub\Terra\terra\ai\aiplayer.py", line 128, in handle_orders_phase
    self.confirm_assignments(assignments)

  File "C:\Users\Ian\Documents\GitHub\Terra\terra\ai\aiplayer.py", line 89, in confirm_assignments
    self.set_order_for_task(assignment.piece, assignment.task)

  File "C:\Users\Ian\Documents\GitHub\Terra\terra\ai\aiplayer.py", line 100, in set_order_for_task
    path = piece.get_path_to_destinations(adjacent_tiles)

  File "C:\Users\Ian\Documents\GitHub\Terra\terra\piece\piece.py", line 377, in get_path_to_destinations
    self.current_path = max(paths, key=lambda p: len(p))

  File "C:\Users\Ian\Documents\GitHub\Terra\terra\piece\piece.py", line 377, in <lambda>
    self.current_path = max(paths, key=lambda p: len(p))

2018-04-18 14:29:21,073 WARNING [WARN]: Caught exception while sending message 'b'[TEAM_FI][RED]None''. Retry 2 of 3.
2018-04-18 14:29:21,073 WARNING [WARN]: Caught exception while sending message 'b'[TEAM_FI][RED]None''. Retry 3 of 3.
2018-04-18 14:29:39,189 ERROR [ERROR]: Caught exception in the launcher.
2018-04-18 14:29:39,190 ERROR [ERROR]: !=== Caught a fatal exception: ===!
2018-04-18 14:29:39,190 ERROR [ERROR]: Exception: 
object of type 'NoneType' has no len()
  File "C:/Users/Ian/Documents/GitHub/Terra/launcher.py", line 8, in <module>
    Main().run()

  File "C:\Users\Ian\Documents\GitHub\Terra\terra\main.py", line 193, in run
    self.step(event)

  File "C:\Users\Ian\Documents\GitHub\Terra\terra\main.py", line 140, in step
    EVENT_BUS.invoke_handlers(event)

  File "C:\Users\Ian\Documents\GitHub\Terra\terra\event\eventbus.py", line 46, in invoke_handlers
    handler(event)

  File "C:\Users\Ian\Documents\GitHub\Terra\terra\ai\aiplayer.py", line 128, in handle_orders_phase
    self.confirm_assignments(assignments)

  File "C:\Users\Ian\Documents\GitHub\Terra\terra\ai\aiplayer.py", line 89, in confirm_assignments
    self.set_order_for_task(assignment.piece, assignment.task)

  File "C:\Users\Ian\Documents\GitHub\Terra\terra\ai\aiplayer.py", line 100, in set_order_for_task
    path = piece.get_path_to_destinations(adjacent_tiles)

  File "C:\Users\Ian\Documents\GitHub\Terra\terra\piece\piece.py", line 378, in get_path_to_destinations
    self.current_path = max(paths, key=lambda p: len(p))

  File "C:\Users\Ian\Documents\GitHub\Terra\terra\piece\piece.py", line 378, in <lambda>
    self.current_path = max(paths, key=lambda p: len(p))

2018-04-18 14:31:01,909 WARNING [WARN]: Caught exception while sending message 'b'[TEAM_FI][RED]None''. Retry 2 of 3.
2018-04-18 14:31:01,909 WARNING [WARN]: Caught exception while sending message 'b'[TEAM_FI][RED]None''. Retry 3 of 3.
2018-04-18 14:31:01,923 ERROR [ERROR]: Caught exception in the launcher.
2018-04-18 14:31:01,925 ERROR [ERROR]: !=== Caught a fatal exception: ===!
2018-04-18 14:31:01,925 ERROR [ERROR]: Exception: 
invalid syntax (piece.py, line 371)
  File "C:/Users/Ian/Documents/GitHub/Terra/launcher.py", line 8, in <module>
    Main().run()

  File "C:\Users\Ian\Documents\GitHub\Terra\terra\main.py", line 193, in run
    self.step(event)

  File "C:\Users\Ian\Documents\GitHub\Terra\terra\main.py", line 140, in step
    EVENT_BUS.invoke_handlers(event)

  File "C:\Users\Ian\Documents\GitHub\Terra\terra\event\eventbus.py", line 46, in invoke_handlers
    handler(event)

  File "C:\Users\Ian\Documents\GitHub\Terra\terra\main.py", line 99, in handle_menu_selections
    self.set_screen_from_mode(Mode.LOBBY, event.mapname, map_type=AssetType.SAVE)

  File "C:\Users\Ian\Documents\GitHub\Terra\terra\main.py", line 64, in set_screen_from_mode
    new_screen = Lobby(False, map_name, map_type)

  File "C:\Users\Ian\Documents\GitHub\Terra\terra\screens\lobby.py", line 31, in __init__
    Session.set_up_local_game(map_name, map_type)

  File "C:\Users\Ian\Documents\GitHub\Terra\terra\managers\session.py", line 45, in set_up_local_game
    SESSION.__set_up__(map_name, bitmap, pieces, teams, upgrades, meta)

  File "C:\Users\Ian\Documents\GitHub\Terra\terra\managers\session.py", line 112, in __set_up__
    from terra.piece.piecemanager import PieceManager

  File "C:\Users\Ian\Documents\GitHub\Terra\terra\piece\piecemanager.py", line 10, in <module>
    from terra.piece.piece import Piece

2018-04-18 14:31:10,371 WARNING [WARN]: Caught exception while sending message 'b'[TEAM_FI][RED]None''. Retry 2 of 3.
2018-04-18 14:31:10,371 WARNING [WARN]: Caught exception while sending message 'b'[TEAM_FI][RED]None''. Retry 3 of 3.
2018-04-18 14:31:10,419 ERROR [ERROR]: Caught exception in the launcher.
2018-04-18 14:31:10,420 ERROR [ERROR]: !=== Caught a fatal exception: ===!
2018-04-18 14:31:10,420 ERROR [ERROR]: Exception: 
'Piece' object has no attribute 'get_path'
  File "C:/Users/Ian/Documents/GitHub/Terra/launcher.py", line 8, in <module>
    Main().run()

  File "C:\Users\Ian\Documents\GitHub\Terra\terra\main.py", line 193, in run
    self.step(event)

  File "C:\Users\Ian\Documents\GitHub\Terra\terra\main.py", line 140, in step
    EVENT_BUS.invoke_handlers(event)

  File "C:\Users\Ian\Documents\GitHub\Terra\terra\event\eventbus.py", line 46, in invoke_handlers
    handler(event)

  File "C:\Users\Ian\Documents\GitHub\Terra\terra\ai\aiplayer.py", line 126, in handle_orders_phase
    assignments = self.assign_tasks(tasks)

  File "C:\Users\Ian\Documents\GitHub\Terra\terra\ai\aiplayer.py", line 65, in assign_tasks
    possible_assignments[piece] = task.score_piece_for_task(piece, self.get_manager(Manager.MAP))

  File "C:\Users\Ian\Documents\GitHub\Terra\terra\ai\task.py", line 53, in score_piece_for_task
    path = piece.get_path((self.tx, self.ty))

2018-04-18 14:31:56,851 WARNING [WARN]: Caught exception while sending message 'b'[TEAM_FI][RED]None''. Retry 2 of 3.
2018-04-18 14:31:56,851 WARNING [WARN]: Caught exception while sending message 'b'[TEAM_FI][RED]None''. Retry 3 of 3.
2018-04-18 14:32:18,549 ERROR [ERROR]: Caught exception in the launcher.
2018-04-18 14:32:18,550 ERROR [ERROR]: !=== Caught a fatal exception: ===!
2018-04-18 14:32:18,551 ERROR [ERROR]: Exception: 
object of type 'NoneType' has no len()
  File "C:/Users/Ian/Documents/GitHub/Terra/launcher.py", line 8, in <module>
    Main().run()

  File "C:\Users\Ian\Documents\GitHub\Terra\terra\main.py", line 193, in run
    self.step(event)

  File "C:\Users\Ian\Documents\GitHub\Terra\terra\main.py", line 140, in step
    EVENT_BUS.invoke_handlers(event)

  File "C:\Users\Ian\Documents\GitHub\Terra\terra\event\eventbus.py", line 46, in invoke_handlers
    handler(event)

  File "C:\Users\Ian\Documents\GitHub\Terra\terra\ai\aiplayer.py", line 128, in handle_orders_phase
    self.confirm_assignments(assignments)

  File "C:\Users\Ian\Documents\GitHub\Terra\terra\ai\aiplayer.py", line 89, in confirm_assignments
    self.set_order_for_task(assignment.piece, assignment.task)

  File "C:\Users\Ian\Documents\GitHub\Terra\terra\ai\aiplayer.py", line 100, in set_order_for_task
    path = piece.get_path_to_destinations(adjacent_tiles)

  File "C:\Users\Ian\Documents\GitHub\Terra\terra\piece\piece.py", line 374, in get_path_to_destinations
    self.current_path = max(paths, key=lambda p: len(p))

  File "C:\Users\Ian\Documents\GitHub\Terra\terra\piece\piece.py", line 374, in <lambda>
    self.current_path = max(paths, key=lambda p: len(p))

2018-04-18 14:33:25,405 WARNING [WARN]: Caught exception while sending message 'b'[TEAM_FI][RED]None''. Retry 2 of 3.
2018-04-18 14:33:25,405 WARNING [WARN]: Caught exception while sending message 'b'[TEAM_FI][RED]None''. Retry 3 of 3.
2018-04-18 14:35:05,249 WARNING [WARN]: Caught exception while sending message 'b'[TEAM_FI][RED]None''. Retry 2 of 3.
2018-04-18 14:35:05,250 WARNING [WARN]: Caught exception while sending message 'b'[TEAM_FI][RED]None''. Retry 3 of 3.
2018-04-18 14:37:34,598 WARNING [WARN]: Caught exception while sending message 'b'[TEAM_FI][RED]None''. Retry 2 of 3.
2018-04-18 14:37:34,598 WARNING [WARN]: Caught exception while sending message 'b'[TEAM_FI][RED]None''. Retry 3 of 3.
2018-04-18 14:41:21,481 WARNING [WARN]: Caught exception while sending message 'b'[TEAM_FI][RED]None''. Retry 2 of 3.
2018-04-18 14:41:21,481 WARNING [WARN]: Caught exception while sending message 'b'[TEAM_FI][RED]None''. Retry 3 of 3.
2018-04-18 14:46:06,667 WARNING [WARN]: Caught exception while sending message 'b'[TEAM_FI][RED]None''. Retry 2 of 3.
2018-04-18 14:46:06,668 WARNING [WARN]: Caught exception while sending message 'b'[TEAM_FI][RED]None''. Retry 3 of 3.
2018-04-18 14:46:59,603 WARNING [WARN]: Caught exception while sending message 'b'[TEAM_FI][RED]None''. Retry 2 of 3.
2018-04-18 14:46:59,604 WARNING [WARN]: Caught exception while sending message 'b'[TEAM_FI][RED]None''. Retry 3 of 3.
2018-04-18 14:49:45,375 WARNING [WARN]: Caught exception while sending message 'b'[TEAM_FI][RED]None''. Retry 2 of 3.
2018-04-18 14:49:45,376 WARNING [WARN]: Caught exception while sending message 'b'[TEAM_FI][RED]None''. Retry 3 of 3.
2018-04-18 14:50:16,293 WARNING [WARN]: Caught exception while sending message 'b'[TEAM_FI][RED]None''. Retry 2 of 3.
2018-04-18 14:50:16,293 WARNING [WARN]: Caught exception while sending message 'b'[TEAM_FI][RED]None''. Retry 3 of 3.
2018-04-18 14:50:22,508 ERROR [ERROR]: Caught exception in the launcher.
2018-04-18 14:50:22,509 ERROR [ERROR]: !=== Caught a fatal exception: ===!
2018-04-18 14:50:22,509 ERROR [ERROR]: Exception: 
object of type 'NoneType' has no len()
  File "C:/Users/Ian/Documents/GitHub/Terra/launcher.py", line 8, in <module>
    Main().run()

  File "C:\Users\Ian\Documents\GitHub\Terra\terra\main.py", line 193, in run
    self.step(event)

  File "C:\Users\Ian\Documents\GitHub\Terra\terra\main.py", line 140, in step
    EVENT_BUS.invoke_handlers(event)

  File "C:\Users\Ian\Documents\GitHub\Terra\terra\event\eventbus.py", line 46, in invoke_handlers
    handler(event)

  File "C:\Users\Ian\Documents\GitHub\Terra\terra\ai\aiplayer.py", line 133, in handle_orders_phase
    self.confirm_assignments(assignments)

  File "C:\Users\Ian\Documents\GitHub\Terra\terra\ai\aiplayer.py", line 89, in confirm_assignments
    self.set_order_for_task(assignment.piece, assignment.task)

  File "C:\Users\Ian\Documents\GitHub\Terra\terra\ai\aiplayer.py", line 106, in set_order_for_task
    destination = piece.step_along_path(path)

  File "C:\Users\Ian\Documents\GitHub\Terra\terra\piece\piece.py", line 388, in step_along_path
    steps = min(self.attr(Attribute.MOVEMENT_RANGE), len(path) - 1)

2018-04-18 14:51:02,255 WARNING [WARN]: Caught exception while sending message 'b'[TEAM_FI][RED]None''. Retry 2 of 3.
2018-04-18 14:51:02,255 WARNING [WARN]: Caught exception while sending message 'b'[TEAM_FI][RED]None''. Retry 3 of 3.
2018-04-18 14:51:48,660 WARNING [WARN]: Caught exception while sending message 'b'[TEAM_FI][RED]None''. Retry 2 of 3.
2018-04-18 14:51:48,660 WARNING [WARN]: Caught exception while sending message 'b'[TEAM_FI][RED]None''. Retry 3 of 3.
2018-04-18 14:55:22,660 WARNING [WARN]: Caught exception while sending message 'b'[TEAM_FI][RED]None''. Retry 2 of 3.
2018-04-18 14:55:22,660 WARNING [WARN]: Caught exception while sending message 'b'[TEAM_FI][RED]None''. Retry 3 of 3.
2018-04-18 14:59:30,239 ERROR [ERROR]: Caught exception in the launcher.
2018-04-18 14:59:30,264 ERROR [ERROR]: !=== Caught a fatal exception: ===!
2018-04-18 14:59:30,264 ERROR [ERROR]: Exception: 
video system not initialized
  File "C:/Users/Ian/Documents/GitHub/Terra/launcher.py", line 8, in <module>
    Main().run()

  File "C:\Users\Ian\Documents\GitHub\Terra\terra\main.py", line 193, in run
    self.step(event)

  File "C:\Users\Ian\Documents\GitHub\Terra\terra\main.py", line 137, in step
    INPUT_CONTROLLER.invoke_handlers(event)

  File "C:\Users\Ian\Documents\GitHub\Terra\terra\control\inputcontroller.py", line 55, in invoke_handlers
    handler()

  File "C:\Users\Ian\Documents\GitHub\Terra\terra\menu\menu.py", line 101, in set_cursor_pos_to_mouse_coords
    if self.cursor_in_menu_bounds():

  File "C:\Users\Ian\Documents\GitHub\Terra\terra\menu\menu.py", line 94, in cursor_in_menu_bounds
    mouse_x = get_pos()[0] / SETTINGS.get(Setting.SCREEN_SCALE)

2018-04-18 15:08:45,374 WARNING [WARN]: Caught exception while sending message 'b'[TEAM_FI][RED]None''. Retry 2 of 3.
2018-04-18 15:08:45,375 WARNING [WARN]: Caught exception while sending message 'b'[TEAM_FI][RED]None''. Retry 3 of 3.
2018-04-18 15:09:02,408 WARNING [WARN]: Caught exception while sending message 'b'[TEAM_FI][RED]None''. Retry 2 of 3.
2018-04-18 15:09:02,408 WARNING [WARN]: Caught exception while sending message 'b'[TEAM_FI][RED]None''. Retry 3 of 3.
2018-04-18 15:09:59,947 WARNING [WARN]: Caught exception while sending message 'b'[TEAM_FI][RED]None''. Retry 2 of 3.
2018-04-18 15:09:59,947 WARNING [WARN]: Caught exception while sending message 'b'[TEAM_FI][RED]None''. Retry 3 of 3.
2018-04-18 15:10:48,381 WARNING [WARN]: Caught exception while sending message 'b'[TEAM_FI][RED]None''. Retry 2 of 3.
2018-04-18 15:10:48,382 WARNING [WARN]: Caught exception while sending message 'b'[TEAM_FI][RED]None''. Retry 3 of 3.
2018-04-18 15:11:21,888 WARNING [WARN]: Caught exception while sending message 'b'[TEAM_FI][RED]None''. Retry 2 of 3.
2018-04-18 15:11:21,888 WARNING [WARN]: Caught exception while sending message 'b'[TEAM_FI][RED]None''. Retry 3 of 3.
2018-04-18 15:11:53,949 WARNING [WARN]: Caught exception while sending message 'b'[TEAM_FI][RED]None''. Retry 2 of 3.
2018-04-18 15:11:53,949 WARNING [WARN]: Caught exception while sending message 'b'[TEAM_FI][RED]None''. Retry 3 of 3.
2018-04-18 15:12:21,204 WARNING [WARN]: Caught exception while sending message 'b'[TEAM_FI][RED]None''. Retry 2 of 3.
2018-04-18 15:12:21,204 WARNING [WARN]: Caught exception while sending message 'b'[TEAM_FI][RED]None''. Retry 3 of 3.
2018-04-18 15:12:27,407 WARNING [WARN]: Caught exception while sending message 'b'[TEAM_FI][RED]None''. Retry 2 of 3.
2018-04-18 15:12:27,407 WARNING [WARN]: Caught exception while sending message 'b'[TEAM_FI][RED]None''. Retry 3 of 3.
2018-04-18 15:13:55,348 WARNING [WARN]: Caught exception while sending message 'b'[TEAM_FI][RED]None''. Retry 2 of 3.
2018-04-18 15:13:55,349 WARNING [WARN]: Caught exception while sending message 'b'[TEAM_FI][RED]None''. Retry 3 of 3.
2018-04-18 15:13:58,768 WARNING [WARN]: Caught exception while sending message 'b'[TEAM_FI][RED]None''. Retry 2 of 3.
2018-04-18 15:13:58,768 WARNING [WARN]: Caught exception while sending message 'b'[TEAM_FI][RED]None''. Retry 3 of 3.
2018-04-18 15:15:17,428 WARNING [WARN]: Caught exception while sending message 'b'[TEAM_FI][RED]None''. Retry 2 of 3.
2018-04-18 15:15:17,428 WARNING [WARN]: Caught exception while sending message 'b'[TEAM_FI][RED]None''. Retry 3 of 3.
2018-04-18 15:15:49,590 WARNING [WARN]: Caught exception while sending message 'b'[TEAM_FI][RED]None''. Retry 2 of 3.
2018-04-18 15:15:49,591 WARNING [WARN]: Caught exception while sending message 'b'[TEAM_FI][RED]None''. Retry 3 of 3.
2018-04-18 15:16:06,265 WARNING [WARN]: Caught exception while sending message 'b'[TEAM_FI][RED]None''. Retry 2 of 3.
2018-04-18 15:16:06,265 WARNING [WARN]: Caught exception while sending message 'b'[TEAM_FI][RED]None''. Retry 3 of 3.
2018-04-18 15:16:30,092 WARNING [WARN]: Caught exception while sending message 'b'[TEAM_FI][RED]None''. Retry 2 of 3.
2018-04-18 15:16:30,092 WARNING [WARN]: Caught exception while sending message 'b'[TEAM_FI][RED]None''. Retry 3 of 3.
2018-04-18 15:17:24,157 WARNING [WARN]: Caught exception while sending message 'b'[TEAM_FI][RED]None''. Retry 2 of 3.
2018-04-18 15:17:24,157 WARNING [WARN]: Caught exception while sending message 'b'[TEAM_FI][RED]None''. Retry 3 of 3.
2018-04-18 15:18:09,980 WARNING [WARN]: Caught exception while sending message 'b'[TEAM_FI][RED]None''. Retry 2 of 3.
2018-04-18 15:18:09,980 WARNING [WARN]: Caught exception while sending message 'b'[TEAM_FI][RED]None''. Retry 3 of 3.
2018-04-18 15:19:14,169 WARNING [WARN]: Caught exception while sending message 'b'[TEAM_FI][RED]None''. Retry 2 of 3.
2018-04-18 15:19:14,170 WARNING [WARN]: Caught exception while sending message 'b'[TEAM_FI][RED]None''. Retry 3 of 3.
2018-04-18 15:21:29,729 WARNING [WARN]: Caught exception while sending message 'b'[TEAM_FI][RED]None''. Retry 2 of 3.
2018-04-18 15:21:29,729 WARNING [WARN]: Caught exception while sending message 'b'[TEAM_FI][RED]None''. Retry 3 of 3.
2018-04-18 15:21:40,810 WARNING [WARN]: Caught exception while sending message 'b'[TEAM_FI][RED]None''. Retry 2 of 3.
2018-04-18 15:21:40,810 WARNING [WARN]: Caught exception while sending message 'b'[TEAM_FI][RED]None''. Retry 3 of 3.
2018-04-18 15:21:58,148 WARNING [WARN]: Caught exception while sending message 'b'[TEAM_FI][RED]None''. Retry 2 of 3.
2018-04-18 15:21:58,148 WARNING [WARN]: Caught exception while sending message 'b'[TEAM_FI][RED]None''. Retry 3 of 3.
2018-04-18 15:22:14,543 WARNING [WARN]: Caught exception while sending message 'b'[TEAM_FI][RED]None''. Retry 2 of 3.
2018-04-18 15:22:14,544 WARNING [WARN]: Caught exception while sending message 'b'[TEAM_FI][RED]None''. Retry 3 of 3.
2018-04-18 15:22:16,968 WARNING [WARN]: Caught exception while sending message 'b'[TEAM_FI][RED]None''. Retry 2 of 3.
2018-04-18 15:22:16,968 WARNING [WARN]: Caught exception while sending message 'b'[TEAM_FI][RED]None''. Retry 3 of 3.
2018-04-18 15:22:25,261 WARNING [WARN]: Caught exception while sending message 'b'[TEAM_FI][RED]None''. Retry 2 of 3.
2018-04-18 15:22:25,261 WARNING [WARN]: Caught exception while sending message 'b'[TEAM_FI][RED]None''. Retry 3 of 3.
2018-04-18 15:25:42,255 WARNING [WARN]: Caught exception while sending message 'b'[TEAM_FI][RED]None''. Retry 2 of 3.
2018-04-18 15:25:42,255 WARNING [WARN]: Caught exception while sending message 'b'[TEAM_FI][RED]None''. Retry 3 of 3.
2018-04-18 15:25:42,272 ERROR [ERROR]: Caught exception in the launcher.
2018-04-18 15:25:42,273 ERROR [ERROR]: !=== Caught a fatal exception: ===!
2018-04-18 15:25:42,274 ERROR [ERROR]: Exception: 
invalid syntax (aiplayer.py, line 55)
  File "C:/Users/Ian/Documents/GitHub/Terra/launcher.py", line 8, in <module>
    Main().run()

  File "C:\Users\Ian\Documents\GitHub\Terra\terra\main.py", line 193, in run
    self.step(event)

  File "C:\Users\Ian\Documents\GitHub\Terra\terra\main.py", line 140, in step
    EVENT_BUS.invoke_handlers(event)

  File "C:\Users\Ian\Documents\GitHub\Terra\terra\event\eventbus.py", line 46, in invoke_handlers
    handler(event)

  File "C:\Users\Ian\Documents\GitHub\Terra\terra\main.py", line 97, in handle_menu_selections
    self.set_screen_from_mode(Mode.LOBBY, event.mapname)

  File "C:\Users\Ian\Documents\GitHub\Terra\terra\main.py", line 66, in set_screen_from_mode
    new_screen = Lobby(False, map_name, map_type)

  File "C:\Users\Ian\Documents\GitHub\Terra\terra\screens\lobby.py", line 31, in __init__
    Session.set_up_local_game(map_name, map_type)

  File "C:\Users\Ian\Documents\GitHub\Terra\terra\managers\session.py", line 45, in set_up_local_game
    SESSION.__set_up__(map_name, bitmap, pieces, teams, upgrades, meta)

  File "C:\Users\Ian\Documents\GitHub\Terra\terra\managers\session.py", line 113, in __set_up__
    from terra.team.playermanager import PlayerManager

  File "C:\Users\Ian\Documents\GitHub\Terra\terra\team\playermanager.py", line 8, in <module>
    from terra.ai.aiplayer import AIPlayer

2018-04-18 15:25:50,982 WARNING [WARN]: Caught exception while sending message 'b'[TEAM_FI][RED]None''. Retry 2 of 3.
2018-04-18 15:25:50,982 WARNING [WARN]: Caught exception while sending message 'b'[TEAM_FI][RED]None''. Retry 3 of 3.
2018-04-18 15:34:00,108 WARNING [WARN]: Caught exception while sending message 'b'[TEAM_FI][RED]None''. Retry 2 of 3.
2018-04-18 15:34:00,108 WARNING [WARN]: Caught exception while sending message 'b'[TEAM_FI][RED]None''. Retry 3 of 3.
2018-04-18 15:34:47,281 WARNING [WARN]: Caught exception while sending message 'b'[TEAM_FI][RED]None''. Retry 2 of 3.
2018-04-18 15:34:47,283 WARNING [WARN]: Caught exception while sending message 'b'[TEAM_FI][RED]None''. Retry 3 of 3.
2018-04-18 15:35:34,024 WARNING [WARN]: Caught exception while sending message 'b'[TEAM_FI][RED]None''. Retry 2 of 3.
2018-04-18 15:35:34,025 WARNING [WARN]: Caught exception while sending message 'b'[TEAM_FI][RED]None''. Retry 3 of 3.
2018-04-18 17:12:26,600 WARNING [WARN]: Caught exception while sending message 'b'[TEAM_FI][RED]None''. Retry 2 of 3.
2018-04-18 17:12:26,601 WARNING [WARN]: Caught exception while sending message 'b'[TEAM_FI][RED]None''. Retry 3 of 3.
2018-04-18 17:15:31,257 WARNING [WARN]: Caught exception while sending message 'b'[TEAM_FI][RED]None''. Retry 2 of 3.
2018-04-18 17:15:31,257 WARNING [WARN]: Caught exception while sending message 'b'[TEAM_FI][RED]None''. Retry 3 of 3.
2018-04-18 17:15:44,374 WARNING [WARN]: Caught exception while sending message 'b'[TEAM_FI][RED]None''. Retry 2 of 3.
2018-04-18 17:15:44,374 WARNING [WARN]: Caught exception while sending message 'b'[TEAM_FI][RED]None''. Retry 3 of 3.
2018-04-18 17:16:08,086 WARNING [WARN]: Caught exception while sending message 'b'[TEAM_FI][RED]None''. Retry 2 of 3.
2018-04-18 17:16:08,086 WARNING [WARN]: Caught exception while sending message 'b'[TEAM_FI][RED]None''. Retry 3 of 3.
2018-04-18 17:35:54,491 WARNING [WARN]: Caught exception while sending message 'b'[TEAM_FI][RED]None''. Retry 2 of 3.
2018-04-18 17:35:54,491 WARNING [WARN]: Caught exception while sending message 'b'[TEAM_FI][RED]None''. Retry 3 of 3.
2018-04-18 17:35:59,027 WARNING [WARN]: Caught exception while sending message 'b'[TEAM_FI][RED]None''. Retry 2 of 3.
2018-04-18 17:35:59,027 WARNING [WARN]: Caught exception while sending message 'b'[TEAM_FI][RED]None''. Retry 3 of 3.
2018-04-18 17:36:09,444 WARNING [WARN]: Caught exception while sending message 'b'[TEAM_FI][RED]None''. Retry 2 of 3.
2018-04-18 17:36:09,444 WARNING [WARN]: Caught exception while sending message 'b'[TEAM_FI][RED]None''. Retry 3 of 3.
2018-04-18 17:36:23,850 WARNING [WARN]: Caught exception while sending message 'b'[TEAM_FI][RED]None''. Retry 2 of 3.
2018-04-18 17:36:23,851 WARNING [WARN]: Caught exception while sending message 'b'[TEAM_FI][RED]None''. Retry 3 of 3.
2018-04-18 17:37:23,014 WARNING [WARN]: Caught exception while sending message 'b'[TEAM_FI][RED]None''. Retry 2 of 3.
2018-04-18 17:37:23,014 WARNING [WARN]: Caught exception while sending message 'b'[TEAM_FI][RED]None''. Retry 3 of 3.
2018-04-18 17:37:23,054 ERROR [ERROR]: Caught exception in the launcher.
2018-04-18 17:37:23,056 ERROR [ERROR]: !=== Caught a fatal exception: ===!
2018-04-18 17:37:23,056 ERROR [ERROR]: Exception: 
'type' object is not subscriptable
  File "C:/Users/Ian/Documents/GitHub/Terra/launcher.py", line 8, in <module>
    Main().run()

  File "C:\Users\Ian\Documents\GitHub\Terra\terra\main.py", line 193, in run
    self.step(event)

  File "C:\Users\Ian\Documents\GitHub\Terra\terra\main.py", line 140, in step
    EVENT_BUS.invoke_handlers(event)

  File "C:\Users\Ian\Documents\GitHub\Terra\terra\event\eventbus.py", line 46, in invoke_handlers
    handler(event)

  File "C:\Users\Ian\Documents\GitHub\Terra\terra\main.py", line 97, in handle_menu_selections
    self.set_screen_from_mode(Mode.LOBBY, event.mapname)

  File "C:\Users\Ian\Documents\GitHub\Terra\terra\main.py", line 66, in set_screen_from_mode
    new_screen = Lobby(False, map_name, map_type)

  File "C:\Users\Ian\Documents\GitHub\Terra\terra\screens\lobby.py", line 31, in __init__
    Session.set_up_local_game(map_name, map_type)

  File "C:\Users\Ian\Documents\GitHub\Terra\terra\managers\session.py", line 45, in set_up_local_game
    SESSION.__set_up__(map_name, bitmap, pieces, teams, upgrades, meta)

  File "C:\Users\Ian\Documents\GitHub\Terra\terra\managers\session.py", line 124, in __set_up__
    self.managers[Manager.PLAYER] = PlayerManager()

  File "C:\Users\Ian\Documents\GitHub\Terra\terra\team\playermanager.py", line 26, in __init__
    self.cursors[team] = Cursor[team]

2018-04-18 17:37:34,663 WARNING [WARN]: Caught exception while sending message 'b'[TEAM_FI][RED]None''. Retry 2 of 3.
2018-04-18 17:37:34,663 WARNING [WARN]: Caught exception while sending message 'b'[TEAM_FI][RED]None''. Retry 3 of 3.
2018-04-18 17:38:10,313 WARNING [WARN]: Caught exception while sending message 'b'[TEAM_FI][RED]None''. Retry 2 of 3.
2018-04-18 17:38:10,314 WARNING [WARN]: Caught exception while sending message 'b'[TEAM_FI][RED]None''. Retry 3 of 3.
2018-04-18 17:38:54,784 WARNING [WARN]: Caught exception while sending message 'b'[TEAM_FI][RED]None''. Retry 2 of 3.
2018-04-18 17:38:54,784 WARNING [WARN]: Caught exception while sending message 'b'[TEAM_FI][RED]None''. Retry 3 of 3.
2018-04-18 17:39:24,773 WARNING [WARN]: Caught exception while sending message 'b'[TEAM_FI][RED]None''. Retry 2 of 3.
2018-04-18 17:39:24,773 WARNING [WARN]: Caught exception while sending message 'b'[TEAM_FI][RED]None''. Retry 3 of 3.
2018-04-18 17:39:45,232 WARNING [WARN]: Caught exception while sending message 'b'[TEAM_FI][RED]None''. Retry 2 of 3.
2018-04-18 17:39:45,232 WARNING [WARN]: Caught exception while sending message 'b'[TEAM_FI][RED]None''. Retry 3 of 3.
2018-04-18 17:41:24,624 WARNING [WARN]: Caught exception while sending message 'b'[TEAM_FI][RED]None''. Retry 2 of 3.
2018-04-18 17:41:24,624 WARNING [WARN]: Caught exception while sending message 'b'[TEAM_FI][RED]None''. Retry 3 of 3.
2018-04-18 17:45:14,378 WARNING [WARN]: Caught exception while sending message 'b'[TEAM_FI][RED]None''. Retry 2 of 3.
2018-04-18 17:45:14,379 WARNING [WARN]: Caught exception while sending message 'b'[TEAM_FI][RED]None''. Retry 3 of 3.
2018-04-18 17:46:34,665 WARNING [WARN]: Caught exception while sending message 'b'[TEAM_FI][RED]None''. Retry 2 of 3.
2018-04-18 17:46:34,666 WARNING [WARN]: Caught exception while sending message 'b'[TEAM_FI][RED]None''. Retry 3 of 3.
2018-04-18 17:46:56,615 WARNING [WARN]: Caught exception while sending message 'b'[TEAM_FI][RED]None''. Retry 2 of 3.
2018-04-18 17:46:56,615 WARNING [WARN]: Caught exception while sending message 'b'[TEAM_FI][RED]None''. Retry 3 of 3.
2018-04-18 18:09:56,876 WARNING [WARN]: Caught exception while sending message 'b'[TEAM_FI][RED]None''. Retry 2 of 3.
2018-04-18 18:09:56,876 WARNING [WARN]: Caught exception while sending message 'b'[TEAM_FI][RED]None''. Retry 3 of 3.
2018-04-18 18:10:31,218 WARNING [WARN]: Caught exception while sending message 'b'[TEAM_FI][RED]None''. Retry 2 of 3.
2018-04-18 18:10:31,218 WARNING [WARN]: Caught exception while sending message 'b'[TEAM_FI][RED]None''. Retry 3 of 3.
2018-04-18 18:12:18,783 WARNING [WARN]: Caught exception while sending message 'b'[TEAM_FI][RED]None''. Retry 2 of 3.
2018-04-18 18:12:18,783 WARNING [WARN]: Caught exception while sending message 'b'[TEAM_FI][RED]None''. Retry 3 of 3.
2018-04-18 18:18:43,905 WARNING [WARN]: Caught exception while sending message 'b'[TEAM_FI][RED]None''. Retry 2 of 3.
2018-04-18 18:18:43,905 WARNING [WARN]: Caught exception while sending message 'b'[TEAM_FI][RED]None''. Retry 3 of 3.
2018-04-18 18:19:11,429 WARNING [WARN]: Caught exception while sending message 'b'[TEAM_FI][RED]None''. Retry 2 of 3.
2018-04-18 18:19:11,429 WARNING [WARN]: Caught exception while sending message 'b'[TEAM_FI][RED]None''. Retry 3 of 3.
2018-04-18 18:19:14,407 WARNING [WARN]: Caught exception while sending message 'b'[TEAM_FI][RED]None''. Retry 2 of 3.
2018-04-18 18:19:14,407 WARNING [WARN]: Caught exception while sending message 'b'[TEAM_FI][RED]None''. Retry 3 of 3.
2018-04-18 18:21:27,041 WARNING [WARN]: Caught exception while sending message 'b'[TEAM_FI][RED]None''. Retry 2 of 3.
2018-04-18 18:21:27,043 WARNING [WARN]: Caught exception while sending message 'b'[TEAM_FI][RED]None''. Retry 3 of 3.
2018-04-19 09:52:51,659 WARNING [WARN]: Caught exception while sending message 'b'[TEAM_FI][RED]None''. Retry 2 of 3.
2018-04-19 09:52:51,659 WARNING [WARN]: Caught exception while sending message 'b'[TEAM_FI][RED]None''. Retry 3 of 3.
2018-04-19 09:53:10,045 WARNING [WARN]: Caught exception while sending message 'b'[TEAM_FI][RED]None''. Retry 2 of 3.
2018-04-19 09:53:10,046 WARNING [WARN]: Caught exception while sending message 'b'[TEAM_FI][RED]None''. Retry 3 of 3.
2018-04-19 09:53:37,950 WARNING [WARN]: Caught exception while sending message 'b'[TEAM_FI][RED]None''. Retry 2 of 3.
2018-04-19 09:53:37,950 WARNING [WARN]: Caught exception while sending message 'b'[TEAM_FI][RED]None''. Retry 3 of 3.
2018-04-20 10:47:06,991 WARNING [WARN]: Caught exception while sending message 'b'[TEAM_FI][RED]None''. Retry 2 of 3.
2018-04-20 10:47:06,992 WARNING [WARN]: Caught exception while sending message 'b'[TEAM_FI][RED]None''. Retry 3 of 3.
2018-04-20 11:07:55,144 WARNING [WARN]: Caught exception while sending message 'b'[TEAM_FI][RED]None''. Retry 2 of 3.
2018-04-20 11:07:55,146 WARNING [WARN]: Caught exception while sending message 'b'[TEAM_FI][RED]None''. Retry 3 of 3.
2018-04-20 11:10:03,030 WARNING [WARN]: Caught exception while sending message 'b'[TEAM_FI][RED]None''. Retry 2 of 3.
2018-04-20 11:10:03,031 WARNING [WARN]: Caught exception while sending message 'b'[TEAM_FI][RED]None''. Retry 3 of 3.
2018-04-20 11:10:24,121 WARNING [WARN]: Caught exception while sending message 'b'[TEAM_FI][RED]None''. Retry 2 of 3.
2018-04-20 11:10:24,121 WARNING [WARN]: Caught exception while sending message 'b'[TEAM_FI][RED]None''. Retry 3 of 3.
2018-04-20 11:12:24,430 WARNING [WARN]: Caught exception while sending message 'b'[TEAM_FI][RED]None''. Retry 2 of 3.
2018-04-20 11:12:24,431 WARNING [WARN]: Caught exception while sending message 'b'[TEAM_FI][RED]None''. Retry 3 of 3.
2018-04-20 11:12:37,679 WARNING [WARN]: Caught exception while sending message 'b'[TEAM_FI][RED]None''. Retry 2 of 3.
2018-04-20 11:12:37,680 WARNING [WARN]: Caught exception while sending message 'b'[TEAM_FI][RED]None''. Retry 3 of 3.
2018-04-20 11:13:24,156 WARNING [WARN]: Caught exception while sending message 'b'[TEAM_FI][RED]None''. Retry 2 of 3.
2018-04-20 11:13:24,157 WARNING [WARN]: Caught exception while sending message 'b'[TEAM_FI][RED]None''. Retry 3 of 3.
2018-04-20 11:13:36,519 WARNING [WARN]: Caught exception while sending message 'b'[TEAM_FI][RED]None''. Retry 2 of 3.
2018-04-20 11:13:36,519 WARNING [WARN]: Caught exception while sending message 'b'[TEAM_FI][RED]None''. Retry 3 of 3.
2018-04-20 11:14:18,368 WARNING [WARN]: Caught exception while sending message 'b'[TEAM_FI][RED]None''. Retry 2 of 3.
2018-04-20 11:14:18,368 WARNING [WARN]: Caught exception while sending message 'b'[TEAM_FI][RED]None''. Retry 3 of 3.
2018-04-20 11:14:46,206 WARNING [WARN]: Caught exception while sending message 'b'[TEAM_FI][RED]None''. Retry 2 of 3.
2018-04-20 11:14:46,207 WARNING [WARN]: Caught exception while sending message 'b'[TEAM_FI][RED]None''. Retry 3 of 3.
2018-04-20 11:15:16,864 WARNING [WARN]: Caught exception while sending message 'b'[TEAM_FI][RED]None''. Retry 2 of 3.
2018-04-20 11:15:16,865 WARNING [WARN]: Caught exception while sending message 'b'[TEAM_FI][RED]None''. Retry 3 of 3.
2018-04-20 11:18:00,162 WARNING [WARN]: Caught exception while sending message 'b'[TEAM_FI][RED]None''. Retry 2 of 3.
2018-04-20 11:18:00,164 WARNING [WARN]: Caught exception while sending message 'b'[TEAM_FI][RED]None''. Retry 3 of 3.
2018-04-20 11:18:06,251 WARNING [WARN]: Caught exception while sending message 'b'[TEAM_FI][RED]None''. Retry 2 of 3.
2018-04-20 11:18:06,251 WARNING [WARN]: Caught exception while sending message 'b'[TEAM_FI][RED]None''. Retry 3 of 3.
2018-04-20 11:19:05,347 WARNING [WARN]: Caught exception while sending message 'b'[TEAM_FI][RED]None''. Retry 2 of 3.
2018-04-20 11:19:05,347 WARNING [WARN]: Caught exception while sending message 'b'[TEAM_FI][RED]None''. Retry 3 of 3.
2018-04-20 11:19:29,850 WARNING [WARN]: Caught exception while sending message 'b'[TEAM_FI][RED]None''. Retry 2 of 3.
2018-04-20 11:19:29,850 WARNING [WARN]: Caught exception while sending message 'b'[TEAM_FI][RED]None''. Retry 3 of 3.
2018-04-20 11:20:28,678 WARNING [WARN]: Caught exception while sending message 'b'[TEAM_FI][RED]None''. Retry 2 of 3.
2018-04-20 11:20:28,678 WARNING [WARN]: Caught exception while sending message 'b'[TEAM_FI][RED]None''. Retry 3 of 3.
2018-04-20 11:21:02,254 WARNING [WARN]: Caught exception while sending message 'b'[TEAM_FI][RED]None''. Retry 2 of 3.
2018-04-20 11:21:02,254 WARNING [WARN]: Caught exception while sending message 'b'[TEAM_FI][RED]None''. Retry 3 of 3.
2018-04-20 11:21:21,847 WARNING [WARN]: Caught exception while sending message 'b'[TEAM_FI][RED]None''. Retry 2 of 3.
2018-04-20 11:21:21,847 WARNING [WARN]: Caught exception while sending message 'b'[TEAM_FI][RED]None''. Retry 3 of 3.
2018-04-20 12:02:38,757 WARNING [WARN]: Caught exception while sending message 'b'[TEAM_FI][RED]None''. Retry 2 of 3.
2018-04-20 12:02:38,757 WARNING [WARN]: Caught exception while sending message 'b'[TEAM_FI][RED]None''. Retry 3 of 3.
2018-04-20 12:03:07,174 WARNING [WARN]: Caught exception while sending message 'b'[TEAM_FI][RED]None''. Retry 2 of 3.
2018-04-20 12:03:07,174 WARNING [WARN]: Caught exception while sending message 'b'[TEAM_FI][RED]None''. Retry 3 of 3.
2018-04-20 12:03:22,895 WARNING [WARN]: Caught exception while sending message 'b'[TEAM_FI][RED]None''. Retry 2 of 3.
2018-04-20 12:03:22,895 WARNING [WARN]: Caught exception while sending message 'b'[TEAM_FI][RED]None''. Retry 3 of 3.
2018-04-20 12:10:13,897 WARNING [WARN]: Caught exception while sending message 'b'[TEAM_FI][RED]None''. Retry 2 of 3.
2018-04-20 12:10:13,898 WARNING [WARN]: Caught exception while sending message 'b'[TEAM_FI][RED]None''. Retry 3 of 3.
2018-04-20 12:10:45,591 WARNING [WARN]: Caught exception while sending message 'b'[TEAM_FI][RED]None''. Retry 2 of 3.
2018-04-20 12:10:45,591 WARNING [WARN]: Caught exception while sending message 'b'[TEAM_FI][RED]None''. Retry 3 of 3.
2018-04-20 12:11:00,979 WARNING [WARN]: Caught exception while sending message 'b'[TEAM_FI][RED]None''. Retry 2 of 3.
2018-04-20 12:11:00,979 WARNING [WARN]: Caught exception while sending message 'b'[TEAM_FI][RED]None''. Retry 3 of 3.
2018-04-20 12:11:10,700 WARNING [WARN]: Caught exception while sending message 'b'[TEAM_FI][RED]None''. Retry 2 of 3.
2018-04-20 12:11:10,700 WARNING [WARN]: Caught exception while sending message 'b'[TEAM_FI][RED]None''. Retry 3 of 3.
2018-04-20 12:27:53,068 WARNING [WARN]: Caught exception while sending message 'b'[TEAM_FI][RED]None''. Retry 2 of 3.
2018-04-20 12:27:53,068 WARNING [WARN]: Caught exception while sending message 'b'[TEAM_FI][RED]None''. Retry 3 of 3.
2018-04-20 12:28:41,677 WARNING [WARN]: Caught exception while sending message 'b'[TEAM_FI][RED]None''. Retry 2 of 3.
2018-04-20 12:28:41,677 WARNING [WARN]: Caught exception while sending message 'b'[TEAM_FI][RED]None''. Retry 3 of 3.
2018-04-20 13:37:53,632 WARNING [WARN]: Caught exception while sending message 'b'[TEAM_FI][RED]None''. Retry 2 of 3.
2018-04-20 13:37:53,632 WARNING [WARN]: Caught exception while sending message 'b'[TEAM_FI][RED]None''. Retry 3 of 3.
2018-04-20 13:39:58,974 WARNING [WARN]: Caught exception while sending message 'b'[TEAM_FI][RED]None''. Retry 2 of 3.
2018-04-20 13:39:58,976 WARNING [WARN]: Caught exception while sending message 'b'[TEAM_FI][RED]None''. Retry 3 of 3.
2018-04-20 13:42:34,335 WARNING [WARN]: Caught exception while sending message 'b'[TEAM_FI][RED]None''. Retry 2 of 3.
2018-04-20 13:42:34,336 WARNING [WARN]: Caught exception while sending message 'b'[TEAM_FI][RED]None''. Retry 3 of 3.
2018-04-20 13:47:17,139 WARNING [WARN]: Caught exception while sending message 'b'[TEAM_FI][RED]None''. Retry 2 of 3.
2018-04-20 13:47:17,139 WARNING [WARN]: Caught exception while sending message 'b'[TEAM_FI][RED]None''. Retry 3 of 3.
2018-04-20 13:47:45,477 WARNING [WARN]: Caught exception while sending message 'b'[TEAM_FI][RED]None''. Retry 2 of 3.
2018-04-20 13:47:45,478 WARNING [WARN]: Caught exception while sending message 'b'[TEAM_FI][RED]None''. Retry 3 of 3.
2018-04-20 13:48:14,584 WARNING [WARN]: Caught exception while sending message 'b'[TEAM_FI][RED]None''. Retry 2 of 3.
2018-04-20 13:48:14,585 WARNING [WARN]: Caught exception while sending message 'b'[TEAM_FI][RED]None''. Retry 3 of 3.
2018-04-20 13:49:04,922 WARNING [WARN]: Caught exception while sending message 'b'[TEAM_FI][RED]None''. Retry 2 of 3.
2018-04-20 13:49:04,922 WARNING [WARN]: Caught exception while sending message 'b'[TEAM_FI][RED]None''. Retry 3 of 3.
2018-04-20 13:49:11,015 WARNING [WARN]: Caught exception while sending message 'b'[TEAM_FI][RED]None''. Retry 2 of 3.
2018-04-20 13:49:11,015 WARNING [WARN]: Caught exception while sending message 'b'[TEAM_FI][RED]None''. Retry 3 of 3.
2018-04-20 13:49:28,776 WARNING [WARN]: Caught exception while sending message 'b'[TEAM_FI][RED]None''. Retry 2 of 3.
2018-04-20 13:49:28,776 WARNING [WARN]: Caught exception while sending message 'b'[TEAM_FI][RED]None''. Retry 3 of 3.
2018-04-20 14:15:20,454 WARNING [WARN]: Caught exception while sending message 'b'[TEAM_FI][RED]None''. Retry 2 of 3.
2018-04-20 14:15:20,455 WARNING [WARN]: Caught exception while sending message 'b'[TEAM_FI][RED]None''. Retry 3 of 3.
2018-04-20 14:15:20,543 ERROR [ERROR]: Caught exception in the launcher.
2018-04-20 14:15:20,549 ERROR [ERROR]: !=== Caught a fatal exception: ===!
2018-04-20 14:15:20,549 ERROR [ERROR]: Exception: 
get_enemy_pieces_at() missing 1 required positional argument: 'my_team'
  File "C:/Users/Ian/Documents/GitHub/Terra/launcher.py", line 8, in <module>
    Main().run()

  File "C:\Users\Ian\Documents\GitHub\Terra\terra\main.py", line 193, in run
    self.step(event)

  File "C:\Users\Ian\Documents\GitHub\Terra\terra\main.py", line 140, in step
    EVENT_BUS.invoke_handlers(event)

  File "C:\Users\Ian\Documents\GitHub\Terra\terra\event\eventbus.py", line 46, in invoke_handlers
    handler(event)

  File "C:\Users\Ian\Documents\GitHub\Terra\terra\ai\aiplayer.py", line 248, in handle_orders_phase
    assignments = self.assign_tasks(tasks)

  File "C:\Users\Ian\Documents\GitHub\Terra\terra\ai\aiplayer.py", line 115, in assign_tasks
    eligible_pieces = task.get_eligible_pieces_for_task(self.get_manager(Manager.PIECE))

  File "C:\Users\Ian\Documents\GitHub\Terra\terra\ai\task.py", line 67, in get_eligible_pieces_for_task
    targets = piece_manager.get_enemy_pieces_at(self.tx, self.ty)

2018-04-20 14:15:39,732 WARNING [WARN]: Caught exception while sending message 'b'[TEAM_FI][RED]None''. Retry 2 of 3.
2018-04-20 14:15:39,732 WARNING [WARN]: Caught exception while sending message 'b'[TEAM_FI][RED]None''. Retry 3 of 3.
2018-04-20 14:16:03,721 WARNING [WARN]: Caught exception while sending message 'b'[TEAM_FI][RED]None''. Retry 2 of 3.
2018-04-20 14:16:03,722 WARNING [WARN]: Caught exception while sending message 'b'[TEAM_FI][RED]None''. Retry 3 of 3.
2018-04-20 14:19:19,106 WARNING [WARN]: Caught exception while sending message 'b'[TEAM_FI][RED]None''. Retry 2 of 3.
2018-04-20 14:19:19,106 WARNING [WARN]: Caught exception while sending message 'b'[TEAM_FI][RED]None''. Retry 3 of 3.
2018-04-20 14:19:35,511 WARNING [WARN]: Caught exception while sending message 'b'[TEAM_FI][RED]None''. Retry 2 of 3.
2018-04-20 14:19:35,511 WARNING [WARN]: Caught exception while sending message 'b'[TEAM_FI][RED]None''. Retry 3 of 3.
2018-04-20 14:19:44,594 WARNING [WARN]: Caught exception while sending message 'b'[TEAM_FI][RED]None''. Retry 2 of 3.
2018-04-20 14:19:44,594 WARNING [WARN]: Caught exception while sending message 'b'[TEAM_FI][RED]None''. Retry 3 of 3.
2018-04-20 14:20:08,110 WARNING [WARN]: Caught exception while sending message 'b'[TEAM_FI][RED]None''. Retry 2 of 3.
2018-04-20 14:20:08,110 WARNING [WARN]: Caught exception while sending message 'b'[TEAM_FI][RED]None''. Retry 3 of 3.
2018-04-20 14:20:22,747 WARNING [WARN]: Caught exception while sending message 'b'[TEAM_FI][RED]None''. Retry 2 of 3.
2018-04-20 14:20:22,747 WARNING [WARN]: Caught exception while sending message 'b'[TEAM_FI][RED]None''. Retry 3 of 3.
2018-04-20 14:20:30,762 WARNING [WARN]: Caught exception while sending message 'b'[TEAM_FI][RED]None''. Retry 2 of 3.
2018-04-20 14:20:30,762 WARNING [WARN]: Caught exception while sending message 'b'[TEAM_FI][RED]None''. Retry 3 of 3.
2018-04-20 14:20:59,819 WARNING [WARN]: Caught exception while sending message 'b'[TEAM_FI][RED]None''. Retry 2 of 3.
2018-04-20 14:20:59,820 WARNING [WARN]: Caught exception while sending message 'b'[TEAM_FI][RED]None''. Retry 3 of 3.
2018-04-20 14:22:18,821 WARNING [WARN]: Caught exception while sending message 'b'[TEAM_FI][RED]None''. Retry 2 of 3.
2018-04-20 14:22:18,822 WARNING [WARN]: Caught exception while sending message 'b'[TEAM_FI][RED]None''. Retry 3 of 3.
2018-04-20 14:23:17,677 WARNING [WARN]: Caught exception while sending message 'b'[TEAM_FI][RED]None''. Retry 2 of 3.
2018-04-20 14:23:17,677 WARNING [WARN]: Caught exception while sending message 'b'[TEAM_FI][RED]None''. Retry 3 of 3.
2018-04-20 14:23:39,038 WARNING [WARN]: Caught exception while sending message 'b'[TEAM_FI][RED]None''. Retry 2 of 3.
2018-04-20 14:23:39,038 WARNING [WARN]: Caught exception while sending message 'b'[TEAM_FI][RED]None''. Retry 3 of 3.
2018-04-20 14:24:37,740 WARNING [WARN]: Caught exception while sending message 'b'[TEAM_FI][RED]None''. Retry 2 of 3.
2018-04-20 14:24:37,741 WARNING [WARN]: Caught exception while sending message 'b'[TEAM_FI][RED]None''. Retry 3 of 3.
2018-04-20 14:24:58,126 WARNING [WARN]: Caught exception while sending message 'b'[TEAM_FI][RED]None''. Retry 2 of 3.
2018-04-20 14:24:58,126 WARNING [WARN]: Caught exception while sending message 'b'[TEAM_FI][RED]None''. Retry 3 of 3.
2018-04-20 14:25:55,342 WARNING [WARN]: Caught exception while sending message 'b'[TEAM_FI][RED]None''. Retry 2 of 3.
2018-04-20 14:25:55,342 WARNING [WARN]: Caught exception while sending message 'b'[TEAM_FI][RED]None''. Retry 3 of 3.
2018-04-20 14:26:26,812 WARNING [WARN]: Caught exception while sending message 'b'[TEAM_FI][RED]None''. Retry 2 of 3.
2018-04-20 14:26:26,812 WARNING [WARN]: Caught exception while sending message 'b'[TEAM_FI][RED]None''. Retry 3 of 3.
2018-04-20 14:26:30,652 WARNING [WARN]: Caught exception while sending message 'b'[TEAM_FI][RED]None''. Retry 2 of 3.
2018-04-20 14:26:30,653 WARNING [WARN]: Caught exception while sending message 'b'[TEAM_FI][RED]None''. Retry 3 of 3.
2018-04-20 16:00:45,086 WARNING [WARN]: Caught exception while sending message 'b'[TEAM_FI][RED]None''. Retry 2 of 3.
2018-04-20 16:00:45,087 WARNING [WARN]: Caught exception while sending message 'b'[TEAM_FI][RED]None''. Retry 3 of 3.
2018-04-20 16:00:45,135 ERROR [ERROR]: Caught exception in the launcher.
2018-04-20 16:00:45,136 ERROR [ERROR]: !=== Caught a fatal exception: ===!
2018-04-20 16:00:45,136 ERROR [ERROR]: Exception: 
'PieceManager' object is not iterable
  File "C:/Users/Ian/Documents/GitHub/Terra/launcher.py", line 8, in <module>
    Main().run()

  File "C:\Users\Ian\Documents\GitHub\Terra\terra\main.py", line 193, in run
    self.step(event)

  File "C:\Users\Ian\Documents\GitHub\Terra\terra\main.py", line 140, in step
    EVENT_BUS.invoke_handlers(event)

  File "C:\Users\Ian\Documents\GitHub\Terra\terra\event\eventbus.py", line 46, in invoke_handlers
    handler(event)

  File "C:\Users\Ian\Documents\GitHub\Terra\terra\ai\aiplayer.py", line 264, in handle_orders_phase
    tasks = self.generate_tasks()

  File "C:\Users\Ian\Documents\GitHub\Terra\terra\ai\aiplayer.py", line 57, in generate_tasks
    combat_tasks = self.generate_combat_tasks()

  File "C:\Users\Ian\Documents\GitHub\Terra\terra\ai\aiplayer.py", line 89, in generate_combat_tasks
    enemy_bases = [piece for piece in enemy_pieces if piece.piece_type == PieceType.BASE]

2018-04-20 16:01:12,625 WARNING [WARN]: Caught exception while sending message 'b'[TEAM_FI][RED]None''. Retry 2 of 3.
2018-04-20 16:01:12,625 WARNING [WARN]: Caught exception while sending message 'b'[TEAM_FI][RED]None''. Retry 3 of 3.
2018-04-20 16:01:58,603 WARNING [WARN]: Caught exception while sending message 'b'[TEAM_FI][RED]None''. Retry 2 of 3.
2018-04-20 16:01:58,603 WARNING [WARN]: Caught exception while sending message 'b'[TEAM_FI][RED]None''. Retry 3 of 3.
2018-04-20 16:02:59,935 WARNING [WARN]: Caught exception while sending message 'b'[TEAM_FI][RED]None''. Retry 2 of 3.
2018-04-20 16:02:59,936 WARNING [WARN]: Caught exception while sending message 'b'[TEAM_FI][RED]None''. Retry 3 of 3.
2018-04-20 16:07:08,597 WARNING [WARN]: Caught exception while sending message 'b'[TEAM_FI][RED]None''. Retry 2 of 3.
2018-04-20 16:07:08,597 WARNING [WARN]: Caught exception while sending message 'b'[TEAM_FI][RED]None''. Retry 3 of 3.
2018-04-20 16:07:21,565 WARNING [WARN]: Caught exception while sending message 'b'[TEAM_FI][RED]None''. Retry 2 of 3.
2018-04-20 16:07:21,566 WARNING [WARN]: Caught exception while sending message 'b'[TEAM_FI][RED]None''. Retry 3 of 3.
2018-04-20 16:27:32,657 WARNING [WARN]: Caught exception while sending message 'b'[TEAM_FI][RED]None''. Retry 2 of 3.
2018-04-20 16:27:32,658 WARNING [WARN]: Caught exception while sending message 'b'[TEAM_FI][RED]None''. Retry 3 of 3.
2018-04-20 16:29:09,109 WARNING [WARN]: Caught exception while sending message 'b'[TEAM_FI][RED]None''. Retry 2 of 3.
2018-04-20 16:29:09,109 WARNING [WARN]: Caught exception while sending message 'b'[TEAM_FI][RED]None''. Retry 3 of 3.
2018-04-20 16:33:02,600 WARNING [WARN]: Caught exception while sending message 'b'[TEAM_FI][RED]None''. Retry 2 of 3.
2018-04-20 16:33:02,600 WARNING [WARN]: Caught exception while sending message 'b'[TEAM_FI][RED]None''. Retry 3 of 3.
2018-04-20 16:34:18,279 WARNING [WARN]: Caught exception while sending message 'b'[TEAM_FI][RED]None''. Retry 2 of 3.
2018-04-20 16:34:18,280 WARNING [WARN]: Caught exception while sending message 'b'[TEAM_FI][RED]None''. Retry 3 of 3.
2018-04-20 16:35:32,777 WARNING [WARN]: Caught exception while sending message 'b'[TEAM_FI][RED]None''. Retry 2 of 3.
2018-04-20 16:35:32,778 WARNING [WARN]: Caught exception while sending message 'b'[TEAM_FI][RED]None''. Retry 3 of 3.
2018-04-20 16:36:43,754 WARNING [WARN]: Caught exception while sending message 'b'[TEAM_FI][RED]None''. Retry 2 of 3.
2018-04-20 16:36:43,754 WARNING [WARN]: Caught exception while sending message 'b'[TEAM_FI][RED]None''. Retry 3 of 3.
2018-04-20 16:36:46,827 WARNING [WARN]: Caught exception while sending message 'b'[TEAM_FI][RED]None''. Retry 2 of 3.
2018-04-20 16:36:46,827 WARNING [WARN]: Caught exception while sending message 'b'[TEAM_FI][RED]None''. Retry 3 of 3.
2018-04-20 16:37:05,802 WARNING [WARN]: Caught exception while sending message 'b'[TEAM_FI][RED]None''. Retry 2 of 3.
2018-04-20 16:37:05,803 WARNING [WARN]: Caught exception while sending message 'b'[TEAM_FI][RED]None''. Retry 3 of 3.
2018-04-20 16:37:50,683 WARNING [WARN]: Caught exception while sending message 'b'[TEAM_FI][RED]None''. Retry 2 of 3.
2018-04-20 16:37:50,683 WARNING [WARN]: Caught exception while sending message 'b'[TEAM_FI][RED]None''. Retry 3 of 3.
2018-04-20 16:38:41,489 WARNING [WARN]: Caught exception while sending message 'b'[TEAM_FI][RED]None''. Retry 2 of 3.
2018-04-20 16:38:41,489 WARNING [WARN]: Caught exception while sending message 'b'[TEAM_FI][RED]None''. Retry 3 of 3.
2018-04-20 16:38:53,410 WARNING [WARN]: Caught exception while sending message 'b'[TEAM_FI][RED]None''. Retry 2 of 3.
2018-04-20 16:38:53,411 WARNING [WARN]: Caught exception while sending message 'b'[TEAM_FI][RED]None''. Retry 3 of 3.
2018-04-20 16:39:06,704 WARNING [WARN]: Caught exception while sending message 'b'[TEAM_FI][RED]None''. Retry 2 of 3.
2018-04-20 16:39:06,706 WARNING [WARN]: Caught exception while sending message 'b'[TEAM_FI][RED]None''. Retry 3 of 3.
2018-04-20 16:39:50,843 WARNING [WARN]: Caught exception while sending message 'b'[TEAM_FI][RED]None''. Retry 2 of 3.
2018-04-20 16:39:50,844 WARNING [WARN]: Caught exception while sending message 'b'[TEAM_FI][RED]None''. Retry 3 of 3.
2018-04-20 16:40:05,802 WARNING [WARN]: Caught exception while sending message 'b'[TEAM_FI][RED]None''. Retry 2 of 3.
2018-04-20 16:40:05,803 WARNING [WARN]: Caught exception while sending message 'b'[TEAM_FI][RED]None''. Retry 3 of 3.
2018-04-20 16:40:38,396 WARNING [WARN]: Caught exception while sending message 'b'[TEAM_FI][RED]None''. Retry 2 of 3.
2018-04-20 16:40:38,396 WARNING [WARN]: Caught exception while sending message 'b'[TEAM_FI][RED]None''. Retry 3 of 3.
2018-04-20 16:41:02,997 WARNING [WARN]: Caught exception while sending message 'b'[TEAM_FI][RED]None''. Retry 2 of 3.
2018-04-20 16:41:02,997 WARNING [WARN]: Caught exception while sending message 'b'[TEAM_FI][RED]None''. Retry 3 of 3.
2018-04-20 16:48:09,821 WARNING [WARN]: Caught exception while sending message 'b'[TEAM_FI][RED]None''. Retry 2 of 3.
2018-04-20 16:48:09,821 WARNING [WARN]: Caught exception while sending message 'b'[TEAM_FI][RED]None''. Retry 3 of 3.
2018-04-20 16:48:21,598 WARNING [WARN]: Caught exception while sending message 'b'[TEAM_FI][RED]None''. Retry 2 of 3.
2018-04-20 16:48:21,598 WARNING [WARN]: Caught exception while sending message 'b'[TEAM_FI][RED]None''. Retry 3 of 3.
2018-04-20 16:48:37,547 WARNING [WARN]: Caught exception while sending message 'b'[TEAM_FI][RED]None''. Retry 2 of 3.
2018-04-20 16:48:37,547 WARNING [WARN]: Caught exception while sending message 'b'[TEAM_FI][RED]None''. Retry 3 of 3.
2018-04-20 16:49:25,261 WARNING [WARN]: Caught exception while sending message 'b'[TEAM_FI][RED]None''. Retry 2 of 3.
2018-04-20 16:49:25,262 WARNING [WARN]: Caught exception while sending message 'b'[TEAM_FI][RED]None''. Retry 3 of 3.
2018-04-20 16:49:31,514 WARNING [WARN]: Caught exception while sending message 'b'[TEAM_FI][RED]None''. Retry 2 of 3.
2018-04-20 16:49:31,514 WARNING [WARN]: Caught exception while sending message 'b'[TEAM_FI][RED]None''. Retry 3 of 3.
2018-04-20 16:49:42,797 WARNING [WARN]: Caught exception while sending message 'b'[TEAM_FI][RED]None''. Retry 2 of 3.
2018-04-20 16:49:42,798 WARNING [WARN]: Caught exception while sending message 'b'[TEAM_FI][RED]None''. Retry 3 of 3.
2018-04-20 16:49:53,736 WARNING [WARN]: Caught exception while sending message 'b'[TEAM_FI][RED]None''. Retry 2 of 3.
2018-04-20 16:49:53,737 WARNING [WARN]: Caught exception while sending message 'b'[TEAM_FI][RED]None''. Retry 3 of 3.
2018-04-20 16:50:05,506 WARNING [WARN]: Caught exception while sending message 'b'[TEAM_FI][RED]None''. Retry 2 of 3.
2018-04-20 16:50:05,507 WARNING [WARN]: Caught exception while sending message 'b'[TEAM_FI][RED]None''. Retry 3 of 3.
2018-04-20 16:51:00,867 WARNING [WARN]: Caught exception while sending message 'b'[TEAM_FI][RED]None''. Retry 2 of 3.
2018-04-20 16:51:00,869 WARNING [WARN]: Caught exception while sending message 'b'[TEAM_FI][RED]None''. Retry 3 of 3.
2018-04-20 16:52:38,527 WARNING [WARN]: Caught exception while sending message 'b'[TEAM_FI][RED]None''. Retry 2 of 3.
2018-04-20 16:52:38,527 WARNING [WARN]: Caught exception while sending message 'b'[TEAM_FI][RED]None''. Retry 3 of 3.
2018-04-20 16:52:38,587 ERROR [ERROR]: Caught exception in the launcher.
2018-04-20 16:52:38,588 ERROR [ERROR]: !=== Caught a fatal exception: ===!
2018-04-20 16:52:38,588 ERROR [ERROR]: Exception: 
'Task' object has no attribute 'path'
  File "C:/Users/Ian/Documents/GitHub/Terra/launcher.py", line 8, in <module>
    Main().run()

  File "C:\Users\Ian\Documents\GitHub\Terra\terra\main.py", line 193, in run
    self.step(event)

  File "C:\Users\Ian\Documents\GitHub\Terra\terra\main.py", line 140, in step
    EVENT_BUS.invoke_handlers(event)

  File "C:\Users\Ian\Documents\GitHub\Terra\terra\event\eventbus.py", line 46, in invoke_handlers
    handler(event)

  File "C:\Users\Ian\Documents\GitHub\Terra\terra\ai\aiplayer.py", line 274, in handle_orders_phase
    assigned_pieces, assigned_tasks = self.confirm_assignments(assignments)

  File "C:\Users\Ian\Documents\GitHub\Terra\terra\ai\aiplayer.py", line 227, in confirm_assignments
    self.set_order_for_task(assignment)

  File "C:\Users\Ian\Documents\GitHub\Terra\terra\ai\aiplayer.py", line 243, in set_order_for_task
    piece.current_path = task.path

2018-04-20 16:53:54,827 WARNING [WARN]: Caught exception while sending message 'b'[TEAM_FI][RED]None''. Retry 2 of 3.
2018-04-20 16:53:54,827 WARNING [WARN]: Caught exception while sending message 'b'[TEAM_FI][RED]None''. Retry 3 of 3.
2018-04-20 16:57:53,188 WARNING [WARN]: Caught exception while sending message 'b'[TEAM_FI][RED]None''. Retry 2 of 3.
2018-04-20 16:57:53,189 WARNING [WARN]: Caught exception while sending message 'b'[TEAM_FI][RED]None''. Retry 3 of 3.
2018-04-20 16:57:53,260 ERROR [ERROR]: Caught exception in the launcher.
2018-04-20 16:57:53,262 ERROR [ERROR]: !=== Caught a fatal exception: ===!
2018-04-20 16:57:53,263 ERROR [ERROR]: Exception: 
get_path_to_destination() takes 4 positional arguments but 5 were given
  File "C:/Users/Ian/Documents/GitHub/Terra/launcher.py", line 8, in <module>
    Main().run()

  File "C:\Users\Ian\Documents\GitHub\Terra\terra\main.py", line 193, in run
    self.step(event)

  File "C:\Users\Ian\Documents\GitHub\Terra\terra\main.py", line 140, in step
    EVENT_BUS.invoke_handlers(event)

  File "C:\Users\Ian\Documents\GitHub\Terra\terra\event\eventbus.py", line 46, in invoke_handlers
    handler(event)

  File "C:\Users\Ian\Documents\GitHub\Terra\terra\ai\aiplayer.py", line 272, in handle_orders_phase
    assignments = self.assign_tasks(tasks)

  File "C:\Users\Ian\Documents\GitHub\Terra\terra\ai\aiplayer.py", line 140, in assign_tasks
    assignment = self.create_assignment(piece, task)

  File "C:\Users\Ian\Documents\GitHub\Terra\terra\ai\aiplayer.py", line 168, in create_assignment
    path = piece.get_path_to_destinations(tiles)

  File "C:\Users\Ian\Documents\GitHub\Terra\terra\piece\piece.py", line 397, in get_path_to_destinations
    self, avoid_enemies)

2018-04-20 16:58:20,561 WARNING [WARN]: Caught exception while sending message 'b'[TEAM_FI][RED]None''. Retry 2 of 3.
2018-04-20 16:58:20,562 WARNING [WARN]: Caught exception while sending message 'b'[TEAM_FI][RED]None''. Retry 3 of 3.
2018-04-20 16:58:49,642 WARNING [WARN]: Caught exception while sending message 'b'[TEAM_FI][RED]None''. Retry 2 of 3.
2018-04-20 16:58:49,643 WARNING [WARN]: Caught exception while sending message 'b'[TEAM_FI][RED]None''. Retry 3 of 3.
2018-04-20 17:00:49,449 WARNING [WARN]: Caught exception while sending message 'b'[TEAM_FI][RED]None''. Retry 2 of 3.
2018-04-20 17:00:49,449 WARNING [WARN]: Caught exception while sending message 'b'[TEAM_FI][RED]None''. Retry 3 of 3.
2018-04-20 17:01:02,568 WARNING [WARN]: Caught exception while sending message 'b'[TEAM_FI][RED]None''. Retry 2 of 3.
2018-04-20 17:01:02,569 WARNING [WARN]: Caught exception while sending message 'b'[TEAM_FI][RED]None''. Retry 3 of 3.
2018-04-20 17:01:52,898 WARNING [WARN]: Caught exception while sending message 'b'[TEAM_FI][RED]None''. Retry 2 of 3.
2018-04-20 17:01:52,899 WARNING [WARN]: Caught exception while sending message 'b'[TEAM_FI][RED]None''. Retry 3 of 3.
2018-04-20 17:04:31,523 WARNING [WARN]: Caught exception while sending message 'b'[TEAM_FI][RED]None''. Retry 2 of 3.
2018-04-20 17:04:31,523 WARNING [WARN]: Caught exception while sending message 'b'[TEAM_FI][RED]None''. Retry 3 of 3.
2018-04-20 17:04:33,347 ERROR [ERROR]: Caught exception in the launcher.
2018-04-20 17:04:33,369 ERROR [ERROR]: !=== Caught a fatal exception: ===!
2018-04-20 17:04:33,369 ERROR [ERROR]: Exception: 
text must be a unicode or bytes
  File "C:/Users/Ian/Documents/GitHub/Terra/launcher.py", line 8, in <module>
    Main().run()

  File "C:\Users\Ian\Documents\GitHub\Terra\terra\main.py", line 199, in run
    self.render()

  File "C:\Users\Ian\Documents\GitHub\Terra\terra\main.py", line 156, in render
    game_screen = self.current_screen.render(ui_screen)

  File "C:\Users\Ian\Documents\GitHub\Terra\terra\screens\battle.py", line 44, in render
    SESSION.render(map_screen, ui_screen)

  File "C:\Users\Ian\Documents\GitHub\Terra\terra\managers\session.py", line 136, in render
    manager.render(game_screen, ui_screen)

  File "C:\Users\Ian\Documents\GitHub\Terra\terra\piece\piecemanager.py", line 395, in render
    piece.render(game_screen, ui_screen)

  File "C:\Users\Ian\Documents\GitHub\Terra\terra\piece\piece.py", line 813, in render
    self.preview_path(game_screen)

  File "C:\Users\Ian\Documents\GitHub\Terra\terra\piece\piece.py", line 764, in preview_path
    game_screen.blit(draw_text(self.get_move_score((self.gx, self.gy), (x, y)), light_color), (x * 24 + 8, y * 24 + 8))

  File "C:\Users\Ian\Documents\GitHub\Terra\terra\util\drawingutil.py", line 44, in draw_text
    return font_pixelmix.render(text, False, color)

2018-04-20 17:05:36,744 WARNING [WARN]: Caught exception while sending message 'b'[TEAM_FI][RED]None''. Retry 2 of 3.
2018-04-20 17:05:36,745 WARNING [WARN]: Caught exception while sending message 'b'[TEAM_FI][RED]None''. Retry 3 of 3.
2018-04-20 17:05:46,867 ERROR [ERROR]: Caught exception in the launcher.
2018-04-20 17:05:46,870 ERROR [ERROR]: !=== Caught a fatal exception: ===!
2018-04-20 17:05:46,870 ERROR [ERROR]: Exception: 
text must be a unicode or bytes
  File "C:/Users/Ian/Documents/GitHub/Terra/launcher.py", line 8, in <module>
    Main().run()

  File "C:/Users/Ian/Documents/GitHub/Terra\terra\main.py", line 199, in run
    self.render()

  File "C:/Users/Ian/Documents/GitHub/Terra\terra\main.py", line 156, in render
    game_screen = self.current_screen.render(ui_screen)

  File "C:/Users/Ian/Documents/GitHub/Terra\terra\screens\battle.py", line 44, in render
    SESSION.render(map_screen, ui_screen)

  File "C:/Users/Ian/Documents/GitHub/Terra\terra\managers\session.py", line 136, in render
    manager.render(game_screen, ui_screen)

  File "C:/Users/Ian/Documents/GitHub/Terra\terra\piece\piecemanager.py", line 395, in render
    piece.render(game_screen, ui_screen)

  File "C:/Users/Ian/Documents/GitHub/Terra\terra\piece\piece.py", line 814, in render
    self.preview_path(game_screen)

  File "C:/Users/Ian/Documents/GitHub/Terra\terra\piece\piece.py", line 764, in preview_path
    score = draw_text(self.get_move_score((self.gx, self.gy), (x, y)), light_color)

  File "C:/Users/Ian/Documents/GitHub/Terra\terra\util\drawingutil.py", line 44, in draw_text
    return font_pixelmix.render(text, False, color)

2018-04-20 17:06:15,974 WARNING [WARN]: Caught exception while sending message 'b'[TEAM_FI][RED]None''. Retry 2 of 3.
2018-04-20 17:06:15,974 WARNING [WARN]: Caught exception while sending message 'b'[TEAM_FI][RED]None''. Retry 3 of 3.
2018-04-20 17:07:43,068 WARNING [WARN]: Caught exception while sending message 'b'[TEAM_FI][RED]None''. Retry 2 of 3.
2018-04-20 17:07:43,069 WARNING [WARN]: Caught exception while sending message 'b'[TEAM_FI][RED]None''. Retry 3 of 3.
2018-04-20 17:09:26,386 WARNING [WARN]: Caught exception while sending message 'b'[TEAM_FI][RED]None''. Retry 2 of 3.
2018-04-20 17:09:26,387 WARNING [WARN]: Caught exception while sending message 'b'[TEAM_FI][RED]None''. Retry 3 of 3.
2018-04-20 17:12:16,104 WARNING [WARN]: Caught exception while sending message 'b'[TEAM_FI][RED]None''. Retry 2 of 3.
2018-04-20 17:12:16,104 WARNING [WARN]: Caught exception while sending message 'b'[TEAM_FI][RED]None''. Retry 3 of 3.
2018-04-20 17:13:15,673 WARNING [WARN]: Caught exception while sending message 'b'[TEAM_FI][RED]None''. Retry 2 of 3.
2018-04-20 17:13:15,674 WARNING [WARN]: Caught exception while sending message 'b'[TEAM_FI][RED]None''. Retry 3 of 3.
2018-04-20 17:16:59,510 WARNING [WARN]: Caught exception while sending message 'b'[TEAM_FI][RED]None''. Retry 2 of 3.
2018-04-20 17:16:59,511 WARNING [WARN]: Caught exception while sending message 'b'[TEAM_FI][RED]None''. Retry 3 of 3.
2018-04-23 13:39:57,262 WARNING [WARN]: Caught exception while sending message 'b'[TEAM_FI][RED]None''. Retry 2 of 3.
2018-04-23 13:39:57,262 WARNING [WARN]: Caught exception while sending message 'b'[TEAM_FI][RED]None''. Retry 3 of 3.
2018-04-23 13:40:22,998 WARNING [WARN]: Caught exception while sending message 'b'[TEAM_FI][RED]None''. Retry 2 of 3.
2018-04-23 13:40:22,998 WARNING [WARN]: Caught exception while sending message 'b'[TEAM_FI][RED]None''. Retry 3 of 3.
2018-04-23 13:40:42,747 WARNING [WARN]: Caught exception while sending message 'b'[TEAM_FI][RED]None''. Retry 2 of 3.
2018-04-23 13:40:42,747 WARNING [WARN]: Caught exception while sending message 'b'[TEAM_FI][RED]None''. Retry 3 of 3.
2018-04-23 13:48:47,724 WARNING [WARN]: Caught exception while sending message 'b'[TEAM_FI][RED]None''. Retry 2 of 3.
2018-04-23 13:48:47,724 WARNING [WARN]: Caught exception while sending message 'b'[TEAM_FI][RED]None''. Retry 3 of 3.
2018-04-23 13:48:50,430 WARNING [WARN]: Caught exception while sending message 'b'[TEAM_FI][RED]None''. Retry 2 of 3.
2018-04-23 13:48:50,430 WARNING [WARN]: Caught exception while sending message 'b'[TEAM_FI][RED]None''. Retry 3 of 3.
2018-04-23 13:49:11,344 WARNING [WARN]: Caught exception while sending message 'b'[TEAM_FI][RED]None''. Retry 2 of 3.
2018-04-23 13:49:11,344 WARNING [WARN]: Caught exception while sending message 'b'[TEAM_FI][RED]None''. Retry 3 of 3.
2018-04-23 13:49:25,345 WARNING [WARN]: Caught exception while sending message 'b'[TEAM_FI][RED]None''. Retry 2 of 3.
2018-04-23 13:49:25,345 WARNING [WARN]: Caught exception while sending message 'b'[TEAM_FI][RED]None''. Retry 3 of 3.
2018-04-23 13:49:51,885 WARNING [WARN]: Caught exception while sending message 'b'[TEAM_FI][RED]None''. Retry 2 of 3.
2018-04-23 13:49:51,885 WARNING [WARN]: Caught exception while sending message 'b'[TEAM_FI][RED]None''. Retry 3 of 3.
2018-04-23 13:49:59,502 WARNING [WARN]: Caught exception while sending message 'b'[TEAM_FI][RED]None''. Retry 2 of 3.
2018-04-23 13:49:59,502 WARNING [WARN]: Caught exception while sending message 'b'[TEAM_FI][RED]None''. Retry 3 of 3.
2018-04-23 13:50:24,507 WARNING [WARN]: Caught exception while sending message 'b'[TEAM_FI][RED]None''. Retry 2 of 3.
2018-04-23 13:50:24,508 WARNING [WARN]: Caught exception while sending message 'b'[TEAM_FI][RED]None''. Retry 3 of 3.
2018-04-23 13:50:32,075 WARNING [WARN]: Caught exception while sending message 'b'[TEAM_FI][RED]None''. Retry 2 of 3.
2018-04-23 13:50:32,075 WARNING [WARN]: Caught exception while sending message 'b'[TEAM_FI][RED]None''. Retry 3 of 3.
2018-04-23 13:51:52,294 WARNING [WARN]: Caught exception while sending message 'b'[TEAM_FI][RED]None''. Retry 2 of 3.
2018-04-23 13:51:52,294 WARNING [WARN]: Caught exception while sending message 'b'[TEAM_FI][RED]None''. Retry 3 of 3.
2018-04-23 13:53:04,819 WARNING [WARN]: Caught exception while sending message 'b'[TEAM_FI][RED]None''. Retry 2 of 3.
2018-04-23 13:53:04,819 WARNING [WARN]: Caught exception while sending message 'b'[TEAM_FI][RED]None''. Retry 3 of 3.
2018-04-23 13:53:23,388 WARNING [WARN]: Caught exception while sending message 'b'[TEAM_FI][RED]None''. Retry 2 of 3.
2018-04-23 13:53:23,388 WARNING [WARN]: Caught exception while sending message 'b'[TEAM_FI][RED]None''. Retry 3 of 3.
2018-04-23 13:53:37,881 WARNING [WARN]: Caught exception while sending message 'b'[TEAM_FI][RED]None''. Retry 2 of 3.
2018-04-23 13:53:37,881 WARNING [WARN]: Caught exception while sending message 'b'[TEAM_FI][RED]None''. Retry 3 of 3.
2018-04-23 13:53:48,282 WARNING [WARN]: Caught exception while sending message 'b'[TEAM_FI][RED]None''. Retry 2 of 3.
2018-04-23 13:53:48,282 WARNING [WARN]: Caught exception while sending message 'b'[TEAM_FI][RED]None''. Retry 3 of 3.
2018-04-23 13:54:08,928 WARNING [WARN]: Caught exception while sending message 'b'[TEAM_FI][RED]None''. Retry 2 of 3.
2018-04-23 13:54:08,930 WARNING [WARN]: Caught exception while sending message 'b'[TEAM_FI][RED]None''. Retry 3 of 3.
2018-04-23 13:55:06,597 WARNING [WARN]: Caught exception while sending message 'b'[TEAM_FI][RED]None''. Retry 2 of 3.
2018-04-23 13:55:06,597 WARNING [WARN]: Caught exception while sending message 'b'[TEAM_FI][RED]None''. Retry 3 of 3.
2018-04-23 13:56:24,062 WARNING [WARN]: Caught exception while sending message 'b'[TEAM_FI][RED]None''. Retry 2 of 3.
2018-04-23 13:56:24,062 WARNING [WARN]: Caught exception while sending message 'b'[TEAM_FI][RED]None''. Retry 3 of 3.
2018-04-23 13:56:39,813 WARNING [WARN]: Caught exception while sending message 'b'[TEAM_FI][RED]None''. Retry 2 of 3.
2018-04-23 13:56:39,814 WARNING [WARN]: Caught exception while sending message 'b'[TEAM_FI][RED]None''. Retry 3 of 3.
2018-04-23 13:56:47,797 WARNING [WARN]: Caught exception while sending message 'b'[TEAM_FI][RED]None''. Retry 2 of 3.
2018-04-23 13:56:47,797 WARNING [WARN]: Caught exception while sending message 'b'[TEAM_FI][RED]None''. Retry 3 of 3.
2018-04-23 14:03:13,396 WARNING [WARN]: Caught exception while sending message 'b'[TEAM_FI][RED]None''. Retry 2 of 3.
2018-04-23 14:03:13,396 WARNING [WARN]: Caught exception while sending message 'b'[TEAM_FI][RED]None''. Retry 3 of 3.
2018-04-23 14:03:45,632 WARNING [WARN]: Caught exception while sending message 'b'[TEAM_FI][RED]None''. Retry 2 of 3.
2018-04-23 14:03:45,632 WARNING [WARN]: Caught exception while sending message 'b'[TEAM_FI][RED]None''. Retry 3 of 3.
2018-04-23 14:04:48,352 WARNING [WARN]: Caught exception while sending message 'b'[TEAM_FI][RED]None''. Retry 2 of 3.
2018-04-23 14:04:48,352 WARNING [WARN]: Caught exception while sending message 'b'[TEAM_FI][RED]None''. Retry 3 of 3.
2018-04-23 14:05:25,829 WARNING [WARN]: Caught exception while sending message 'b'[TEAM_FI][RED]None''. Retry 2 of 3.
2018-04-23 14:05:25,829 WARNING [WARN]: Caught exception while sending message 'b'[TEAM_FI][RED]None''. Retry 3 of 3.
2018-04-23 14:05:54,764 WARNING [WARN]: Caught exception while sending message 'b'[TEAM_FI][RED]None''. Retry 2 of 3.
2018-04-23 14:05:54,764 WARNING [WARN]: Caught exception while sending message 'b'[TEAM_FI][RED]None''. Retry 3 of 3.
2018-04-23 14:06:45,055 WARNING [WARN]: Caught exception while sending message 'b'[TEAM_FI][RED]None''. Retry 2 of 3.
2018-04-23 14:06:45,055 WARNING [WARN]: Caught exception while sending message 'b'[TEAM_FI][RED]None''. Retry 3 of 3.
2018-04-23 14:07:05,893 WARNING [WARN]: Caught exception while sending message 'b'[TEAM_FI][RED]None''. Retry 2 of 3.
2018-04-23 14:07:05,893 WARNING [WARN]: Caught exception while sending message 'b'[TEAM_FI][RED]None''. Retry 3 of 3.
2018-04-23 14:07:11,026 ERROR [ERROR]: Caught exception in the launcher.
2018-04-23 14:07:11,041 ERROR [ERROR]: !=== Caught a fatal exception: ===!
2018-04-23 14:07:11,041 ERROR [ERROR]: Exception: 
unsupported operand type(s) for *: 'NoneType' and 'int'
  File "C:/Users/Ian/Documents/GitHub/Terra/launcher.py", line 8, in <module>
    Main().run()

  File "C:\Users\Ian\Documents\GitHub\Terra\terra\main.py", line 193, in run
    self.step(event)

  File "C:\Users\Ian\Documents\GitHub\Terra\terra\main.py", line 140, in step
    EVENT_BUS.invoke_handlers(event)

  File "C:\Users\Ian\Documents\GitHub\Terra\terra\event\eventbus.py", line 46, in invoke_handlers
    handler(event)

  File "C:\Users\Ian\Documents\GitHub\Terra\terra\piece\piecemanager.py", line 224, in register_piece_from_event
    self.register_piece(Piece(event.new_piece_type, event.team, event.tx, event.ty))

  File "C:\Users\Ian\Documents\GitHub\Terra\terra\piece\piece.py", line 50, in __init__
    self.rendered_gx = self.gx * GRID_WIDTH

2018-04-23 14:18:55,443 WARNING [WARN]: Caught exception while sending message 'b'[TEAM_FI][RED]None''. Retry 2 of 3.
2018-04-23 14:18:55,443 WARNING [WARN]: Caught exception while sending message 'b'[TEAM_FI][RED]None''. Retry 3 of 3.
2018-04-23 14:20:11,351 WARNING [WARN]: Caught exception while sending message 'b'[TEAM_FI][RED]None''. Retry 2 of 3.
2018-04-23 14:20:11,352 WARNING [WARN]: Caught exception while sending message 'b'[TEAM_FI][RED]None''. Retry 3 of 3.
2018-04-23 14:25:10,173 WARNING [WARN]: Caught exception while sending message 'b'[TEAM_FI][RED]None''. Retry 2 of 3.
2018-04-23 14:25:10,173 WARNING [WARN]: Caught exception while sending message 'b'[TEAM_FI][RED]None''. Retry 3 of 3.
2018-04-23 14:25:51,026 ERROR [ERROR]: Caught exception in the launcher.
2018-04-23 14:25:51,031 ERROR [ERROR]: !=== Caught a fatal exception: ===!
2018-04-23 14:25:51,032 ERROR [ERROR]: Exception: 
unsupported operand type(s) for *: 'NoneType' and 'int'
  File "C:/Users/Ian/Documents/GitHub/Terra/launcher.py", line 8, in <module>
    Main().run()

  File "C:/Users/Ian/Documents/GitHub/Terra\terra\main.py", line 193, in run
    self.step(event)

  File "C:/Users/Ian/Documents/GitHub/Terra\terra\main.py", line 140, in step
    EVENT_BUS.invoke_handlers(event)

  File "C:/Users/Ian/Documents/GitHub/Terra\terra\event\eventbus.py", line 46, in invoke_handlers
    handler(event)

  File "C:/Users/Ian/Documents/GitHub/Terra\terra\piece\piecemanager.py", line 224, in register_piece_from_event
    self.register_piece(Piece(event.new_piece_type, event.team, event.tx, event.ty))

  File "C:/Users/Ian/Documents/GitHub/Terra\terra\piece\piece.py", line 50, in __init__
    self.rendered_gx = self.gx * GRID_WIDTH

2018-04-23 14:26:03,467 WARNING [WARN]: Caught exception while sending message 'b'[TEAM_FI][RED]None''. Retry 2 of 3.
2018-04-23 14:26:03,468 WARNING [WARN]: Caught exception while sending message 'b'[TEAM_FI][RED]None''. Retry 3 of 3.
2018-04-23 14:26:08,815 ERROR [ERROR]: Caught exception in the launcher.
2018-04-23 14:26:08,825 ERROR [ERROR]: !=== Caught a fatal exception: ===!
2018-04-23 14:26:08,825 ERROR [ERROR]: Exception: 
unsupported operand type(s) for *: 'NoneType' and 'int'
  File "C:/Users/Ian/Documents/GitHub/Terra/launcher.py", line 8, in <module>
    Main().run()

  File "C:/Users/Ian/Documents/GitHub/Terra\terra\main.py", line 199, in run
    self.render()

  File "C:/Users/Ian/Documents/GitHub/Terra\terra\main.py", line 156, in render
    game_screen = self.current_screen.render(ui_screen)

  File "C:/Users/Ian/Documents/GitHub/Terra\terra\screens\battle.py", line 44, in render
    SESSION.render(map_screen, ui_screen)

  File "C:/Users/Ian/Documents/GitHub/Terra\terra\managers\session.py", line 136, in render
    manager.render(game_screen, ui_screen)

  File "C:/Users/Ian/Documents/GitHub/Terra\terra\piece\piecemanager.py", line 395, in render
    piece.render(game_screen, ui_screen)

  File "C:/Users/Ian/Documents/GitHub/Terra\terra\piece\piece.py", line 830, in render
    self.preview_order(game_screen)

  File "C:/Users/Ian/Documents/GitHub/Terra\terra\piece\piece.py", line 762, in preview_order
    game_screen.blit(target_sprite, (self.current_order.tx * GRID_WIDTH,

2018-04-23 14:26:42,200 WARNING [WARN]: Caught exception while sending message 'b'[TEAM_FI][RED]None''. Retry 2 of 3.
2018-04-23 14:26:42,200 WARNING [WARN]: Caught exception while sending message 'b'[TEAM_FI][RED]None''. Retry 3 of 3.
2018-04-23 14:30:13,843 WARNING [WARN]: Caught exception while sending message 'b'[TEAM_FI][RED]None''. Retry 2 of 3.
2018-04-23 14:30:13,843 WARNING [WARN]: Caught exception while sending message 'b'[TEAM_FI][RED]None''. Retry 3 of 3.
2018-04-23 14:30:40,605 WARNING [WARN]: Caught exception while sending message 'b'[TEAM_FI][RED]None''. Retry 2 of 3.
2018-04-23 14:30:40,606 WARNING [WARN]: Caught exception while sending message 'b'[TEAM_FI][RED]None''. Retry 3 of 3.
2018-04-23 14:33:30,890 WARNING [WARN]: Caught exception while sending message 'b'[TEAM_FI][RED]None''. Retry 2 of 3.
2018-04-23 14:33:30,890 WARNING [WARN]: Caught exception while sending message 'b'[TEAM_FI][RED]None''. Retry 3 of 3.
2018-04-23 14:33:37,172 WARNING [WARN]: Caught exception while sending message 'b'[TEAM_FI][RED]None''. Retry 2 of 3.
2018-04-23 14:33:37,172 WARNING [WARN]: Caught exception while sending message 'b'[TEAM_FI][RED]None''. Retry 3 of 3.
2018-04-23 14:33:48,804 WARNING [WARN]: Caught exception while sending message 'b'[TEAM_FI][RED]None''. Retry 2 of 3.
2018-04-23 14:33:48,804 WARNING [WARN]: Caught exception while sending message 'b'[TEAM_FI][RED]None''. Retry 3 of 3.
2018-04-23 14:34:05,104 WARNING [WARN]: Caught exception while sending message 'b'[TEAM_FI][RED]None''. Retry 2 of 3.
2018-04-23 14:34:05,104 WARNING [WARN]: Caught exception while sending message 'b'[TEAM_FI][RED]None''. Retry 3 of 3.
2018-04-23 14:34:34,049 WARNING [WARN]: Caught exception while sending message 'b'[TEAM_FI][RED]None''. Retry 2 of 3.
2018-04-23 14:34:34,050 WARNING [WARN]: Caught exception while sending message 'b'[TEAM_FI][RED]None''. Retry 3 of 3.
2018-04-23 14:35:51,220 WARNING [WARN]: Caught exception while sending message 'b'[TEAM_FI][RED]None''. Retry 2 of 3.
2018-04-23 14:35:51,220 WARNING [WARN]: Caught exception while sending message 'b'[TEAM_FI][RED]None''. Retry 3 of 3.
2018-04-23 14:36:06,534 WARNING [WARN]: Caught exception while sending message 'b'[TEAM_FI][RED]None''. Retry 2 of 3.
2018-04-23 14:36:06,534 WARNING [WARN]: Caught exception while sending message 'b'[TEAM_FI][RED]None''. Retry 3 of 3.
2018-04-23 14:37:29,407 WARNING [WARN]: Caught exception while sending message 'b'[TEAM_FI][RED]None''. Retry 2 of 3.
2018-04-23 14:37:29,407 WARNING [WARN]: Caught exception while sending message 'b'[TEAM_FI][RED]None''. Retry 3 of 3.
2018-04-23 14:38:41,754 WARNING [WARN]: Caught exception while sending message 'b'[TEAM_FI][RED]None''. Retry 2 of 3.
2018-04-23 14:38:41,754 WARNING [WARN]: Caught exception while sending message 'b'[TEAM_FI][RED]None''. Retry 3 of 3.
2018-04-23 15:07:53,802 WARNING [WARN]: Caught exception while sending message 'b'[TEAM_FI][RED]None''. Retry 2 of 3.
2018-04-23 15:07:53,802 WARNING [WARN]: Caught exception while sending message 'b'[TEAM_FI][RED]None''. Retry 3 of 3.
2018-04-23 15:08:01,140 WARNING [WARN]: Caught exception while sending message 'b'[TEAM_FI][RED]None''. Retry 2 of 3.
2018-04-23 15:08:01,140 WARNING [WARN]: Caught exception while sending message 'b'[TEAM_FI][RED]None''. Retry 3 of 3.
2018-04-23 15:08:36,033 WARNING [WARN]: Caught exception while sending message 'b'[TEAM_FI][RED]None''. Retry 2 of 3.
2018-04-23 15:08:36,033 WARNING [WARN]: Caught exception while sending message 'b'[TEAM_FI][RED]None''. Retry 3 of 3.
2018-04-23 15:08:51,437 WARNING [WARN]: Caught exception while sending message 'b'[TEAM_FI][RED]None''. Retry 2 of 3.
2018-04-23 15:08:51,437 WARNING [WARN]: Caught exception while sending message 'b'[TEAM_FI][RED]None''. Retry 3 of 3.
2018-04-23 15:09:31,890 WARNING [WARN]: Caught exception while sending message 'b'[TEAM_FI][RED]None''. Retry 2 of 3.
2018-04-23 15:09:31,890 WARNING [WARN]: Caught exception while sending message 'b'[TEAM_FI][RED]None''. Retry 3 of 3.
2018-04-23 15:11:16,013 WARNING [WARN]: Caught exception while sending message 'b'[TEAM_FI][RED]None''. Retry 2 of 3.
2018-04-23 15:11:16,013 WARNING [WARN]: Caught exception while sending message 'b'[TEAM_FI][RED]None''. Retry 3 of 3.
2018-04-23 15:15:44,387 WARNING [WARN]: Caught exception while sending message 'b'[TEAM_FI][RED]None''. Retry 2 of 3.
2018-04-23 15:15:44,387 WARNING [WARN]: Caught exception while sending message 'b'[TEAM_FI][RED]None''. Retry 3 of 3.
2018-04-23 15:50:54,505 WARNING [WARN]: Caught exception while sending message 'b'[TEAM_FI][RED]None''. Retry 2 of 3.
2018-04-23 15:50:54,506 WARNING [WARN]: Caught exception while sending message 'b'[TEAM_FI][RED]None''. Retry 3 of 3.
2018-04-23 15:50:59,220 WARNING [WARN]: Caught exception while sending message 'b'[TEAM_FI][RED]None''. Retry 2 of 3.
2018-04-23 15:50:59,220 WARNING [WARN]: Caught exception while sending message 'b'[TEAM_FI][RED]None''. Retry 3 of 3.
2018-04-23 15:53:02,906 WARNING [WARN]: Caught exception while sending message 'b'[TEAM_FI][RED]None''. Retry 2 of 3.
2018-04-23 15:53:02,906 WARNING [WARN]: Caught exception while sending message 'b'[TEAM_FI][RED]None''. Retry 3 of 3.
2018-04-23 15:57:04,270 WARNING [WARN]: Caught exception while sending message 'b'[TEAM_FI][RED]None''. Retry 2 of 3.
2018-04-23 15:57:04,270 WARNING [WARN]: Caught exception while sending message 'b'[TEAM_FI][RED]None''. Retry 3 of 3.
2018-04-23 15:57:24,541 WARNING [WARN]: Caught exception while sending message 'b'[TEAM_FI][RED]None''. Retry 2 of 3.
2018-04-23 15:57:24,542 WARNING [WARN]: Caught exception while sending message 'b'[TEAM_FI][RED]None''. Retry 3 of 3.
2018-04-23 15:58:59,613 WARNING [WARN]: Caught exception while sending message 'b'[TEAM_FI][RED]None''. Retry 2 of 3.
2018-04-23 15:58:59,613 WARNING [WARN]: Caught exception while sending message 'b'[TEAM_FI][RED]None''. Retry 3 of 3.
2018-04-23 15:59:11,333 WARNING [WARN]: Caught exception while sending message 'b'[TEAM_FI][RED]None''. Retry 2 of 3.
2018-04-23 15:59:11,333 WARNING [WARN]: Caught exception while sending message 'b'[TEAM_FI][RED]None''. Retry 3 of 3.
2018-04-23 16:00:02,672 WARNING [WARN]: Caught exception while sending message 'b'[TEAM_FI][RED]None''. Retry 2 of 3.
2018-04-23 16:00:02,672 WARNING [WARN]: Caught exception while sending message 'b'[TEAM_FI][RED]None''. Retry 3 of 3.
2018-04-23 16:00:10,851 WARNING [WARN]: Caught exception while sending message 'b'[TEAM_FI][RED]None''. Retry 2 of 3.
2018-04-23 16:00:10,851 WARNING [WARN]: Caught exception while sending message 'b'[TEAM_FI][RED]None''. Retry 3 of 3.
2018-04-23 16:00:22,347 WARNING [WARN]: Caught exception while sending message 'b'[TEAM_FI][RED]None''. Retry 2 of 3.
2018-04-23 16:00:22,347 WARNING [WARN]: Caught exception while sending message 'b'[TEAM_FI][RED]None''. Retry 3 of 3.
2018-04-23 17:05:05,699 WARNING [WARN]: Caught exception while sending message 'b'[TEAM_FI][RED]None''. Retry 2 of 3.
2018-04-23 17:05:05,699 WARNING [WARN]: Caught exception while sending message 'b'[TEAM_FI][RED]None''. Retry 3 of 3.
2018-04-23 18:45:11,641 WARNING [WARN]: Caught exception while sending message 'b'[TEAM_FI][RED]None''. Retry 2 of 3.
2018-04-23 18:45:11,641 WARNING [WARN]: Caught exception while sending message 'b'[TEAM_FI][RED]None''. Retry 3 of 3.
2018-04-23 18:45:21,154 ERROR [ERROR]: Caught exception in the launcher.
2018-04-23 18:45:21,155 ERROR [ERROR]: !=== Caught a fatal exception: ===!
2018-04-23 18:45:21,156 ERROR [ERROR]: Exception: 
<TaskType.RETREAT: 'Retreat'>
  File "C:/Users/Ian/Documents/GitHub/Terra/launcher.py", line 8, in <module>
    Main().run()

  File "C:\Users\Ian\Documents\GitHub\Terra\terra\main.py", line 193, in run
    self.step(event)

  File "C:\Users\Ian\Documents\GitHub\Terra\terra\main.py", line 140, in step
    EVENT_BUS.invoke_handlers(event)

  File "C:\Users\Ian\Documents\GitHub\Terra\terra\event\eventbus.py", line 46, in invoke_handlers
    handler(event)

  File "C:\Users\Ian\Documents\GitHub\Terra\terra\ai\aiplayer.py", line 318, in handle_orders_phase
    assignments = self.assign_tasks(tasks)

  File "C:\Users\Ian\Documents\GitHub\Terra\terra\ai\aiplayer.py", line 158, in assign_tasks
    eligible_pieces = task.get_eligible_pieces_for_task(self.get_manager(Manager.PIECE))

  File "C:\Users\Ian\Documents\GitHub\Terra\terra\ai\task.py", line 76, in get_eligible_pieces_for_task
    for archetype in task_type_to_piece_archetype[self.task_type]:

2018-04-23 18:49:20,706 WARNING [WARN]: Caught exception while sending message 'b'[TEAM_FI][RED]None''. Retry 2 of 3.
2018-04-23 18:49:20,707 WARNING [WARN]: Caught exception while sending message 'b'[TEAM_FI][RED]None''. Retry 3 of 3.
2018-04-23 18:50:01,881 WARNING [WARN]: Caught exception while sending message 'b'[TEAM_FI][RED]None''. Retry 2 of 3.
2018-04-23 18:50:01,881 WARNING [WARN]: Caught exception while sending message 'b'[TEAM_FI][RED]None''. Retry 3 of 3.
2018-04-23 19:06:47,163 WARNING [WARN]: Caught exception while sending message 'b'[TEAM_FI][RED]None''. Retry 2 of 3.
2018-04-23 19:06:47,163 WARNING [WARN]: Caught exception while sending message 'b'[TEAM_FI][RED]None''. Retry 3 of 3.
2018-04-23 19:09:51,001 WARNING [WARN]: Caught exception while sending message 'b'[TEAM_FI][RED]None''. Retry 2 of 3.
2018-04-23 19:09:51,001 WARNING [WARN]: Caught exception while sending message 'b'[TEAM_FI][RED]None''. Retry 3 of 3.
2018-04-23 19:13:05,995 WARNING [WARN]: Caught exception while sending message 'b'[TEAM_FI][RED]None''. Retry 2 of 3.
2018-04-23 19:13:05,995 WARNING [WARN]: Caught exception while sending message 'b'[TEAM_FI][RED]None''. Retry 3 of 3.
2018-04-23 19:14:09,486 WARNING [WARN]: Caught exception while sending message 'b'[TEAM_FI][RED]None''. Retry 2 of 3.
2018-04-23 19:14:09,486 WARNING [WARN]: Caught exception while sending message 'b'[TEAM_FI][RED]None''. Retry 3 of 3.
2018-04-23 19:20:37,397 WARNING [WARN]: Caught exception while sending message 'b'[TEAM_FI][RED]None''. Retry 2 of 3.
2018-04-23 19:20:37,397 WARNING [WARN]: Caught exception while sending message 'b'[TEAM_FI][RED]None''. Retry 3 of 3.
2018-04-23 19:21:46,878 WARNING [WARN]: Caught exception while sending message 'b'[TEAM_FI][RED]None''. Retry 2 of 3.
2018-04-23 19:21:46,878 WARNING [WARN]: Caught exception while sending message 'b'[TEAM_FI][RED]None''. Retry 3 of 3.
2018-04-23 19:22:03,535 WARNING [WARN]: Caught exception while sending message 'b'[TEAM_FI][RED]None''. Retry 2 of 3.
2018-04-23 19:22:03,536 WARNING [WARN]: Caught exception while sending message 'b'[TEAM_FI][RED]None''. Retry 3 of 3.
2018-04-23 19:22:13,480 WARNING [WARN]: Caught exception while sending message 'b'[TEAM_FI][RED]None''. Retry 2 of 3.
2018-04-23 19:22:13,480 WARNING [WARN]: Caught exception while sending message 'b'[TEAM_FI][RED]None''. Retry 3 of 3.
2018-04-23 19:23:40,921 WARNING [WARN]: Caught exception while sending message 'b'[TEAM_FI][RED]None''. Retry 2 of 3.
2018-04-23 19:23:40,921 WARNING [WARN]: Caught exception while sending message 'b'[TEAM_FI][RED]None''. Retry 3 of 3.
2018-04-23 19:24:00,727 WARNING [WARN]: Caught exception while sending message 'b'[TEAM_FI][RED]None''. Retry 2 of 3.
2018-04-23 19:24:00,728 WARNING [WARN]: Caught exception while sending message 'b'[TEAM_FI][RED]None''. Retry 3 of 3.
2018-04-23 19:25:58,447 WARNING [WARN]: Caught exception while sending message 'b'[TEAM_FI][RED]None''. Retry 2 of 3.
2018-04-23 19:25:58,448 WARNING [WARN]: Caught exception while sending message 'b'[TEAM_FI][RED]None''. Retry 3 of 3.
2018-04-23 19:26:41,617 WARNING [WARN]: Caught exception while sending message 'b'[TEAM_FI][RED]None''. Retry 2 of 3.
2018-04-23 19:26:41,617 WARNING [WARN]: Caught exception while sending message 'b'[TEAM_FI][RED]None''. Retry 3 of 3.
2018-04-23 19:27:33,883 WARNING [WARN]: Caught exception while sending message 'b'[TEAM_FI][RED]None''. Retry 2 of 3.
2018-04-23 19:27:33,883 WARNING [WARN]: Caught exception while sending message 'b'[TEAM_FI][RED]None''. Retry 3 of 3.
2018-04-23 19:27:41,010 WARNING [WARN]: Caught exception while sending message 'b'[TEAM_FI][RED]None''. Retry 2 of 3.
2018-04-23 19:27:41,011 WARNING [WARN]: Caught exception while sending message 'b'[TEAM_FI][RED]None''. Retry 3 of 3.
2018-04-23 19:38:56,868 WARNING [WARN]: Caught exception while sending message 'b'[TEAM_FI][RED]None''. Retry 2 of 3.
2018-04-23 19:38:56,868 WARNING [WARN]: Caught exception while sending message 'b'[TEAM_FI][RED]None''. Retry 3 of 3.
2018-04-23 19:52:25,834 WARNING [WARN]: Caught exception while sending message 'b'[TEAM_FI][RED]None''. Retry 2 of 3.
2018-04-23 19:52:25,834 WARNING [WARN]: Caught exception while sending message 'b'[TEAM_FI][RED]None''. Retry 3 of 3.
2018-04-23 19:55:00,902 WARNING [WARN]: Caught exception while sending message 'b'[TEAM_FI][RED]None''. Retry 2 of 3.
2018-04-23 19:55:00,902 WARNING [WARN]: Caught exception while sending message 'b'[TEAM_FI][RED]None''. Retry 3 of 3.
2018-04-23 19:55:13,407 ERROR [ERROR]: Caught exception in the launcher.
2018-04-23 19:55:13,433 ERROR [ERROR]: !=== Caught a fatal exception: ===!
2018-04-23 19:55:13,433 ERROR [ERROR]: Exception: 
video system not initialized
  File "C:/Users/Ian/Documents/GitHub/Terra/launcher.py", line 8, in <module>
    Main().run()

  File "C:\Users\Ian\Documents\GitHub\Terra\terra\main.py", line 193, in run
    self.step(event)

  File "C:\Users\Ian\Documents\GitHub\Terra\terra\main.py", line 137, in step
    INPUT_CONTROLLER.invoke_handlers(event)

  File "C:\Users\Ian\Documents\GitHub\Terra\terra\control\inputcontroller.py", line 55, in invoke_handlers
    handler()

  File "C:\Users\Ian\Documents\GitHub\Terra\terra\menu\menu.py", line 101, in set_cursor_pos_to_mouse_coords
    if self.cursor_in_menu_bounds():

  File "C:\Users\Ian\Documents\GitHub\Terra\terra\menu\menu.py", line 94, in cursor_in_menu_bounds
    mouse_x = get_pos()[0] / SETTINGS.get(Setting.SCREEN_SCALE)

2018-04-23 19:56:46,178 WARNING [WARN]: Caught exception while sending message 'b'[TEAM_FI][RED]None''. Retry 2 of 3.
2018-04-23 19:56:46,178 WARNING [WARN]: Caught exception while sending message 'b'[TEAM_FI][RED]None''. Retry 3 of 3.
2018-04-23 19:57:16,994 WARNING [WARN]: Caught exception while sending message 'b'[TEAM_FI][RED]None''. Retry 2 of 3.
2018-04-23 19:57:16,994 WARNING [WARN]: Caught exception while sending message 'b'[TEAM_FI][RED]None''. Retry 3 of 3.
