2018-05-01 14:40:25,071 WARNING [WARN]: Caught exception while sending message 'b'[TEAM_FI][RED]None''. Retry 2 of 3.
2018-05-01 14:40:25,072 WARNING [WARN]: Caught exception while sending message 'b'[TEAM_FI][RED]None''. Retry 3 of 3.
2018-05-01 14:54:01,185 ERROR [ERROR]: Caught exception in the launcher.
2018-05-01 14:54:01,201 ERROR [ERROR]: !=== Caught a fatal exception: ===!
2018-05-01 14:54:01,201 ERROR [ERROR]: Exception: 
'NoneType' object has no attribute 'team'
  File "C:/Users/Ian/Documents/GitHub/Terra/launcher.py", line 8, in <module>
    Main().run()

  File "C:\Users\Ian\Documents\GitHub\Terra\terra\main.py", line 193, in run
    self.step(event)

  File "C:\Users\Ian\Documents\GitHub\Terra\terra\main.py", line 140, in step
    EVENT_BUS.invoke_handlers(event)

  File "C:\Users\Ian\Documents\GitHub\Terra\terra\event\eventbus.py", line 46, in invoke_handlers
    handler(event)

  File "C:\Users\Ian\Documents\GitHub\Terra\terra\piece\piecemanager.py", line 405, in conduct_ranged_attack_from_event
    self.ranged_attack(event.gx, event.gy, event.team, event.tx, event.ty)

  File "C:\Users\Ian\Documents\GitHub\Terra\terra\piece\piecemanager.py", line 372, in ranged_attack
    aoe_multiplier = self.get_manager(Manager.TEAM).attr(origin_unit.team, origin_unit.piece_type, Attribute.RANGED_AOE_MULTIPLIER)

2018-05-01 14:54:57,935 WARNING [WARN]: Caught exception while sending message 'b'[TEAM_FI][RED]None''. Retry 2 of 3.
2018-05-01 14:54:57,935 WARNING [WARN]: Caught exception while sending message 'b'[TEAM_FI][RED]None''. Retry 3 of 3.
2018-05-01 14:54:57,976 ERROR [ERROR]: Caught exception in the launcher.
2018-05-01 14:54:57,999 ERROR [ERROR]: !=== Caught a fatal exception: ===!
2018-05-01 14:54:57,999 ERROR [ERROR]: Exception: 
<Manager.PIECE: 'piece'>
  File "C:/Users/Ian/Documents/GitHub/Terra/launcher.py", line 8, in <module>
    Main().run()

  File "C:/Users/Ian/Documents/GitHub/Terra\terra\main.py", line 193, in run
    self.step(event)

  File "C:/Users/Ian/Documents/GitHub/Terra\terra\main.py", line 140, in step
    EVENT_BUS.invoke_handlers(event)

  File "C:/Users/Ian/Documents/GitHub/Terra\terra\event\eventbus.py", line 46, in invoke_handlers
    handler(event)

  File "C:/Users/Ian/Documents/GitHub/Terra\terra\main.py", line 99, in handle_menu_selections
    self.set_screen_from_mode(Mode.LOBBY, event.mapname, map_type=AssetType.SAVE)

  File "C:/Users/Ian/Documents/GitHub/Terra\terra\main.py", line 66, in set_screen_from_mode
    new_screen = Lobby(False, map_name, map_type)

  File "C:/Users/Ian/Documents/GitHub/Terra\terra\screens\lobby.py", line 31, in __init__
    Session.set_up_local_game(map_name, map_type)

  File "C:/Users/Ian/Documents/GitHub/Terra\terra\managers\session.py", line 45, in set_up_local_game
    SESSION.__set_up__(map_name, bitmap, pieces, teams, upgrades, meta)

  File "C:/Users/Ian/Documents/GitHub/Terra\terra\managers\session.py", line 121, in __set_up__
    self.managers[Manager.TEAM] = TeamManager(teams, upgrades)

  File "C:/Users/Ian/Documents/GitHub/Terra\terra\team\teammanager.py", line 74, in __init__
    self.purchase_upgrade(team, UpgradeType[upgrade])

  File "C:/Users/Ian/Documents/GitHub/Terra\terra\team\teammanager.py", line 168, in purchase_upgrade
    self.on_upgrade_purchase(team, upgrade_type)

  File "C:/Users/Ian/Documents/GitHub/Terra\terra\team\teammanager.py", line 193, in on_upgrade_purchase
    for piece in self.get_manager(Manager.PIECE).get_all_pieces_for_team(team, piece_type=piece_type):

  File "C:/Users/Ian/Documents/GitHub/Terra\terra\engine\gameobject.py", line 45, in get_manager
    return SESSION.get(manager_type)

  File "C:/Users/Ian/Documents/GitHub/Terra\terra\managers\session.py", line 33, in get
    return self.managers[manager_type]

2018-05-01 14:56:23,754 WARNING [WARN]: Caught exception while sending message 'b'[TEAM_FI][RED]None''. Retry 2 of 3.
2018-05-01 14:56:23,755 WARNING [WARN]: Caught exception while sending message 'b'[TEAM_FI][RED]None''. Retry 3 of 3.
2018-05-01 14:56:23,796 ERROR [ERROR]: Caught exception in the launcher.
2018-05-01 14:56:23,799 ERROR [ERROR]: !=== Caught a fatal exception: ===!
2018-05-01 14:56:23,799 ERROR [ERROR]: Exception: 
<Manager.PIECE: 'piece'>
  File "C:/Users/Ian/Documents/GitHub/Terra/launcher.py", line 8, in <module>
    Main().run()

  File "C:/Users/Ian/Documents/GitHub/Terra\terra\main.py", line 193, in run
    self.step(event)

  File "C:/Users/Ian/Documents/GitHub/Terra\terra\main.py", line 140, in step
    EVENT_BUS.invoke_handlers(event)

  File "C:/Users/Ian/Documents/GitHub/Terra\terra\event\eventbus.py", line 46, in invoke_handlers
    handler(event)

  File "C:/Users/Ian/Documents/GitHub/Terra\terra\main.py", line 99, in handle_menu_selections
    self.set_screen_from_mode(Mode.LOBBY, event.mapname, map_type=AssetType.SAVE)

  File "C:/Users/Ian/Documents/GitHub/Terra\terra\main.py", line 66, in set_screen_from_mode
    new_screen = Lobby(False, map_name, map_type)

  File "C:/Users/Ian/Documents/GitHub/Terra\terra\screens\lobby.py", line 31, in __init__
    Session.set_up_local_game(map_name, map_type)

  File "C:/Users/Ian/Documents/GitHub/Terra\terra\managers\session.py", line 45, in set_up_local_game
    SESSION.__set_up__(map_name, bitmap, pieces, teams, upgrades, meta)

  File "C:/Users/Ian/Documents/GitHub/Terra\terra\managers\session.py", line 121, in __set_up__
    self.managers[Manager.TEAM] = TeamManager(teams, upgrades)

  File "C:/Users/Ian/Documents/GitHub/Terra\terra\team\teammanager.py", line 74, in __init__
    self.purchase_upgrade(team, UpgradeType[upgrade])

  File "C:/Users/Ian/Documents/GitHub/Terra\terra\team\teammanager.py", line 168, in purchase_upgrade
    self.on_upgrade_purchase(team, upgrade_type)

  File "C:/Users/Ian/Documents/GitHub/Terra\terra\team\teammanager.py", line 193, in on_upgrade_purchase
    for piece in self.get_manager(Manager.PIECE).get_all_pieces_for_team(team, piece_type=piece_type):

  File "C:/Users/Ian/Documents/GitHub/Terra\terra\engine\gameobject.py", line 45, in get_manager
    return SESSION.get(manager_type)

  File "C:/Users/Ian/Documents/GitHub/Terra\terra\managers\session.py", line 33, in get
    return self.managers[manager_type]

2018-05-01 14:59:24,126 WARNING [WARN]: Caught exception while sending message 'b'[TEAM_FI][RED]None''. Retry 2 of 3.
2018-05-01 14:59:24,127 WARNING [WARN]: Caught exception while sending message 'b'[TEAM_FI][RED]None''. Retry 3 of 3.
2018-05-01 15:02:03,266 ERROR [ERROR]: Caught exception in the launcher.
2018-05-01 15:02:03,268 ERROR [ERROR]: !=== Caught a fatal exception: ===!
2018-05-01 15:02:03,268 ERROR [ERROR]: Exception: 
'NoneType' object has no attribute 'team'
  File "C:/Users/Ian/Documents/GitHub/Terra/launcher.py", line 8, in <module>
    Main().run()

  File "C:/Users/Ian/Documents/GitHub/Terra\terra\main.py", line 193, in run
    self.step(event)

  File "C:/Users/Ian/Documents/GitHub/Terra\terra\main.py", line 140, in step
    EVENT_BUS.invoke_handlers(event)

  File "C:/Users/Ian/Documents/GitHub/Terra\terra\event\eventbus.py", line 46, in invoke_handlers
    handler(event)

  File "C:/Users/Ian/Documents/GitHub/Terra\terra\piece\piecemanager.py", line 405, in conduct_ranged_attack_from_event
    self.ranged_attack(event.gx, event.gy, event.team, event.tx, event.ty)

  File "C:/Users/Ian/Documents/GitHub/Terra\terra\piece\piecemanager.py", line 372, in ranged_attack
    aoe_multiplier = self.get_manager(Manager.TEAM).attr(origin_unit.team, origin_unit.piece_type, Attribute.RANGED_AOE_MULTIPLIER)

2018-05-01 15:20:06,250 WARNING [WARN]: Caught exception while sending message 'b'[TEAM_FI][RED]None''. Retry 2 of 3.
2018-05-01 15:20:06,251 WARNING [WARN]: Caught exception while sending message 'b'[TEAM_FI][RED]None''. Retry 3 of 3.
2018-05-01 15:20:30,478 WARNING [WARN]: Caught exception while sending message 'b'[TEAM_FI][RED]None''. Retry 2 of 3.
2018-05-01 15:20:30,479 WARNING [WARN]: Caught exception while sending message 'b'[TEAM_FI][RED]None''. Retry 3 of 3.
2018-05-01 15:20:47,692 WARNING [WARN]: Caught exception while sending message 'b'[TEAM_FI][RED]None''. Retry 2 of 3.
2018-05-01 15:20:47,693 WARNING [WARN]: Caught exception while sending message 'b'[TEAM_FI][RED]None''. Retry 3 of 3.
2018-05-01 15:28:04,024 WARNING [WARN]: Caught exception while sending message 'b'[TEAM_FI][RED]None''. Retry 2 of 3.
2018-05-01 15:28:04,024 WARNING [WARN]: Caught exception while sending message 'b'[TEAM_FI][RED]None''. Retry 3 of 3.
2018-05-01 16:30:22,022 WARNING [WARN]: Caught exception while sending message 'b'[TEAM_FI][RED]None''. Retry 2 of 3.
2018-05-01 16:30:22,022 WARNING [WARN]: Caught exception while sending message 'b'[TEAM_FI][RED]None''. Retry 3 of 3.
2018-05-01 16:30:22,042 ERROR [ERROR]: Caught exception in the launcher.
2018-05-01 16:30:22,062 ERROR [ERROR]: !=== Caught a fatal exception: ===!
2018-05-01 16:30:22,063 ERROR [ERROR]: Exception: 
Expecting property name enclosed in double quotes: line 1 column 226 (char 225)
  File "C:/Users/Ian/Documents/GitHub/Terra/launcher.py", line 8, in <module>
    Main().run()

  File "C:\Users\Ian\Documents\GitHub\Terra\terra\main.py", line 193, in run
    self.step(event)

  File "C:\Users\Ian\Documents\GitHub\Terra\terra\main.py", line 140, in step
    EVENT_BUS.invoke_handlers(event)

  File "C:\Users\Ian\Documents\GitHub\Terra\terra\event\eventbus.py", line 46, in invoke_handlers
    handler(event)

  File "C:\Users\Ian\Documents\GitHub\Terra\terra\main.py", line 97, in handle_menu_selections
    self.set_screen_from_mode(Mode.LOBBY, event.mapname)

  File "C:\Users\Ian\Documents\GitHub\Terra\terra\main.py", line 66, in set_screen_from_mode
    new_screen = Lobby(False, map_name, map_type)

  File "C:\Users\Ian\Documents\GitHub\Terra\terra\screens\lobby.py", line 31, in __init__
    Session.set_up_local_game(map_name, map_type)

  File "C:\Users\Ian\Documents\GitHub\Terra\terra\managers\session.py", line 45, in set_up_local_game
    SESSION.__set_up__(map_name, bitmap, pieces, teams, upgrades, meta)

  File "C:\Users\Ian\Documents\GitHub\Terra\terra\managers\session.py", line 112, in __set_up__
    from terra.piece.piecemanager import PieceManager

  File "C:\Users\Ian\Documents\GitHub\Terra\terra\piece\piecemanager.py", line 4, in <module>
    from terra.economy.upgrades import base_upgrades

  File "C:\Users\Ian\Documents\GitHub\Terra\terra\economy\upgrades.py", line 21, in <module>
    base_upgrades = read_upgrade_attributes_from_file()

  File "C:\Users\Ian\Documents\GitHub\Terra\terra\economy\upgrades.py", line 14, in read_upgrade_attributes_from_file
    return json.loads(attributes_file.read().replace('\n', ''), object_hook=as_enum)

  File "C:\Users\Ian\AppData\Local\Programs\Python\Python36-32\lib\json\__init__.py", line 367, in loads
    return cls(**kw).decode(s)

  File "C:\Users\Ian\AppData\Local\Programs\Python\Python36-32\lib\json\decoder.py", line 339, in decode
    obj, end = self.raw_decode(s, idx=_w(s, 0).end())

  File "C:\Users\Ian\AppData\Local\Programs\Python\Python36-32\lib\json\decoder.py", line 355, in raw_decode
    obj, end = self.scan_once(s, idx)

2018-05-01 16:30:56,909 WARNING [WARN]: Caught exception while sending message 'b'[TEAM_FI][RED]None''. Retry 2 of 3.
2018-05-01 16:30:56,909 WARNING [WARN]: Caught exception while sending message 'b'[TEAM_FI][RED]None''. Retry 3 of 3.
2018-05-01 16:31:40,643 WARNING [WARN]: Caught exception while sending message 'b'[TEAM_FI][RED]None''. Retry 2 of 3.
2018-05-01 16:31:40,643 WARNING [WARN]: Caught exception while sending message 'b'[TEAM_FI][RED]None''. Retry 3 of 3.
2018-05-01 16:36:26,743 WARNING [WARN]: Caught exception while sending message 'b'[TEAM_FI][RED]None''. Retry 2 of 3.
2018-05-01 16:36:26,743 WARNING [WARN]: Caught exception while sending message 'b'[TEAM_FI][RED]None''. Retry 3 of 3.
2018-05-01 16:36:56,096 WARNING [WARN]: Caught exception while sending message 'b'[TEAM_FI][RED]None''. Retry 2 of 3.
2018-05-01 16:36:56,096 WARNING [WARN]: Caught exception while sending message 'b'[TEAM_FI][RED]None''. Retry 3 of 3.
2018-05-01 16:37:10,819 WARNING [WARN]: Caught exception while sending message 'b'[TEAM_FI][RED]None''. Retry 2 of 3.
2018-05-01 16:37:10,819 WARNING [WARN]: Caught exception while sending message 'b'[TEAM_FI][RED]None''. Retry 3 of 3.
2018-05-01 16:48:17,920 WARNING [WARN]: Caught exception while sending message 'b'[TEAM_FI][RED]None''. Retry 2 of 3.
2018-05-01 16:48:17,921 WARNING [WARN]: Caught exception while sending message 'b'[TEAM_FI][RED]None''. Retry 3 of 3.
2018-05-01 16:50:18,442 WARNING [WARN]: Caught exception while sending message 'b'[TEAM_FI][RED]None''. Retry 2 of 3.
2018-05-01 16:50:18,442 WARNING [WARN]: Caught exception while sending message 'b'[TEAM_FI][RED]None''. Retry 3 of 3.
2018-05-01 16:50:29,908 WARNING [WARN]: Caught exception while sending message 'b'[TEAM_FI][RED]None''. Retry 2 of 3.
2018-05-01 16:50:29,908 WARNING [WARN]: Caught exception while sending message 'b'[TEAM_FI][RED]None''. Retry 3 of 3.
2018-05-01 16:50:46,652 WARNING [WARN]: Caught exception while sending message 'b'[TEAM_FI][RED]None''. Retry 2 of 3.
2018-05-01 16:50:46,652 WARNING [WARN]: Caught exception while sending message 'b'[TEAM_FI][RED]None''. Retry 3 of 3.
2018-05-01 16:51:23,206 WARNING [WARN]: Caught exception while sending message 'b'[TEAM_FI][RED]None''. Retry 2 of 3.
2018-05-01 16:51:23,206 WARNING [WARN]: Caught exception while sending message 'b'[TEAM_FI][RED]None''. Retry 3 of 3.
2018-05-01 17:51:06,641 WARNING [WARN]: Caught exception while sending message 'b'[TEAM_FI][RED]None''. Retry 2 of 3.
2018-05-01 17:51:06,641 WARNING [WARN]: Caught exception while sending message 'b'[TEAM_FI][RED]None''. Retry 3 of 3.
2018-05-02 00:11:51,217 WARNING [WARN]: Caught exception while sending message 'b'[TEAM_FI][RED]None''. Retry 2 of 3.
2018-05-02 00:11:51,218 WARNING [WARN]: Caught exception while sending message 'b'[TEAM_FI][RED]None''. Retry 3 of 3.
2018-05-02 00:11:51,239 ERROR [ERROR]: Caught exception in the launcher.
2018-05-02 00:11:51,248 ERROR [ERROR]: !=== Caught a fatal exception: ===!
2018-05-02 00:11:51,249 ERROR [ERROR]: Exception: 
'RESOURCE_PRODUCTION_1'
  File "C:/Users/Ian/Documents/GitHub/Terra/launcher.py", line 8, in <module>
    Main().run()

  File "C:\Users\Ian\Documents\GitHub\Terra\terra\main.py", line 193, in run
    self.step(event)

  File "C:\Users\Ian\Documents\GitHub\Terra\terra\main.py", line 140, in step
    EVENT_BUS.invoke_handlers(event)

  File "C:\Users\Ian\Documents\GitHub\Terra\terra\event\eventbus.py", line 46, in invoke_handlers
    handler(event)

  File "C:\Users\Ian\Documents\GitHub\Terra\terra\main.py", line 99, in handle_menu_selections
    self.set_screen_from_mode(Mode.LOBBY, event.mapname, map_type=AssetType.SAVE)

  File "C:\Users\Ian\Documents\GitHub\Terra\terra\main.py", line 66, in set_screen_from_mode
    new_screen = Lobby(False, map_name, map_type)

  File "C:\Users\Ian\Documents\GitHub\Terra\terra\screens\lobby.py", line 31, in __init__
    Session.set_up_local_game(map_name, map_type)

  File "C:\Users\Ian\Documents\GitHub\Terra\terra\managers\session.py", line 45, in set_up_local_game
    SESSION.__set_up__(map_name, bitmap, pieces, teams, upgrades, meta)

  File "C:\Users\Ian\Documents\GitHub\Terra\terra\managers\session.py", line 121, in __set_up__
    self.managers[Manager.TEAM] = TeamManager(teams, upgrades)

  File "C:\Users\Ian\Documents\GitHub\Terra\terra\team\teammanager.py", line 74, in __init__
    self.purchase_upgrade(team, UpgradeType[upgrade])

  File "C:\Users\Ian\AppData\Local\Programs\Python\Python36-32\lib\enum.py", line 327, in __getitem__
    return cls._member_map_[name]

2018-05-02 00:12:16,702 WARNING [WARN]: Caught exception while sending message 'b'[TEAM_FI][RED]None''. Retry 2 of 3.
2018-05-02 00:12:16,702 WARNING [WARN]: Caught exception while sending message 'b'[TEAM_FI][RED]None''. Retry 3 of 3.
2018-05-02 10:58:30,731 WARNING [WARN]: Caught exception while sending message 'b'[TEAM_FI][RED]None''. Retry 2 of 3.
2018-05-02 10:58:30,731 WARNING [WARN]: Caught exception while sending message 'b'[TEAM_FI][RED]None''. Retry 3 of 3.
2018-05-02 11:02:11,397 ERROR [ERROR]: Caught exception in the launcher.
2018-05-02 11:02:11,421 ERROR [ERROR]: !=== Caught a fatal exception: ===!
2018-05-02 11:02:11,422 ERROR [ERROR]: Exception: 
<Team.BLUE: '[BLU]'>
  File "C:/Users/Ian/Documents/GitHub/Terra/launcher.py", line 8, in <module>
    Main().run()

  File "C:\Users\Ian\Documents\GitHub\Terra\terra\main.py", line 193, in run
    self.step(event)

  File "C:\Users\Ian\Documents\GitHub\Terra\terra\main.py", line 140, in step
    EVENT_BUS.invoke_handlers(event)

  File "C:\Users\Ian\Documents\GitHub\Terra\terra\event\eventbus.py", line 46, in invoke_handlers
    handler(event)

  File "C:\Users\Ian\Documents\GitHub\Terra\terra\team\teammanager.py", line 301, in handle_base_destroyed
    self.remove_team(event.team)

  File "C:\Users\Ian\Documents\GitHub\Terra\terra\team\teammanager.py", line 291, in remove_team
    self.get_manager(Manager.PLAYER).handle_team_defeated(team)

  File "C:\Users\Ian\Documents\GitHub\Terra\terra\team\playermanager.py", line 103, in handle_team_defeated
    self.cursors[team].destroy()

2018-05-02 11:03:05,156 WARNING [WARN]: Caught exception while sending message 'b'[TEAM_FI][RED]None''. Retry 2 of 3.
2018-05-02 11:03:05,156 WARNING [WARN]: Caught exception while sending message 'b'[TEAM_FI][RED]None''. Retry 3 of 3.
2018-05-02 12:20:53,519 WARNING [WARN]: Caught exception while sending message 'b'[TEAM_FI][RED]None''. Retry 2 of 3.
2018-05-02 12:20:53,520 WARNING [WARN]: Caught exception while sending message 'b'[TEAM_FI][RED]None''. Retry 3 of 3.
2018-05-02 12:23:46,631 WARNING [WARN]: Caught exception while sending message 'b'[TEAM_FI][RED]None''. Retry 2 of 3.
2018-05-02 12:23:46,632 WARNING [WARN]: Caught exception while sending message 'b'[TEAM_FI][RED]None''. Retry 3 of 3.
2018-05-02 12:23:46,935 ERROR [ERROR]: Caught exception in the launcher.
2018-05-02 12:23:46,944 ERROR [ERROR]: !=== Caught a fatal exception: ===!
2018-05-02 12:23:46,945 ERROR [ERROR]: Exception: 
unsupported operand type(s) for *: 'int' and 'NoneType'
  File "C:/Users/Ian/Documents/GitHub/Terra/launcher.py", line 8, in <module>
    Main().run()

  File "C:/Users/Ian/Documents/GitHub/Terra\terra\main.py", line 193, in run
    self.step(event)

  File "C:/Users/Ian/Documents/GitHub/Terra\terra\main.py", line 140, in step
    EVENT_BUS.invoke_handlers(event)

  File "C:/Users/Ian/Documents/GitHub/Terra\terra\event\eventbus.py", line 46, in invoke_handlers
    handler(event)

  File "C:/Users/Ian/Documents/GitHub/Terra\terra\ai\aiplayer.py", line 532, in handle_orders_phase
    self.tasks = self.generate_tasks()

  File "C:/Users/Ian/Documents/GitHub/Terra\terra\ai\aiplayer.py", line 122, in generate_tasks
    tasks.extend(self.generate_research_tasks())

  File "C:/Users/Ian/Documents/GitHub/Terra\terra\ai\aiplayer.py", line 235, in generate_research_tasks
    upgrades_to_research.put(upgrade, self.score_researchable_upgrade(upgrade))

  File "C:/Users/Ian/Documents/GitHub/Terra\terra\ai\aiplayer.py", line 269, in score_researchable_upgrade
    score -= 2 * self.my_piece_counts.get(piece_type) / total_pieces

2018-05-02 12:24:11,075 WARNING [WARN]: Caught exception while sending message 'b'[TEAM_FI][RED]None''. Retry 2 of 3.
2018-05-02 12:24:11,076 WARNING [WARN]: Caught exception while sending message 'b'[TEAM_FI][RED]None''. Retry 3 of 3.
2018-05-02 12:24:11,377 ERROR [ERROR]: Caught exception in the launcher.
2018-05-02 12:24:11,395 ERROR [ERROR]: !=== Caught a fatal exception: ===!
2018-05-02 12:24:11,395 ERROR [ERROR]: Exception: 
'<' not supported between instances of 'UpgradeType' and 'UpgradeType'
  File "C:/Users/Ian/Documents/GitHub/Terra/launcher.py", line 8, in <module>
    Main().run()

  File "C:/Users/Ian/Documents/GitHub/Terra\terra\main.py", line 193, in run
    self.step(event)

  File "C:/Users/Ian/Documents/GitHub/Terra\terra\main.py", line 140, in step
    EVENT_BUS.invoke_handlers(event)

  File "C:/Users/Ian/Documents/GitHub/Terra\terra\event\eventbus.py", line 46, in invoke_handlers
    handler(event)

  File "C:/Users/Ian/Documents/GitHub/Terra\terra\ai\aiplayer.py", line 532, in handle_orders_phase
    self.tasks = self.generate_tasks()

  File "C:/Users/Ian/Documents/GitHub/Terra\terra\ai\aiplayer.py", line 122, in generate_tasks
    tasks.extend(self.generate_research_tasks())

  File "C:/Users/Ian/Documents/GitHub/Terra\terra\ai\aiplayer.py", line 235, in generate_research_tasks
    upgrades_to_research.put(upgrade, self.score_researchable_upgrade(upgrade))

  File "C:\Users\Ian\AppData\Local\Programs\Python\Python36-32\lib\queue.py", line 143, in put
    self._put(item)

  File "C:\Users\Ian\AppData\Local\Programs\Python\Python36-32\lib\queue.py", line 227, in _put
    heappush(self.queue, item)

2018-05-02 12:29:57,610 WARNING [WARN]: Caught exception while sending message 'b'[TEAM_FI][RED]None''. Retry 2 of 3.
2018-05-02 12:29:57,610 WARNING [WARN]: Caught exception while sending message 'b'[TEAM_FI][RED]None''. Retry 3 of 3.
2018-05-02 12:29:57,909 ERROR [ERROR]: Caught exception in the launcher.
2018-05-02 12:29:57,911 ERROR [ERROR]: !=== Caught a fatal exception: ===!
2018-05-02 12:29:57,911 ERROR [ERROR]: Exception: 
'<' not supported between instances of 'UpgradeType' and 'UpgradeType'
  File "C:/Users/Ian/Documents/GitHub/Terra/launcher.py", line 8, in <module>
    Main().run()

  File "C:/Users/Ian/Documents/GitHub/Terra\terra\main.py", line 193, in run
    self.step(event)

  File "C:/Users/Ian/Documents/GitHub/Terra\terra\main.py", line 140, in step
    EVENT_BUS.invoke_handlers(event)

  File "C:/Users/Ian/Documents/GitHub/Terra\terra\event\eventbus.py", line 46, in invoke_handlers
    handler(event)

  File "C:/Users/Ian/Documents/GitHub/Terra\terra\ai\aiplayer.py", line 537, in handle_orders_phase
    self.tasks = self.generate_tasks()

  File "C:/Users/Ian/Documents/GitHub/Terra\terra\ai\aiplayer.py", line 122, in generate_tasks
    tasks.extend(self.generate_research_tasks())

  File "C:/Users/Ian/Documents/GitHub/Terra\terra\ai\aiplayer.py", line 240, in generate_research_tasks
    queue_upgrade(upgrade)

  File "C:/Users/Ian/Documents/GitHub/Terra\terra\ai\aiplayer.py", line 222, in queue_upgrade
    upgrades_to_research.put((score, upgrade))

  File "C:\Users\Ian\AppData\Local\Programs\Python\Python36-32\lib\queue.py", line 143, in put
    self._put(item)

  File "C:\Users\Ian\AppData\Local\Programs\Python\Python36-32\lib\queue.py", line 227, in _put
    heappush(self.queue, item)

2018-05-02 12:30:14,355 WARNING [WARN]: Caught exception while sending message 'b'[TEAM_FI][RED]None''. Retry 2 of 3.
2018-05-02 12:30:14,355 WARNING [WARN]: Caught exception while sending message 'b'[TEAM_FI][RED]None''. Retry 3 of 3.
2018-05-02 12:31:15,753 WARNING [WARN]: Caught exception while sending message 'b'[TEAM_FI][RED]None''. Retry 2 of 3.
2018-05-02 12:31:15,753 WARNING [WARN]: Caught exception while sending message 'b'[TEAM_FI][RED]None''. Retry 3 of 3.
2018-05-02 12:31:50,367 ERROR [ERROR]: Caught exception in the launcher.
2018-05-02 12:31:50,372 ERROR [ERROR]: !=== Caught a fatal exception: ===!
2018-05-02 12:31:50,373 ERROR [ERROR]: Exception: 
'<' not supported between instances of 'UpgradeType' and 'UpgradeType'
  File "C:/Users/Ian/Documents/GitHub/Terra/launcher.py", line 8, in <module>
    Main().run()

  File "C:/Users/Ian/Documents/GitHub/Terra\terra\main.py", line 193, in run
    self.step(event)

  File "C:/Users/Ian/Documents/GitHub/Terra\terra\main.py", line 140, in step
    EVENT_BUS.invoke_handlers(event)

  File "C:/Users/Ian/Documents/GitHub/Terra\terra\event\eventbus.py", line 46, in invoke_handlers
    handler(event)

  File "C:/Users/Ian/Documents/GitHub/Terra\terra\ai\aiplayer.py", line 537, in handle_orders_phase
    self.tasks = self.generate_tasks()

  File "C:/Users/Ian/Documents/GitHub/Terra\terra\ai\aiplayer.py", line 122, in generate_tasks
    tasks.extend(self.generate_research_tasks())

  File "C:/Users/Ian/Documents/GitHub/Terra\terra\ai\aiplayer.py", line 249, in generate_research_tasks
    tasks.append(self.create_research_task(upgrades_to_research.get()))

  File "C:\Users\Ian\AppData\Local\Programs\Python\Python36-32\lib\queue.py", line 174, in get
    item = self._get()

  File "C:\Users\Ian\AppData\Local\Programs\Python\Python36-32\lib\queue.py", line 230, in _get
    return heappop(self.queue)

2018-05-02 12:32:24,789 WARNING [WARN]: Caught exception while sending message 'b'[TEAM_FI][RED]None''. Retry 2 of 3.
2018-05-02 12:32:24,789 WARNING [WARN]: Caught exception while sending message 'b'[TEAM_FI][RED]None''. Retry 3 of 3.
2018-05-02 12:32:25,851 ERROR [ERROR]: Caught exception in the launcher.
2018-05-02 12:32:25,853 ERROR [ERROR]: !=== Caught a fatal exception: ===!
2018-05-02 12:32:25,854 ERROR [ERROR]: Exception: 
'<' not supported between instances of 'UpgradeType' and 'UpgradeType'
  File "C:/Users/Ian/Documents/GitHub/Terra/launcher.py", line 8, in <module>
    Main().run()

  File "C:/Users/Ian/Documents/GitHub/Terra\terra\main.py", line 193, in run
    self.step(event)

  File "C:/Users/Ian/Documents/GitHub/Terra\terra\main.py", line 140, in step
    EVENT_BUS.invoke_handlers(event)

  File "C:/Users/Ian/Documents/GitHub/Terra\terra\event\eventbus.py", line 46, in invoke_handlers
    handler(event)

  File "C:/Users/Ian/Documents/GitHub/Terra\terra\ai\aiplayer.py", line 538, in handle_orders_phase
    self.tasks = self.generate_tasks()

  File "C:/Users/Ian/Documents/GitHub/Terra\terra\ai\aiplayer.py", line 122, in generate_tasks
    tasks.extend(self.generate_research_tasks())

  File "C:/Users/Ian/Documents/GitHub/Terra\terra\ai\aiplayer.py", line 249, in generate_research_tasks
    _, upgrade = upgrades_to_research.get()

  File "C:\Users\Ian\AppData\Local\Programs\Python\Python36-32\lib\queue.py", line 174, in get
    item = self._get()

  File "C:\Users\Ian\AppData\Local\Programs\Python\Python36-32\lib\queue.py", line 230, in _get
    return heappop(self.queue)

2018-05-02 12:32:43,756 WARNING [WARN]: Caught exception while sending message 'b'[TEAM_FI][RED]None''. Retry 2 of 3.
2018-05-02 12:32:43,757 WARNING [WARN]: Caught exception while sending message 'b'[TEAM_FI][RED]None''. Retry 3 of 3.
2018-05-02 12:33:32,551 ERROR [ERROR]: Caught exception in the launcher.
2018-05-02 12:33:32,553 ERROR [ERROR]: !=== Caught a fatal exception: ===!
2018-05-02 12:33:32,554 ERROR [ERROR]: Exception: 
'<' not supported between instances of 'UpgradeType' and 'UpgradeType'
  File "C:/Users/Ian/Documents/GitHub/Terra/launcher.py", line 8, in <module>
    Main().run()

  File "C:/Users/Ian/Documents/GitHub/Terra\terra\main.py", line 193, in run
    self.step(event)

  File "C:/Users/Ian/Documents/GitHub/Terra\terra\main.py", line 140, in step
    EVENT_BUS.invoke_handlers(event)

  File "C:/Users/Ian/Documents/GitHub/Terra\terra\event\eventbus.py", line 46, in invoke_handlers
    handler(event)

  File "C:/Users/Ian/Documents/GitHub/Terra\terra\ai\aiplayer.py", line 538, in handle_orders_phase
    self.tasks = self.generate_tasks()

  File "C:/Users/Ian/Documents/GitHub/Terra\terra\ai\aiplayer.py", line 122, in generate_tasks
    tasks.extend(self.generate_research_tasks())

  File "C:/Users/Ian/Documents/GitHub/Terra\terra\ai\aiplayer.py", line 249, in generate_research_tasks
    _, upgrade = upgrades_to_research.get()

  File "C:\Users\Ian\AppData\Local\Programs\Python\Python36-32\lib\queue.py", line 174, in get
    item = self._get()

  File "C:\Users\Ian\AppData\Local\Programs\Python\Python36-32\lib\queue.py", line 230, in _get
    return heappop(self.queue)

2018-05-02 12:35:46,276 WARNING [WARN]: Caught exception while sending message 'b'[TEAM_FI][RED]None''. Retry 2 of 3.
2018-05-02 12:35:46,276 WARNING [WARN]: Caught exception while sending message 'b'[TEAM_FI][RED]None''. Retry 3 of 3.
2018-05-02 12:37:21,434 WARNING [WARN]: Caught exception while sending message 'b'[TEAM_FI][RED]None''. Retry 2 of 3.
2018-05-02 12:37:21,435 WARNING [WARN]: Caught exception while sending message 'b'[TEAM_FI][RED]None''. Retry 3 of 3.
2018-05-02 12:38:33,574 WARNING [WARN]: Caught exception while sending message 'b'[TEAM_FI][RED]None''. Retry 2 of 3.
2018-05-02 12:38:33,575 WARNING [WARN]: Caught exception while sending message 'b'[TEAM_FI][RED]None''. Retry 3 of 3.
2018-05-02 12:39:04,366 WARNING [WARN]: Caught exception while sending message 'b'[TEAM_FI][RED]None''. Retry 2 of 3.
2018-05-02 12:39:04,367 WARNING [WARN]: Caught exception while sending message 'b'[TEAM_FI][RED]None''. Retry 3 of 3.
2018-05-02 12:40:56,724 WARNING [WARN]: Caught exception while sending message 'b'[TEAM_FI][RED]None''. Retry 2 of 3.
2018-05-02 12:40:56,724 WARNING [WARN]: Caught exception while sending message 'b'[TEAM_FI][RED]None''. Retry 3 of 3.
2018-05-02 12:42:05,771 WARNING [WARN]: Caught exception while sending message 'b'[TEAM_FI][RED]None''. Retry 2 of 3.
2018-05-02 12:42:05,771 WARNING [WARN]: Caught exception while sending message 'b'[TEAM_FI][RED]None''. Retry 3 of 3.
2018-05-02 14:40:15,046 WARNING [WARN]: Caught exception while sending message 'b'[TEAM_FI][RED]None''. Retry 2 of 3.
2018-05-02 14:40:15,046 WARNING [WARN]: Caught exception while sending message 'b'[TEAM_FI][RED]None''. Retry 3 of 3.
2018-05-02 15:01:00,223 WARNING [WARN]: Caught exception while sending message 'b'[TEAM_FI][RED]None''. Retry 2 of 3.
2018-05-02 15:01:00,223 WARNING [WARN]: Caught exception while sending message 'b'[TEAM_FI][RED]None''. Retry 3 of 3.
2018-05-02 15:04:16,086 WARNING [WARN]: Caught exception while sending message 'b'[TEAM_FI][RED]None''. Retry 2 of 3.
2018-05-02 15:04:16,086 WARNING [WARN]: Caught exception while sending message 'b'[TEAM_FI][RED]None''. Retry 3 of 3.
2018-05-02 15:17:35,138 WARNING [WARN]: Caught exception while sending message 'b'[TEAM_FI][RED]None''. Retry 2 of 3.
2018-05-02 15:17:35,138 WARNING [WARN]: Caught exception while sending message 'b'[TEAM_FI][RED]None''. Retry 3 of 3.
2018-05-02 15:17:54,863 WARNING [WARN]: Caught exception while sending message 'b'[TEAM_FI][RED]None''. Retry 2 of 3.
2018-05-02 15:17:54,863 WARNING [WARN]: Caught exception while sending message 'b'[TEAM_FI][RED]None''. Retry 3 of 3.
2018-05-02 15:32:30,714 WARNING [WARN]: Caught exception while sending message 'b'[TEAM_FI][RED]None''. Retry 2 of 3.
2018-05-02 15:32:30,714 WARNING [WARN]: Caught exception while sending message 'b'[TEAM_FI][RED]None''. Retry 3 of 3.
2018-05-02 15:32:37,557 WARNING [WARN]: Caught exception while sending message 'b'[TEAM_FI][RED]None''. Retry 2 of 3.
2018-05-02 15:32:37,557 WARNING [WARN]: Caught exception while sending message 'b'[TEAM_FI][RED]None''. Retry 3 of 3.
2018-05-02 15:34:16,431 WARNING [WARN]: Caught exception while sending message 'b'[TEAM_FI][RED]None''. Retry 2 of 3.
2018-05-02 15:34:16,431 WARNING [WARN]: Caught exception while sending message 'b'[TEAM_FI][RED]None''. Retry 3 of 3.
2018-05-02 16:17:12,062 WARNING [WARN]: Caught exception while sending message 'b'[TEAM_FI][RED]None''. Retry 2 of 3.
2018-05-02 16:17:12,062 WARNING [WARN]: Caught exception while sending message 'b'[TEAM_FI][RED]None''. Retry 3 of 3.
2018-05-02 16:36:19,474 WARNING [WARN]: Caught exception while sending message 'b'[TEAM_FI][RED]None''. Retry 2 of 3.
2018-05-02 16:36:19,475 WARNING [WARN]: Caught exception while sending message 'b'[TEAM_FI][RED]None''. Retry 3 of 3.
2018-05-04 13:12:47,437 WARNING [WARN]: Caught exception while sending message 'b'[TEAM_FI][RED]None''. Retry 2 of 3.
2018-05-04 13:12:47,437 WARNING [WARN]: Caught exception while sending message 'b'[TEAM_FI][RED]None''. Retry 3 of 3.
2018-05-04 13:12:47,500 ERROR [ERROR]: Caught exception in the launcher.
2018-05-04 13:12:47,548 ERROR [ERROR]: !=== Caught a fatal exception: ===!
2018-05-04 13:12:47,548 ERROR [ERROR]: Exception: 
GUARDIAN_ENTRENCHMENT
  File "C:/Users/Ian/Documents/GitHub/Terra/launcher.py", line 8, in <module>
    Main().run()

  File "C:\Users\Ian\Documents\GitHub\Terra\terra\main.py", line 193, in run
    self.step(event)

  File "C:\Users\Ian\Documents\GitHub\Terra\terra\main.py", line 140, in step
    EVENT_BUS.invoke_handlers(event)

  File "C:\Users\Ian\Documents\GitHub\Terra\terra\event\eventbus.py", line 46, in invoke_handlers
    handler(event)

  File "C:\Users\Ian\Documents\GitHub\Terra\terra\main.py", line 99, in handle_menu_selections
    self.set_screen_from_mode(Mode.LOBBY, event.mapname, map_type=AssetType.SAVE)

  File "C:\Users\Ian\Documents\GitHub\Terra\terra\main.py", line 66, in set_screen_from_mode
    new_screen = Lobby(False, map_name, map_type)

  File "C:\Users\Ian\Documents\GitHub\Terra\terra\screens\lobby.py", line 31, in __init__
    Session.set_up_local_game(map_name, map_type)

  File "C:\Users\Ian\Documents\GitHub\Terra\terra\managers\session.py", line 45, in set_up_local_game
    SESSION.__set_up__(map_name, bitmap, pieces, teams, upgrades, meta)

  File "C:\Users\Ian\Documents\GitHub\Terra\terra\managers\session.py", line 112, in __set_up__
    from terra.piece.piecemanager import PieceManager

  File "C:\Users\Ian\Documents\GitHub\Terra\terra\piece\piecemanager.py", line 4, in <module>
    from terra.economy.upgrades import base_upgrades

  File "C:\Users\Ian\Documents\GitHub\Terra\terra\economy\upgrades.py", line 21, in <module>
    base_upgrades = read_upgrade_attributes_from_file()

  File "C:\Users\Ian\Documents\GitHub\Terra\terra\economy\upgrades.py", line 14, in read_upgrade_attributes_from_file
    return json.loads(attributes_file.read().replace('\n', ''), object_hook=as_enum)

  File "C:\Users\Ian\AppData\Local\Programs\Python\Python36-32\lib\json\__init__.py", line 367, in loads
    return cls(**kw).decode(s)

  File "C:\Users\Ian\AppData\Local\Programs\Python\Python36-32\lib\json\decoder.py", line 339, in decode
    obj, end = self.raw_decode(s, idx=_w(s, 0).end())

  File "C:\Users\Ian\AppData\Local\Programs\Python\Python36-32\lib\json\decoder.py", line 355, in raw_decode
    obj, end = self.scan_once(s, idx)

  File "C:\Users\Ian\Documents\GitHub\Terra\terra\util\jsonutil.py", line 44, in as_enum
    new_dict[parse_enum(key)] = parse_enum(value)

  File "C:\Users\Ian\Documents\GitHub\Terra\terra\util\jsonutil.py", line 38, in parse_enum
    return [parse_enum(element) for element in obj]

  File "C:\Users\Ian\Documents\GitHub\Terra\terra\util\jsonutil.py", line 38, in <listcomp>
    return [parse_enum(element) for element in obj]

  File "C:\Users\Ian\Documents\GitHub\Terra\terra\util\jsonutil.py", line 33, in parse_enum
    return getattr(KNOWN_ENUMS[split_str[0]], split_str[1])

  File "C:\Users\Ian\AppData\Local\Programs\Python\Python36-32\lib\enum.py", line 324, in __getattr__
    raise AttributeError(name) from None

2018-05-04 13:13:27,019 WARNING [WARN]: Caught exception while sending message 'b'[TEAM_FI][RED]None''. Retry 2 of 3.
2018-05-04 13:13:27,020 WARNING [WARN]: Caught exception while sending message 'b'[TEAM_FI][RED]None''. Retry 3 of 3.
2018-05-04 13:15:43,555 WARNING [WARN]: Caught exception while sending message 'b'[TEAM_FI][RED]None''. Retry 2 of 3.
2018-05-04 13:15:43,556 WARNING [WARN]: Caught exception while sending message 'b'[TEAM_FI][RED]None''. Retry 3 of 3.
2018-05-06 13:49:52,026 WARNING [WARN]: Caught exception while sending message 'b'[TEAM_FI][RED]None''. Retry 2 of 3.
2018-05-06 13:49:52,027 WARNING [WARN]: Caught exception while sending message 'b'[TEAM_FI][RED]None''. Retry 3 of 3.
2018-05-06 14:02:45,721 WARNING [WARN]: Caught exception while sending message 'b'[TEAM_FI][RED]None''. Retry 2 of 3.
2018-05-06 14:02:45,722 WARNING [WARN]: Caught exception while sending message 'b'[TEAM_FI][RED]None''. Retry 3 of 3.
2018-05-06 14:02:46,054 ERROR [ERROR]: Caught exception in the launcher.
2018-05-06 14:02:46,061 ERROR [ERROR]: !=== Caught a fatal exception: ===!
2018-05-06 14:02:46,061 ERROR [ERROR]: Exception: 
'Personality' object has no attribute 'unit_construction_weight'
  File "C:/Users/Ian/Documents/GitHub/Terra/launcher.py", line 8, in <module>
    Main().run()

  File "C:\Users\Ian\Documents\GitHub\Terra\terra\main.py", line 193, in run
    self.step(event)

  File "C:\Users\Ian\Documents\GitHub\Terra\terra\main.py", line 140, in step
    EVENT_BUS.invoke_handlers(event)

  File "C:\Users\Ian\Documents\GitHub\Terra\terra\event\eventbus.py", line 46, in invoke_handlers
    handler(event)

  File "C:\Users\Ian\Documents\GitHub\Terra\terra\ai\aiplayer.py", line 534, in handle_orders_phase
    self.tasks = self.generate_tasks()

  File "C:\Users\Ian\Documents\GitHub\Terra\terra\ai\aiplayer.py", line 120, in generate_tasks
    tasks.extend(self.generate_economic_tasks())

  File "C:\Users\Ian\Documents\GitHub\Terra\terra\ai\aiplayer.py", line 197, in generate_economic_tasks
    tasks.extend(self.create_build_military_tasks())

  File "C:\Users\Ian\Documents\GitHub\Terra\terra\ai\aiplayer.py", line 344, in create_build_military_tasks
    counts_map[archetype] = count / self.personality.unit_construction_weight[archetype]

2018-05-06 14:03:15,248 WARNING [WARN]: Caught exception while sending message 'b'[TEAM_FI][RED]None''. Retry 2 of 3.
2018-05-06 14:03:15,248 WARNING [WARN]: Caught exception while sending message 'b'[TEAM_FI][RED]None''. Retry 3 of 3.
2018-05-06 14:40:44,302 WARNING [WARN]: Caught exception while sending message 'b'[TEAM_FI][RED]None''. Retry 2 of 3.
2018-05-06 14:40:44,302 WARNING [WARN]: Caught exception while sending message 'b'[TEAM_FI][RED]None''. Retry 3 of 3.
2018-05-06 14:40:44,385 ERROR [ERROR]: Caught exception in the launcher.
2018-05-06 14:40:44,395 ERROR [ERROR]: !=== Caught a fatal exception: ===!
2018-05-06 14:40:44,395 ERROR [ERROR]: Exception: 
'NoneType' object is not iterable
  File "C:/Users/Ian/Documents/GitHub/Terra/launcher.py", line 8, in <module>
    Main().run()

  File "C:\Users\Ian\Documents\GitHub\Terra\terra\main.py", line 193, in run
    self.step(event)

  File "C:\Users\Ian\Documents\GitHub\Terra\terra\main.py", line 140, in step
    EVENT_BUS.invoke_handlers(event)

  File "C:\Users\Ian\Documents\GitHub\Terra\terra\event\eventbus.py", line 46, in invoke_handlers
    handler(event)

  File "C:\Users\Ian\Documents\GitHub\Terra\terra\ai\aiplayer.py", line 536, in threaded_handle_orders_phase
    process = Process(target=self.debug_handle_orders_phase, args=(None))

  File "C:\Users\Ian\AppData\Local\Programs\Python\Python36-32\lib\multiprocessing\process.py", line 80, in __init__
    self._args = tuple(args)

2018-05-06 14:41:06,561 WARNING [WARN]: Caught exception while sending message 'b'[TEAM_FI][RED]None''. Retry 2 of 3.
2018-05-06 14:41:06,561 WARNING [WARN]: Caught exception while sending message 'b'[TEAM_FI][RED]None''. Retry 3 of 3.
2018-05-06 14:41:06,675 ERROR [ERROR]: Caught exception in the launcher.
2018-05-06 14:41:06,687 ERROR [ERROR]: !=== Caught a fatal exception: ===!
2018-05-06 14:41:06,688 ERROR [ERROR]: Exception: 
can't pickle pygame.Surface objects
  File "C:/Users/Ian/Documents/GitHub/Terra/launcher.py", line 8, in <module>
    Main().run()

  File "C:\Users\Ian\Documents\GitHub\Terra\terra\main.py", line 193, in run
    self.step(event)

  File "C:\Users\Ian\Documents\GitHub\Terra\terra\main.py", line 140, in step
    EVENT_BUS.invoke_handlers(event)

  File "C:\Users\Ian\Documents\GitHub\Terra\terra\event\eventbus.py", line 46, in invoke_handlers
    handler(event)

  File "C:\Users\Ian\Documents\GitHub\Terra\terra\ai\aiplayer.py", line 539, in threaded_handle_orders_phase
    process.start()

  File "C:\Users\Ian\AppData\Local\Programs\Python\Python36-32\lib\multiprocessing\process.py", line 105, in start
    self._popen = self._Popen(self)

  File "C:\Users\Ian\AppData\Local\Programs\Python\Python36-32\lib\multiprocessing\context.py", line 223, in _Popen
    return _default_context.get_context().Process._Popen(process_obj)

  File "C:\Users\Ian\AppData\Local\Programs\Python\Python36-32\lib\multiprocessing\context.py", line 322, in _Popen
    return Popen(process_obj)

  File "C:\Users\Ian\AppData\Local\Programs\Python\Python36-32\lib\multiprocessing\popen_spawn_win32.py", line 65, in __init__
    reduction.dump(process_obj, to_child)

  File "C:\Users\Ian\AppData\Local\Programs\Python\Python36-32\lib\multiprocessing\reduction.py", line 60, in dump
    ForkingPickler(file, protocol).dump(obj)

2018-05-06 14:49:03,336 WARNING [WARN]: Caught exception while sending message 'b'[TEAM_FI][RED]None''. Retry 2 of 3.
2018-05-06 14:49:03,336 WARNING [WARN]: Caught exception while sending message 'b'[TEAM_FI][RED]None''. Retry 3 of 3.
2018-05-06 14:49:35,298 WARNING [WARN]: Caught exception while sending message 'b'[TEAM_FI][RED]None''. Retry 2 of 3.
2018-05-06 14:49:35,298 WARNING [WARN]: Caught exception while sending message 'b'[TEAM_FI][RED]None''. Retry 3 of 3.
2018-05-06 14:49:54,914 WARNING [WARN]: Caught exception while sending message 'b'[TEAM_FI][RED]None''. Retry 2 of 3.
2018-05-06 14:49:54,914 WARNING [WARN]: Caught exception while sending message 'b'[TEAM_FI][RED]None''. Retry 3 of 3.
2018-05-06 14:50:25,868 WARNING [WARN]: Caught exception while sending message 'b'[TEAM_FI][RED]None''. Retry 2 of 3.
2018-05-06 14:50:25,868 WARNING [WARN]: Caught exception while sending message 'b'[TEAM_FI][RED]None''. Retry 3 of 3.
2018-05-06 14:50:44,957 WARNING [WARN]: Caught exception while sending message 'b'[TEAM_FI][RED]None''. Retry 2 of 3.
2018-05-06 14:50:44,958 WARNING [WARN]: Caught exception while sending message 'b'[TEAM_FI][RED]None''. Retry 3 of 3.
2018-05-06 14:51:03,663 WARNING [WARN]: Caught exception while sending message 'b'[TEAM_FI][RED]None''. Retry 2 of 3.
2018-05-06 14:51:03,663 WARNING [WARN]: Caught exception while sending message 'b'[TEAM_FI][RED]None''. Retry 3 of 3.
2018-05-06 14:54:10,941 WARNING [WARN]: Caught exception while sending message 'b'[TEAM_FI][RED]None''. Retry 2 of 3.
2018-05-06 14:54:10,941 WARNING [WARN]: Caught exception while sending message 'b'[TEAM_FI][RED]None''. Retry 3 of 3.
2018-05-06 15:04:47,043 WARNING [WARN]: Caught exception while sending message 'b'[TEAM_FI][RED]None''. Retry 2 of 3.
2018-05-06 15:04:47,043 WARNING [WARN]: Caught exception while sending message 'b'[TEAM_FI][RED]None''. Retry 3 of 3.
2018-05-06 15:04:52,099 ERROR [ERROR]: Caught exception in the launcher.
2018-05-06 15:04:52,111 ERROR [ERROR]: !=== Caught a fatal exception: ===!
2018-05-06 15:04:52,111 ERROR [ERROR]: Exception: 
<Team.BLUE: '[BLU]'>
  File "C:/Users/Ian/Documents/GitHub/Terra/launcher.py", line 8, in <module>
    Main().run()

  File "C:\Users\Ian\Documents\GitHub\Terra\terra\main.py", line 199, in run
    self.render()

  File "C:\Users\Ian\Documents\GitHub\Terra\terra\main.py", line 156, in render
    game_screen = self.current_screen.render(ui_screen)

  File "C:\Users\Ian\Documents\GitHub\Terra\terra\screens\battle.py", line 44, in render
    SESSION.render(map_screen, ui_screen)

  File "C:\Users\Ian\Documents\GitHub\Terra\terra\managers\session.py", line 136, in render
    manager.render(game_screen, ui_screen)

  File "C:\Users\Ian\Documents\GitHub\Terra\terra\team\teammanager.py", line 351, in render
    phase_bar.render(game_screen, ui_screen)

  File "C:\Users\Ian\Documents\GitHub\Terra\terra\ui\phasebar.py", line 85, in render
    ui_screen.blit(sprite[team], (GRID_WIDTH * x, RESOLUTION_HEIGHT - GRID_HEIGHT))

2018-05-06 15:05:48,846 WARNING [WARN]: Caught exception while sending message 'b'[TEAM_FI][RED]None''. Retry 2 of 3.
2018-05-06 15:05:48,846 WARNING [WARN]: Caught exception while sending message 'b'[TEAM_FI][RED]None''. Retry 3 of 3.
2018-05-06 15:05:54,860 WARNING [WARN]: Caught exception while sending message 'b'[TEAM_FI][RED]None''. Retry 2 of 3.
2018-05-06 15:05:54,860 WARNING [WARN]: Caught exception while sending message 'b'[TEAM_FI][RED]None''. Retry 3 of 3.
2018-05-06 15:07:54,543 WARNING [WARN]: Caught exception while sending message 'b'[TEAM_FI][RED]None''. Retry 2 of 3.
2018-05-06 15:07:54,543 WARNING [WARN]: Caught exception while sending message 'b'[TEAM_FI][RED]None''. Retry 3 of 3.
2018-05-06 15:11:58,209 WARNING [WARN]: Caught exception while sending message 'b'[TEAM_FI][RED]None''. Retry 2 of 3.
2018-05-06 15:11:58,209 WARNING [WARN]: Caught exception while sending message 'b'[TEAM_FI][RED]None''. Retry 3 of 3.
2018-05-06 15:12:01,828 WARNING [WARN]: Caught exception while sending message 'b'[TEAM_FI][RED]None''. Retry 2 of 3.
2018-05-06 15:12:01,828 WARNING [WARN]: Caught exception while sending message 'b'[TEAM_FI][RED]None''. Retry 3 of 3.
2018-05-06 15:15:56,914 WARNING [WARN]: Caught exception while sending message 'b'[TEAM_FI][RED]None''. Retry 2 of 3.
2018-05-06 15:15:56,914 WARNING [WARN]: Caught exception while sending message 'b'[TEAM_FI][RED]None''. Retry 3 of 3.
2018-05-06 15:17:01,180 WARNING [WARN]: Caught exception while sending message 'b'[TEAM_FI][RED]None''. Retry 2 of 3.
2018-05-06 15:17:01,180 WARNING [WARN]: Caught exception while sending message 'b'[TEAM_FI][RED]None''. Retry 3 of 3.
2018-05-06 15:17:58,802 WARNING [WARN]: Caught exception while sending message 'b'[TEAM_FI][RED]None''. Retry 2 of 3.
2018-05-06 15:17:58,802 WARNING [WARN]: Caught exception while sending message 'b'[TEAM_FI][RED]None''. Retry 3 of 3.
2018-05-06 15:18:08,801 WARNING [WARN]: Caught exception while sending message 'b'[TEAM_FI][RED]None''. Retry 2 of 3.
2018-05-06 15:18:08,802 WARNING [WARN]: Caught exception while sending message 'b'[TEAM_FI][RED]None''. Retry 3 of 3.
2018-05-06 15:21:19,087 WARNING [WARN]: Caught exception while sending message 'b'[TEAM_FI][RED]None''. Retry 2 of 3.
2018-05-06 15:21:19,087 WARNING [WARN]: Caught exception while sending message 'b'[TEAM_FI][RED]None''. Retry 3 of 3.
2018-05-06 15:22:25,943 WARNING [WARN]: Caught exception while sending message 'b'[TEAM_FI][RED]None''. Retry 2 of 3.
2018-05-06 15:22:25,943 WARNING [WARN]: Caught exception while sending message 'b'[TEAM_FI][RED]None''. Retry 3 of 3.
2018-05-06 15:26:25,444 WARNING [WARN]: Caught exception while sending message 'b'[TEAM_FI][RED]None''. Retry 2 of 3.
2018-05-06 15:26:25,445 WARNING [WARN]: Caught exception while sending message 'b'[TEAM_FI][RED]None''. Retry 3 of 3.
2018-05-06 16:42:02,787 WARNING [WARN]: Caught exception while sending message 'b'[TEAM_FI][RED]None''. Retry 2 of 3.
2018-05-06 16:42:02,787 WARNING [WARN]: Caught exception while sending message 'b'[TEAM_FI][RED]None''. Retry 3 of 3.
2018-05-06 16:43:17,890 WARNING [WARN]: Caught exception while sending message 'b'[TEAM_FI][RED]None''. Retry 2 of 3.
2018-05-06 16:43:17,891 WARNING [WARN]: Caught exception while sending message 'b'[TEAM_FI][RED]None''. Retry 3 of 3.
2018-05-06 16:43:55,707 WARNING [WARN]: Caught exception while sending message 'b'[TEAM_FI][RED]None''. Retry 2 of 3.
2018-05-06 16:43:55,707 WARNING [WARN]: Caught exception while sending message 'b'[TEAM_FI][RED]None''. Retry 3 of 3.
2018-05-06 16:56:43,683 WARNING [WARN]: Caught exception while sending message 'b'[TEAM_FI][RED]None''. Retry 2 of 3.
2018-05-06 16:56:43,683 WARNING [WARN]: Caught exception while sending message 'b'[TEAM_FI][RED]None''. Retry 3 of 3.
2018-05-06 16:57:31,502 WARNING [WARN]: Caught exception while sending message 'b'[TEAM_FI][RED]None''. Retry 2 of 3.
2018-05-06 16:57:31,502 WARNING [WARN]: Caught exception while sending message 'b'[TEAM_FI][RED]None''. Retry 3 of 3.
