2018-03-30 19:19:24,564 ERROR [ERROR]: Caught exception during network step.
2018-03-30 19:19:24,565 ERROR [ERROR]: !=== Caught a fatal exception: ===!
2018-03-30 19:19:24,565 ERROR [ERROR]: Exception: 
[WinError 10054] An existing connection was forcibly closed by the remote host
  File "C:\Users\Ian\Documents\GitHub\Terra\terra\managers\networkmanager.py", line 219, in network_step
    message, address = f.recvfrom(2048)

2018-03-30 19:19:24,566 ERROR [ERROR]: Failed to connect to host
2018-03-30 19:19:24,566 ERROR [ERROR]: !=== Caught a fatal exception: ===!
2018-03-30 19:19:24,566 ERROR [ERROR]: Exception: 
[WinError 10054] An existing connection was forcibly closed by the remote host
  File "C:\Users\Ian\Documents\GitHub\Terra\terra\managers\networkmanager.py", line 77, in connect_to_host
    self.network_step(blocking=True)

  File "C:\Users\Ian\Documents\GitHub\Terra\terra\managers\networkmanager.py", line 228, in network_step
    raise err

  File "C:\Users\Ian\Documents\GitHub\Terra\terra\managers\networkmanager.py", line 219, in network_step
    message, address = f.recvfrom(2048)

2018-03-30 19:19:24,579 ERROR [ERROR]: Caught exception in the launcher.
2018-03-30 19:19:24,580 ERROR [ERROR]: !=== Caught a fatal exception: ===!
2018-03-30 19:19:24,580 ERROR [ERROR]: Exception: 
<Team.NONE: '[NON]'>
  File "C:/Users/Ian/Documents/GitHub/Terra/launcher.py", line 9, in <module>
    Main().run()

  File "C:\Users\Ian\Documents\GitHub\Terra\terra\main.py", line 188, in run
    self.step(event)

  File "C:\Users\Ian\Documents\GitHub\Terra\terra\main.py", line 138, in step
    self.current_screen.step(event)

  File "C:\Users\Ian\Documents\GitHub\Terra\terra\screens\battle.py", line 56, in step
    Managers.step(event)

  File "C:\Users\Ian\Documents\GitHub\Terra\terra\managers\managers.py", line 198, in step
    Managers.player_manager.step(event)

  File "C:\Users\Ian\Documents\GitHub\Terra\terra\managers\playermanager.py", line 48, in step
    self.cursors[self.active_team].step(event)

